id,cluster_name,namespace,event_type,reason,message,involved_object_kind,involved_object_name,source_component,first_timestamp,last_timestamp,count,collected_at
1,prod-use2-eks,ledger,Warning,Unhealthy,Readiness probe failed: timeout for ledger-svc-f4a6d64-16dde,Pod,ledger-svc-f4a6d64-16dde,kubelet,2026-06-22 21:56:39,2026-06-22 23:45:39,6,2026-06-23 12:00:00
2,prod-usw2-eks,ledger,Warning,Evicted,Pod ledger-svc-2014124-29b88 evicted: node was low on resource ephemeral-storage,Pod,ledger-svc-2014124-29b88,default-scheduler,2026-06-20 05:19:36,2026-06-20 05:56:36,33,2026-06-23 12:00:00
3,staging-use2-eks,identity,Normal,Scheduled,Successfully assigned auth-gateway-41b4f33-14ef9 to ip-10-14-70-252,Pod,auth-gateway-41b4f33-14ef9,controllermanager,2026-05-27 20:39:01,2026-05-27 21:05:01,1,2026-06-23 12:00:00
4,prod-use2-eks,payments,Warning,OOMKilling,Container payments-api exceeded memory limit; OOMKilled,Pod,payments-api-c9c2b74-00142,controllermanager,2026-06-22 18:00:45,2026-06-22 18:47:45,17,2026-06-23 12:00:00
5,dr-use1-eks,checkout,Warning,Evicted,Pod checkout-web-4263246-52f3a evicted: node memory pressure,Pod,checkout-web-4263246-52f3a,default-scheduler,2026-06-18 19:50:31,2026-06-18 21:28:31,34,2026-06-23 12:00:00
6,prod-use2-eks,orders,Warning,Evicted,Pod orders-api-bfb2f93-32ad3 evicted: node memory pressure,Pod,orders-api-bfb2f93-32ad3,default-scheduler,2026-06-14 06:05:14,2026-06-14 07:35:14,10,2026-06-23 12:00:00
7,prod-usw2-eks,orders,Warning,BackOff,Back-off restarting failed container orders-api in pod orders-api-cbca488-26609,Pod,orders-api-cbca488-26609,controllermanager,2026-06-16 09:02:21,2026-06-16 09:28:21,25,2026-06-23 12:00:00
8,prod-use2-eks,payments,Warning,OOMKilling,Container payments-api exceeded memory limit; OOMKilled,Pod,payments-api-7fa4649-debd8,controllermanager,2026-06-23 03:38:49,2026-06-23 03:47:49,33,2026-06-23 12:00:00
9,staging-use2-eks,platform,Warning,Evicted,Pod config-svc-929cd33-16be4 evicted: node was low on resource ephemeral-storage,Pod,config-svc-929cd33-16be4,kubelet,2026-06-13 10:14:08,2026-06-13 10:38:08,29,2026-06-23 12:00:00
10,prod-usw2-eks,search,Warning,FreeDiskSpaceFailed,Failed to garbage collect on node ip-10-14-16-161,Pod,search-api-8352074-5b766,kubelet,2026-06-21 22:58:05,2026-06-21 23:52:05,14,2026-06-23 12:00:00
11,prod-usw2-eks,orders,Warning,Evicted,Pod orders-worker-b907131-2627d evicted: node was low on resource ephemeral-storage,Pod,orders-worker-b907131-2627d,controllermanager,2026-06-17 14:35:12,2026-06-17 15:10:12,39,2026-06-23 12:00:00
12,prod-usw2-eks,search,Warning,FreeDiskSpaceFailed,Failed to garbage collect on node ip-10-14-16-161,Pod,search-api-a47d446-4ffe2,kubelet,2026-06-16 20:52:48,2026-06-16 22:42:48,39,2026-06-23 12:00:00
13,staging-use2-eks,search,Warning,Unhealthy,Readiness probe errored: dial tcp i/o timeout for search-api-1605640-8abaf,Pod,search-api-1605640-8abaf,kubelet,2026-06-22 04:15:59,2026-06-22 04:18:59,30,2026-06-23 12:00:00
14,prod-usw2-eks,kube-system,Warning,DNSConfigForming,Search line limits exceeded for coredns-37f1521-4cd3d,Pod,coredns-37f1521-4cd3d,kubelet,2026-06-20 09:31:56,2026-06-20 10:45:56,1,2026-06-23 12:00:00
15,dr-use1-eks,search,Warning,Evicted,Pod search-api-d416b43-7cb20 evicted: node was low on resource ephemeral-storage,Pod,search-api-d416b43-7cb20,controllermanager,2026-06-04 14:45:43,2026-06-04 15:38:43,4,2026-06-23 12:00:00
16,prod-use2-eks,search,Normal,Scheduled,Successfully assigned indexer-4680271-0a829 to ip-10-17-79-110,Pod,indexer-4680271-0a829,kubelet,2026-06-02 10:44:09,2026-06-02 12:26:09,1,2026-06-23 12:00:00
17,prod-use2-eks,kube-system,Warning,FreeDiskSpaceFailed,Failed to garbage collect on node ip-10-6-44-216,Pod,coredns-47d4438-c55d7,controllermanager,2026-06-10 13:36:13,2026-06-10 14:43:13,35,2026-06-23 12:00:00
18,prod-usw2-eks,inventory,Warning,Unhealthy,Liveness probe failed: HTTP 500 for inventory-svc-bf8f159-02345,Pod,inventory-svc-bf8f159-02345,default-scheduler,2026-06-01 17:21:09,2026-06-01 18:37:09,30,2026-06-23 12:00:00
19,staging-use2-eks,checkout,Warning,Rebooted,Node ip-10-8-126-134 has been rebooted,Pod,checkout-web-2b77739-52fdd,default-scheduler,2026-06-22 18:26:41,2026-06-22 20:22:41,34,2026-06-23 12:00:00
20,prod-usw2-eks,ledger,Warning,Evicted,Pod ledger-svc-2014124-29b88 evicted: node was low on resource ephemeral-storage,Pod,ledger-svc-2014124-29b88,default-scheduler,2026-06-20 19:14:44,2026-06-20 20:49:44,36,2026-06-23 12:00:00
21,prod-use2-eks,search,Normal,Scheduled,Successfully assigned recommendation-c460126-52814 to ip-10-37-142-3,Pod,recommendation-c460126-52814,kubelet,2026-05-30 20:19:57,2026-05-30 22:13:57,1,2026-06-23 12:00:00
22,prod-usw2-eks,payments,Warning,OOMKilling,Container payments-api exceeded memory limit; OOMKilled,Pod,payments-api-423b015-b80bd,controllermanager,2026-06-22 12:37:54,2026-06-22 14:27:54,20,2026-06-23 12:00:00
23,prod-usw2-eks,kube-system,Warning,Unhealthy,Readiness probe errored: dial tcp i/o timeout for coredns-37f1521-4cd3d,Pod,coredns-37f1521-4cd3d,controllermanager,2026-06-19 18:46:27,2026-06-19 20:42:27,35,2026-06-23 12:00:00
24,prod-usw2-eks,search,Normal,Pulled,Container image pulled for recommendation,Pod,recommendation-1e52697-e4756,controllermanager,2026-05-30 08:43:31,2026-05-30 10:30:31,1,2026-06-23 12:00:00
25,prod-use2-eks,checkout,Warning,BackOff,Back-off restarting failed container checkout-web in pod checkout-web-0101b48-2b2af,Pod,checkout-web-0101b48-2b2af,default-scheduler,2026-06-12 02:13:56,2026-06-12 03:41:56,3,2026-06-23 12:00:00
26,prod-use2-eks,checkout,Warning,Evicted,Pod cart-svc-26a7d77-aafdc evicted: node memory pressure,Pod,cart-svc-26a7d77-aafdc,default-scheduler,2026-06-16 11:43:27,2026-06-16 12:36:27,20,2026-06-23 12:00:00
27,prod-use2-eks,ledger,Normal,Throttling,CPU throttled for container ledger-svc,Pod,ledger-svc-f4a6d64-16dde,controllermanager,2026-06-21 18:29:55,2026-06-21 19:03:55,1,2026-06-23 12:00:00
28,prod-use2-eks,checkout,Normal,Pulled,Container image pulled for checkout-web,Pod,checkout-web-47df111-4e24c,kubelet,2026-06-17 19:34:19,2026-06-17 19:38:19,1,2026-06-23 12:00:00
29,prod-use2-eks,orders,Warning,Evicted,Pod orders-api-e9b4a39-c3784 evicted: node memory pressure,Pod,orders-api-e9b4a39-c3784,controllermanager,2026-06-12 04:58:59,2026-06-12 05:54:59,11,2026-06-23 12:00:00
30,prod-use2-eks,payments,Warning,OOMKilling,Container payments-api exceeded memory limit; OOMKilled,Pod,payments-api-1ce3577-591ac,default-scheduler,2026-06-22 17:42:32,2026-06-22 17:42:32,33,2026-06-23 12:00:00
31,prod-use2-eks,identity,Warning,Evicted,Pod session-store-1ac5266-1ca26 evicted: node memory pressure,Pod,session-store-1ac5266-1ca26,default-scheduler,2026-06-12 04:11:48,2026-06-12 05:07:48,6,2026-06-23 12:00:00
32,prod-use2-eks,identity,Normal,Started,Started container auth-gateway,Pod,auth-gateway-7b28269-a7447,kubelet,2026-06-02 20:21:22,2026-06-02 21:50:22,1,2026-06-23 12:00:00
33,prod-use2-eks,orders,Warning,OOMKilling,Container orders-api exceeded memory limit; OOMKilled,Pod,orders-api-7f89525-97cdd,kubelet,2026-06-13 13:57:14,2026-06-13 14:10:14,25,2026-06-23 12:00:00
34,dr-use1-eks,search,Warning,Evicted,Pod search-api-d416b43-7cb20 evicted: node was low on resource ephemeral-storage,Pod,search-api-d416b43-7cb20,kubelet,2026-06-19 20:23:57,2026-06-19 20:34:57,25,2026-06-23 12:00:00
35,prod-use2-eks,checkout,Warning,OOMKilling,Memory cgroup out of memory: Killed process in checkout-web-c2eb578-2d181,Pod,checkout-web-c2eb578-2d181,default-scheduler,2026-06-17 08:55:23,2026-06-17 09:38:23,2,2026-06-23 12:00:00
36,prod-usw2-eks,checkout,Normal,Pulled,Container image pulled for checkout-web,Pod,checkout-web-2e5d994-d724e,default-scheduler,2026-06-04 20:56:25,2026-06-04 22:52:25,1,2026-06-23 12:00:00
37,prod-usw2-eks,platform,Normal,Pulled,Container image pulled for config-svc,Pod,config-svc-370d832-a686a,kubelet,2026-06-08 12:33:31,2026-06-08 13:21:31,1,2026-06-23 12:00:00
38,prod-use2-eks,ledger,Warning,Unhealthy,Readiness probe failed: timeout for ledger-svc-204e643-7d23b,Pod,ledger-svc-204e643-7d23b,default-scheduler,2026-06-20 04:45:21,2026-06-20 06:28:21,6,2026-06-23 12:00:00
39,prod-use2-eks,ledger,Normal,Throttling,CPU throttled for container ledger-svc,Pod,ledger-svc-204e643-7d23b,default-scheduler,2026-06-21 01:40:39,2026-06-21 02:15:39,1,2026-06-23 12:00:00
40,staging-use2-eks,platform,Warning,FreeDiskSpaceFailed,Failed to garbage collect on node ip-10-8-126-134,Pod,config-svc-929cd33-16be4,kubelet,2026-06-18 17:03:53,2026-06-18 17:04:53,28,2026-06-23 12:00:00
41,prod-use2-eks,payments,Warning,OOMKilling,Container payments-api exceeded memory limit; OOMKilled,Pod,payments-api-58c5e74-26d34,controllermanager,2026-06-22 13:34:10,2026-06-22 13:51:10,27,2026-06-23 12:00:00
42,staging-use2-eks,search,Normal,Scheduled,Successfully assigned search-api-8ca0b98-505ff to ip-10-20-108-255,Pod,search-api-8ca0b98-505ff,controllermanager,2026-06-23 10:13:57,2026-06-23 11:01:57,1,2026-06-23 12:00:00
43,prod-usw2-eks,orders,Warning,OOMKilling,Memory cgroup out of memory: Killed process in orders-api-21c5d48-15186,Pod,orders-api-21c5d48-15186,controllermanager,2026-06-20 14:51:14,2026-06-20 16:40:14,7,2026-06-23 12:00:00
44,staging-use2-eks,search,Warning,DNSConfigForming,Search line limits exceeded for search-api-1605640-8abaf,Pod,search-api-1605640-8abaf,default-scheduler,2026-06-23 01:35:54,2026-06-23 03:17:54,14,2026-06-23 12:00:00
45,prod-usw2-eks,identity,Warning,FreeDiskSpaceFailed,Failed to garbage collect on node ip-10-12-35-23,Pod,session-store-d825e25-14f9f,controllermanager,2026-06-14 09:41:27,2026-06-14 10:22:27,4,2026-06-23 12:00:00
46,prod-usw2-eks,checkout,Warning,FreeDiskSpaceFailed,Failed to garbage collect on node ip-10-6-194-142,Pod,cart-svc-ee38458-64d46,kubelet,2026-06-01 00:51:51,2026-06-01 01:24:51,38,2026-06-23 12:00:00
47,prod-usw2-eks,platform,Normal,Started,Started container image-resizer,Pod,image-resizer-9683178-b7560,default-scheduler,2026-06-10 16:58:56,2026-06-10 18:25:56,1,2026-06-23 12:00:00
48,prod-use2-eks,kube-system,Warning,Unhealthy,Readiness probe errored: dial tcp i/o timeout for metrics-server-e2e6924-29c37,Pod,metrics-server-e2e6924-29c37,kubelet,2026-06-14 21:57:15,2026-06-14 22:49:15,5,2026-06-23 12:00:00
49,staging-use2-eks,inventory,Warning,Evicted,Pod inventory-svc-1d6f570-1b50d evicted: node memory pressure,Pod,inventory-svc-1d6f570-1b50d,kubelet,2026-06-22 02:56:19,2026-06-22 03:31:19,2,2026-06-23 12:00:00
50,prod-usw2-eks,checkout,Warning,FreeDiskSpaceFailed,Failed to garbage collect on node ip-10-6-194-142,Pod,cart-svc-ee38458-64d46,controllermanager,2026-06-13 10:39:39,2026-06-13 11:39:39,13,2026-06-23 12:00:00
51,prod-use2-eks,payments,Warning,OOMKilling,Container payments-api exceeded memory limit; OOMKilled,Pod,payments-api-1ce3577-591ac,default-scheduler,2026-06-23 04:21:41,2026-06-23 06:19:41,12,2026-06-23 12:00:00
52,prod-usw2-eks,ledger,Warning,FreeDiskSpaceFailed,Failed to garbage collect on node ip-10-6-194-142,Pod,ledger-svc-0744083-43011,default-scheduler,2026-06-22 10:29:34,2026-06-22 12:12:34,8,2026-06-23 12:00:00
53,dr-use1-eks,checkout,Normal,Pulled,Container image pulled for cart-svc,Pod,cart-svc-da3cf51-00806,controllermanager,2026-06-01 03:39:35,2026-06-01 05:14:35,1,2026-06-23 12:00:00
54,prod-usw2-eks,search,Normal,Pulled,Container image pulled for indexer,Pod,indexer-b957537-8aa20,kubelet,2026-06-02 07:27:08,2026-06-02 09:01:08,1,2026-06-23 12:00:00
55,prod-usw2-eks,orders,Warning,Unhealthy,Liveness probe failed: HTTP 500 for orders-api-21c5d48-15186,Pod,orders-api-21c5d48-15186,default-scheduler,2026-06-20 17:19:20,2026-06-20 17:35:20,23,2026-06-23 12:00:00
56,prod-use2-eks,checkout,Warning,Unhealthy,Liveness probe failed: HTTP 500 for checkout-web-c2eb578-2d181,Pod,checkout-web-c2eb578-2d181,kubelet,2026-05-30 07:41:55,2026-05-30 08:34:55,1,2026-06-23 12:00:00
57,prod-usw2-eks,kube-system,Warning,Unhealthy,Readiness probe errored: dial tcp i/o timeout for coredns-37f1521-4cd3d,Pod,coredns-37f1521-4cd3d,kubelet,2026-06-21 05:06:47,2026-06-21 05:40:47,29,2026-06-23 12:00:00
58,prod-usw2-eks,inventory,Warning,Unhealthy,Liveness probe failed: HTTP 500 for inventory-svc-bf8f159-02345,Pod,inventory-svc-bf8f159-02345,controllermanager,2026-06-17 19:16:23,2026-06-17 19:39:23,21,2026-06-23 12:00:00
59,prod-usw2-eks,ledger,Warning,Evicted,Pod ledger-svc-842cd31-95bfa evicted: node was low on resource ephemeral-storage,Pod,ledger-svc-842cd31-95bfa,controllermanager,2026-06-21 22:05:27,2026-06-21 22:34:27,14,2026-06-23 12:00:00
60,prod-usw2-eks,payments,Warning,OOMKilling,Memory cgroup out of memory: Killed process in payments-worker-1d1bf52-dff66,Pod,payments-worker-1d1bf52-dff66,controllermanager,2026-06-21 03:22:05,2026-06-21 04:24:05,33,2026-06-23 12:00:00
61,prod-usw2-eks,ledger,Warning,Evicted,Pod ledger-svc-842cd31-95bfa evicted: node was low on resource ephemeral-storage,Pod,ledger-svc-842cd31-95bfa,kubelet,2026-06-15 08:46:27,2026-06-15 09:45:27,29,2026-06-23 12:00:00
62,dr-use1-eks,checkout,Warning,OOMKilling,Container checkout-web exceeded memory limit; OOMKilled,Pod,checkout-web-6e9e217-a5c79,default-scheduler,2026-06-19 01:46:26,2026-06-19 03:07:26,40,2026-06-23 12:00:00
63,prod-usw2-eks,payments,Warning,OOMKilling,Memory cgroup out of memory: Killed process in payments-worker-bbc0947-0aa1a,Pod,payments-worker-bbc0947-0aa1a,kubelet,2026-06-22 06:00:18,2026-06-22 07:49:18,16,2026-06-23 12:00:00
64,staging-use2-eks,search,Normal,Started,Started container search-api,Pod,search-api-8ca0b98-505ff,default-scheduler,2026-06-22 07:39:25,2026-06-22 07:50:25,1,2026-06-23 12:00:00
65,staging-use2-eks,platform,Warning,FreeDiskSpaceFailed,Failed to garbage collect on node ip-10-8-126-134,Pod,config-svc-929cd33-16be4,default-scheduler,2026-06-11 08:10:51,2026-06-11 09:41:51,16,2026-06-23 12:00:00
66,prod-use2-eks,search,Normal,Started,Started container search-api,Pod,search-api-61d1d17-0014f,kubelet,2026-05-30 13:26:06,2026-05-30 14:27:06,1,2026-06-23 12:00:00
67,prod-usw2-eks,search,Warning,FreeDiskSpaceFailed,Failed to garbage collect on node ip-10-14-16-161,Pod,search-api-8352074-5b766,controllermanager,2026-06-20 08:13:27,2026-06-20 09:15:27,26,2026-06-23 12:00:00
68,prod-usw2-eks,identity,Warning,Evicted,Pod session-store-28ebc77-cf7c8 evicted: node was low on resource ephemeral-storage,Pod,session-store-28ebc77-cf7c8,kubelet,2026-06-14 10:36:02,2026-06-14 11:29:02,4,2026-06-23 12:00:00
69,prod-usw2-eks,payments,Warning,Evicted,Pod payments-api-1e23165-1e35b evicted: node memory pressure,Pod,payments-api-1e23165-1e35b,kubelet,2026-06-13 17:27:04,2026-06-13 19:12:04,31,2026-06-23 12:00:00
70,prod-usw2-eks,identity,Warning,Evicted,Pod session-store-d825e25-14f9f evicted: node was low on resource ephemeral-storage,Pod,session-store-d825e25-14f9f,controllermanager,2026-06-20 09:37:42,2026-06-20 11:27:42,5,2026-06-23 12:00:00
71,prod-usw2-eks,orders,Warning,BackOff,Back-off restarting failed container orders-api in pod orders-api-cbca488-26609,Pod,orders-api-cbca488-26609,controllermanager,2026-06-20 12:14:07,2026-06-20 12:49:07,34,2026-06-23 12:00:00
72,prod-usw2-eks,platform,Normal,Scheduled,Successfully assigned image-resizer-6542c92-1100b to ip-10-15-83-236,Pod,image-resizer-6542c92-1100b,controllermanager,2026-06-08 03:06:06,2026-06-08 03:21:06,1,2026-06-23 12:00:00
73,prod-usw2-eks,payments,Warning,BackOff,Back-off restarting failed container payments-worker in pod payments-worker-1d1bf52-dff66,Pod,payments-worker-1d1bf52-dff66,default-scheduler,2026-05-30 10:10:27,2026-05-30 10:42:27,26,2026-06-23 12:00:00
74,prod-usw2-eks,checkout,Warning,Evicted,Pod cart-svc-0a94879-c1bba evicted: node was low on resource ephemeral-storage,Pod,cart-svc-0a94879-c1bba,controllermanager,2026-06-22 18:16:44,2026-06-22 18:46:44,38,2026-06-23 12:00:00
75,prod-usw2-eks,search,Normal,Pulled,Container image pulled for indexer,Pod,indexer-b957537-8aa20,default-scheduler,2026-06-04 09:32:00,2026-06-04 09:54:00,1,2026-06-23 12:00:00
76,prod-use2-eks,platform,Warning,DNSConfigForming,Search line limits exceeded for image-resizer-9994630-7c707,Pod,image-resizer-9994630-7c707,controllermanager,2026-06-20 18:32:19,2026-06-20 20:21:19,34,2026-06-23 12:00:00
77,prod-use2-eks,kube-system,Warning,Evicted,Pod coredns-47d4438-c55d7 evicted: node was low on resource ephemeral-storage,Pod,coredns-47d4438-c55d7,default-scheduler,2026-06-09 14:46:45,2026-06-09 15:57:45,31,2026-06-23 12:00:00
78,dr-use1-eks,notifications,Warning,Unhealthy,Liveness probe failed: HTTP 500 for notifications-b036879-82982,Pod,notifications-b036879-82982,kubelet,2026-06-22 13:42:56,2026-06-22 14:42:56,1,2026-06-23 12:00:00
79,dr-use1-eks,orders,Warning,Unhealthy,Readiness probe errored: dial tcp i/o timeout for orders-api-8330e48-f22f4,Pod,orders-api-8330e48-f22f4,kubelet,2026-06-17 02:08:56,2026-06-17 02:30:56,22,2026-06-23 12:00:00
80,prod-use2-eks,orders,Normal,Scheduled,Successfully assigned orders-worker-06e2683-7270e to ip-10-17-79-110,Pod,orders-worker-06e2683-7270e,controllermanager,2026-05-27 02:18:47,2026-05-27 03:51:47,1,2026-06-23 12:00:00
81,staging-use2-eks,checkout,Warning,NodeNotReady,Node ip-10-8-126-134 status is now: NodeNotReady,Pod,checkout-web-2b77739-52fdd,kubelet,2026-06-23 02:18:07,2026-06-23 03:09:07,11,2026-06-23 12:00:00
82,dr-use1-eks,notifications,Warning,Unhealthy,Liveness probe failed: HTTP 500 for notifications-b036879-82982,Pod,notifications-b036879-82982,controllermanager,2026-06-21 18:29:26,2026-06-21 19:20:26,27,2026-06-23 12:00:00
83,prod-use2-eks,payments,Warning,OOMKilling,Container payments-api exceeded memory limit; OOMKilled,Pod,payments-api-c9c2b74-00142,controllermanager,2026-06-23 00:39:21,2026-06-23 02:26:21,24,2026-06-23 12:00:00
84,prod-use2-eks,inventory,Normal,Started,Started container inventory-svc,Pod,inventory-svc-df6d343-0a45b,default-scheduler,2026-06-12 21:32:34,2026-06-12 22:30:34,1,2026-06-23 12:00:00
85,prod-use2-eks,ledger,Normal,Pulled,Container image pulled for ledger-svc,Pod,ledger-svc-1232e29-49ea1,controllermanager,2026-06-21 21:39:20,2026-06-21 22:46:20,1,2026-06-23 12:00:00
86,prod-use2-eks,identity,Normal,Started,Started container auth-gateway,Pod,auth-gateway-bf1d422-2018d,kubelet,2026-05-24 12:50:16,2026-05-24 13:14:16,1,2026-06-23 12:00:00
87,prod-usw2-eks,kube-system,Warning,DNSConfigForming,Search line limits exceeded for coredns-37f1521-4cd3d,Pod,coredns-37f1521-4cd3d,kubelet,2026-06-17 01:24:49,2026-06-17 02:21:49,38,2026-06-23 12:00:00
88,prod-use2-eks,checkout,Warning,OOMKilling,Memory cgroup out of memory: Killed process in checkout-web-c343d41-6a8d2,Pod,checkout-web-c343d41-6a8d2,controllermanager,2026-06-11 19:23:18,2026-06-11 20:43:18,4,2026-06-23 12:00:00
89,prod-usw2-eks,kube-system,Warning,DNSConfigForming,Search line limits exceeded for coredns-4a8b365-1d9fc,Pod,coredns-4a8b365-1d9fc,controllermanager,2026-06-22 23:21:51,2026-06-22 23:49:51,28,2026-06-23 12:00:00
90,prod-usw2-eks,identity,Normal,Started,Started container auth-gateway,Pod,auth-gateway-fb1c283-81cc8,controllermanager,2026-05-25 13:17:18,2026-05-25 13:47:18,1,2026-06-23 12:00:00
91,prod-use2-eks,checkout,Warning,OOMKilling,Container cart-svc exceeded memory limit; OOMKilled,Pod,cart-svc-527eb80-045c0,default-scheduler,2026-06-19 21:18:21,2026-06-19 22:50:21,28,2026-06-23 12:00:00
92,prod-usw2-eks,orders,Warning,OOMKilling,Memory cgroup out of memory: Killed process in orders-api-cbca488-26609,Pod,orders-api-cbca488-26609,controllermanager,2026-06-22 21:23:29,2026-06-22 22:15:29,12,2026-06-23 12:00:00
93,staging-use2-eks,platform,Warning,FreeDiskSpaceFailed,Failed to garbage collect on node ip-10-8-126-134,Pod,config-svc-929cd33-16be4,default-scheduler,2026-06-20 12:48:53,2026-06-20 13:38:53,18,2026-06-23 12:00:00
94,prod-use2-eks,identity,Warning,Evicted,Pod session-store-1ac5266-1ca26 evicted: node memory pressure,Pod,session-store-1ac5266-1ca26,controllermanager,2026-06-15 11:27:45,2026-06-15 12:02:45,24,2026-06-23 12:00:00
95,prod-usw2-eks,inventory,Normal,Started,Started container inventory-svc,Pod,inventory-svc-4453f63-e15f3,kubelet,2026-06-01 10:27:16,2026-06-01 11:24:16,1,2026-06-23 12:00:00
96,prod-use2-eks,ledger,Normal,Throttling,CPU throttled for container ledger-svc,Pod,ledger-svc-f4a6d64-16dde,default-scheduler,2026-06-20 01:04:47,2026-06-20 01:04:47,1,2026-06-23 12:00:00
97,staging-use2-eks,identity,Warning,Unhealthy,Readiness probe errored: dial tcp i/o timeout for session-store-a097c68-649a1,Pod,session-store-a097c68-649a1,kubelet,2026-06-08 07:51:32,2026-06-08 09:27:32,22,2026-06-23 12:00:00
98,prod-use2-eks,search,Normal,Pulled,Container image pulled for indexer,Pod,indexer-4680271-0a829,default-scheduler,2026-06-22 17:58:38,2026-06-22 19:16:38,1,2026-06-23 12:00:00
99,prod-use2-eks,checkout,Warning,OOMKilling,Container cart-svc exceeded memory limit; OOMKilled,Pod,cart-svc-527eb80-045c0,controllermanager,2026-06-14 20:43:22,2026-06-14 22:38:22,25,2026-06-23 12:00:00
100,prod-use2-eks,search,Normal,Pulled,Container image pulled for search-api,Pod,search-api-4350294-dbefb,kubelet,2026-06-22 01:45:42,2026-06-22 02:15:42,1,2026-06-23 12:00:00
101,dr-use1-eks,ledger,Normal,Started,Started container ledger-svc,Pod,ledger-svc-e00a046-6e2d6,default-scheduler,2026-06-16 06:26:03,2026-06-16 08:02:03,1,2026-06-23 12:00:00
102,prod-use2-eks,ledger,Warning,Unhealthy,Readiness probe failed: timeout for ledger-svc-204e643-7d23b,Pod,ledger-svc-204e643-7d23b,default-scheduler,2026-06-21 17:36:33,2026-06-21 17:47:33,15,2026-06-23 12:00:00
103,prod-use2-eks,kube-system,Warning,Evicted,Pod coredns-47d4438-c55d7 evicted: node was low on resource ephemeral-storage,Pod,coredns-47d4438-c55d7,default-scheduler,2026-06-17 01:07:04,2026-06-17 01:58:04,18,2026-06-23 12:00:00
104,prod-use2-eks,kube-system,Warning,Unhealthy,Readiness probe errored: dial tcp i/o timeout for metrics-server-e2e6924-29c37,Pod,metrics-server-e2e6924-29c37,kubelet,2026-06-07 01:02:33,2026-06-07 02:03:33,36,2026-06-23 12:00:00
105,prod-usw2-eks,search,Warning,Evicted,Pod search-api-8352074-5b766 evicted: node was low on resource ephemeral-storage,Pod,search-api-8352074-5b766,kubelet,2026-06-13 04:21:10,2026-06-13 05:12:10,23,2026-06-23 12:00:00
106,staging-use2-eks,search,Warning,DNSConfigForming,Search line limits exceeded for search-api-1605640-8abaf,Pod,search-api-1605640-8abaf,kubelet,2026-06-22 19:46:59,2026-06-22 20:03:59,14,2026-06-23 12:00:00
107,prod-use2-eks,checkout,Warning,OOMKilling,Container cart-svc exceeded memory limit; OOMKilled,Pod,cart-svc-527eb80-045c0,kubelet,2026-06-23 10:07:25,2026-06-23 11:15:25,9,2026-06-23 12:00:00
108,prod-usw2-eks,ledger,Warning,FreeDiskSpaceFailed,Failed to garbage collect on node ip-10-14-16-161,Pod,ledger-svc-2014124-29b88,kubelet,2026-06-16 06:41:34,2026-06-16 07:40:34,34,2026-06-23 12:00:00
109,staging-use2-eks,notifications,Normal,Scheduled,Successfully assigned notifications-26e9347-44fc8 to ip-10-20-108-255,Pod,notifications-26e9347-44fc8,kubelet,2026-06-08 10:03:02,2026-06-08 10:26:02,1,2026-06-23 12:00:00
110,prod-usw2-eks,inventory,Warning,BackOff,Back-off restarting failed container inventory-svc in pod inventory-svc-bf8f159-02345,Pod,inventory-svc-bf8f159-02345,kubelet,2026-05-30 21:47:15,2026-05-30 23:18:15,15,2026-06-23 12:00:00
111,staging-use2-eks,search,Warning,Unhealthy,Readiness probe errored: dial tcp i/o timeout for search-api-1605640-8abaf,Pod,search-api-1605640-8abaf,default-scheduler,2026-06-21 19:41:23,2026-06-21 19:59:23,38,2026-06-23 12:00:00
112,prod-use2-eks,ledger,Warning,Unhealthy,Readiness probe failed: timeout for ledger-svc-204e643-7d23b,Pod,ledger-svc-204e643-7d23b,kubelet,2026-06-18 05:57:05,2026-06-18 06:31:05,29,2026-06-23 12:00:00
113,prod-use2-eks,checkout,Normal,Scheduled,Successfully assigned checkout-web-47df111-4e24c to ip-10-40-57-12,Pod,checkout-web-47df111-4e24c,controllermanager,2026-06-15 18:29:24,2026-06-15 19:49:24,1,2026-06-23 12:00:00
114,staging-use2-eks,identity,Warning,Unhealthy,Readiness probe errored: dial tcp i/o timeout for session-store-a097c68-649a1,Pod,session-store-a097c68-649a1,default-scheduler,2026-06-14 17:13:43,2026-06-14 18:34:43,24,2026-06-23 12:00:00
115,prod-use2-eks,orders,Warning,OOMKilling,Container orders-api exceeded memory limit; OOMKilled,Pod,orders-api-7f89525-97cdd,controllermanager,2026-06-12 16:00:20,2026-06-12 17:20:20,32,2026-06-23 12:00:00
116,prod-use2-eks,ledger,Normal,Throttling,CPU throttled for container ledger-svc,Pod,ledger-svc-f4a6d64-16dde,kubelet,2026-06-18 08:16:54,2026-06-18 09:31:54,1,2026-06-23 12:00:00
117,prod-usw2-eks,ledger,Warning,FreeDiskSpaceFailed,Failed to garbage collect on node ip-10-6-194-142,Pod,ledger-svc-0744083-43011,default-scheduler,2026-06-21 09:01:33,2026-06-21 09:54:33,8,2026-06-23 12:00:00
118,prod-usw2-eks,payments,Warning,OOMKilling,Container payments-api exceeded memory limit; OOMKilled,Pod,payments-api-1e23165-1e35b,default-scheduler,2026-06-20 15:14:22,2026-06-20 16:01:22,25,2026-06-23 12:00:00
119,prod-use2-eks,kube-system,Warning,FreeDiskSpaceFailed,Failed to garbage collect on node ip-10-32-13-101,Pod,coredns-e513a45-fb7bf,kubelet,2026-06-10 17:41:14,2026-06-10 18:28:14,10,2026-06-23 12:00:00
120,prod-usw2-eks,ledger,Warning,Evicted,Pod ledger-svc-2014124-29b88 evicted: node was low on resource ephemeral-storage,Pod,ledger-svc-2014124-29b88,default-scheduler,2026-06-18 21:24:39,2026-06-18 22:01:39,11,2026-06-23 12:00:00
121,prod-use2-eks,inventory,Normal,Started,Started container inventory-svc,Pod,inventory-svc-3e28589-98330,default-scheduler,2026-05-28 20:44:17,2026-05-28 21:09:17,1,2026-06-23 12:00:00
122,dr-use1-eks,checkout,Warning,Evicted,Pod checkout-web-4263246-52f3a evicted: node memory pressure,Pod,checkout-web-4263246-52f3a,controllermanager,2026-06-21 01:59:17,2026-06-21 02:25:17,24,2026-06-23 12:00:00
123,dr-use1-eks,platform,Normal,Scheduled,Successfully assigned config-svc-0f5b883-4b9e2 to ip-10-21-57-150,Pod,config-svc-0f5b883-4b9e2,controllermanager,2026-06-09 06:50:40,2026-06-09 07:17:40,1,2026-06-23 12:00:00
124,prod-usw2-eks,search,Warning,Evicted,Pod search-api-8352074-5b766 evicted: node was low on resource ephemeral-storage,Pod,search-api-8352074-5b766,controllermanager,2026-06-14 22:21:03,2026-06-15 00:17:03,30,2026-06-23 12:00:00
125,dr-use1-eks,search,Warning,Evicted,Pod search-api-d416b43-7cb20 evicted: node was low on resource ephemeral-storage,Pod,search-api-d416b43-7cb20,controllermanager,2026-06-15 02:42:19,2026-06-15 03:29:19,6,2026-06-23 12:00:00
126,prod-use2-eks,search,Normal,Scheduled,Successfully assigned search-api-4350294-dbefb to ip-10-17-79-110,Pod,search-api-4350294-dbefb,default-scheduler,2026-06-11 07:34:52,2026-06-11 09:10:52,1,2026-06-23 12:00:00
127,prod-usw2-eks,ledger,Warning,FreeDiskSpaceFailed,Failed to garbage collect on node ip-10-6-194-142,Pod,ledger-svc-842cd31-95bfa,kubelet,2026-06-23 04:34:06,2026-06-23 06:01:06,24,2026-06-23 12:00:00
128,prod-use2-eks,payments,Warning,OOMKilling,Container payments-api exceeded memory limit; OOMKilled,Pod,payments-api-c9c2b74-00142,default-scheduler,2026-06-22 19:28:33,2026-06-22 20:23:33,26,2026-06-23 12:00:00
129,prod-usw2-eks,kube-system,Warning,DNSConfigForming,Search line limits exceeded for coredns-37f1521-4cd3d,Pod,coredns-37f1521-4cd3d,default-scheduler,2026-06-21 03:28:46,2026-06-21 04:50:46,3,2026-06-23 12:00:00
130,prod-use2-eks,platform,Warning,DNSConfigForming,Search line limits exceeded for image-resizer-9994630-7c707,Pod,image-resizer-9994630-7c707,default-scheduler,2026-06-21 11:33:35,2026-06-21 13:19:35,6,2026-06-23 12:00:00
131,prod-usw2-eks,ledger,Warning,FreeDiskSpaceFailed,Failed to garbage collect on node ip-10-6-194-142,Pod,ledger-svc-842cd31-95bfa,controllermanager,2026-06-17 00:41:04,2026-06-17 01:26:04,36,2026-06-23 12:00:00
132,prod-use2-eks,orders,Warning,OOMKilling,Container orders-api exceeded memory limit; OOMKilled,Pod,orders-api-7f89525-97cdd,kubelet,2026-06-10 11:37:21,2026-06-10 12:16:21,22,2026-06-23 12:00:00
133,prod-usw2-eks,orders,Warning,FreeDiskSpaceFailed,Failed to garbage collect on node ip-10-14-16-161,Pod,orders-worker-8482791-f2d9f,default-scheduler,2026-06-18 12:50:34,2026-06-18 13:35:34,7,2026-06-23 12:00:00
134,prod-usw2-eks,payments,Warning,OOMKilling,Container payments-api exceeded memory limit; OOMKilled,Pod,payments-api-b9a1287-dbbfe,default-scheduler,2026-06-21 00:13:31,2026-06-21 00:39:31,29,2026-06-23 12:00:00
135,prod-usw2-eks,payments,Warning,OOMKilling,Container payments-api exceeded memory limit; OOMKilled,Pod,payments-api-423b015-b80bd,controllermanager,2026-06-12 15:10:28,2026-06-12 15:53:28,17,2026-06-23 12:00:00
136,prod-use2-eks,platform,Warning,Unhealthy,Readiness probe errored: dial tcp i/o timeout for image-resizer-7bb3c89-50e74,Pod,image-resizer-7bb3c89-50e74,default-scheduler,2026-06-20 17:33:19,2026-06-20 18:14:19,37,2026-06-23 12:00:00
137,prod-use2-eks,platform,Warning,DNSConfigForming,Search line limits exceeded for image-resizer-7bb3c89-50e74,Pod,image-resizer-7bb3c89-50e74,kubelet,2026-06-21 06:57:51,2026-06-21 07:06:51,24,2026-06-23 12:00:00
138,prod-usw2-eks,orders,Warning,FreeDiskSpaceFailed,Failed to garbage collect on node ip-10-14-16-161,Pod,orders-worker-b907131-2627d,kubelet,2026-06-18 19:46:05,2026-06-18 21:20:05,4,2026-06-23 12:00:00
139,prod-use2-eks,payments,Warning,OOMKilling,Container payments-api exceeded memory limit; OOMKilled,Pod,payments-api-c9c2b74-00142,kubelet,2026-06-23 05:28:50,2026-06-23 06:16:50,30,2026-06-23 12:00:00
140,prod-use2-eks,checkout,Warning,OOMKilling,Container cart-svc exceeded memory limit; OOMKilled,Pod,cart-svc-527eb80-045c0,controllermanager,2026-06-16 08:14:23,2026-06-16 09:55:23,25,2026-06-23 12:00:00
141,prod-usw2-eks,kube-system,Warning,Unhealthy,Readiness probe errored: dial tcp i/o timeout for coredns-4a8b365-1d9fc,Pod,coredns-4a8b365-1d9fc,default-scheduler,2026-06-18 02:26:53,2026-06-18 04:23:53,14,2026-06-23 12:00:00
142,prod-use2-eks,ledger,Warning,Unhealthy,Readiness probe failed: timeout for ledger-svc-f4a6d64-16dde,Pod,ledger-svc-f4a6d64-16dde,default-scheduler,2026-06-20 20:22:15,2026-06-20 21:47:15,5,2026-06-23 12:00:00
143,staging-use2-eks,identity,Warning,Unhealthy,Readiness probe errored: dial tcp i/o timeout for session-store-a097c68-649a1,Pod,session-store-a097c68-649a1,controllermanager,2026-06-15 14:24:23,2026-06-15 14:25:23,3,2026-06-23 12:00:00
144,prod-usw2-eks,identity,Warning,FreeDiskSpaceFailed,Failed to garbage collect on node ip-10-12-35-23,Pod,session-store-d825e25-14f9f,controllermanager,2026-06-07 10:31:26,2026-06-07 11:27:26,2,2026-06-23 12:00:00
145,staging-use2-eks,platform,Warning,Evicted,Pod config-svc-929cd33-16be4 evicted: node was low on resource ephemeral-storage,Pod,config-svc-929cd33-16be4,default-scheduler,2026-06-14 20:48:33,2026-06-14 22:27:33,20,2026-06-23 12:00:00
146,dr-use1-eks,orders,Warning,Unhealthy,Readiness probe errored: dial tcp i/o timeout for orders-api-8330e48-f22f4,Pod,orders-api-8330e48-f22f4,default-scheduler,2026-06-17 15:31:32,2026-06-17 16:49:32,33,2026-06-23 12:00:00
147,dr-use1-eks,checkout,Warning,Evicted,Pod checkout-web-4263246-52f3a evicted: node memory pressure,Pod,checkout-web-4263246-52f3a,kubelet,2026-06-18 21:38:02,2026-06-18 23:18:02,28,2026-06-23 12:00:00
148,prod-usw2-eks,checkout,Warning,Evicted,Pod cart-svc-0a94879-c1bba evicted: node was low on resource ephemeral-storage,Pod,cart-svc-0a94879-c1bba,kubelet,2026-06-14 07:19:14,2026-06-14 09:16:14,32,2026-06-23 12:00:00
149,dr-use1-eks,search,Warning,FreeDiskSpaceFailed,Failed to garbage collect on node ip-10-40-81-216,Pod,search-api-d416b43-7cb20,kubelet,2026-06-14 02:12:34,2026-06-14 02:13:34,36,2026-06-23 12:00:00
150,prod-usw2-eks,kube-system,Warning,DNSConfigForming,Search line limits exceeded for coredns-37f1521-4cd3d,Pod,coredns-37f1521-4cd3d,default-scheduler,2026-06-22 07:03:45,2026-06-22 07:58:45,18,2026-06-23 12:00:00
151,staging-use2-eks,checkout,Warning,Rebooted,Node ip-10-8-126-134 has been rebooted,Pod,checkout-web-2b77739-52fdd,kubelet,2026-06-22 19:55:18,2026-06-22 21:23:18,32,2026-06-23 12:00:00
152,prod-use2-eks,checkout,Warning,Evicted,Pod cart-svc-527eb80-045c0 evicted: node memory pressure,Pod,cart-svc-527eb80-045c0,controllermanager,2026-06-20 22:38:15,2026-06-21 00:16:15,4,2026-06-23 12:00:00
153,dr-use1-eks,checkout,Warning,Evicted,Pod checkout-web-6e9e217-a5c79 evicted: node memory pressure,Pod,checkout-web-6e9e217-a5c79,kubelet,2026-06-19 02:25:11,2026-06-19 03:49:11,37,2026-06-23 12:00:00
154,prod-usw2-eks,payments,Warning,OOMKilling,Memory cgroup out of memory: Killed process in payments-worker-bbc0947-0aa1a,Pod,payments-worker-bbc0947-0aa1a,controllermanager,2026-06-21 08:57:42,2026-06-21 09:21:42,6,2026-06-23 12:00:00
155,staging-use2-eks,identity,Warning,DNSConfigForming,Search line limits exceeded for session-store-a097c68-649a1,Pod,session-store-a097c68-649a1,kubelet,2026-06-18 14:37:39,2026-06-18 15:52:39,29,2026-06-23 12:00:00
156,prod-usw2-eks,kube-system,Warning,NodeNotReady,Node ip-10-6-194-142 status is now: NodeNotReady,Pod,metrics-server-6162d13-d4a14,kubelet,2026-06-23 06:42:11,2026-06-23 08:26:11,18,2026-06-23 12:00:00
157,prod-use2-eks,payments,Normal,Started,Started container payments-worker,Pod,payments-worker-6e38c94-75bbf,controllermanager,2026-06-18 01:58:33,2026-06-18 02:38:33,1,2026-06-23 12:00:00
158,prod-usw2-eks,orders,Warning,Evicted,Pod orders-worker-b907131-2627d evicted: node was low on resource ephemeral-storage,Pod,orders-worker-b907131-2627d,kubelet,2026-06-19 21:16:12,2026-06-19 21:35:12,21,2026-06-23 12:00:00
159,prod-usw2-eks,identity,Normal,Started,Started container auth-gateway,Pod,auth-gateway-d4d3364-aac01,controllermanager,2026-06-12 20:20:44,2026-06-12 21:09:44,1,2026-06-23 12:00:00
160,staging-use2-eks,identity,Warning,Unhealthy,Readiness probe errored: dial tcp i/o timeout for session-store-a097c68-649a1,Pod,session-store-a097c68-649a1,default-scheduler,2026-06-09 16:06:14,2026-06-09 17:45:14,15,2026-06-23 12:00:00
161,prod-use2-eks,kube-system,Warning,FreeDiskSpaceFailed,Failed to garbage collect on node ip-10-32-13-101,Pod,coredns-e513a45-fb7bf,default-scheduler,2026-06-14 20:54:10,2026-06-14 21:16:10,39,2026-06-23 12:00:00
162,prod-use2-eks,checkout,Warning,BackOff,Back-off restarting failed container checkout-web in pod checkout-web-c343d41-6a8d2,Pod,checkout-web-c343d41-6a8d2,kubelet,2026-06-15 20:22:44,2026-06-15 22:07:44,25,2026-06-23 12:00:00
163,prod-usw2-eks,orders,Warning,BackOff,Back-off restarting failed container orders-api in pod orders-api-21c5d48-15186,Pod,orders-api-21c5d48-15186,kubelet,2026-06-14 08:13:20,2026-06-14 08:39:20,35,2026-06-23 12:00:00
164,prod-use2-eks,ledger,Normal,Pulled,Container image pulled for ledger-svc,Pod,ledger-svc-1232e29-49ea1,default-scheduler,2026-06-21 00:05:43,2026-06-21 00:59:43,1,2026-06-23 12:00:00
165,prod-use2-eks,ledger,Warning,Unhealthy,Readiness probe failed: timeout for ledger-svc-f4a6d64-16dde,Pod,ledger-svc-f4a6d64-16dde,default-scheduler,2026-06-18 07:08:37,2026-06-18 08:04:37,26,2026-06-23 12:00:00
166,prod-usw2-eks,payments,Warning,Unhealthy,Liveness probe failed: HTTP 500 for payments-worker-bbc0947-0aa1a,Pod,payments-worker-bbc0947-0aa1a,controllermanager,2026-06-21 06:13:10,2026-06-21 07:47:10,8,2026-06-23 12:00:00
167,prod-usw2-eks,payments,Warning,BackOff,Back-off restarting failed container payments-worker in pod payments-worker-1d1bf52-dff66,Pod,payments-worker-1d1bf52-dff66,default-scheduler,2026-06-02 07:05:26,2026-06-02 07:10:26,8,2026-06-23 12:00:00
168,prod-use2-eks,notifications,Normal,Throttling,CPU throttled for container notifications,Pod,notifications-1938743-28dca,default-scheduler,2026-06-16 18:24:34,2026-06-16 19:34:34,1,2026-06-23 12:00:00
169,prod-usw2-eks,ledger,Warning,Evicted,Pod ledger-svc-0744083-43011 evicted: node was low on resource ephemeral-storage,Pod,ledger-svc-0744083-43011,kubelet,2026-06-20 09:28:08,2026-06-20 11:08:08,3,2026-06-23 12:00:00
170,prod-use2-eks,identity,Warning,Evicted,Pod session-store-1ac5266-1ca26 evicted: node memory pressure,Pod,session-store-1ac5266-1ca26,kubelet,2026-06-16 05:44:43,2026-06-16 06:11:43,15,2026-06-23 12:00:00
171,staging-use2-eks,search,Normal,Started,Started container recommendation,Pod,recommendation-2071c72-c0b22,controllermanager,2026-06-05 23:30:30,2026-06-06 00:54:30,1,2026-06-23 12:00:00
172,prod-use2-eks,orders,Warning,OOMKilling,Container orders-api exceeded memory limit; OOMKilled,Pod,orders-api-e9b4a39-c3784,controllermanager,2026-06-15 07:12:44,2026-06-15 07:12:44,21,2026-06-23 12:00:00
173,prod-use2-eks,payments,Warning,OOMKilling,Container payments-api exceeded memory limit; OOMKilled,Pod,payments-api-c9c2b74-00142,kubelet,2026-06-23 01:46:04,2026-06-23 03:27:04,31,2026-06-23 12:00:00
174,prod-use2-eks,orders,Warning,OOMKilling,Container orders-api exceeded memory limit; OOMKilled,Pod,orders-api-e9b4a39-c3784,default-scheduler,2026-06-07 17:35:27,2026-06-07 19:24:27,19,2026-06-23 12:00:00
175,dr-use1-eks,checkout,Warning,OOMKilling,Container checkout-web exceeded memory limit; OOMKilled,Pod,checkout-web-4263246-52f3a,kubelet,2026-06-23 01:12:59,2026-06-23 02:01:59,36,2026-06-23 12:00:00
176,prod-usw2-eks,checkout,Warning,Evicted,Pod cart-svc-882ca58-64a75 evicted: node was low on resource ephemeral-storage,Pod,cart-svc-882ca58-64a75,controllermanager,2026-06-14 06:21:57,2026-06-14 07:59:57,39,2026-06-23 12:00:00
177,prod-use2-eks,checkout,Warning,Evicted,Pod cart-svc-26a7d77-aafdc evicted: node memory pressure,Pod,cart-svc-26a7d77-aafdc,kubelet,2026-06-19 08:53:29,2026-06-19 10:45:29,24,2026-06-23 12:00:00
178,prod-use2-eks,identity,Normal,Started,Started container auth-gateway,Pod,auth-gateway-9bddb17-f3d59,controllermanager,2026-05-27 08:19:11,2026-05-27 10:02:11,1,2026-06-23 12:00:00
179,staging-use2-eks,checkout,Warning,Rebooted,Node ip-10-8-126-134 has been rebooted,Pod,checkout-web-2b77739-52fdd,controllermanager,2026-06-23 01:54:22,2026-06-23 02:49:22,6,2026-06-23 12:00:00
180,prod-usw2-eks,orders,Warning,BackOff,Back-off restarting failed container orders-api in pod orders-api-402bb51-ad48f,Pod,orders-api-402bb51-ad48f,kubelet,2026-06-18 17:47:50,2026-06-18 19:09:50,35,2026-06-23 12:00:00
181,dr-use1-eks,notifications,Warning,BackOff,Back-off restarting failed container notifications in pod notifications-b036879-82982,Pod,notifications-b036879-82982,controllermanager,2026-06-22 18:12:57,2026-06-22 18:32:57,14,2026-06-23 12:00:00
182,dr-use1-eks,checkout,Warning,Evicted,Pod checkout-web-6e9e217-a5c79 evicted: node memory pressure,Pod,checkout-web-6e9e217-a5c79,controllermanager,2026-06-18 12:38:03,2026-06-18 13:32:03,7,2026-06-23 12:00:00
183,dr-use1-eks,platform,Normal,Started,Started container config-svc,Pod,config-svc-0f5b883-4b9e2,kubelet,2026-05-31 02:24:08,2026-05-31 02:33:08,1,2026-06-23 12:00:00
184,prod-use2-eks,ledger,Normal,Throttling,CPU throttled for container ledger-svc,Pod,ledger-svc-f4a6d64-16dde,kubelet,2026-06-17 23:25:15,2026-06-17 23:30:15,1,2026-06-23 12:00:00
185,dr-use1-eks,checkout,Warning,Evicted,Pod checkout-web-6e9e217-a5c79 evicted: node memory pressure,Pod,checkout-web-6e9e217-a5c79,kubelet,2026-06-18 15:33:31,2026-06-18 16:34:31,4,2026-06-23 12:00:00
186,prod-use2-eks,orders,Warning,Evicted,Pod orders-api-bfb2f93-32ad3 evicted: node memory pressure,Pod,orders-api-bfb2f93-32ad3,controllermanager,2026-06-14 23:15:00,2026-06-14 23:59:00,34,2026-06-23 12:00:00
187,prod-usw2-eks,platform,Normal,Pulled,Container image pulled for image-resizer,Pod,image-resizer-9683178-b7560,kubelet,2026-06-01 03:31:06,2026-06-01 04:20:06,1,2026-06-23 12:00:00
188,prod-use2-eks,orders,Warning,OOMKilling,Container orders-api exceeded memory limit; OOMKilled,Pod,orders-api-7f89525-97cdd,controllermanager,2026-06-21 21:27:04,2026-06-21 21:31:04,9,2026-06-23 12:00:00
189,dr-use1-eks,search,Warning,Evicted,Pod search-api-d416b43-7cb20 evicted: node was low on resource ephemeral-storage,Pod,search-api-d416b43-7cb20,default-scheduler,2026-06-23 08:40:31,2026-06-23 10:40:31,38,2026-06-23 12:00:00
190,prod-use2-eks,search,Normal,Pulled,Container image pulled for recommendation,Pod,recommendation-c460126-52814,kubelet,2026-06-13 17:07:02,2026-06-13 17:21:02,1,2026-06-23 12:00:00
191,prod-usw2-eks,payments,Warning,BackOff,Back-off restarting failed container payments-worker in pod payments-worker-bbc0947-0aa1a,Pod,payments-worker-bbc0947-0aa1a,controllermanager,2026-06-19 02:35:49,2026-06-19 02:45:49,5,2026-06-23 12:00:00
192,prod-usw2-eks,checkout,Warning,Evicted,Pod cart-svc-0a94879-c1bba evicted: node was low on resource ephemeral-storage,Pod,cart-svc-0a94879-c1bba,controllermanager,2026-06-20 08:46:53,2026-06-20 10:04:53,15,2026-06-23 12:00:00
193,dr-use1-eks,search,Warning,Evicted,Pod search-api-be84964-d972c evicted: node was low on resource ephemeral-storage,Pod,search-api-be84964-d972c,default-scheduler,2026-06-02 13:37:05,2026-06-02 14:22:05,12,2026-06-23 12:00:00
194,prod-usw2-eks,kube-system,Warning,DNSConfigForming,Search line limits exceeded for coredns-37f1521-4cd3d,Pod,coredns-37f1521-4cd3d,kubelet,2026-06-20 18:34:08,2026-06-20 19:28:08,9,2026-06-23 12:00:00
195,prod-use2-eks,checkout,Warning,OOMKilling,Container cart-svc exceeded memory limit; OOMKilled,Pod,cart-svc-527eb80-045c0,controllermanager,2026-06-21 04:37:04,2026-06-21 05:32:04,22,2026-06-23 12:00:00
196,prod-usw2-eks,ledger,Warning,Evicted,Pod ledger-svc-2014124-29b88 evicted: node was low on resource ephemeral-storage,Pod,ledger-svc-2014124-29b88,controllermanager,2026-06-22 04:12:52,2026-06-22 05:01:52,38,2026-06-23 12:00:00
197,prod-usw2-eks,search,Warning,FreeDiskSpaceFailed,Failed to garbage collect on node ip-10-14-16-161,Pod,search-api-8352074-5b766,default-scheduler,2026-06-21 23:05:26,2026-06-21 23:50:26,4,2026-06-23 12:00:00
198,prod-use2-eks,search,Normal,Scheduled,Successfully assigned search-api-1271443-2f040 to ip-10-37-142-3,Pod,search-api-1271443-2f040,kubelet,2026-05-26 10:52:24,2026-05-26 12:39:24,1,2026-06-23 12:00:00
199,prod-usw2-eks,payments,Normal,Scheduled,Successfully assigned payments-worker-b4be648-d2dcb to ip-10-29-63-193,Pod,payments-worker-b4be648-d2dcb,default-scheduler,2026-06-10 23:06:01,2026-06-11 00:46:01,1,2026-06-23 12:00:00
200,prod-use2-eks,identity,Normal,Started,Started container auth-gateway,Pod,auth-gateway-bf1d422-2018d,kubelet,2026-06-20 04:46:08,2026-06-20 05:18:08,1,2026-06-23 12:00:00
201,staging-use2-eks,inventory,Warning,Evicted,Pod inventory-svc-1d6f570-1b50d evicted: node memory pressure,Pod,inventory-svc-1d6f570-1b50d,controllermanager,2026-06-21 23:11:37,2026-06-21 23:20:37,35,2026-06-23 12:00:00
202,prod-usw2-eks,orders,Warning,BackOff,Back-off restarting failed container orders-api in pod orders-api-402bb51-ad48f,Pod,orders-api-402bb51-ad48f,kubelet,2026-06-16 15:47:25,2026-06-16 16:21:25,36,2026-06-23 12:00:00
203,prod-use2-eks,platform,Normal,Throttling,CPU throttled for container config-svc,Pod,config-svc-027a395-39a4d,default-scheduler,2026-06-18 23:24:13,2026-06-18 23:27:13,1,2026-06-23 12:00:00
204,prod-use2-eks,payments,Warning,Evicted,Pod payments-api-58c5e74-26d34 evicted: node memory pressure,Pod,payments-api-58c5e74-26d34,kubelet,2026-06-23 07:45:48,2026-06-23 08:37:48,33,2026-06-23 12:00:00
205,prod-usw2-eks,ledger,Warning,FreeDiskSpaceFailed,Failed to garbage collect on node ip-10-14-16-161,Pod,ledger-svc-2014124-29b88,default-scheduler,2026-06-17 03:54:48,2026-06-17 05:10:48,26,2026-06-23 12:00:00
206,prod-usw2-eks,ledger,Warning,FreeDiskSpaceFailed,Failed to garbage collect on node ip-10-6-194-142,Pod,ledger-svc-842cd31-95bfa,default-scheduler,2026-06-19 19:39:42,2026-06-19 20:12:42,3,2026-06-23 12:00:00
207,prod-use2-eks,notifications,Warning,Unhealthy,Readiness probe failed: timeout for notifications-1938743-28dca,Pod,notifications-1938743-28dca,controllermanager,2026-06-07 23:13:31,2026-06-07 23:15:31,40,2026-06-23 12:00:00
208,prod-use2-eks,platform,Normal,Pulled,Container image pulled for config-svc,Pod,config-svc-ddd1723-06ca5,controllermanager,2026-06-23 01:25:18,2026-06-23 02:21:18,1,2026-06-23 12:00:00
209,prod-use2-eks,checkout,Warning,OOMKilling,Memory cgroup out of memory: Killed process in checkout-web-c343d41-6a8d2,Pod,checkout-web-c343d41-6a8d2,default-scheduler,2026-06-19 19:05:19,2026-06-19 20:03:19,35,2026-06-23 12:00:00
210,prod-usw2-eks,payments,Warning,OOMKilling,Container payments-api exceeded memory limit; OOMKilled,Pod,payments-api-1e23165-1e35b,kubelet,2026-06-20 05:12:47,2026-06-20 05:17:47,23,2026-06-23 12:00:00
211,dr-use1-eks,checkout,Warning,Evicted,Pod checkout-web-4263246-52f3a evicted: node memory pressure,Pod,checkout-web-4263246-52f3a,controllermanager,2026-06-20 22:42:20,2026-06-20 23:33:20,34,2026-06-23 12:00:00
212,prod-use2-eks,ledger,Normal,Throttling,CPU throttled for container ledger-svc,Pod,ledger-svc-204e643-7d23b,default-scheduler,2026-06-22 18:35:38,2026-06-22 19:49:38,1,2026-06-23 12:00:00
213,prod-use2-eks,identity,Warning,Evicted,Pod session-store-4732511-0dba8 evicted: node memory pressure,Pod,session-store-4732511-0dba8,default-scheduler,2026-06-10 07:13:32,2026-06-10 07:23:32,29,2026-06-23 12:00:00
214,prod-usw2-eks,payments,Warning,Evicted,Pod payments-api-1e23165-1e35b evicted: node memory pressure,Pod,payments-api-1e23165-1e35b,default-scheduler,2026-05-31 06:07:15,2026-05-31 07:02:15,35,2026-06-23 12:00:00
215,prod-use2-eks,search,Normal,Pulled,Container image pulled for indexer,Pod,indexer-b07f520-eaf04,kubelet,2026-06-11 09:40:12,2026-06-11 10:14:12,1,2026-06-23 12:00:00
216,prod-usw2-eks,payments,Warning,Evicted,Pod payments-api-b9a1287-dbbfe evicted: node memory pressure,Pod,payments-api-b9a1287-dbbfe,kubelet,2026-06-09 13:49:27,2026-06-09 14:39:27,3,2026-06-23 12:00:00
217,prod-use2-eks,search,Normal,Pulled,Container image pulled for search-api,Pod,search-api-1271443-2f040,controllermanager,2026-06-15 21:07:41,2026-06-15 21:44:41,1,2026-06-23 12:00:00
218,prod-use2-eks,orders,Warning,Evicted,Pod orders-api-7f89525-97cdd evicted: node memory pressure,Pod,orders-api-7f89525-97cdd,kubelet,2026-06-20 11:37:36,2026-06-20 12:03:36,32,2026-06-23 12:00:00
219,dr-use1-eks,checkout,Warning,OOMKilling,Container checkout-web exceeded memory limit; OOMKilled,Pod,checkout-web-4263246-52f3a,kubelet,2026-06-20 01:40:58,2026-06-20 02:05:58,18,2026-06-23 12:00:00
220,prod-use2-eks,platform,Warning,DNSConfigForming,Search line limits exceeded for image-resizer-9994630-7c707,Pod,image-resizer-9994630-7c707,controllermanager,2026-06-22 21:57:24,2026-06-22 22:38:24,1,2026-06-23 12:00:00
221,prod-usw2-eks,orders,Warning,FreeDiskSpaceFailed,Failed to garbage collect on node ip-10-14-16-161,Pod,orders-worker-8482791-f2d9f,default-scheduler,2026-06-21 02:40:48,2026-06-21 03:03:48,5,2026-06-23 12:00:00
222,dr-use1-eks,checkout,Normal,Scheduled,Successfully assigned cart-svc-da3cf51-00806 to ip-10-29-128-5,Pod,cart-svc-da3cf51-00806,kubelet,2026-06-03 16:25:30,2026-06-03 16:26:30,1,2026-06-23 12:00:00
223,dr-use1-eks,search,Warning,Evicted,Pod search-api-d416b43-7cb20 evicted: node was low on resource ephemeral-storage,Pod,search-api-d416b43-7cb20,kubelet,2026-06-06 01:48:28,2026-06-06 03:20:28,6,2026-06-23 12:00:00
224,prod-use2-eks,checkout,Warning,Evicted,Pod cart-svc-527eb80-045c0 evicted: node memory pressure,Pod,cart-svc-527eb80-045c0,default-scheduler,2026-06-22 14:26:39,2026-06-22 15:44:39,2,2026-06-23 12:00:00
225,prod-usw2-eks,inventory,Warning,BackOff,Back-off restarting failed container inventory-svc in pod inventory-svc-bf8f159-02345,Pod,inventory-svc-bf8f159-02345,kubelet,2026-06-04 19:09:34,2026-06-04 19:28:34,10,2026-06-23 12:00:00
226,prod-usw2-eks,platform,Normal,Started,Started container image-resizer,Pod,image-resizer-9683178-b7560,controllermanager,2026-05-28 04:58:38,2026-05-28 05:08:38,1,2026-06-23 12:00:00
227,dr-use1-eks,search,Warning,FreeDiskSpaceFailed,Failed to garbage collect on node ip-10-40-81-216,Pod,search-api-d416b43-7cb20,controllermanager,2026-06-21 07:47:40,2026-06-21 08:00:40,15,2026-06-23 12:00:00
228,prod-use2-eks,ledger,Warning,Unhealthy,Readiness probe failed: timeout for ledger-svc-f4a6d64-16dde,Pod,ledger-svc-f4a6d64-16dde,controllermanager,2026-06-18 18:05:29,2026-06-18 20:03:29,2,2026-06-23 12:00:00
229,prod-usw2-eks,orders,Warning,Evicted,Pod orders-worker-b907131-2627d evicted: node was low on resource ephemeral-storage,Pod,orders-worker-b907131-2627d,controllermanager,2026-06-19 02:39:20,2026-06-19 04:26:20,13,2026-06-23 12:00:00
230,dr-use1-eks,orders,Warning,DNSConfigForming,Search line limits exceeded for orders-api-8330e48-f22f4,Pod,orders-api-8330e48-f22f4,kubelet,2026-06-16 09:04:29,2026-06-16 10:32:29,35,2026-06-23 12:00:00
231,prod-use2-eks,payments,Warning,OOMKilling,Container payments-api exceeded memory limit; OOMKilled,Pod,payments-api-1ce3577-591ac,default-scheduler,2026-06-22 13:40:02,2026-06-22 15:39:02,8,2026-06-23 12:00:00
232,prod-use2-eks,checkout,Warning,OOMKilling,Container cart-svc exceeded memory limit; OOMKilled,Pod,cart-svc-527eb80-045c0,controllermanager,2026-06-14 20:48:12,2026-06-14 22:38:12,40,2026-06-23 12:00:00
233,prod-usw2-eks,kube-system,Warning,Unhealthy,Readiness probe errored: dial tcp i/o timeout for coredns-37f1521-4cd3d,Pod,coredns-37f1521-4cd3d,kubelet,2026-06-20 06:18:23,2026-06-20 08:00:23,1,2026-06-23 12:00:00
234,prod-usw2-eks,payments,Warning,OOMKilling,Container payments-api exceeded memory limit; OOMKilled,Pod,payments-api-1e23165-1e35b,default-scheduler,2026-06-19 18:28:00,2026-06-19 19:12:00,11,2026-06-23 12:00:00
235,prod-usw2-eks,orders,Warning,FreeDiskSpaceFailed,Failed to garbage collect on node ip-10-14-16-161,Pod,orders-worker-8482791-f2d9f,default-scheduler,2026-06-22 08:52:09,2026-06-22 09:56:09,22,2026-06-23 12:00:00
236,dr-use1-eks,notifications,Warning,OOMKilling,Memory cgroup out of memory: Killed process in notifications-b036879-82982,Pod,notifications-b036879-82982,kubelet,2026-06-23 02:07:03,2026-06-23 03:00:03,23,2026-06-23 12:00:00
237,prod-usw2-eks,search,Normal,Pulled,Container image pulled for recommendation,Pod,recommendation-87e3198-026ea,controllermanager,2026-06-08 13:38:00,2026-06-08 13:56:00,1,2026-06-23 12:00:00
238,prod-usw2-eks,kube-system,Warning,DNSConfigForming,Search line limits exceeded for coredns-37f1521-4cd3d,Pod,coredns-37f1521-4cd3d,default-scheduler,2026-06-22 08:31:22,2026-06-22 09:10:22,10,2026-06-23 12:00:00
239,prod-use2-eks,search,Normal,Scheduled,Successfully assigned indexer-4680271-0a829 to ip-10-17-79-110,Pod,indexer-4680271-0a829,kubelet,2026-06-12 16:21:50,2026-06-12 17:02:50,1,2026-06-23 12:00:00
240,dr-use1-eks,inventory,Normal,Pulled,Container image pulled for inventory-svc,Pod,inventory-svc-4ccbe67-9cbde,controllermanager,2026-06-22 14:23:52,2026-06-22 15:34:52,1,2026-06-23 12:00:00
241,prod-usw2-eks,identity,Warning,Evicted,Pod session-store-28ebc77-cf7c8 evicted: node was low on resource ephemeral-storage,Pod,session-store-28ebc77-cf7c8,default-scheduler,2026-06-05 16:52:58,2026-06-05 17:35:58,16,2026-06-23 12:00:00
242,prod-usw2-eks,search,Warning,Evicted,Pod search-api-15a6d76-12766 evicted: node was low on resource ephemeral-storage,Pod,search-api-15a6d76-12766,kubelet,2026-06-18 02:51:36,2026-06-18 02:51:36,31,2026-06-23 12:00:00
243,prod-usw2-eks,payments,Warning,OOMKilling,Memory cgroup out of memory: Killed process in payments-worker-bbc0947-0aa1a,Pod,payments-worker-bbc0947-0aa1a,default-scheduler,2026-06-09 18:17:59,2026-06-09 19:47:59,25,2026-06-23 12:00:00
244,prod-use2-eks,identity,Normal,Started,Started container auth-gateway,Pod,auth-gateway-ec6b034-0575b,default-scheduler,2026-06-09 21:06:25,2026-06-09 21:44:25,1,2026-06-23 12:00:00
245,prod-usw2-eks,search,Normal,Started,Started container recommendation,Pod,recommendation-87e3198-026ea,controllermanager,2026-06-06 21:39:25,2026-06-06 23:04:25,1,2026-06-23 12:00:00
246,prod-usw2-eks,checkout,Normal,Pulled,Container image pulled for checkout-web,Pod,checkout-web-2e5d994-d724e,kubelet,2026-06-02 21:39:08,2026-06-02 23:06:08,1,2026-06-23 12:00:00
247,prod-use2-eks,checkout,Warning,Evicted,Pod cart-svc-51c2594-4d271 evicted: node memory pressure,Pod,cart-svc-51c2594-4d271,kubelet,2026-06-18 14:21:38,2026-06-18 14:34:38,39,2026-06-23 12:00:00
248,prod-usw2-eks,kube-system,Warning,Unhealthy,Readiness probe errored: dial tcp i/o timeout for coredns-37f1521-4cd3d,Pod,coredns-37f1521-4cd3d,controllermanager,2026-06-19 13:44:34,2026-06-19 15:07:34,7,2026-06-23 12:00:00
249,staging-use2-eks,kube-system,Normal,Pulled,Container image pulled for coredns,Pod,coredns-b16ea15-07544,kubelet,2026-06-14 20:32:53,2026-06-14 21:04:53,1,2026-06-23 12:00:00
250,prod-use2-eks,ledger,Warning,Unhealthy,Readiness probe failed: timeout for ledger-svc-204e643-7d23b,Pod,ledger-svc-204e643-7d23b,kubelet,2026-06-16 22:09:58,2026-06-16 23:52:58,8,2026-06-23 12:00:00
251,prod-use2-eks,notifications,Normal,Throttling,CPU throttled for container notifications,Pod,notifications-1938743-28dca,controllermanager,2026-06-09 02:16:20,2026-06-09 03:56:20,1,2026-06-23 12:00:00
252,prod-usw2-eks,payments,Warning,Evicted,Pod payments-api-1e23165-1e35b evicted: node memory pressure,Pod,payments-api-1e23165-1e35b,default-scheduler,2026-06-06 01:23:43,2026-06-06 01:57:43,30,2026-06-23 12:00:00
253,prod-use2-eks,checkout,Warning,OOMKilling,Container cart-svc exceeded memory limit; OOMKilled,Pod,cart-svc-51c2594-4d271,default-scheduler,2026-06-19 00:52:11,2026-06-19 01:04:11,40,2026-06-23 12:00:00
254,prod-usw2-eks,ledger,Warning,FreeDiskSpaceFailed,Failed to garbage collect on node ip-10-6-194-142,Pod,ledger-svc-842cd31-95bfa,default-scheduler,2026-06-16 20:35:46,2026-06-16 22:15:46,16,2026-06-23 12:00:00
255,prod-usw2-eks,payments,Warning,BackOff,Back-off restarting failed container payments-worker in pod payments-worker-bbc0947-0aa1a,Pod,payments-worker-bbc0947-0aa1a,default-scheduler,2026-06-13 15:44:17,2026-06-13 15:47:17,40,2026-06-23 12:00:00
256,prod-usw2-eks,kube-system,Warning,Unhealthy,Readiness probe errored: dial tcp i/o timeout for coredns-37f1521-4cd3d,Pod,coredns-37f1521-4cd3d,kubelet,2026-06-21 20:24:07,2026-06-21 21:01:07,20,2026-06-23 12:00:00
257,prod-usw2-eks,inventory,Normal,Pulled,Container image pulled for inventory-svc,Pod,inventory-svc-4453f63-e15f3,controllermanager,2026-06-06 19:10:09,2026-06-06 20:19:09,1,2026-06-23 12:00:00
258,staging-use2-eks,checkout,Warning,Rebooted,Node ip-10-14-70-252 has been rebooted,Pod,checkout-web-aca9086-f5fe6,controllermanager,2026-06-23 03:56:54,2026-06-23 05:00:54,34,2026-06-23 12:00:00
259,dr-use1-eks,checkout,Warning,Evicted,Pod checkout-web-6e9e217-a5c79 evicted: node memory pressure,Pod,checkout-web-6e9e217-a5c79,controllermanager,2026-06-21 00:41:36,2026-06-21 02:40:36,4,2026-06-23 12:00:00
260,prod-use2-eks,identity,Warning,OOMKilling,Container session-store exceeded memory limit; OOMKilled,Pod,session-store-4732511-0dba8,kubelet,2026-06-13 21:25:24,2026-06-13 22:28:24,38,2026-06-23 12:00:00
261,prod-use2-eks,checkout,Warning,Evicted,Pod cart-svc-51c2594-4d271 evicted: node memory pressure,Pod,cart-svc-51c2594-4d271,controllermanager,2026-06-17 07:02:42,2026-06-17 07:18:42,15,2026-06-23 12:00:00
262,prod-use2-eks,platform,Warning,Unhealthy,Readiness probe errored: dial tcp i/o timeout for image-resizer-7bb3c89-50e74,Pod,image-resizer-7bb3c89-50e74,kubelet,2026-06-23 08:03:21,2026-06-23 08:18:21,14,2026-06-23 12:00:00
263,prod-use2-eks,search,Normal,Scheduled,Successfully assigned indexer-4680271-0a829 to ip-10-17-79-110,Pod,indexer-4680271-0a829,default-scheduler,2026-06-19 15:04:46,2026-06-19 15:37:46,1,2026-06-23 12:00:00
264,dr-use1-eks,search,Warning,FreeDiskSpaceFailed,Failed to garbage collect on node ip-10-40-81-216,Pod,search-api-be84964-d972c,kubelet,2026-05-28 20:00:45,2026-05-28 21:27:45,29,2026-06-23 12:00:00
265,prod-use2-eks,ledger,Normal,Started,Started container ledger-svc,Pod,ledger-svc-1232e29-49ea1,controllermanager,2026-06-23 02:46:45,2026-06-23 04:38:45,1,2026-06-23 12:00:00
266,prod-use2-eks,checkout,Warning,Evicted,Pod cart-svc-51c2594-4d271 evicted: node memory pressure,Pod,cart-svc-51c2594-4d271,default-scheduler,2026-06-18 14:23:42,2026-06-18 15:23:42,20,2026-06-23 12:00:00
267,prod-usw2-eks,orders,Warning,OOMKilling,Memory cgroup out of memory: Killed process in orders-api-402bb51-ad48f,Pod,orders-api-402bb51-ad48f,kubelet,2026-06-14 08:30:09,2026-06-14 09:21:09,2,2026-06-23 12:00:00
268,staging-use2-eks,payments,Warning,FreeDiskSpaceFailed,Failed to garbage collect on node ip-10-20-108-255,Pod,payments-api-2729261-453da,controllermanager,2026-06-08 15:42:37,2026-06-08 16:39:37,1,2026-06-23 12:00:00
269,prod-usw2-eks,platform,Normal,Scheduled,Successfully assigned image-resizer-9683178-b7560 to ip-10-6-194-142,Pod,image-resizer-9683178-b7560,controllermanager,2026-05-29 08:40:44,2026-05-29 10:29:44,1,2026-06-23 12:00:00
270,staging-use2-eks,payments,Warning,Evicted,Pod payments-api-2729261-453da evicted: node was low on resource ephemeral-storage,Pod,payments-api-2729261-453da,kubelet,2026-06-18 05:18:45,2026-06-18 05:33:45,35,2026-06-23 12:00:00
271,dr-use1-eks,search,Warning,Evicted,Pod search-api-be84964-d972c evicted: node was low on resource ephemeral-storage,Pod,search-api-be84964-d972c,default-scheduler,2026-06-19 19:45:20,2026-06-19 21:35:20,33,2026-06-23 12:00:00
272,prod-use2-eks,checkout,Warning,OOMKilling,Memory cgroup out of memory: Killed process in checkout-web-c2eb578-2d181,Pod,checkout-web-c2eb578-2d181,default-scheduler,2026-06-12 16:05:51,2026-06-12 16:22:51,17,2026-06-23 12:00:00
273,prod-usw2-eks,ledger,Warning,Evicted,Pod ledger-svc-0744083-43011 evicted: node was low on resource ephemeral-storage,Pod,ledger-svc-0744083-43011,kubelet,2026-06-20 01:16:07,2026-06-20 03:12:07,13,2026-06-23 12:00:00
274,staging-use2-eks,search,Normal,Pulled,Container image pulled for search-api,Pod,search-api-8ca0b98-505ff,default-scheduler,2026-06-22 21:32:37,2026-06-22 22:44:37,1,2026-06-23 12:00:00
275,prod-usw2-eks,kube-system,Warning,NodeNotReady,Node ip-10-6-194-142 status is now: NodeNotReady,Pod,metrics-server-6162d13-d4a14,controllermanager,2026-06-22 13:19:54,2026-06-22 14:09:54,26,2026-06-23 12:00:00
276,prod-use2-eks,checkout,Warning,Evicted,Pod cart-svc-527eb80-045c0 evicted: node memory pressure,Pod,cart-svc-527eb80-045c0,kubelet,2026-06-23 08:57:59,2026-06-23 09:22:59,7,2026-06-23 12:00:00
277,dr-use1-eks,search,Warning,FreeDiskSpaceFailed,Failed to garbage collect on node ip-10-40-81-216,Pod,search-api-d416b43-7cb20,controllermanager,2026-06-02 19:48:44,2026-06-02 21:31:44,22,2026-06-23 12:00:00
278,prod-usw2-eks,search,Warning,Evicted,Pod search-api-15a6d76-12766 evicted: node was low on resource ephemeral-storage,Pod,search-api-15a6d76-12766,controllermanager,2026-06-13 17:42:51,2026-06-13 18:21:51,34,2026-06-23 12:00:00
279,staging-use2-eks,identity,Warning,DNSConfigForming,Search line limits exceeded for session-store-a097c68-649a1,Pod,session-store-a097c68-649a1,default-scheduler,2026-06-11 07:04:11,2026-06-11 07:27:11,10,2026-06-23 12:00:00
280,staging-use2-eks,payments,Normal,Pulled,Container image pulled for payments-api,Pod,payments-api-dde4d16-a3d09,default-scheduler,2026-06-17 06:36:53,2026-06-17 07:47:53,1,2026-06-23 12:00:00
281,prod-usw2-eks,orders,Warning,Unhealthy,Liveness probe failed: HTTP 500 for orders-api-21c5d48-15186,Pod,orders-api-21c5d48-15186,controllermanager,2026-06-14 11:17:09,2026-06-14 12:49:09,36,2026-06-23 12:00:00
282,staging-use2-eks,inventory,Warning,Evicted,Pod inventory-svc-1d6f570-1b50d evicted: node memory pressure,Pod,inventory-svc-1d6f570-1b50d,kubelet,2026-06-16 08:12:15,2026-06-16 08:22:15,34,2026-06-23 12:00:00
283,prod-usw2-eks,kube-system,Warning,DNSConfigForming,Search line limits exceeded for coredns-4a8b365-1d9fc,Pod,coredns-4a8b365-1d9fc,controllermanager,2026-06-20 18:20:47,2026-06-20 20:04:47,24,2026-06-23 12:00:00
284,prod-usw2-eks,checkout,Warning,FreeDiskSpaceFailed,Failed to garbage collect on node ip-10-6-194-142,Pod,cart-svc-ee38458-64d46,kubelet,2026-06-13 16:34:48,2026-06-13 16:43:48,17,2026-06-23 12:00:00
285,prod-usw2-eks,orders,Warning,Unhealthy,Liveness probe failed: HTTP 500 for orders-api-402bb51-ad48f,Pod,orders-api-402bb51-ad48f,kubelet,2026-06-21 05:48:46,2026-06-21 07:25:46,7,2026-06-23 12:00:00
286,prod-use2-eks,checkout,Warning,Evicted,Pod cart-svc-26a7d77-aafdc evicted: node memory pressure,Pod,cart-svc-26a7d77-aafdc,kubelet,2026-06-16 04:24:38,2026-06-16 05:26:38,32,2026-06-23 12:00:00
287,prod-usw2-eks,payments,Normal,Started,Started container payments-worker,Pod,payments-worker-b4be648-d2dcb,default-scheduler,2026-06-10 06:31:48,2026-06-10 07:17:48,1,2026-06-23 12:00:00
288,prod-use2-eks,kube-system,Warning,DNSConfigForming,Search line limits exceeded for metrics-server-e2e6924-29c37,Pod,metrics-server-e2e6924-29c37,kubelet,2026-06-06 01:00:23,2026-06-06 02:02:23,20,2026-06-23 12:00:00
289,prod-usw2-eks,inventory,Normal,Scheduled,Successfully assigned inventory-svc-4453f63-e15f3 to ip-10-22-107-136,Pod,inventory-svc-4453f63-e15f3,kubelet,2026-06-12 14:13:07,2026-06-12 15:52:07,1,2026-06-23 12:00:00
290,prod-usw2-eks,identity,Warning,Evicted,Pod session-store-28ebc77-cf7c8 evicted: node was low on resource ephemeral-storage,Pod,session-store-28ebc77-cf7c8,default-scheduler,2026-06-22 10:24:54,2026-06-22 10:46:54,35,2026-06-23 12:00:00
291,prod-usw2-eks,orders,Warning,BackOff,Back-off restarting failed container orders-api in pod orders-api-402bb51-ad48f,Pod,orders-api-402bb51-ad48f,controllermanager,2026-06-16 01:30:18,2026-06-16 01:31:18,39,2026-06-23 12:00:00
292,prod-usw2-eks,orders,Warning,OOMKilling,Memory cgroup out of memory: Killed process in orders-api-402bb51-ad48f,Pod,orders-api-402bb51-ad48f,kubelet,2026-06-15 08:29:37,2026-06-15 08:41:37,2,2026-06-23 12:00:00
293,prod-use2-eks,checkout,Warning,Unhealthy,Liveness probe failed: HTTP 500 for checkout-web-0101b48-2b2af,Pod,checkout-web-0101b48-2b2af,controllermanager,2026-06-01 17:18:38,2026-06-01 17:18:38,20,2026-06-23 12:00:00
294,prod-use2-eks,search,Normal,Started,Started container indexer,Pod,indexer-4680271-0a829,default-scheduler,2026-05-30 11:08:34,2026-05-30 12:11:34,1,2026-06-23 12:00:00
295,prod-usw2-eks,kube-system,Warning,NodeNotReady,Node ip-10-6-194-142 status is now: NodeNotReady,Pod,metrics-server-6162d13-d4a14,controllermanager,2026-06-16 12:22:53,2026-06-16 12:23:53,38,2026-06-23 12:00:00
296,staging-use2-eks,payments,Warning,FreeDiskSpaceFailed,Failed to garbage collect on node ip-10-20-108-255,Pod,payments-api-2729261-453da,default-scheduler,2026-06-01 01:56:38,2026-06-01 03:41:38,25,2026-06-23 12:00:00
297,prod-usw2-eks,search,Warning,Evicted,Pod search-api-a47d446-4ffe2 evicted: node was low on resource ephemeral-storage,Pod,search-api-a47d446-4ffe2,controllermanager,2026-06-15 22:21:03,2026-06-15 22:32:03,39,2026-06-23 12:00:00
298,dr-use1-eks,inventory,Normal,Pulled,Container image pulled for inventory-svc,Pod,inventory-svc-4ccbe67-9cbde,controllermanager,2026-05-31 05:24:13,2026-05-31 07:22:13,1,2026-06-23 12:00:00
299,prod-usw2-eks,orders,Warning,Unhealthy,Liveness probe failed: HTTP 500 for orders-api-402bb51-ad48f,Pod,orders-api-402bb51-ad48f,default-scheduler,2026-06-22 22:26:15,2026-06-22 23:51:15,25,2026-06-23 12:00:00
300,prod-usw2-eks,orders,Warning,BackOff,Back-off restarting failed container orders-api in pod orders-api-21c5d48-15186,Pod,orders-api-21c5d48-15186,controllermanager,2026-06-23 07:05:51,2026-06-23 07:55:51,38,2026-06-23 12:00:00
301,staging-use2-eks,identity,Warning,Unhealthy,Readiness probe errored: dial tcp i/o timeout for session-store-a097c68-649a1,Pod,session-store-a097c68-649a1,kubelet,2026-06-19 00:21:01,2026-06-19 01:16:01,30,2026-06-23 12:00:00
302,prod-usw2-eks,ledger,Warning,Evicted,Pod ledger-svc-842cd31-95bfa evicted: node was low on resource ephemeral-storage,Pod,ledger-svc-842cd31-95bfa,default-scheduler,2026-06-15 09:37:20,2026-06-15 10:49:20,33,2026-06-23 12:00:00
303,dr-use1-eks,notifications,Warning,BackOff,Back-off restarting failed container notifications in pod notifications-b036879-82982,Pod,notifications-b036879-82982,controllermanager,2026-06-23 07:23:48,2026-06-23 08:23:48,24,2026-06-23 12:00:00
304,staging-use2-eks,search,Normal,Started,Started container recommendation,Pod,recommendation-2071c72-c0b22,controllermanager,2026-06-04 10:06:21,2026-06-04 11:02:21,1,2026-06-23 12:00:00
305,prod-use2-eks,checkout,Warning,OOMKilling,Memory cgroup out of memory: Killed process in checkout-web-c2eb578-2d181,Pod,checkout-web-c2eb578-2d181,kubelet,2026-06-10 12:13:38,2026-06-10 13:40:38,8,2026-06-23 12:00:00
306,prod-usw2-eks,ledger,Warning,Evicted,Pod ledger-svc-842cd31-95bfa evicted: node was low on resource ephemeral-storage,Pod,ledger-svc-842cd31-95bfa,controllermanager,2026-06-22 01:40:57,2026-06-22 02:43:57,30,2026-06-23 12:00:00
307,staging-use2-eks,identity,Normal,Scheduled,Successfully assigned auth-gateway-c975434-e6ef9 to ip-10-14-70-252,Pod,auth-gateway-c975434-e6ef9,default-scheduler,2026-06-15 09:42:48,2026-06-15 09:42:48,1,2026-06-23 12:00:00
308,prod-usw2-eks,search,Warning,FreeDiskSpaceFailed,Failed to garbage collect on node ip-10-6-194-142,Pod,search-api-15a6d76-12766,controllermanager,2026-06-18 02:07:07,2026-06-18 03:17:07,27,2026-06-23 12:00:00
309,staging-use2-eks,payments,Warning,FreeDiskSpaceFailed,Failed to garbage collect on node ip-10-20-108-255,Pod,payments-api-2729261-453da,controllermanager,2026-06-17 09:34:23,2026-06-17 10:17:23,3,2026-06-23 12:00:00
310,prod-usw2-eks,orders,Warning,BackOff,Back-off restarting failed container orders-api in pod orders-api-21c5d48-15186,Pod,orders-api-21c5d48-15186,default-scheduler,2026-06-22 23:08:07,2026-06-23 00:09:07,33,2026-06-23 12:00:00
311,staging-use2-eks,checkout,Warning,Rebooted,Node ip-10-14-70-252 has been rebooted,Pod,checkout-web-aca9086-f5fe6,default-scheduler,2026-06-23 08:18:57,2026-06-23 08:53:57,13,2026-06-23 12:00:00
312,prod-usw2-eks,identity,Normal,Scheduled,Successfully assigned auth-gateway-fb1c283-81cc8 to ip-10-14-16-161,Pod,auth-gateway-fb1c283-81cc8,kubelet,2026-05-29 13:06:56,2026-05-29 13:25:56,1,2026-06-23 12:00:00
313,staging-use2-eks,checkout,Warning,Rebooted,Node ip-10-8-126-134 has been rebooted,Pod,checkout-web-2b77739-52fdd,controllermanager,2026-06-23 04:36:59,2026-06-23 05:26:59,23,2026-06-23 12:00:00
314,staging-use2-eks,identity,Warning,DNSConfigForming,Search line limits exceeded for session-store-a097c68-649a1,Pod,session-store-a097c68-649a1,default-scheduler,2026-06-18 12:27:37,2026-06-18 13:50:37,34,2026-06-23 12:00:00
315,prod-usw2-eks,payments,Warning,Evicted,Pod payments-api-1e23165-1e35b evicted: node memory pressure,Pod,payments-api-1e23165-1e35b,default-scheduler,2026-06-18 15:09:03,2026-06-18 16:44:03,17,2026-06-23 12:00:00
316,prod-use2-eks,platform,Normal,Started,Started container config-svc,Pod,config-svc-ddd1723-06ca5,kubelet,2026-06-22 07:11:40,2026-06-22 07:46:40,1,2026-06-23 12:00:00
317,dr-use1-eks,search,Warning,FreeDiskSpaceFailed,Failed to garbage collect on node ip-10-40-81-216,Pod,search-api-d416b43-7cb20,controllermanager,2026-06-19 22:45:51,2026-06-20 00:06:51,3,2026-06-23 12:00:00
318,prod-use2-eks,payments,Warning,Evicted,Pod payments-api-7fa4649-debd8 evicted: node memory pressure,Pod,payments-api-7fa4649-debd8,kubelet,2026-06-22 17:14:38,2026-06-22 18:30:38,32,2026-06-23 12:00:00
319,prod-usw2-eks,identity,Warning,FreeDiskSpaceFailed,Failed to garbage collect on node ip-10-14-16-161,Pod,session-store-28ebc77-cf7c8,controllermanager,2026-06-14 23:10:06,2026-06-15 00:00:06,34,2026-06-23 12:00:00
320,prod-use2-eks,checkout,Normal,Started,Started container checkout-web,Pod,checkout-web-47df111-4e24c,default-scheduler,2026-06-14 07:57:07,2026-06-14 09:49:07,1,2026-06-23 12:00:00
321,prod-usw2-eks,orders,Warning,OOMKilling,Memory cgroup out of memory: Killed process in orders-api-cbca488-26609,Pod,orders-api-cbca488-26609,default-scheduler,2026-06-16 20:52:18,2026-06-16 21:59:18,3,2026-06-23 12:00:00
322,prod-use2-eks,checkout,Normal,Started,Started container checkout-web,Pod,checkout-web-47df111-4e24c,controllermanager,2026-06-04 09:26:16,2026-06-04 10:34:16,1,2026-06-23 12:00:00
323,prod-usw2-eks,payments,Warning,OOMKilling,Container payments-api exceeded memory limit; OOMKilled,Pod,payments-api-423b015-b80bd,kubelet,2026-06-01 14:04:28,2026-06-01 14:35:28,39,2026-06-23 12:00:00
324,prod-usw2-eks,payments,Warning,Evicted,Pod payments-api-1e23165-1e35b evicted: node memory pressure,Pod,payments-api-1e23165-1e35b,kubelet,2026-06-22 20:29:42,2026-06-22 21:58:42,34,2026-06-23 12:00:00
325,staging-use2-eks,identity,Warning,Unhealthy,Readiness probe errored: dial tcp i/o timeout for session-store-a097c68-649a1,Pod,session-store-a097c68-649a1,kubelet,2026-06-13 14:44:02,2026-06-13 14:51:02,30,2026-06-23 12:00:00
326,dr-use1-eks,orders,Warning,DNSConfigForming,Search line limits exceeded for orders-api-8330e48-f22f4,Pod,orders-api-8330e48-f22f4,controllermanager,2026-06-07 13:54:25,2026-06-07 15:46:25,1,2026-06-23 12:00:00
327,prod-use2-eks,search,Normal,Started,Started container search-api,Pod,search-api-eff0684-a368a,kubelet,2026-06-01 05:26:55,2026-06-01 06:06:55,1,2026-06-23 12:00:00
328,staging-use2-eks,identity,Warning,Unhealthy,Readiness probe errored: dial tcp i/o timeout for session-store-a097c68-649a1,Pod,session-store-a097c68-649a1,kubelet,2026-06-12 08:25:19,2026-06-12 10:16:19,34,2026-06-23 12:00:00
329,prod-usw2-eks,checkout,Warning,FreeDiskSpaceFailed,Failed to garbage collect on node ip-10-6-194-142,Pod,cart-svc-ee38458-64d46,default-scheduler,2026-06-05 06:31:03,2026-06-05 07:30:03,19,2026-06-23 12:00:00
330,prod-usw2-eks,payments,Normal,Pulled,Container image pulled for payments-worker,Pod,payments-worker-b4be648-d2dcb,default-scheduler,2026-06-15 11:09:46,2026-06-15 12:59:46,1,2026-06-23 12:00:00
331,prod-use2-eks,payments,Warning,OOMKilling,Container payments-api exceeded memory limit; OOMKilled,Pod,payments-api-1ce3577-591ac,default-scheduler,2026-06-22 16:40:37,2026-06-22 17:05:37,9,2026-06-23 12:00:00
332,prod-usw2-eks,search,Warning,FreeDiskSpaceFailed,Failed to garbage collect on node ip-10-14-16-161,Pod,search-api-8352074-5b766,controllermanager,2026-06-15 09:50:09,2026-06-15 10:08:09,22,2026-06-23 12:00:00
333,prod-usw2-eks,ledger,Warning,FreeDiskSpaceFailed,Failed to garbage collect on node ip-10-6-194-142,Pod,ledger-svc-0744083-43011,kubelet,2026-06-21 22:30:46,2026-06-22 00:22:46,5,2026-06-23 12:00:00
334,prod-use2-eks,search,Normal,Started,Started container search-api,Pod,search-api-eff0684-a368a,kubelet,2026-06-08 04:14:52,2026-06-08 05:15:52,1,2026-06-23 12:00:00
335,prod-use2-eks,identity,Warning,Evicted,Pod session-store-1ac5266-1ca26 evicted: node memory pressure,Pod,session-store-1ac5266-1ca26,controllermanager,2026-06-10 01:57:07,2026-06-10 02:30:07,20,2026-06-23 12:00:00
336,prod-usw2-eks,orders,Warning,OOMKilling,Memory cgroup out of memory: Killed process in orders-api-cbca488-26609,Pod,orders-api-cbca488-26609,kubelet,2026-06-19 12:04:42,2026-06-19 13:10:42,31,2026-06-23 12:00:00
337,prod-use2-eks,checkout,Warning,BackOff,Back-off restarting failed container checkout-web in pod checkout-web-c2eb578-2d181,Pod,checkout-web-c2eb578-2d181,default-scheduler,2026-06-09 12:57:26,2026-06-09 13:24:26,17,2026-06-23 12:00:00
338,prod-usw2-eks,payments,Warning,Unhealthy,Liveness probe failed: HTTP 500 for payments-worker-bbc0947-0aa1a,Pod,payments-worker-bbc0947-0aa1a,controllermanager,2026-06-07 02:45:11,2026-06-07 04:00:11,31,2026-06-23 12:00:00
339,prod-use2-eks,platform,Warning,Unhealthy,Readiness probe errored: dial tcp i/o timeout for image-resizer-9994630-7c707,Pod,image-resizer-9994630-7c707,controllermanager,2026-06-23 07:29:43,2026-06-23 09:05:43,23,2026-06-23 12:00:00
340,prod-usw2-eks,ledger,Warning,Evicted,Pod ledger-svc-842cd31-95bfa evicted: node was low on resource ephemeral-storage,Pod,ledger-svc-842cd31-95bfa,default-scheduler,2026-06-18 10:20:45,2026-06-18 10:23:45,12,2026-06-23 12:00:00
341,staging-use2-eks,payments,Warning,FreeDiskSpaceFailed,Failed to garbage collect on node ip-10-20-108-255,Pod,payments-api-2729261-453da,kubelet,2026-06-06 23:07:25,2026-06-07 00:08:25,31,2026-06-23 12:00:00
342,staging-use2-eks,search,Normal,Started,Started container recommendation,Pod,recommendation-2071c72-c0b22,kubelet,2026-06-09 18:03:39,2026-06-09 20:03:39,1,2026-06-23 12:00:00
343,prod-use2-eks,search,Normal,Scheduled,Successfully assigned indexer-4680271-0a829 to ip-10-17-79-110,Pod,indexer-4680271-0a829,default-scheduler,2026-06-19 23:47:35,2026-06-20 01:45:35,1,2026-06-23 12:00:00
344,prod-use2-eks,inventory,Normal,Started,Started container inventory-svc,Pod,inventory-svc-df6d343-0a45b,kubelet,2026-05-27 19:02:48,2026-05-27 20:04:48,1,2026-06-23 12:00:00
345,prod-use2-eks,kube-system,Warning,DNSConfigForming,Search line limits exceeded for metrics-server-e2e6924-29c37,Pod,metrics-server-e2e6924-29c37,controllermanager,2026-06-22 17:55:14,2026-06-22 19:29:14,7,2026-06-23 12:00:00
346,dr-use1-eks,search,Warning,Evicted,Pod search-api-d416b43-7cb20 evicted: node was low on resource ephemeral-storage,Pod,search-api-d416b43-7cb20,default-scheduler,2026-06-10 10:35:49,2026-06-10 10:36:49,33,2026-06-23 12:00:00
347,prod-usw2-eks,ledger,Warning,Evicted,Pod ledger-svc-0744083-43011 evicted: node was low on resource ephemeral-storage,Pod,ledger-svc-0744083-43011,kubelet,2026-06-19 02:42:41,2026-06-19 04:02:41,5,2026-06-23 12:00:00
348,prod-usw2-eks,payments,Warning,Evicted,Pod payments-api-b9a1287-dbbfe evicted: node memory pressure,Pod,payments-api-b9a1287-dbbfe,default-scheduler,2026-05-30 18:29:00,2026-05-30 19:03:00,2,2026-06-23 12:00:00
349,prod-use2-eks,payments,Normal,Pulled,Container image pulled for payments-worker,Pod,payments-worker-7a57672-86691,controllermanager,2026-06-09 07:57:05,2026-06-09 09:24:05,1,2026-06-23 12:00:00
350,prod-usw2-eks,payments,Warning,Unhealthy,Liveness probe failed: HTTP 500 for payments-worker-bbc0947-0aa1a,Pod,payments-worker-bbc0947-0aa1a,kubelet,2026-06-16 11:36:44,2026-06-16 13:19:44,33,2026-06-23 12:00:00
351,prod-use2-eks,checkout,Warning,Evicted,Pod cart-svc-26a7d77-aafdc evicted: node memory pressure,Pod,cart-svc-26a7d77-aafdc,default-scheduler,2026-06-17 13:44:58,2026-06-17 15:08:58,28,2026-06-23 12:00:00
352,prod-usw2-eks,ledger,Warning,Evicted,Pod ledger-svc-842cd31-95bfa evicted: node was low on resource ephemeral-storage,Pod,ledger-svc-842cd31-95bfa,controllermanager,2026-06-22 08:46:57,2026-06-22 09:02:57,17,2026-06-23 12:00:00
353,prod-usw2-eks,orders,Warning,Evicted,Pod orders-worker-b907131-2627d evicted: node was low on resource ephemeral-storage,Pod,orders-worker-b907131-2627d,kubelet,2026-06-21 04:42:24,2026-06-21 06:32:24,13,2026-06-23 12:00:00
354,staging-use2-eks,payments,Warning,Evicted,Pod payments-api-2729261-453da evicted: node was low on resource ephemeral-storage,Pod,payments-api-2729261-453da,default-scheduler,2026-06-18 07:56:42,2026-06-18 08:27:42,25,2026-06-23 12:00:00
355,prod-use2-eks,orders,Warning,Evicted,Pod orders-api-7f89525-97cdd evicted: node memory pressure,Pod,orders-api-7f89525-97cdd,default-scheduler,2026-06-14 21:47:46,2026-06-14 23:22:46,34,2026-06-23 12:00:00
356,staging-use2-eks,checkout,Warning,Rebooted,Node ip-10-8-126-134 has been rebooted,Pod,checkout-web-2b77739-52fdd,kubelet,2026-06-23 10:52:53,2026-06-23 12:02:53,18,2026-06-23 12:00:00
357,prod-usw2-eks,search,Warning,FreeDiskSpaceFailed,Failed to garbage collect on node ip-10-14-16-161,Pod,search-api-8352074-5b766,kubelet,2026-06-23 11:04:48,2026-06-23 11:07:48,38,2026-06-23 12:00:00
358,prod-use2-eks,search,Normal,Started,Started container indexer,Pod,indexer-4680271-0a829,controllermanager,2026-05-25 12:14:43,2026-05-25 14:07:43,1,2026-06-23 12:00:00
359,prod-use2-eks,payments,Warning,Evicted,Pod payments-api-58c5e74-26d34 evicted: node memory pressure,Pod,payments-api-58c5e74-26d34,controllermanager,2026-06-22 15:05:50,2026-06-22 16:44:50,40,2026-06-23 12:00:00
360,prod-usw2-eks,kube-system,Warning,DNSConfigForming,Search line limits exceeded for coredns-4a8b365-1d9fc,Pod,coredns-4a8b365-1d9fc,kubelet,2026-06-18 00:43:19,2026-06-18 02:00:19,3,2026-06-23 12:00:00
361,prod-usw2-eks,checkout,Warning,FreeDiskSpaceFailed,Failed to garbage collect on node ip-10-29-63-193,Pod,cart-svc-0a94879-c1bba,kubelet,2026-06-09 07:00:15,2026-06-09 08:16:15,15,2026-06-23 12:00:00
362,prod-use2-eks,checkout,Warning,BackOff,Back-off restarting failed container checkout-web in pod checkout-web-c2eb578-2d181,Pod,checkout-web-c2eb578-2d181,default-scheduler,2026-06-07 20:39:44,2026-06-07 21:12:44,26,2026-06-23 12:00:00
363,dr-use1-eks,notifications,Warning,BackOff,Back-off restarting failed container notifications in pod notifications-b036879-82982,Pod,notifications-b036879-82982,controllermanager,2026-06-21 17:07:08,2026-06-21 18:22:08,39,2026-06-23 12:00:00
364,prod-use2-eks,platform,Normal,Pulled,Container image pulled for config-svc,Pod,config-svc-ddd1723-06ca5,kubelet,2026-06-22 06:34:57,2026-06-22 08:16:57,1,2026-06-23 12:00:00
365,prod-usw2-eks,orders,Warning,Evicted,Pod orders-worker-b907131-2627d evicted: node was low on resource ephemeral-storage,Pod,orders-worker-b907131-2627d,kubelet,2026-06-23 01:09:35,2026-06-23 01:27:35,2,2026-06-23 12:00:00
366,prod-usw2-eks,checkout,Warning,FreeDiskSpaceFailed,Failed to garbage collect on node ip-10-6-194-142,Pod,cart-svc-ee38458-64d46,default-scheduler,2026-06-05 11:29:26,2026-06-05 11:29:26,36,2026-06-23 12:00:00
367,prod-use2-eks,identity,Normal,Scheduled,Successfully assigned auth-gateway-ec6b034-0575b to ip-10-6-44-216,Pod,auth-gateway-ec6b034-0575b,controllermanager,2026-05-26 20:26:16,2026-05-26 20:43:16,1,2026-06-23 12:00:00
368,prod-usw2-eks,kube-system,Warning,Rebooted,Node ip-10-6-194-142 has been rebooted,Pod,metrics-server-6162d13-d4a14,kubelet,2026-06-22 20:51:19,2026-06-22 21:29:19,9,2026-06-23 12:00:00
369,prod-use2-eks,identity,Warning,OOMKilling,Container session-store exceeded memory limit; OOMKilled,Pod,session-store-1ac5266-1ca26,default-scheduler,2026-06-16 22:17:44,2026-06-16 22:55:44,4,2026-06-23 12:00:00
370,prod-usw2-eks,ledger,Warning,FreeDiskSpaceFailed,Failed to garbage collect on node ip-10-6-194-142,Pod,ledger-svc-0744083-43011,default-scheduler,2026-06-16 18:41:08,2026-06-16 19:37:08,34,2026-06-23 12:00:00
371,prod-usw2-eks,orders,Warning,Unhealthy,Liveness probe failed: HTTP 500 for orders-api-402bb51-ad48f,Pod,orders-api-402bb51-ad48f,controllermanager,2026-06-18 09:51:16,2026-06-18 11:34:16,14,2026-06-23 12:00:00
372,prod-usw2-eks,kube-system,Warning,Unhealthy,Readiness probe errored: dial tcp i/o timeout for coredns-37f1521-4cd3d,Pod,coredns-37f1521-4cd3d,controllermanager,2026-06-18 18:11:41,2026-06-18 19:38:41,22,2026-06-23 12:00:00
373,prod-usw2-eks,identity,Warning,Evicted,Pod session-store-28ebc77-cf7c8 evicted: node was low on resource ephemeral-storage,Pod,session-store-28ebc77-cf7c8,controllermanager,2026-06-06 20:44:32,2026-06-06 21:04:32,6,2026-06-23 12:00:00
374,staging-use2-eks,payments,Warning,Evicted,Pod payments-api-2729261-453da evicted: node was low on resource ephemeral-storage,Pod,payments-api-2729261-453da,default-scheduler,2026-06-17 15:45:00,2026-06-17 17:44:00,9,2026-06-23 12:00:00
375,prod-use2-eks,identity,Normal,Started,Started container auth-gateway,Pod,auth-gateway-ec6b034-0575b,kubelet,2026-06-04 03:37:32,2026-06-04 04:41:32,1,2026-06-23 12:00:00
376,staging-use2-eks,payments,Normal,Pulled,Container image pulled for payments-api,Pod,payments-api-dde4d16-a3d09,default-scheduler,2026-06-07 17:36:21,2026-06-07 19:03:21,1,2026-06-23 12:00:00
377,prod-usw2-eks,orders,Warning,Evicted,Pod orders-worker-8482791-f2d9f evicted: node was low on resource ephemeral-storage,Pod,orders-worker-8482791-f2d9f,controllermanager,2026-06-19 12:52:43,2026-06-19 12:57:43,22,2026-06-23 12:00:00
378,dr-use1-eks,checkout,Warning,OOMKilling,Container checkout-web exceeded memory limit; OOMKilled,Pod,checkout-web-6e9e217-a5c79,default-scheduler,2026-06-21 08:24:02,2026-06-21 10:12:02,40,2026-06-23 12:00:00
379,prod-usw2-eks,platform,Normal,Started,Started container config-svc,Pod,config-svc-370d832-a686a,kubelet,2026-06-07 02:30:26,2026-06-07 03:56:26,1,2026-06-23 12:00:00
380,prod-use2-eks,payments,Warning,Evicted,Pod payments-api-58c5e74-26d34 evicted: node memory pressure,Pod,payments-api-58c5e74-26d34,controllermanager,2026-06-22 23:56:51,2026-06-23 01:30:51,19,2026-06-23 12:00:00
381,prod-usw2-eks,platform,Normal,Pulled,Container image pulled for image-resizer,Pod,image-resizer-9683178-b7560,controllermanager,2026-06-15 14:42:28,2026-06-15 15:55:28,1,2026-06-23 12:00:00
382,prod-use2-eks,checkout,Warning,Evicted,Pod cart-svc-26a7d77-aafdc evicted: node memory pressure,Pod,cart-svc-26a7d77-aafdc,kubelet,2026-06-16 23:08:15,2026-06-16 23:38:15,19,2026-06-23 12:00:00
383,prod-use2-eks,payments,Warning,Evicted,Pod payments-api-c9c2b74-00142 evicted: node memory pressure,Pod,payments-api-c9c2b74-00142,controllermanager,2026-06-23 10:20:17,2026-06-23 12:19:17,27,2026-06-23 12:00:00
384,staging-use2-eks,notifications,Normal,Pulled,Container image pulled for notifications,Pod,notifications-26e9347-44fc8,kubelet,2026-06-11 12:57:38,2026-06-11 13:44:38,1,2026-06-23 12:00:00
385,prod-usw2-eks,orders,Warning,Evicted,Pod orders-worker-b907131-2627d evicted: node was low on resource ephemeral-storage,Pod,orders-worker-b907131-2627d,controllermanager,2026-06-22 15:45:22,2026-06-22 16:02:22,33,2026-06-23 12:00:00
386,prod-usw2-eks,payments,Warning,OOMKilling,Memory cgroup out of memory: Killed process in payments-worker-bbc0947-0aa1a,Pod,payments-worker-bbc0947-0aa1a,default-scheduler,2026-06-17 15:53:18,2026-06-17 17:31:18,20,2026-06-23 12:00:00
387,prod-usw2-eks,checkout,Warning,FreeDiskSpaceFailed,Failed to garbage collect on node ip-10-6-194-142,Pod,cart-svc-ee38458-64d46,default-scheduler,2026-06-21 23:30:37,2026-06-22 00:43:37,18,2026-06-23 12:00:00
388,prod-use2-eks,kube-system,Warning,DNSConfigForming,Search line limits exceeded for metrics-server-e2e6924-29c37,Pod,metrics-server-e2e6924-29c37,kubelet,2026-06-21 05:32:50,2026-06-21 05:59:50,8,2026-06-23 12:00:00
389,prod-use2-eks,checkout,Warning,OOMKilling,Memory cgroup out of memory: Killed process in checkout-web-0101b48-2b2af,Pod,checkout-web-0101b48-2b2af,default-scheduler,2026-06-17 01:59:24,2026-06-17 03:15:24,16,2026-06-23 12:00:00
390,prod-use2-eks,payments,Warning,OOMKilling,Container payments-api exceeded memory limit; OOMKilled,Pod,payments-api-1ce3577-591ac,default-scheduler,2026-06-22 23:28:37,2026-06-23 01:22:37,19,2026-06-23 12:00:00
391,prod-use2-eks,notifications,Normal,Started,Started container notifications,Pod,notifications-c882a21-88bb7,controllermanager,2026-06-19 17:57:09,2026-06-19 19:25:09,1,2026-06-23 12:00:00
392,prod-usw2-eks,orders,Warning,OOMKilling,Memory cgroup out of memory: Killed process in orders-api-cbca488-26609,Pod,orders-api-cbca488-26609,default-scheduler,2026-06-22 18:46:27,2026-06-22 19:40:27,7,2026-06-23 12:00:00
393,prod-usw2-eks,ledger,Warning,FreeDiskSpaceFailed,Failed to garbage collect on node ip-10-6-194-142,Pod,ledger-svc-842cd31-95bfa,kubelet,2026-06-21 16:18:49,2026-06-21 16:37:49,32,2026-06-23 12:00:00
394,prod-usw2-eks,inventory,Normal,Scheduled,Successfully assigned inventory-svc-0d33458-c137f to ip-10-15-83-236,Pod,inventory-svc-0d33458-c137f,kubelet,2026-06-06 06:03:36,2026-06-06 08:02:36,1,2026-06-23 12:00:00
395,prod-usw2-eks,orders,Warning,OOMKilling,Memory cgroup out of memory: Killed process in orders-api-21c5d48-15186,Pod,orders-api-21c5d48-15186,controllermanager,2026-06-18 09:47:02,2026-06-18 11:28:02,40,2026-06-23 12:00:00
396,prod-use2-eks,ledger,Warning,Unhealthy,Readiness probe failed: timeout for ledger-svc-f4a6d64-16dde,Pod,ledger-svc-f4a6d64-16dde,default-scheduler,2026-06-22 01:29:56,2026-06-22 01:47:56,10,2026-06-23 12:00:00
397,prod-usw2-eks,payments,Warning,Evicted,Pod payments-api-b9a1287-dbbfe evicted: node memory pressure,Pod,payments-api-b9a1287-dbbfe,default-scheduler,2026-06-01 21:03:59,2026-06-01 22:47:59,5,2026-06-23 12:00:00
398,prod-use2-eks,identity,Normal,Started,Started container auth-gateway,Pod,auth-gateway-7b28269-a7447,default-scheduler,2026-06-12 07:52:58,2026-06-12 08:05:58,1,2026-06-23 12:00:00
399,dr-use1-eks,search,Warning,Evicted,Pod search-api-be84964-d972c evicted: node was low on resource ephemeral-storage,Pod,search-api-be84964-d972c,default-scheduler,2026-05-29 22:18:33,2026-05-29 23:01:33,19,2026-06-23 12:00:00
400,staging-use2-eks,inventory,Warning,Evicted,Pod inventory-svc-1d6f570-1b50d evicted: node memory pressure,Pod,inventory-svc-1d6f570-1b50d,default-scheduler,2026-06-17 07:21:42,2026-06-17 09:14:42,40,2026-06-23 12:00:00
401,dr-use1-eks,search,Warning,FreeDiskSpaceFailed,Failed to garbage collect on node ip-10-40-81-216,Pod,search-api-be84964-d972c,default-scheduler,2026-06-18 07:58:05,2026-06-18 09:09:05,8,2026-06-23 12:00:00
402,prod-usw2-eks,checkout,Warning,Evicted,Pod cart-svc-0a94879-c1bba evicted: node was low on resource ephemeral-storage,Pod,cart-svc-0a94879-c1bba,controllermanager,2026-06-05 05:10:27,2026-06-05 07:00:27,31,2026-06-23 12:00:00
403,prod-usw2-eks,payments,Warning,OOMKilling,Container payments-api exceeded memory limit; OOMKilled,Pod,payments-api-423b015-b80bd,default-scheduler,2026-06-11 15:50:53,2026-06-11 17:27:53,40,2026-06-23 12:00:00
404,staging-use2-eks,identity,Warning,Unhealthy,Readiness probe errored: dial tcp i/o timeout for session-store-a097c68-649a1,Pod,session-store-a097c68-649a1,controllermanager,2026-06-05 05:50:38,2026-06-05 05:56:38,27,2026-06-23 12:00:00
405,prod-use2-eks,orders,Normal,Pulled,Container image pulled for orders-worker,Pod,orders-worker-9681c18-374c7,default-scheduler,2026-05-27 03:55:55,2026-05-27 05:22:55,1,2026-06-23 12:00:00
406,prod-use2-eks,platform,Warning,Unhealthy,Readiness probe failed: timeout for config-svc-027a395-39a4d,Pod,config-svc-027a395-39a4d,default-scheduler,2026-06-17 19:10:47,2026-06-17 20:24:47,38,2026-06-23 12:00:00
407,prod-usw2-eks,payments,Warning,Evicted,Pod payments-api-b9a1287-dbbfe evicted: node memory pressure,Pod,payments-api-b9a1287-dbbfe,controllermanager,2026-06-20 11:03:03,2026-06-20 11:34:03,40,2026-06-23 12:00:00
408,prod-usw2-eks,checkout,Warning,FreeDiskSpaceFailed,Failed to garbage collect on node ip-10-29-63-193,Pod,cart-svc-0a94879-c1bba,controllermanager,2026-06-01 08:53:31,2026-06-01 09:57:31,37,2026-06-23 12:00:00
409,prod-usw2-eks,checkout,Warning,Evicted,Pod cart-svc-882ca58-64a75 evicted: node was low on resource ephemeral-storage,Pod,cart-svc-882ca58-64a75,default-scheduler,2026-06-23 00:42:55,2026-06-23 01:29:55,3,2026-06-23 12:00:00
410,prod-usw2-eks,identity,Warning,Evicted,Pod session-store-28ebc77-cf7c8 evicted: node was low on resource ephemeral-storage,Pod,session-store-28ebc77-cf7c8,kubelet,2026-06-12 18:48:04,2026-06-12 19:35:04,6,2026-06-23 12:00:00
411,prod-use2-eks,checkout,Warning,BackOff,Back-off restarting failed container checkout-web in pod checkout-web-c343d41-6a8d2,Pod,checkout-web-c343d41-6a8d2,kubelet,2026-06-03 01:46:11,2026-06-03 01:50:11,19,2026-06-23 12:00:00
412,prod-use2-eks,checkout,Warning,OOMKilling,Container cart-svc exceeded memory limit; OOMKilled,Pod,cart-svc-26a7d77-aafdc,default-scheduler,2026-06-20 06:37:41,2026-06-20 07:08:41,37,2026-06-23 12:00:00
413,prod-use2-eks,payments,Warning,OOMKilling,Container payments-api exceeded memory limit; OOMKilled,Pod,payments-api-1ce3577-591ac,controllermanager,2026-06-23 09:45:58,2026-06-23 10:56:58,16,2026-06-23 12:00:00
414,prod-usw2-eks,orders,Warning,Evicted,Pod orders-worker-8482791-f2d9f evicted: node was low on resource ephemeral-storage,Pod,orders-worker-8482791-f2d9f,controllermanager,2026-06-23 03:55:08,2026-06-23 05:03:08,5,2026-06-23 12:00:00
415,prod-usw2-eks,orders,Warning,FreeDiskSpaceFailed,Failed to garbage collect on node ip-10-14-16-161,Pod,orders-worker-8482791-f2d9f,controllermanager,2026-06-19 05:14:56,2026-06-19 05:26:56,29,2026-06-23 12:00:00
416,prod-usw2-eks,payments,Warning,Evicted,Pod payments-api-423b015-b80bd evicted: node memory pressure,Pod,payments-api-423b015-b80bd,controllermanager,2026-06-08 04:57:18,2026-06-08 06:49:18,16,2026-06-23 12:00:00
417,staging-use2-eks,kube-system,Normal,Scheduled,Successfully assigned coredns-b16ea15-07544 to ip-10-8-126-134,Pod,coredns-b16ea15-07544,controllermanager,2026-06-15 16:11:12,2026-06-15 16:40:12,1,2026-06-23 12:00:00
418,prod-usw2-eks,search,Normal,Scheduled,Successfully assigned recommendation-87e3198-026ea to ip-10-15-83-236,Pod,recommendation-87e3198-026ea,kubelet,2026-05-30 01:37:40,2026-05-30 03:12:40,1,2026-06-23 12:00:00
419,prod-usw2-eks,payments,Warning,OOMKilling,Memory cgroup out of memory: Killed process in payments-worker-1d1bf52-dff66,Pod,payments-worker-1d1bf52-dff66,controllermanager,2026-06-09 23:15:09,2026-06-10 00:59:09,10,2026-06-23 12:00:00
420,prod-use2-eks,ledger,Warning,Unhealthy,Readiness probe failed: timeout for ledger-svc-f4a6d64-16dde,Pod,ledger-svc-f4a6d64-16dde,kubelet,2026-06-18 14:23:13,2026-06-18 16:01:13,36,2026-06-23 12:00:00
421,prod-use2-eks,checkout,Warning,OOMKilling,Memory cgroup out of memory: Killed process in checkout-web-c2eb578-2d181,Pod,checkout-web-c2eb578-2d181,default-scheduler,2026-06-13 17:38:22,2026-06-13 18:08:22,28,2026-06-23 12:00:00
422,staging-use2-eks,inventory,Warning,Evicted,Pod inventory-svc-1d6f570-1b50d evicted: node memory pressure,Pod,inventory-svc-1d6f570-1b50d,default-scheduler,2026-06-18 21:18:00,2026-06-18 22:14:00,36,2026-06-23 12:00:00
423,prod-use2-eks,platform,Warning,DNSConfigForming,Search line limits exceeded for image-resizer-9994630-7c707,Pod,image-resizer-9994630-7c707,default-scheduler,2026-06-22 03:30:50,2026-06-22 04:19:50,11,2026-06-23 12:00:00
424,prod-usw2-eks,checkout,Warning,Evicted,Pod cart-svc-0a94879-c1bba evicted: node was low on resource ephemeral-storage,Pod,cart-svc-0a94879-c1bba,default-scheduler,2026-06-07 13:36:11,2026-06-07 15:20:11,17,2026-06-23 12:00:00
425,dr-use1-eks,notifications,Warning,Unhealthy,Liveness probe failed: HTTP 500 for notifications-b036879-82982,Pod,notifications-b036879-82982,kubelet,2026-06-22 19:03:44,2026-06-22 19:14:44,22,2026-06-23 12:00:00
426,prod-use2-eks,kube-system,Warning,FreeDiskSpaceFailed,Failed to garbage collect on node ip-10-6-44-216,Pod,coredns-47d4438-c55d7,kubelet,2026-06-12 14:00:20,2026-06-12 15:18:20,10,2026-06-23 12:00:00
427,dr-use1-eks,checkout,Warning,OOMKilling,Container checkout-web exceeded memory limit; OOMKilled,Pod,checkout-web-4263246-52f3a,kubelet,2026-06-21 14:38:46,2026-06-21 16:26:46,38,2026-06-23 12:00:00
428,prod-usw2-eks,search,Warning,FreeDiskSpaceFailed,Failed to garbage collect on node ip-10-14-16-161,Pod,search-api-8352074-5b766,default-scheduler,2026-06-15 10:50:32,2026-06-15 11:39:32,38,2026-06-23 12:00:00
429,staging-use2-eks,identity,Warning,Unhealthy,Readiness probe errored: dial tcp i/o timeout for session-store-a097c68-649a1,Pod,session-store-a097c68-649a1,controllermanager,2026-06-22 17:21:42,2026-06-22 18:29:42,8,2026-06-23 12:00:00
430,prod-use2-eks,identity,Warning,OOMKilling,Container session-store exceeded memory limit; OOMKilled,Pod,session-store-1ac5266-1ca26,default-scheduler,2026-06-12 00:31:58,2026-06-12 01:20:58,9,2026-06-23 12:00:00
431,prod-use2-eks,identity,Warning,OOMKilling,Container session-store exceeded memory limit; OOMKilled,Pod,session-store-4732511-0dba8,default-scheduler,2026-06-22 00:49:03,2026-06-22 01:15:03,15,2026-06-23 12:00:00
432,prod-usw2-eks,search,Normal,Started,Started container recommendation,Pod,recommendation-1e52697-e4756,kubelet,2026-06-16 16:56:50,2026-06-16 17:45:50,1,2026-06-23 12:00:00
433,prod-use2-eks,orders,Warning,OOMKilling,Container orders-api exceeded memory limit; OOMKilled,Pod,orders-api-bfb2f93-32ad3,default-scheduler,2026-06-15 06:49:44,2026-06-15 08:19:44,32,2026-06-23 12:00:00
434,prod-usw2-eks,orders,Warning,FreeDiskSpaceFailed,Failed to garbage collect on node ip-10-14-16-161,Pod,orders-worker-8482791-f2d9f,kubelet,2026-06-20 11:42:27,2026-06-20 13:40:27,16,2026-06-23 12:00:00
435,prod-use2-eks,platform,Warning,DNSConfigForming,Search line limits exceeded for image-resizer-7bb3c89-50e74,Pod,image-resizer-7bb3c89-50e74,controllermanager,2026-06-22 01:24:46,2026-06-22 03:03:46,21,2026-06-23 12:00:00
436,prod-usw2-eks,payments,Warning,Evicted,Pod payments-api-b9a1287-dbbfe evicted: node memory pressure,Pod,payments-api-b9a1287-dbbfe,controllermanager,2026-06-18 19:17:42,2026-06-18 20:06:42,30,2026-06-23 12:00:00
437,prod-use2-eks,payments,Warning,OOMKilling,Container payments-api exceeded memory limit; OOMKilled,Pod,payments-api-58c5e74-26d34,kubelet,2026-06-23 09:11:55,2026-06-23 10:59:55,22,2026-06-23 12:00:00
438,dr-use1-eks,search,Warning,FreeDiskSpaceFailed,Failed to garbage collect on node ip-10-40-81-216,Pod,search-api-d416b43-7cb20,controllermanager,2026-06-14 01:23:52,2026-06-14 02:17:52,31,2026-06-23 12:00:00
439,prod-use2-eks,checkout,Warning,Evicted,Pod cart-svc-26a7d77-aafdc evicted: node memory pressure,Pod,cart-svc-26a7d77-aafdc,kubelet,2026-06-14 20:13:39,2026-06-14 20:34:39,27,2026-06-23 12:00:00
440,prod-use2-eks,kube-system,Warning,DNSConfigForming,Search line limits exceeded for metrics-server-e2e6924-29c37,Pod,metrics-server-e2e6924-29c37,default-scheduler,2026-06-06 17:01:07,2026-06-06 17:25:07,28,2026-06-23 12:00:00
441,staging-use2-eks,identity,Warning,DNSConfigForming,Search line limits exceeded for session-store-a097c68-649a1,Pod,session-store-a097c68-649a1,default-scheduler,2026-06-08 00:30:53,2026-06-08 00:49:53,4,2026-06-23 12:00:00
442,prod-usw2-eks,ledger,Warning,FreeDiskSpaceFailed,Failed to garbage collect on node ip-10-14-16-161,Pod,ledger-svc-2014124-29b88,controllermanager,2026-06-18 17:11:12,2026-06-18 17:23:12,30,2026-06-23 12:00:00
443,prod-use2-eks,identity,Warning,OOMKilling,Container session-store exceeded memory limit; OOMKilled,Pod,session-store-4732511-0dba8,controllermanager,2026-06-12 02:55:21,2026-06-12 04:08:21,6,2026-06-23 12:00:00
444,prod-usw2-eks,identity,Warning,FreeDiskSpaceFailed,Failed to garbage collect on node ip-10-14-16-161,Pod,session-store-28ebc77-cf7c8,default-scheduler,2026-06-14 17:42:17,2026-06-14 18:34:17,2,2026-06-23 12:00:00
445,prod-use2-eks,orders,Normal,Scheduled,Successfully assigned orders-worker-06e2683-7270e to ip-10-17-79-110,Pod,orders-worker-06e2683-7270e,controllermanager,2026-05-31 05:08:04,2026-05-31 05:48:04,1,2026-06-23 12:00:00
446,prod-use2-eks,orders,Normal,Started,Started container orders-worker,Pod,orders-worker-6ee3345-b0d20,kubelet,2026-06-01 09:26:24,2026-06-01 11:22:24,1,2026-06-23 12:00:00
447,prod-use2-eks,search,Normal,Started,Started container indexer,Pod,indexer-4680271-0a829,default-scheduler,2026-06-10 09:06:40,2026-06-10 11:01:40,1,2026-06-23 12:00:00
448,prod-usw2-eks,ledger,Warning,Evicted,Pod ledger-svc-0744083-43011 evicted: node was low on resource ephemeral-storage,Pod,ledger-svc-0744083-43011,controllermanager,2026-06-16 12:13:23,2026-06-16 13:28:23,32,2026-06-23 12:00:00
449,prod-use2-eks,payments,Warning,Evicted,Pod payments-api-7fa4649-debd8 evicted: node memory pressure,Pod,payments-api-7fa4649-debd8,controllermanager,2026-06-22 14:27:47,2026-06-22 14:39:47,14,2026-06-23 12:00:00
450,prod-use2-eks,payments,Normal,Started,Started container payments-worker,Pod,payments-worker-6e38c94-75bbf,controllermanager,2026-06-17 12:17:17,2026-06-17 12:26:17,1,2026-06-23 12:00:00
451,prod-usw2-eks,orders,Warning,BackOff,Back-off restarting failed container orders-api in pod orders-api-402bb51-ad48f,Pod,orders-api-402bb51-ad48f,kubelet,2026-06-14 15:31:24,2026-06-14 16:48:24,10,2026-06-23 12:00:00
452,prod-use2-eks,checkout,Warning,Evicted,Pod cart-svc-527eb80-045c0 evicted: node memory pressure,Pod,cart-svc-527eb80-045c0,controllermanager,2026-06-17 12:52:23,2026-06-17 14:38:23,19,2026-06-23 12:00:00
453,prod-use2-eks,kube-system,Warning,Unhealthy,Readiness probe errored: dial tcp i/o timeout for metrics-server-e2e6924-29c37,Pod,metrics-server-e2e6924-29c37,default-scheduler,2026-06-10 23:13:10,2026-06-10 23:15:10,9,2026-06-23 12:00:00
454,prod-use2-eks,kube-system,Warning,FreeDiskSpaceFailed,Failed to garbage collect on node ip-10-32-13-101,Pod,coredns-e513a45-fb7bf,default-scheduler,2026-06-06 22:53:21,2026-06-06 23:20:21,8,2026-06-23 12:00:00
455,prod-usw2-eks,identity,Normal,Scheduled,Successfully assigned auth-gateway-7d2aa28-56f78 to ip-10-12-35-23,Pod,auth-gateway-7d2aa28-56f78,kubelet,2026-05-25 20:13:04,2026-05-25 21:33:04,1,2026-06-23 12:00:00
456,prod-usw2-eks,kube-system,Warning,DNSConfigForming,Search line limits exceeded for coredns-4a8b365-1d9fc,Pod,coredns-4a8b365-1d9fc,default-scheduler,2026-06-17 19:11:18,2026-06-17 19:20:18,3,2026-06-23 12:00:00
457,prod-usw2-eks,kube-system,Warning,Unhealthy,Readiness probe errored: dial tcp i/o timeout for coredns-37f1521-4cd3d,Pod,coredns-37f1521-4cd3d,kubelet,2026-06-22 19:56:31,2026-06-22 20:47:31,9,2026-06-23 12:00:00
458,prod-usw2-eks,orders,Warning,OOMKilling,Memory cgroup out of memory: Killed process in orders-api-cbca488-26609,Pod,orders-api-cbca488-26609,default-scheduler,2026-06-17 10:00:52,2026-06-17 10:14:52,13,2026-06-23 12:00:00
459,prod-usw2-eks,orders,Warning,BackOff,Back-off restarting failed container orders-api in pod orders-api-21c5d48-15186,Pod,orders-api-21c5d48-15186,kubelet,2026-06-23 04:35:00,2026-06-23 05:11:00,10,2026-06-23 12:00:00
460,prod-usw2-eks,checkout,Normal,Scheduled,Successfully assigned checkout-web-f628153-c1833 to ip-10-22-107-136,Pod,checkout-web-f628153-c1833,kubelet,2026-06-06 19:17:53,2026-06-06 20:59:53,1,2026-06-23 12:00:00
461,prod-usw2-eks,payments,Normal,Pulled,Container image pulled for payments-api,Pod,payments-api-6c2b997-3e07d,default-scheduler,2026-06-07 15:21:01,2026-06-07 17:10:01,1,2026-06-23 12:00:00
462,prod-use2-eks,checkout,Warning,BackOff,Back-off restarting failed container checkout-web in pod checkout-web-0101b48-2b2af,Pod,checkout-web-0101b48-2b2af,default-scheduler,2026-06-08 22:05:48,2026-06-08 22:48:48,27,2026-06-23 12:00:00
463,prod-usw2-eks,payments,Warning,OOMKilling,Container payments-api exceeded memory limit; OOMKilled,Pod,payments-api-423b015-b80bd,default-scheduler,2026-06-03 07:27:46,2026-06-03 08:10:46,21,2026-06-23 12:00:00
464,prod-usw2-eks,orders,Warning,BackOff,Back-off restarting failed container orders-api in pod orders-api-402bb51-ad48f,Pod,orders-api-402bb51-ad48f,default-scheduler,2026-06-22 12:38:18,2026-06-22 13:58:18,16,2026-06-23 12:00:00
465,prod-usw2-eks,kube-system,Warning,Unhealthy,Readiness probe errored: dial tcp i/o timeout for coredns-37f1521-4cd3d,Pod,coredns-37f1521-4cd3d,kubelet,2026-06-17 22:23:01,2026-06-17 22:23:01,21,2026-06-23 12:00:00
466,dr-use1-eks,checkout,Normal,Pulled,Container image pulled for cart-svc,Pod,cart-svc-da3cf51-00806,controllermanager,2026-06-20 14:27:45,2026-06-20 16:25:45,1,2026-06-23 12:00:00
467,prod-usw2-eks,orders,Warning,BackOff,Back-off restarting failed container orders-api in pod orders-api-402bb51-ad48f,Pod,orders-api-402bb51-ad48f,default-scheduler,2026-06-18 05:15:30,2026-06-18 06:14:30,1,2026-06-23 12:00:00
468,staging-use2-eks,search,Warning,Unhealthy,Readiness probe errored: dial tcp i/o timeout for search-api-1605640-8abaf,Pod,search-api-1605640-8abaf,controllermanager,2026-06-23 10:50:31,2026-06-23 11:56:31,6,2026-06-23 12:00:00
469,prod-usw2-eks,payments,Warning,Evicted,Pod payments-api-1e23165-1e35b evicted: node memory pressure,Pod,payments-api-1e23165-1e35b,kubelet,2026-06-19 23:37:45,2026-06-20 01:20:45,39,2026-06-23 12:00:00
470,prod-use2-eks,checkout,Warning,OOMKilling,Memory cgroup out of memory: Killed process in checkout-web-c2eb578-2d181,Pod,checkout-web-c2eb578-2d181,controllermanager,2026-06-18 14:42:15,2026-06-18 16:24:15,13,2026-06-23 12:00:00
471,prod-usw2-eks,search,Normal,Scheduled,Successfully assigned recommendation-87e3198-026ea to ip-10-15-83-236,Pod,recommendation-87e3198-026ea,default-scheduler,2026-05-25 00:01:21,2026-05-25 00:35:21,1,2026-06-23 12:00:00
472,prod-usw2-eks,kube-system,Warning,DNSConfigForming,Search line limits exceeded for coredns-4a8b365-1d9fc,Pod,coredns-4a8b365-1d9fc,default-scheduler,2026-06-23 07:03:17,2026-06-23 08:03:17,27,2026-06-23 12:00:00
473,dr-use1-eks,search,Warning,Rebooted,Node ip-10-21-57-150 has been rebooted,Pod,indexer-6af7422-f66fc,kubelet,2026-06-12 11:40:12,2026-06-12 13:30:12,13,2026-06-23 12:00:00
474,prod-usw2-eks,identity,Warning,Evicted,Pod session-store-28ebc77-cf7c8 evicted: node was low on resource ephemeral-storage,Pod,session-store-28ebc77-cf7c8,kubelet,2026-05-28 17:55:19,2026-05-28 18:45:19,18,2026-06-23 12:00:00
475,prod-usw2-eks,payments,Warning,Evicted,Pod payments-api-423b015-b80bd evicted: node memory pressure,Pod,payments-api-423b015-b80bd,controllermanager,2026-06-13 11:32:45,2026-06-13 11:46:45,22,2026-06-23 12:00:00
476,prod-use2-eks,checkout,Warning,Unhealthy,Liveness probe failed: HTTP 500 for checkout-web-0101b48-2b2af,Pod,checkout-web-0101b48-2b2af,controllermanager,2026-05-30 23:21:15,2026-05-31 01:16:15,5,2026-06-23 12:00:00
477,prod-usw2-eks,search,Normal,Pulled,Container image pulled for recommendation,Pod,recommendation-1e52697-e4756,kubelet,2026-06-09 19:56:54,2026-06-09 21:35:54,1,2026-06-23 12:00:00
478,prod-use2-eks,payments,Normal,Started,Started container payments-worker,Pod,payments-worker-bff7264-02c23,default-scheduler,2026-05-31 03:22:38,2026-05-31 04:12:38,1,2026-06-23 12:00:00
479,prod-usw2-eks,kube-system,Warning,Unhealthy,Readiness probe errored: dial tcp i/o timeout for coredns-4a8b365-1d9fc,Pod,coredns-4a8b365-1d9fc,kubelet,2026-06-18 10:55:02,2026-06-18 12:32:02,27,2026-06-23 12:00:00
480,prod-use2-eks,search,Normal,Pulled,Container image pulled for recommendation,Pod,recommendation-c460126-52814,default-scheduler,2026-06-14 18:14:28,2026-06-14 19:43:28,1,2026-06-23 12:00:00
481,prod-usw2-eks,orders,Warning,Evicted,Pod orders-worker-b907131-2627d evicted: node was low on resource ephemeral-storage,Pod,orders-worker-b907131-2627d,default-scheduler,2026-06-17 13:02:35,2026-06-17 13:17:35,35,2026-06-23 12:00:00
482,prod-use2-eks,ledger,Warning,Unhealthy,Readiness probe failed: timeout for ledger-svc-204e643-7d23b,Pod,ledger-svc-204e643-7d23b,kubelet,2026-06-19 20:59:37,2026-06-19 22:20:37,29,2026-06-23 12:00:00
483,prod-use2-eks,orders,Warning,Evicted,Pod orders-api-e9b4a39-c3784 evicted: node memory pressure,Pod,orders-api-e9b4a39-c3784,default-scheduler,2026-06-06 18:05:08,2026-06-06 18:12:08,18,2026-06-23 12:00:00
484,prod-use2-eks,search,Normal,Pulled,Container image pulled for indexer,Pod,indexer-4680271-0a829,controllermanager,2026-06-14 14:42:35,2026-06-14 15:03:35,1,2026-06-23 12:00:00
485,prod-usw2-eks,ledger,Warning,Evicted,Pod ledger-svc-842cd31-95bfa evicted: node was low on resource ephemeral-storage,Pod,ledger-svc-842cd31-95bfa,controllermanager,2026-06-22 07:40:33,2026-06-22 08:40:33,37,2026-06-23 12:00:00
486,prod-usw2-eks,checkout,Warning,FreeDiskSpaceFailed,Failed to garbage collect on node ip-10-6-194-142,Pod,cart-svc-882ca58-64a75,default-scheduler,2026-06-09 06:46:31,2026-06-09 07:34:31,7,2026-06-23 12:00:00
487,prod-use2-eks,kube-system,Warning,Unhealthy,Readiness probe errored: dial tcp i/o timeout for metrics-server-e2e6924-29c37,Pod,metrics-server-e2e6924-29c37,default-scheduler,2026-06-11 08:38:02,2026-06-11 10:12:02,7,2026-06-23 12:00:00
488,prod-usw2-eks,ledger,Warning,Evicted,Pod ledger-svc-0744083-43011 evicted: node was low on resource ephemeral-storage,Pod,ledger-svc-0744083-43011,kubelet,2026-06-15 04:08:12,2026-06-15 05:35:12,5,2026-06-23 12:00:00
489,prod-use2-eks,kube-system,Warning,Evicted,Pod coredns-47d4438-c55d7 evicted: node was low on resource ephemeral-storage,Pod,coredns-47d4438-c55d7,controllermanager,2026-06-19 08:57:20,2026-06-19 09:21:20,39,2026-06-23 12:00:00
490,prod-usw2-eks,checkout,Warning,Evicted,Pod cart-svc-0a94879-c1bba evicted: node was low on resource ephemeral-storage,Pod,cart-svc-0a94879-c1bba,default-scheduler,2026-06-11 17:58:25,2026-06-11 18:34:25,14,2026-06-23 12:00:00
491,prod-use2-eks,payments,Warning,Evicted,Pod payments-api-c9c2b74-00142 evicted: node memory pressure,Pod,payments-api-c9c2b74-00142,default-scheduler,2026-06-23 05:08:38,2026-06-23 05:52:38,3,2026-06-23 12:00:00
492,staging-use2-eks,identity,Warning,DNSConfigForming,Search line limits exceeded for session-store-a097c68-649a1,Pod,session-store-a097c68-649a1,kubelet,2026-06-22 03:30:45,2026-06-22 05:04:45,23,2026-06-23 12:00:00
493,prod-use2-eks,inventory,Normal,Pulled,Container image pulled for inventory-svc,Pod,inventory-svc-bfded25-1e6d2,controllermanager,2026-06-07 12:18:03,2026-06-07 13:21:03,1,2026-06-23 12:00:00
494,prod-usw2-eks,payments,Warning,Evicted,Pod payments-api-1e23165-1e35b evicted: node memory pressure,Pod,payments-api-1e23165-1e35b,default-scheduler,2026-05-27 17:48:54,2026-05-27 18:11:54,17,2026-06-23 12:00:00
495,prod-usw2-eks,orders,Warning,Unhealthy,Liveness probe failed: HTTP 500 for orders-api-21c5d48-15186,Pod,orders-api-21c5d48-15186,default-scheduler,2026-06-22 09:39:13,2026-06-22 09:57:13,21,2026-06-23 12:00:00
496,prod-usw2-eks,kube-system,Warning,Unhealthy,Readiness probe errored: dial tcp i/o timeout for coredns-4a8b365-1d9fc,Pod,coredns-4a8b365-1d9fc,controllermanager,2026-06-19 22:10:37,2026-06-19 23:54:37,38,2026-06-23 12:00:00
497,prod-use2-eks,payments,Warning,OOMKilling,Container payments-api exceeded memory limit; OOMKilled,Pod,payments-api-7fa4649-debd8,controllermanager,2026-06-23 11:27:39,2026-06-23 13:11:39,25,2026-06-23 12:00:00
498,prod-use2-eks,identity,Warning,Evicted,Pod session-store-1ac5266-1ca26 evicted: node memory pressure,Pod,session-store-1ac5266-1ca26,controllermanager,2026-06-16 02:36:56,2026-06-16 02:51:56,2,2026-06-23 12:00:00
499,prod-usw2-eks,checkout,Normal,Scheduled,Successfully assigned checkout-web-c2b3638-fa6d0 to ip-10-22-107-136,Pod,checkout-web-c2b3638-fa6d0,kubelet,2026-06-06 13:55:25,2026-06-06 15:10:25,1,2026-06-23 12:00:00
500,prod-usw2-eks,search,Warning,FreeDiskSpaceFailed,Failed to garbage collect on node ip-10-6-194-142,Pod,search-api-15a6d76-12766,controllermanager,2026-06-21 18:54:13,2026-06-21 19:02:13,1,2026-06-23 12:00:00
501,prod-use2-eks,payments,Warning,OOMKilling,Container payments-api exceeded memory limit; OOMKilled,Pod,payments-api-7fa4649-debd8,default-scheduler,2026-06-23 08:50:39,2026-06-23 10:18:39,9,2026-06-23 12:00:00
502,prod-use2-eks,checkout,Warning,Unhealthy,Liveness probe failed: HTTP 500 for checkout-web-c2eb578-2d181,Pod,checkout-web-c2eb578-2d181,default-scheduler,2026-05-30 17:16:22,2026-05-30 18:15:22,34,2026-06-23 12:00:00
503,staging-use2-eks,platform,Warning,FreeDiskSpaceFailed,Failed to garbage collect on node ip-10-8-126-134,Pod,config-svc-929cd33-16be4,default-scheduler,2026-06-20 08:01:47,2026-06-20 09:26:47,6,2026-06-23 12:00:00
504,prod-use2-eks,identity,Warning,Evicted,Pod session-store-4732511-0dba8 evicted: node memory pressure,Pod,session-store-4732511-0dba8,kubelet,2026-06-16 00:25:40,2026-06-16 01:37:40,7,2026-06-23 12:00:00
505,prod-usw2-eks,checkout,Warning,FreeDiskSpaceFailed,Failed to garbage collect on node ip-10-6-194-142,Pod,cart-svc-882ca58-64a75,default-scheduler,2026-06-07 13:34:39,2026-06-07 14:31:39,2,2026-06-23 12:00:00
506,prod-use2-eks,search,Normal,Started,Started container recommendation,Pod,recommendation-c460126-52814,controllermanager,2026-06-04 08:39:08,2026-06-04 10:21:08,1,2026-06-23 12:00:00
507,prod-use2-eks,identity,Warning,OOMKilling,Container session-store exceeded memory limit; OOMKilled,Pod,session-store-1ac5266-1ca26,kubelet,2026-06-10 14:26:15,2026-06-10 14:52:15,23,2026-06-23 12:00:00
508,prod-use2-eks,checkout,Warning,Unhealthy,Liveness probe failed: HTTP 500 for checkout-web-c2eb578-2d181,Pod,checkout-web-c2eb578-2d181,default-scheduler,2026-06-19 10:51:50,2026-06-19 12:24:50,30,2026-06-23 12:00:00
509,prod-usw2-eks,checkout,Warning,Evicted,Pod cart-svc-0a94879-c1bba evicted: node was low on resource ephemeral-storage,Pod,cart-svc-0a94879-c1bba,default-scheduler,2026-06-08 14:48:37,2026-06-08 15:33:37,4,2026-06-23 12:00:00
510,prod-usw2-eks,orders,Warning,FreeDiskSpaceFailed,Failed to garbage collect on node ip-10-14-16-161,Pod,orders-worker-b907131-2627d,default-scheduler,2026-06-22 18:41:31,2026-06-22 20:02:31,34,2026-06-23 12:00:00
511,prod-use2-eks,kube-system,Warning,Unhealthy,Readiness probe errored: dial tcp i/o timeout for metrics-server-e2e6924-29c37,Pod,metrics-server-e2e6924-29c37,default-scheduler,2026-06-15 01:17:44,2026-06-15 02:50:44,8,2026-06-23 12:00:00
512,prod-usw2-eks,orders,Warning,FreeDiskSpaceFailed,Failed to garbage collect on node ip-10-14-16-161,Pod,orders-worker-b907131-2627d,default-scheduler,2026-06-23 03:57:10,2026-06-23 04:54:10,19,2026-06-23 12:00:00
513,prod-use2-eks,kube-system,Warning,DNSConfigForming,Search line limits exceeded for metrics-server-e2e6924-29c37,Pod,metrics-server-e2e6924-29c37,kubelet,2026-06-17 00:04:12,2026-06-17 01:12:12,20,2026-06-23 12:00:00
514,prod-usw2-eks,payments,Warning,Evicted,Pod payments-api-1e23165-1e35b evicted: node memory pressure,Pod,payments-api-1e23165-1e35b,default-scheduler,2026-06-16 19:29:08,2026-06-16 19:47:08,12,2026-06-23 12:00:00
515,staging-use2-eks,checkout,Warning,NodeNotReady,Node ip-10-8-126-134 status is now: NodeNotReady,Pod,checkout-web-2b77739-52fdd,controllermanager,2026-06-23 03:37:09,2026-06-23 04:25:09,4,2026-06-23 12:00:00
516,prod-usw2-eks,payments,Warning,Unhealthy,Liveness probe failed: HTTP 500 for payments-worker-1d1bf52-dff66,Pod,payments-worker-1d1bf52-dff66,default-scheduler,2026-06-12 12:02:18,2026-06-12 13:45:18,10,2026-06-23 12:00:00
517,prod-usw2-eks,search,Warning,Evicted,Pod search-api-8352074-5b766 evicted: node was low on resource ephemeral-storage,Pod,search-api-8352074-5b766,controllermanager,2026-06-18 18:07:15,2026-06-18 18:31:15,38,2026-06-23 12:00:00
518,prod-use2-eks,checkout,Warning,Unhealthy,Liveness probe failed: HTTP 500 for checkout-web-c2eb578-2d181,Pod,checkout-web-c2eb578-2d181,kubelet,2026-05-31 01:08:17,2026-05-31 02:45:17,5,2026-06-23 12:00:00
519,prod-usw2-eks,identity,Warning,Evicted,Pod session-store-28ebc77-cf7c8 evicted: node was low on resource ephemeral-storage,Pod,session-store-28ebc77-cf7c8,controllermanager,2026-05-28 22:44:08,2026-05-28 23:00:08,26,2026-06-23 12:00:00
520,prod-usw2-eks,kube-system,Warning,DNSConfigForming,Search line limits exceeded for coredns-37f1521-4cd3d,Pod,coredns-37f1521-4cd3d,default-scheduler,2026-06-19 10:16:28,2026-06-19 12:03:28,16,2026-06-23 12:00:00
521,prod-usw2-eks,payments,Normal,Started,Started container payments-worker,Pod,payments-worker-b4be648-d2dcb,kubelet,2026-06-01 21:57:40,2026-06-01 23:13:40,1,2026-06-23 12:00:00
522,staging-use2-eks,search,Warning,DNSConfigForming,Search line limits exceeded for search-api-1605640-8abaf,Pod,search-api-1605640-8abaf,kubelet,2026-06-22 05:42:09,2026-06-22 05:56:09,33,2026-06-23 12:00:00
523,prod-use2-eks,search,Normal,Pulled,Container image pulled for search-api,Pod,search-api-1271443-2f040,controllermanager,2026-06-11 05:26:27,2026-06-11 06:41:27,1,2026-06-23 12:00:00
524,prod-usw2-eks,kube-system,Warning,DNSConfigForming,Search line limits exceeded for coredns-4a8b365-1d9fc,Pod,coredns-4a8b365-1d9fc,controllermanager,2026-06-17 18:59:18,2026-06-17 19:20:18,15,2026-06-23 12:00:00
525,prod-use2-eks,identity,Warning,OOMKilling,Container session-store exceeded memory limit; OOMKilled,Pod,session-store-4732511-0dba8,controllermanager,2026-06-09 14:12:19,2026-06-09 15:07:19,30,2026-06-23 12:00:00
526,dr-use1-eks,checkout,Warning,OOMKilling,Container checkout-web exceeded memory limit; OOMKilled,Pod,checkout-web-6e9e217-a5c79,controllermanager,2026-06-22 10:52:59,2026-06-22 11:27:59,37,2026-06-23 12:00:00
527,staging-use2-eks,identity,Warning,DNSConfigForming,Search line limits exceeded for session-store-a097c68-649a1,Pod,session-store-a097c68-649a1,default-scheduler,2026-06-11 17:01:26,2026-06-11 17:42:26,4,2026-06-23 12:00:00
528,prod-usw2-eks,ledger,Warning,FreeDiskSpaceFailed,Failed to garbage collect on node ip-10-14-16-161,Pod,ledger-svc-2014124-29b88,kubelet,2026-06-21 03:15:34,2026-06-21 04:13:34,37,2026-06-23 12:00:00
529,prod-use2-eks,orders,Warning,OOMKilling,Container orders-api exceeded memory limit; OOMKilled,Pod,orders-api-e9b4a39-c3784,default-scheduler,2026-06-17 21:39:11,2026-06-17 23:01:11,14,2026-06-23 12:00:00
530,prod-use2-eks,platform,Warning,Unhealthy,Readiness probe failed: timeout for config-svc-027a395-39a4d,Pod,config-svc-027a395-39a4d,kubelet,2026-06-20 08:58:22,2026-06-20 10:26:22,5,2026-06-23 12:00:00
531,prod-use2-eks,platform,Normal,Scheduled,Successfully assigned config-svc-ddd1723-06ca5 to ip-10-24-49-183,Pod,config-svc-ddd1723-06ca5,kubelet,2026-06-22 14:25:27,2026-06-22 16:20:27,1,2026-06-23 12:00:00
532,prod-use2-eks,checkout,Warning,BackOff,Back-off restarting failed container checkout-web in pod checkout-web-c2eb578-2d181,Pod,checkout-web-c2eb578-2d181,kubelet,2026-06-14 05:07:11,2026-06-14 06:40:11,33,2026-06-23 12:00:00
533,prod-usw2-eks,payments,Warning,Evicted,Pod payments-api-1e23165-1e35b evicted: node memory pressure,Pod,payments-api-1e23165-1e35b,default-scheduler,2026-06-08 16:52:15,2026-06-08 17:15:15,23,2026-06-23 12:00:00
534,prod-use2-eks,ledger,Warning,Unhealthy,Readiness probe failed: timeout for ledger-svc-204e643-7d23b,Pod,ledger-svc-204e643-7d23b,default-scheduler,2026-06-18 05:10:04,2026-06-18 06:18:04,7,2026-06-23 12:00:00
535,staging-use2-eks,checkout,Warning,Rebooted,Node ip-10-14-70-252 has been rebooted,Pod,checkout-web-aca9086-f5fe6,controllermanager,2026-06-23 11:29:32,2026-06-23 12:09:32,34,2026-06-23 12:00:00
536,prod-usw2-eks,payments,Warning,Evicted,Pod payments-api-423b015-b80bd evicted: node memory pressure,Pod,payments-api-423b015-b80bd,controllermanager,2026-06-02 16:46:32,2026-06-02 18:43:32,38,2026-06-23 12:00:00
537,staging-use2-eks,identity,Warning,Unhealthy,Readiness probe errored: dial tcp i/o timeout for session-store-a097c68-649a1,Pod,session-store-a097c68-649a1,kubelet,2026-06-05 19:36:31,2026-06-05 20:14:31,5,2026-06-23 12:00:00
538,prod-usw2-eks,identity,Normal,Started,Started container auth-gateway,Pod,auth-gateway-ebb2b70-575e4,default-scheduler,2026-06-11 06:57:47,2026-06-11 08:16:47,1,2026-06-23 12:00:00
539,prod-use2-eks,notifications,Warning,Unhealthy,Readiness probe failed: timeout for notifications-1938743-28dca,Pod,notifications-1938743-28dca,kubelet,2026-06-03 17:08:18,2026-06-03 18:56:18,1,2026-06-23 12:00:00
540,prod-use2-eks,orders,Warning,Evicted,Pod orders-api-bfb2f93-32ad3 evicted: node memory pressure,Pod,orders-api-bfb2f93-32ad3,controllermanager,2026-06-16 22:04:50,2026-06-16 22:18:50,40,2026-06-23 12:00:00
541,prod-use2-eks,search,Normal,Started,Started container search-api,Pod,search-api-61d1d17-0014f,default-scheduler,2026-06-11 02:04:51,2026-06-11 03:01:51,1,2026-06-23 12:00:00
542,prod-use2-eks,platform,Warning,Unhealthy,Readiness probe failed: timeout for config-svc-027a395-39a4d,Pod,config-svc-027a395-39a4d,controllermanager,2026-06-20 12:51:42,2026-06-20 13:00:42,33,2026-06-23 12:00:00
543,prod-use2-eks,search,Normal,Started,Started container recommendation,Pod,recommendation-e5d5555-c6e9b,kubelet,2026-06-08 11:37:43,2026-06-08 12:15:43,1,2026-06-23 12:00:00
544,prod-usw2-eks,payments,Warning,OOMKilling,Container payments-api exceeded memory limit; OOMKilled,Pod,payments-api-b9a1287-dbbfe,default-scheduler,2026-06-13 21:12:31,2026-06-13 22:59:31,27,2026-06-23 12:00:00
545,prod-usw2-eks,ledger,Warning,Evicted,Pod ledger-svc-842cd31-95bfa evicted: node was low on resource ephemeral-storage,Pod,ledger-svc-842cd31-95bfa,default-scheduler,2026-06-18 05:04:46,2026-06-18 07:00:46,20,2026-06-23 12:00:00
546,prod-usw2-eks,payments,Warning,BackOff,Back-off restarting failed container payments-worker in pod payments-worker-1d1bf52-dff66,Pod,payments-worker-1d1bf52-dff66,kubelet,2026-05-28 12:37:58,2026-05-28 14:23:58,12,2026-06-23 12:00:00
547,prod-usw2-eks,search,Normal,Pulled,Container image pulled for recommendation,Pod,recommendation-1e52697-e4756,controllermanager,2026-06-17 06:59:37,2026-06-17 08:29:37,1,2026-06-23 12:00:00
548,prod-use2-eks,checkout,Warning,Unhealthy,Liveness probe failed: HTTP 500 for checkout-web-0101b48-2b2af,Pod,checkout-web-0101b48-2b2af,kubelet,2026-06-05 05:20:58,2026-06-05 06:22:58,19,2026-06-23 12:00:00
549,prod-use2-eks,orders,Warning,Evicted,Pod orders-api-7f89525-97cdd evicted: node memory pressure,Pod,orders-api-7f89525-97cdd,kubelet,2026-06-10 17:43:13,2026-06-10 18:18:13,19,2026-06-23 12:00:00
550,dr-use1-eks,ledger,Normal,Scheduled,Successfully assigned ledger-svc-e00a046-6e2d6 to ip-10-40-81-216,Pod,ledger-svc-e00a046-6e2d6,controllermanager,2026-06-21 01:11:42,2026-06-21 03:09:42,1,2026-06-23 12:00:00
551,dr-use1-eks,search,Warning,FreeDiskSpaceFailed,Failed to garbage collect on node ip-10-40-81-216,Pod,search-api-be84964-d972c,controllermanager,2026-06-09 18:23:30,2026-06-09 19:47:30,4,2026-06-23 12:00:00
552,prod-use2-eks,payments,Normal,Scheduled,Successfully assigned payments-worker-bff7264-02c23 to ip-10-17-79-110,Pod,payments-worker-bff7264-02c23,controllermanager,2026-06-21 06:57:47,2026-06-21 08:46:47,1,2026-06-23 12:00:00
553,prod-use2-eks,payments,Warning,Evicted,Pod payments-api-7fa4649-debd8 evicted: node memory pressure,Pod,payments-api-7fa4649-debd8,kubelet,2026-06-23 01:34:09,2026-06-23 02:24:09,23,2026-06-23 12:00:00
554,prod-use2-eks,identity,Warning,OOMKilling,Container session-store exceeded memory limit; OOMKilled,Pod,session-store-1ac5266-1ca26,controllermanager,2026-06-12 06:38:01,2026-06-12 07:00:01,6,2026-06-23 12:00:00
555,prod-use2-eks,search,Normal,Scheduled,Successfully assigned search-api-4350294-dbefb to ip-10-17-79-110,Pod,search-api-4350294-dbefb,kubelet,2026-06-02 05:34:00,2026-06-02 06:36:00,1,2026-06-23 12:00:00
556,prod-use2-eks,orders,Warning,Evicted,Pod orders-api-7f89525-97cdd evicted: node memory pressure,Pod,orders-api-7f89525-97cdd,default-scheduler,2026-06-15 06:47:38,2026-06-15 07:42:38,39,2026-06-23 12:00:00
557,staging-use2-eks,checkout,Warning,NodeNotReady,Node ip-10-8-126-134 status is now: NodeNotReady,Pod,checkout-web-2b77739-52fdd,default-scheduler,2026-06-23 01:49:52,2026-06-23 02:04:52,22,2026-06-23 12:00:00
558,prod-usw2-eks,ledger,Warning,Evicted,Pod ledger-svc-842cd31-95bfa evicted: node was low on resource ephemeral-storage,Pod,ledger-svc-842cd31-95bfa,controllermanager,2026-06-18 15:28:12,2026-06-18 17:10:12,24,2026-06-23 12:00:00
559,prod-usw2-eks,identity,Warning,FreeDiskSpaceFailed,Failed to garbage collect on node ip-10-12-35-23,Pod,session-store-d825e25-14f9f,kubelet,2026-06-22 23:33:48,2026-06-23 00:15:48,39,2026-06-23 12:00:00
560,prod-usw2-eks,ledger,Warning,FreeDiskSpaceFailed,Failed to garbage collect on node ip-10-14-16-161,Pod,ledger-svc-2014124-29b88,controllermanager,2026-06-19 15:37:35,2026-06-19 16:55:35,29,2026-06-23 12:00:00
561,prod-use2-eks,kube-system,Warning,FreeDiskSpaceFailed,Failed to garbage collect on node ip-10-32-13-101,Pod,coredns-e513a45-fb7bf,kubelet,2026-06-15 05:52:03,2026-06-15 07:22:03,37,2026-06-23 12:00:00
562,prod-usw2-eks,platform,Normal,Pulled,Container image pulled for config-svc,Pod,config-svc-370d832-a686a,kubelet,2026-06-11 06:42:25,2026-06-11 06:52:25,1,2026-06-23 12:00:00
563,staging-use2-eks,payments,Warning,Evicted,Pod payments-api-2729261-453da evicted: node was low on resource ephemeral-storage,Pod,payments-api-2729261-453da,controllermanager,2026-06-14 15:17:45,2026-06-14 15:53:45,7,2026-06-23 12:00:00
564,prod-usw2-eks,inventory,Warning,Unhealthy,Liveness probe failed: HTTP 500 for inventory-svc-bf8f159-02345,Pod,inventory-svc-bf8f159-02345,default-scheduler,2026-06-04 07:55:24,2026-06-04 08:09:24,8,2026-06-23 12:00:00
565,prod-usw2-eks,kube-system,Warning,Unhealthy,Readiness probe errored: dial tcp i/o timeout for coredns-37f1521-4cd3d,Pod,coredns-37f1521-4cd3d,default-scheduler,2026-06-18 09:41:19,2026-06-18 11:09:19,33,2026-06-23 12:00:00
566,dr-use1-eks,search,Warning,NodeNotReady,Node ip-10-21-57-150 status is now: NodeNotReady,Pod,indexer-6af7422-f66fc,kubelet,2026-06-12 10:54:56,2026-06-12 11:46:56,19,2026-06-23 12:00:00
567,prod-use2-eks,payments,Warning,OOMKilling,Container payments-api exceeded memory limit; OOMKilled,Pod,payments-api-58c5e74-26d34,kubelet,2026-06-23 07:46:07,2026-06-23 08:43:07,2,2026-06-23 12:00:00
568,prod-use2-eks,payments,Normal,Scheduled,Successfully assigned payments-worker-6e38c94-75bbf to ip-10-6-44-216,Pod,payments-worker-6e38c94-75bbf,controllermanager,2026-05-26 01:10:53,2026-05-26 02:32:53,1,2026-06-23 12:00:00
569,prod-use2-eks,ledger,Normal,Pulled,Container image pulled for ledger-svc,Pod,ledger-svc-1232e29-49ea1,controllermanager,2026-06-20 23:31:15,2026-06-21 00:36:15,1,2026-06-23 12:00:00
570,prod-usw2-eks,payments,Warning,Evicted,Pod payments-api-b9a1287-dbbfe evicted: node memory pressure,Pod,payments-api-b9a1287-dbbfe,controllermanager,2026-06-06 08:48:16,2026-06-06 08:57:16,20,2026-06-23 12:00:00
571,prod-use2-eks,checkout,Warning,OOMKilling,Memory cgroup out of memory: Killed process in checkout-web-0101b48-2b2af,Pod,checkout-web-0101b48-2b2af,kubelet,2026-06-03 16:18:19,2026-06-03 16:49:19,39,2026-06-23 12:00:00
572,prod-usw2-eks,orders,Warning,Unhealthy,Liveness probe failed: HTTP 500 for orders-api-cbca488-26609,Pod,orders-api-cbca488-26609,kubelet,2026-06-17 07:19:07,2026-06-17 09:15:07,39,2026-06-23 12:00:00
573,dr-use1-eks,checkout,Warning,Evicted,Pod checkout-web-4263246-52f3a evicted: node memory pressure,Pod,checkout-web-4263246-52f3a,kubelet,2026-06-21 22:48:49,2026-06-22 00:44:49,37,2026-06-23 12:00:00
574,prod-use2-eks,checkout,Warning,OOMKilling,Container cart-svc exceeded memory limit; OOMKilled,Pod,cart-svc-26a7d77-aafdc,controllermanager,2026-06-20 09:43:35,2026-06-20 09:46:35,36,2026-06-23 12:00:00
575,prod-use2-eks,orders,Warning,OOMKilling,Container orders-api exceeded memory limit; OOMKilled,Pod,orders-api-e9b4a39-c3784,kubelet,2026-06-07 14:46:11,2026-06-07 15:13:11,21,2026-06-23 12:00:00
576,prod-usw2-eks,payments,Warning,OOMKilling,Container payments-api exceeded memory limit; OOMKilled,Pod,payments-api-423b015-b80bd,default-scheduler,2026-06-20 11:04:47,2026-06-20 11:27:47,16,2026-06-23 12:00:00
577,dr-use1-eks,search,Warning,Evicted,Pod search-api-be84964-d972c evicted: node was low on resource ephemeral-storage,Pod,search-api-be84964-d972c,controllermanager,2026-06-16 09:39:06,2026-06-16 11:31:06,10,2026-06-23 12:00:00
578,prod-use2-eks,ledger,Normal,Throttling,CPU throttled for container ledger-svc,Pod,ledger-svc-204e643-7d23b,default-scheduler,2026-06-18 01:09:27,2026-06-18 02:10:27,1,2026-06-23 12:00:00
579,prod-usw2-eks,checkout,Warning,Evicted,Pod cart-svc-ee38458-64d46 evicted: node was low on resource ephemeral-storage,Pod,cart-svc-ee38458-64d46,kubelet,2026-06-23 11:29:19,2026-06-23 11:46:19,11,2026-06-23 12:00:00
580,dr-use1-eks,checkout,Warning,Evicted,Pod checkout-web-6e9e217-a5c79 evicted: node memory pressure,Pod,checkout-web-6e9e217-a5c79,default-scheduler,2026-06-19 05:50:24,2026-06-19 06:46:24,35,2026-06-23 12:00:00
581,staging-use2-eks,checkout,Warning,Rebooted,Node ip-10-14-70-252 has been rebooted,Pod,checkout-web-aca9086-f5fe6,default-scheduler,2026-06-23 00:39:03,2026-06-23 02:17:03,2,2026-06-23 12:00:00
582,dr-use1-eks,search,Warning,Evicted,Pod search-api-d416b43-7cb20 evicted: node was low on resource ephemeral-storage,Pod,search-api-d416b43-7cb20,controllermanager,2026-06-14 10:31:27,2026-06-14 11:34:27,38,2026-06-23 12:00:00
583,dr-use1-eks,search,Warning,FreeDiskSpaceFailed,Failed to garbage collect on node ip-10-40-81-216,Pod,search-api-d416b43-7cb20,default-scheduler,2026-06-15 21:49:24,2026-06-15 21:55:24,31,2026-06-23 12:00:00
584,prod-usw2-eks,ledger,Warning,FreeDiskSpaceFailed,Failed to garbage collect on node ip-10-14-16-161,Pod,ledger-svc-2014124-29b88,kubelet,2026-06-19 02:11:58,2026-06-19 02:16:58,9,2026-06-23 12:00:00
585,prod-use2-eks,kube-system,Warning,Evicted,Pod coredns-47d4438-c55d7 evicted: node was low on resource ephemeral-storage,Pod,coredns-47d4438-c55d7,kubelet,2026-06-19 17:18:59,2026-06-19 17:48:59,4,2026-06-23 12:00:00
586,prod-usw2-eks,ledger,Warning,Evicted,Pod ledger-svc-2014124-29b88 evicted: node was low on resource ephemeral-storage,Pod,ledger-svc-2014124-29b88,kubelet,2026-06-22 11:46:13,2026-06-22 11:48:13,24,2026-06-23 12:00:00
587,staging-use2-eks,checkout,Warning,Rebooted,Node ip-10-14-70-252 has been rebooted,Pod,checkout-web-aca9086-f5fe6,default-scheduler,2026-06-23 11:16:39,2026-06-23 12:58:39,10,2026-06-23 12:00:00
588,dr-use1-eks,notifications,Warning,BackOff,Back-off restarting failed container notifications in pod notifications-b036879-82982,Pod,notifications-b036879-82982,default-scheduler,2026-06-22 07:02:55,2026-06-22 07:46:55,12,2026-06-23 12:00:00
589,prod-use2-eks,orders,Warning,Evicted,Pod orders-api-7f89525-97cdd evicted: node memory pressure,Pod,orders-api-7f89525-97cdd,controllermanager,2026-06-19 04:22:37,2026-06-19 05:47:37,35,2026-06-23 12:00:00
590,prod-use2-eks,search,Normal,Pulled,Container image pulled for search-api,Pod,search-api-eff0684-a368a,default-scheduler,2026-06-23 10:37:27,2026-06-23 12:13:27,1,2026-06-23 12:00:00
591,prod-usw2-eks,kube-system,Warning,NodeNotReady,Node ip-10-6-194-142 status is now: NodeNotReady,Pod,metrics-server-6162d13-d4a14,controllermanager,2026-06-19 12:52:36,2026-06-19 13:15:36,21,2026-06-23 12:00:00
592,prod-usw2-eks,notifications,Normal,Scheduled,Successfully assigned notifications-b2aff41-e1772 to ip-10-29-63-193,Pod,notifications-b2aff41-e1772,kubelet,2026-06-17 15:33:18,2026-06-17 17:14:18,1,2026-06-23 12:00:00
593,prod-usw2-eks,search,Warning,Evicted,Pod search-api-8352074-5b766 evicted: node was low on resource ephemeral-storage,Pod,search-api-8352074-5b766,controllermanager,2026-06-22 11:40:15,2026-06-22 13:00:15,13,2026-06-23 12:00:00
594,staging-use2-eks,checkout,Warning,Rebooted,Node ip-10-8-126-134 has been rebooted,Pod,checkout-web-2b77739-52fdd,controllermanager,2026-06-23 02:16:24,2026-06-23 02:18:24,28,2026-06-23 12:00:00
595,dr-use1-eks,notifications,Warning,Unhealthy,Liveness probe failed: HTTP 500 for notifications-b036879-82982,Pod,notifications-b036879-82982,kubelet,2026-06-23 08:24:16,2026-06-23 09:47:16,18,2026-06-23 12:00:00
596,prod-use2-eks,kube-system,Warning,FreeDiskSpaceFailed,Failed to garbage collect on node ip-10-32-13-101,Pod,coredns-e513a45-fb7bf,kubelet,2026-06-19 08:26:16,2026-06-19 09:32:16,15,2026-06-23 12:00:00
597,prod-use2-eks,kube-system,Warning,Unhealthy,Readiness probe errored: dial tcp i/o timeout for metrics-server-e2e6924-29c37,Pod,metrics-server-e2e6924-29c37,controllermanager,2026-06-06 00:29:53,2026-06-06 01:23:53,6,2026-06-23 12:00:00
598,prod-usw2-eks,search,Warning,Evicted,Pod search-api-15a6d76-12766 evicted: node was low on resource ephemeral-storage,Pod,search-api-15a6d76-12766,default-scheduler,2026-06-19 22:03:59,2026-06-19 22:34:59,13,2026-06-23 12:00:00
599,prod-usw2-eks,orders,Warning,Evicted,Pod orders-worker-b907131-2627d evicted: node was low on resource ephemeral-storage,Pod,orders-worker-b907131-2627d,controllermanager,2026-06-19 14:15:37,2026-06-19 14:15:37,31,2026-06-23 12:00:00
600,prod-use2-eks,kube-system,Warning,Unhealthy,Readiness probe errored: dial tcp i/o timeout for metrics-server-e2e6924-29c37,Pod,metrics-server-e2e6924-29c37,default-scheduler,2026-06-18 07:02:38,2026-06-18 08:14:38,36,2026-06-23 12:00:00
601,prod-usw2-eks,search,Normal,Started,Started container indexer,Pod,indexer-b957537-8aa20,default-scheduler,2026-06-11 20:36:29,2026-06-11 21:01:29,1,2026-06-23 12:00:00
602,prod-usw2-eks,orders,Warning,OOMKilling,Memory cgroup out of memory: Killed process in orders-api-cbca488-26609,Pod,orders-api-cbca488-26609,kubelet,2026-06-18 22:33:22,2026-06-19 00:11:22,27,2026-06-23 12:00:00
603,prod-usw2-eks,search,Normal,Scheduled,Successfully assigned search-api-db28570-d359e to ip-10-12-35-23,Pod,search-api-db28570-d359e,controllermanager,2026-06-21 10:20:15,2026-06-21 11:05:15,1,2026-06-23 12:00:00
604,staging-use2-eks,search,Normal,Pulled,Container image pulled for search-api,Pod,search-api-8ca0b98-505ff,controllermanager,2026-06-22 17:50:00,2026-06-22 18:35:00,1,2026-06-23 12:00:00
605,prod-use2-eks,search,Normal,Scheduled,Successfully assigned search-api-4350294-dbefb to ip-10-17-79-110,Pod,search-api-4350294-dbefb,controllermanager,2026-06-20 12:09:42,2026-06-20 12:51:42,1,2026-06-23 12:00:00
606,prod-use2-eks,inventory,Normal,Scheduled,Successfully assigned inventory-svc-bfded25-1e6d2 to ip-10-37-142-3,Pod,inventory-svc-bfded25-1e6d2,controllermanager,2026-06-14 17:44:49,2026-06-14 18:25:49,1,2026-06-23 12:00:00
607,prod-use2-eks,kube-system,Warning,FreeDiskSpaceFailed,Failed to garbage collect on node ip-10-32-13-101,Pod,coredns-e513a45-fb7bf,kubelet,2026-06-06 23:08:46,2026-06-07 00:32:46,27,2026-06-23 12:00:00
608,prod-use2-eks,identity,Warning,OOMKilling,Container session-store exceeded memory limit; OOMKilled,Pod,session-store-1ac5266-1ca26,default-scheduler,2026-06-08 17:32:18,2026-06-08 18:11:18,27,2026-06-23 12:00:00
609,prod-usw2-eks,ledger,Warning,Evicted,Pod ledger-svc-842cd31-95bfa evicted: node was low on resource ephemeral-storage,Pod,ledger-svc-842cd31-95bfa,kubelet,2026-06-23 07:19:32,2026-06-23 08:10:32,28,2026-06-23 12:00:00
610,prod-usw2-eks,kube-system,Warning,Unhealthy,Readiness probe errored: dial tcp i/o timeout for coredns-4a8b365-1d9fc,Pod,coredns-4a8b365-1d9fc,controllermanager,2026-06-23 03:04:07,2026-06-23 03:07:07,22,2026-06-23 12:00:00
611,prod-usw2-eks,identity,Normal,Scheduled,Successfully assigned auth-gateway-ebb2b70-575e4 to ip-10-12-35-23,Pod,auth-gateway-ebb2b70-575e4,kubelet,2026-06-08 09:34:18,2026-06-08 09:52:18,1,2026-06-23 12:00:00
612,prod-use2-eks,identity,Warning,Evicted,Pod session-store-1ac5266-1ca26 evicted: node memory pressure,Pod,session-store-1ac5266-1ca26,controllermanager,2026-06-21 11:18:05,2026-06-21 12:58:05,32,2026-06-23 12:00:00
613,staging-use2-eks,payments,Warning,Evicted,Pod payments-api-2729261-453da evicted: node was low on resource ephemeral-storage,Pod,payments-api-2729261-453da,controllermanager,2026-06-23 07:51:20,2026-06-23 08:13:20,13,2026-06-23 12:00:00
614,staging-use2-eks,checkout,Warning,NodeNotReady,Node ip-10-14-70-252 status is now: NodeNotReady,Pod,checkout-web-aca9086-f5fe6,default-scheduler,2026-06-22 17:26:23,2026-06-22 17:34:23,6,2026-06-23 12:00:00
615,staging-use2-eks,payments,Warning,Evicted,Pod payments-api-2729261-453da evicted: node was low on resource ephemeral-storage,Pod,payments-api-2729261-453da,controllermanager,2026-06-07 10:33:28,2026-06-07 11:29:28,20,2026-06-23 12:00:00
616,staging-use2-eks,platform,Warning,FreeDiskSpaceFailed,Failed to garbage collect on node ip-10-8-126-134,Pod,config-svc-929cd33-16be4,kubelet,2026-06-21 16:40:27,2026-06-21 18:35:27,8,2026-06-23 12:00:00
617,prod-usw2-eks,kube-system,Warning,DNSConfigForming,Search line limits exceeded for coredns-4a8b365-1d9fc,Pod,coredns-4a8b365-1d9fc,kubelet,2026-06-23 03:52:55,2026-06-23 05:28:55,28,2026-06-23 12:00:00
618,dr-use1-eks,search,Warning,NodeNotReady,Node ip-10-21-57-150 status is now: NodeNotReady,Pod,indexer-6af7422-f66fc,controllermanager,2026-05-30 00:33:14,2026-05-30 02:20:14,20,2026-06-23 12:00:00
619,prod-use2-eks,notifications,Warning,Unhealthy,Readiness probe failed: timeout for notifications-1938743-28dca,Pod,notifications-1938743-28dca,controllermanager,2026-06-21 05:06:26,2026-06-21 05:57:26,35,2026-06-23 12:00:00
620,prod-use2-eks,checkout,Warning,BackOff,Back-off restarting failed container checkout-web in pod checkout-web-c2eb578-2d181,Pod,checkout-web-c2eb578-2d181,controllermanager,2026-06-19 00:37:51,2026-06-19 02:30:51,22,2026-06-23 12:00:00
621,staging-use2-eks,checkout,Warning,NodeNotReady,Node ip-10-8-126-134 status is now: NodeNotReady,Pod,checkout-web-2b77739-52fdd,kubelet,2026-06-22 14:59:51,2026-06-22 16:04:51,35,2026-06-23 12:00:00
622,prod-use2-eks,notifications,Normal,Throttling,CPU throttled for container notifications,Pod,notifications-1938743-28dca,default-scheduler,2026-06-07 19:21:30,2026-06-07 20:52:30,1,2026-06-23 12:00:00
623,prod-use2-eks,payments,Normal,Scheduled,Successfully assigned payments-worker-7a57672-86691 to ip-10-40-57-12,Pod,payments-worker-7a57672-86691,controllermanager,2026-05-28 08:52:19,2026-05-28 09:11:19,1,2026-06-23 12:00:00
624,prod-usw2-eks,search,Normal,Pulled,Container image pulled for recommendation,Pod,recommendation-1e52697-e4756,kubelet,2026-05-25 05:05:22,2026-05-25 06:02:22,1,2026-06-23 12:00:00
625,prod-usw2-eks,identity,Warning,FreeDiskSpaceFailed,Failed to garbage collect on node ip-10-12-35-23,Pod,session-store-d825e25-14f9f,default-scheduler,2026-06-22 18:26:57,2026-06-22 19:47:57,5,2026-06-23 12:00:00
626,prod-usw2-eks,identity,Warning,FreeDiskSpaceFailed,Failed to garbage collect on node ip-10-12-35-23,Pod,session-store-d825e25-14f9f,kubelet,2026-06-13 23:05:49,2026-06-14 00:42:49,13,2026-06-23 12:00:00
627,prod-usw2-eks,search,Normal,Started,Started container indexer,Pod,indexer-6c1eb29-ca471,kubelet,2026-06-10 17:14:18,2026-06-10 17:40:18,1,2026-06-23 12:00:00
628,dr-use1-eks,checkout,Warning,OOMKilling,Container checkout-web exceeded memory limit; OOMKilled,Pod,checkout-web-4263246-52f3a,controllermanager,2026-06-19 20:33:31,2026-06-19 21:36:31,20,2026-06-23 12:00:00
629,prod-usw2-eks,platform,Normal,Scheduled,Successfully assigned image-resizer-6542c92-1100b to ip-10-15-83-236,Pod,image-resizer-6542c92-1100b,kubelet,2026-06-02 16:53:11,2026-06-02 17:06:11,1,2026-06-23 12:00:00
630,prod-use2-eks,kube-system,Warning,Evicted,Pod coredns-47d4438-c55d7 evicted: node was low on resource ephemeral-storage,Pod,coredns-47d4438-c55d7,default-scheduler,2026-06-21 03:15:34,2026-06-21 05:02:34,2,2026-06-23 12:00:00
631,prod-use2-eks,orders,Warning,OOMKilling,Container orders-api exceeded memory limit; OOMKilled,Pod,orders-api-7f89525-97cdd,kubelet,2026-06-17 05:16:33,2026-06-17 05:31:33,8,2026-06-23 12:00:00
632,prod-use2-eks,kube-system,Warning,FreeDiskSpaceFailed,Failed to garbage collect on node ip-10-6-44-216,Pod,coredns-47d4438-c55d7,controllermanager,2026-06-22 18:27:13,2026-06-22 19:05:13,30,2026-06-23 12:00:00
633,prod-usw2-eks,platform,Normal,Pulled,Container image pulled for image-resizer,Pod,image-resizer-6542c92-1100b,kubelet,2026-06-16 07:05:03,2026-06-16 08:32:03,1,2026-06-23 12:00:00
634,prod-usw2-eks,ledger,Warning,Evicted,Pod ledger-svc-842cd31-95bfa evicted: node was low on resource ephemeral-storage,Pod,ledger-svc-842cd31-95bfa,default-scheduler,2026-06-20 00:52:37,2026-06-20 02:28:37,23,2026-06-23 12:00:00
635,prod-usw2-eks,ledger,Warning,FreeDiskSpaceFailed,Failed to garbage collect on node ip-10-14-16-161,Pod,ledger-svc-2014124-29b88,default-scheduler,2026-06-16 00:44:32,2026-06-16 01:32:32,6,2026-06-23 12:00:00
636,prod-use2-eks,orders,Warning,Evicted,Pod orders-api-bfb2f93-32ad3 evicted: node memory pressure,Pod,orders-api-bfb2f93-32ad3,default-scheduler,2026-06-18 16:20:25,2026-06-18 17:14:25,30,2026-06-23 12:00:00
637,prod-usw2-eks,payments,Warning,OOMKilling,Memory cgroup out of memory: Killed process in payments-worker-bbc0947-0aa1a,Pod,payments-worker-bbc0947-0aa1a,controllermanager,2026-06-19 23:25:34,2026-06-20 00:26:34,14,2026-06-23 12:00:00
638,prod-use2-eks,orders,Warning,OOMKilling,Container orders-api exceeded memory limit; OOMKilled,Pod,orders-api-bfb2f93-32ad3,controllermanager,2026-06-19 22:36:56,2026-06-19 22:46:56,39,2026-06-23 12:00:00
639,prod-usw2-eks,search,Warning,Evicted,Pod search-api-8352074-5b766 evicted: node was low on resource ephemeral-storage,Pod,search-api-8352074-5b766,kubelet,2026-06-19 06:17:50,2026-06-19 06:52:50,11,2026-06-23 12:00:00
640,prod-use2-eks,checkout,Warning,OOMKilling,Container cart-svc exceeded memory limit; OOMKilled,Pod,cart-svc-527eb80-045c0,controllermanager,2026-06-15 12:07:29,2026-06-15 12:39:29,8,2026-06-23 12:00:00
641,prod-usw2-eks,platform,Normal,Started,Started container config-svc,Pod,config-svc-370d832-a686a,controllermanager,2026-06-05 19:07:12,2026-06-05 20:50:12,1,2026-06-23 12:00:00
642,prod-usw2-eks,checkout,Warning,FreeDiskSpaceFailed,Failed to garbage collect on node ip-10-6-194-142,Pod,cart-svc-882ca58-64a75,default-scheduler,2026-06-19 13:23:53,2026-06-19 13:37:53,15,2026-06-23 12:00:00
643,dr-use1-eks,search,Warning,NodeNotReady,Node ip-10-21-57-150 status is now: NodeNotReady,Pod,indexer-6af7422-f66fc,controllermanager,2026-06-10 07:11:30,2026-06-10 08:02:30,38,2026-06-23 12:00:00
644,prod-usw2-eks,kube-system,Warning,Unhealthy,Readiness probe errored: dial tcp i/o timeout for coredns-4a8b365-1d9fc,Pod,coredns-4a8b365-1d9fc,default-scheduler,2026-06-18 14:37:02,2026-06-18 16:29:02,7,2026-06-23 12:00:00
645,prod-use2-eks,platform,Normal,Throttling,CPU throttled for container config-svc,Pod,config-svc-027a395-39a4d,controllermanager,2026-06-21 02:37:07,2026-06-21 02:50:07,1,2026-06-23 12:00:00
646,prod-usw2-eks,identity,Warning,FreeDiskSpaceFailed,Failed to garbage collect on node ip-10-12-35-23,Pod,session-store-d825e25-14f9f,controllermanager,2026-06-03 05:41:36,2026-06-03 05:58:36,26,2026-06-23 12:00:00
647,dr-use1-eks,inventory,Normal,Pulled,Container image pulled for inventory-svc,Pod,inventory-svc-4ccbe67-9cbde,controllermanager,2026-06-18 07:36:42,2026-06-18 08:00:42,1,2026-06-23 12:00:00
648,prod-usw2-eks,search,Warning,Evicted,Pod search-api-15a6d76-12766 evicted: node was low on resource ephemeral-storage,Pod,search-api-15a6d76-12766,default-scheduler,2026-06-17 10:18:07,2026-06-17 10:50:07,37,2026-06-23 12:00:00
649,prod-usw2-eks,payments,Normal,Scheduled,Successfully assigned payments-api-6c2b997-3e07d to ip-10-15-83-236,Pod,payments-api-6c2b997-3e07d,default-scheduler,2026-06-10 11:26:50,2026-06-10 13:20:50,1,2026-06-23 12:00:00
650,prod-use2-eks,identity,Warning,OOMKilling,Container session-store exceeded memory limit; OOMKilled,Pod,session-store-4732511-0dba8,default-scheduler,2026-06-19 12:58:54,2026-06-19 13:23:54,5,2026-06-23 12:00:00
651,prod-usw2-eks,checkout,Warning,FreeDiskSpaceFailed,Failed to garbage collect on node ip-10-29-63-193,Pod,cart-svc-0a94879-c1bba,default-scheduler,2026-06-04 19:27:46,2026-06-04 20:54:46,23,2026-06-23 12:00:00
652,prod-usw2-eks,kube-system,Warning,DNSConfigForming,Search line limits exceeded for coredns-4a8b365-1d9fc,Pod,coredns-4a8b365-1d9fc,default-scheduler,2026-06-21 21:52:37,2026-06-21 22:28:37,21,2026-06-23 12:00:00
653,staging-use2-eks,platform,Warning,Evicted,Pod config-svc-929cd33-16be4 evicted: node was low on resource ephemeral-storage,Pod,config-svc-929cd33-16be4,controllermanager,2026-06-15 09:48:54,2026-06-15 11:03:54,34,2026-06-23 12:00:00
654,prod-usw2-eks,orders,Warning,OOMKilling,Memory cgroup out of memory: Killed process in orders-api-cbca488-26609,Pod,orders-api-cbca488-26609,controllermanager,2026-06-20 17:24:23,2026-06-20 18:32:23,33,2026-06-23 12:00:00
655,prod-usw2-eks,search,Warning,Evicted,Pod search-api-15a6d76-12766 evicted: node was low on resource ephemeral-storage,Pod,search-api-15a6d76-12766,kubelet,2026-06-19 14:06:58,2026-06-19 15:43:58,9,2026-06-23 12:00:00
656,prod-usw2-eks,kube-system,Warning,Unhealthy,Readiness probe errored: dial tcp i/o timeout for coredns-37f1521-4cd3d,Pod,coredns-37f1521-4cd3d,controllermanager,2026-06-19 23:00:52,2026-06-20 00:25:52,9,2026-06-23 12:00:00
657,prod-use2-eks,notifications,Warning,Unhealthy,Readiness probe failed: timeout for notifications-1938743-28dca,Pod,notifications-1938743-28dca,default-scheduler,2026-06-18 08:06:21,2026-06-18 09:09:21,40,2026-06-23 12:00:00
658,prod-use2-eks,orders,Warning,OOMKilling,Container orders-api exceeded memory limit; OOMKilled,Pod,orders-api-bfb2f93-32ad3,default-scheduler,2026-06-19 19:33:04,2026-06-19 19:46:04,19,2026-06-23 12:00:00
659,prod-use2-eks,kube-system,Warning,DNSConfigForming,Search line limits exceeded for metrics-server-e2e6924-29c37,Pod,metrics-server-e2e6924-29c37,default-scheduler,2026-06-14 19:09:50,2026-06-14 19:21:50,1,2026-06-23 12:00:00
660,prod-use2-eks,payments,Warning,Evicted,Pod payments-api-c9c2b74-00142 evicted: node memory pressure,Pod,payments-api-c9c2b74-00142,default-scheduler,2026-06-23 00:55:23,2026-06-23 01:05:23,27,2026-06-23 12:00:00
661,prod-use2-eks,ledger,Normal,Throttling,CPU throttled for container ledger-svc,Pod,ledger-svc-204e643-7d23b,default-scheduler,2026-06-17 21:09:42,2026-06-17 21:25:42,1,2026-06-23 12:00:00
662,prod-use2-eks,platform,Warning,DNSConfigForming,Search line limits exceeded for image-resizer-9994630-7c707,Pod,image-resizer-9994630-7c707,controllermanager,2026-06-20 05:45:53,2026-06-20 06:55:53,17,2026-06-23 12:00:00
663,prod-use2-eks,orders,Warning,OOMKilling,Container orders-api exceeded memory limit; OOMKilled,Pod,orders-api-7f89525-97cdd,controllermanager,2026-06-20 04:51:36,2026-06-20 05:50:36,8,2026-06-23 12:00:00
664,prod-use2-eks,payments,Warning,OOMKilling,Container payments-api exceeded memory limit; OOMKilled,Pod,payments-api-58c5e74-26d34,default-scheduler,2026-06-22 17:15:53,2026-06-22 18:54:53,21,2026-06-23 12:00:00
665,prod-use2-eks,notifications,Normal,Started,Started container notifications,Pod,notifications-c882a21-88bb7,kubelet,2026-06-07 17:10:07,2026-06-07 18:09:07,1,2026-06-23 12:00:00
666,prod-use2-eks,ledger,Normal,Pulled,Container image pulled for ledger-svc,Pod,ledger-svc-1232e29-49ea1,controllermanager,2026-06-21 06:02:17,2026-06-21 07:14:17,1,2026-06-23 12:00:00
667,staging-use2-eks,payments,Warning,FreeDiskSpaceFailed,Failed to garbage collect on node ip-10-20-108-255,Pod,payments-api-2729261-453da,controllermanager,2026-06-14 23:43:33,2026-06-15 01:26:33,17,2026-06-23 12:00:00
668,prod-use2-eks,payments,Warning,OOMKilling,Container payments-api exceeded memory limit; OOMKilled,Pod,payments-api-7fa4649-debd8,default-scheduler,2026-06-23 03:04:38,2026-06-23 04:46:38,4,2026-06-23 12:00:00
669,prod-usw2-eks,orders,Warning,Evicted,Pod orders-worker-b907131-2627d evicted: node was low on resource ephemeral-storage,Pod,orders-worker-b907131-2627d,controllermanager,2026-06-22 07:43:36,2026-06-22 08:59:36,29,2026-06-23 12:00:00
670,prod-usw2-eks,orders,Warning,Evicted,Pod orders-worker-b907131-2627d evicted: node was low on resource ephemeral-storage,Pod,orders-worker-b907131-2627d,kubelet,2026-06-19 02:03:55,2026-06-19 02:39:55,37,2026-06-23 12:00:00
671,prod-use2-eks,platform,Warning,Unhealthy,Readiness probe errored: dial tcp i/o timeout for image-resizer-7bb3c89-50e74,Pod,image-resizer-7bb3c89-50e74,kubelet,2026-06-20 09:35:22,2026-06-20 09:46:22,13,2026-06-23 12:00:00
672,staging-use2-eks,search,Warning,DNSConfigForming,Search line limits exceeded for search-api-1605640-8abaf,Pod,search-api-1605640-8abaf,kubelet,2026-06-22 05:21:24,2026-06-22 07:05:24,16,2026-06-23 12:00:00
673,prod-use2-eks,platform,Normal,Started,Started container config-svc,Pod,config-svc-ddd1723-06ca5,default-scheduler,2026-06-19 14:15:55,2026-06-19 14:27:55,1,2026-06-23 12:00:00
674,prod-use2-eks,identity,Warning,OOMKilling,Container session-store exceeded memory limit; OOMKilled,Pod,session-store-1ac5266-1ca26,kubelet,2026-06-15 08:51:06,2026-06-15 10:45:06,39,2026-06-23 12:00:00
675,prod-use2-eks,payments,Warning,OOMKilling,Container payments-api exceeded memory limit; OOMKilled,Pod,payments-api-7fa4649-debd8,default-scheduler,2026-06-22 17:21:09,2026-06-22 17:55:09,16,2026-06-23 12:00:00
676,staging-use2-eks,kube-system,Normal,Scheduled,Successfully assigned coredns-b16ea15-07544 to ip-10-8-126-134,Pod,coredns-b16ea15-07544,default-scheduler,2026-06-04 02:57:06,2026-06-04 04:40:06,1,2026-06-23 12:00:00
677,prod-use2-eks,platform,Warning,Unhealthy,Readiness probe errored: dial tcp i/o timeout for image-resizer-7bb3c89-50e74,Pod,image-resizer-7bb3c89-50e74,kubelet,2026-06-23 09:42:48,2026-06-23 10:30:48,22,2026-06-23 12:00:00
678,prod-use2-eks,orders,Normal,Started,Started container orders-worker,Pod,orders-worker-6ee3345-b0d20,kubelet,2026-06-13 15:39:46,2026-06-13 15:54:46,1,2026-06-23 12:00:00
679,prod-use2-eks,platform,Warning,DNSConfigForming,Search line limits exceeded for image-resizer-9994630-7c707,Pod,image-resizer-9994630-7c707,kubelet,2026-06-20 09:55:01,2026-06-20 11:10:01,5,2026-06-23 12:00:00
680,dr-use1-eks,search,Warning,NodeNotReady,Node ip-10-21-57-150 status is now: NodeNotReady,Pod,indexer-6af7422-f66fc,default-scheduler,2026-06-14 00:34:11,2026-06-14 00:35:11,2,2026-06-23 12:00:00
681,prod-use2-eks,notifications,Normal,Throttling,CPU throttled for container notifications,Pod,notifications-1938743-28dca,kubelet,2026-06-15 16:03:07,2026-06-15 16:09:07,1,2026-06-23 12:00:00
682,prod-use2-eks,kube-system,Warning,Unhealthy,Readiness probe errored: dial tcp i/o timeout for metrics-server-e2e6924-29c37,Pod,metrics-server-e2e6924-29c37,default-scheduler,2026-06-08 00:14:37,2026-06-08 00:34:37,20,2026-06-23 12:00:00
683,prod-usw2-eks,payments,Warning,OOMKilling,Memory cgroup out of memory: Killed process in payments-worker-1d1bf52-dff66,Pod,payments-worker-1d1bf52-dff66,controllermanager,2026-06-14 11:36:13,2026-06-14 13:12:13,16,2026-06-23 12:00:00
684,prod-use2-eks,inventory,Normal,Started,Started container inventory-svc,Pod,inventory-svc-bfded25-1e6d2,kubelet,2026-06-01 11:10:12,2026-06-01 11:50:12,1,2026-06-23 12:00:00
685,prod-use2-eks,identity,Warning,OOMKilling,Container session-store exceeded memory limit; OOMKilled,Pod,session-store-1ac5266-1ca26,controllermanager,2026-06-20 23:03:19,2026-06-20 23:43:19,7,2026-06-23 12:00:00
686,prod-usw2-eks,inventory,Warning,Unhealthy,Liveness probe failed: HTTP 500 for inventory-svc-bf8f159-02345,Pod,inventory-svc-bf8f159-02345,default-scheduler,2026-06-16 00:33:54,2026-06-16 02:07:54,20,2026-06-23 12:00:00
687,staging-use2-eks,inventory,Warning,OOMKilling,Container inventory-svc exceeded memory limit; OOMKilled,Pod,inventory-svc-1d6f570-1b50d,default-scheduler,2026-06-19 00:53:52,2026-06-19 01:19:52,22,2026-06-23 12:00:00
688,staging-use2-eks,search,Warning,DNSConfigForming,Search line limits exceeded for search-api-1605640-8abaf,Pod,search-api-1605640-8abaf,default-scheduler,2026-06-22 17:08:17,2026-06-22 18:15:17,10,2026-06-23 12:00:00
689,prod-usw2-eks,checkout,Warning,FreeDiskSpaceFailed,Failed to garbage collect on node ip-10-6-194-142,Pod,cart-svc-882ca58-64a75,default-scheduler,2026-06-01 22:06:14,2026-06-01 23:54:14,7,2026-06-23 12:00:00
690,staging-use2-eks,checkout,Warning,Rebooted,Node ip-10-14-70-252 has been rebooted,Pod,checkout-web-aca9086-f5fe6,kubelet,2026-06-23 11:17:54,2026-06-23 11:34:54,12,2026-06-23 12:00:00
691,prod-usw2-eks,search,Warning,FreeDiskSpaceFailed,Failed to garbage collect on node ip-10-14-16-161,Pod,search-api-a47d446-4ffe2,controllermanager,2026-06-19 00:36:19,2026-06-19 00:43:19,23,2026-06-23 12:00:00
692,dr-use1-eks,checkout,Warning,Evicted,Pod checkout-web-6e9e217-a5c79 evicted: node memory pressure,Pod,checkout-web-6e9e217-a5c79,controllermanager,2026-06-22 20:55:32,2026-06-22 22:01:32,11,2026-06-23 12:00:00
693,prod-use2-eks,payments,Warning,Evicted,Pod payments-api-7fa4649-debd8 evicted: node memory pressure,Pod,payments-api-7fa4649-debd8,controllermanager,2026-06-22 19:05:36,2026-06-22 20:30:36,32,2026-06-23 12:00:00
694,prod-usw2-eks,search,Warning,FreeDiskSpaceFailed,Failed to garbage collect on node ip-10-6-194-142,Pod,search-api-15a6d76-12766,default-scheduler,2026-06-21 09:23:42,2026-06-21 11:03:42,24,2026-06-23 12:00:00
695,prod-use2-eks,platform,Warning,Unhealthy,Readiness probe errored: dial tcp i/o timeout for image-resizer-7bb3c89-50e74,Pod,image-resizer-7bb3c89-50e74,controllermanager,2026-06-21 06:37:04,2026-06-21 08:06:04,18,2026-06-23 12:00:00
696,prod-usw2-eks,orders,Warning,OOMKilling,Memory cgroup out of memory: Killed process in orders-api-402bb51-ad48f,Pod,orders-api-402bb51-ad48f,controllermanager,2026-06-16 15:00:27,2026-06-16 15:49:27,18,2026-06-23 12:00:00
697,prod-usw2-eks,inventory,Normal,Scheduled,Successfully assigned inventory-svc-0d33458-c137f to ip-10-15-83-236,Pod,inventory-svc-0d33458-c137f,default-scheduler,2026-05-29 02:51:32,2026-05-29 03:27:32,1,2026-06-23 12:00:00
698,prod-use2-eks,payments,Warning,Evicted,Pod payments-api-7fa4649-debd8 evicted: node memory pressure,Pod,payments-api-7fa4649-debd8,controllermanager,2026-06-22 11:29:34,2026-06-22 13:20:34,37,2026-06-23 12:00:00
699,prod-use2-eks,identity,Warning,Evicted,Pod session-store-4732511-0dba8 evicted: node memory pressure,Pod,session-store-4732511-0dba8,kubelet,2026-06-12 20:25:21,2026-06-12 21:59:21,28,2026-06-23 12:00:00
700,prod-use2-eks,kube-system,Warning,DNSConfigForming,Search line limits exceeded for metrics-server-e2e6924-29c37,Pod,metrics-server-e2e6924-29c37,default-scheduler,2026-06-19 18:45:34,2026-06-19 20:00:34,32,2026-06-23 12:00:00
701,dr-use1-eks,search,Warning,Rebooted,Node ip-10-21-57-150 has been rebooted,Pod,indexer-6af7422-f66fc,controllermanager,2026-06-20 22:50:28,2026-06-21 00:32:28,19,2026-06-23 12:00:00
702,prod-usw2-eks,inventory,Warning,BackOff,Back-off restarting failed container inventory-svc in pod inventory-svc-bf8f159-02345,Pod,inventory-svc-bf8f159-02345,default-scheduler,2026-05-31 21:33:45,2026-05-31 21:36:45,2,2026-06-23 12:00:00
703,staging-use2-eks,payments,Warning,FreeDiskSpaceFailed,Failed to garbage collect on node ip-10-20-108-255,Pod,payments-api-2729261-453da,controllermanager,2026-06-04 22:56:31,2026-06-04 23:21:31,23,2026-06-23 12:00:00
704,prod-use2-eks,payments,Warning,OOMKilling,Container payments-api exceeded memory limit; OOMKilled,Pod,payments-api-1ce3577-591ac,controllermanager,2026-06-23 05:57:34,2026-06-23 07:43:34,4,2026-06-23 12:00:00
705,staging-use2-eks,platform,Warning,Evicted,Pod config-svc-929cd33-16be4 evicted: node was low on resource ephemeral-storage,Pod,config-svc-929cd33-16be4,default-scheduler,2026-06-10 20:44:23,2026-06-10 20:47:23,17,2026-06-23 12:00:00
706,prod-use2-eks,checkout,Warning,OOMKilling,Memory cgroup out of memory: Killed process in checkout-web-0101b48-2b2af,Pod,checkout-web-0101b48-2b2af,controllermanager,2026-06-22 08:02:39,2026-06-22 10:02:39,24,2026-06-23 12:00:00
707,prod-use2-eks,orders,Warning,Evicted,Pod orders-api-e9b4a39-c3784 evicted: node memory pressure,Pod,orders-api-e9b4a39-c3784,controllermanager,2026-06-11 14:14:55,2026-06-11 15:04:55,8,2026-06-23 12:00:00
708,prod-use2-eks,checkout,Warning,OOMKilling,Container cart-svc exceeded memory limit; OOMKilled,Pod,cart-svc-51c2594-4d271,controllermanager,2026-06-16 13:44:46,2026-06-16 15:11:46,15,2026-06-23 12:00:00
709,staging-use2-eks,search,Warning,DNSConfigForming,Search line limits exceeded for search-api-1605640-8abaf,Pod,search-api-1605640-8abaf,controllermanager,2026-06-22 05:24:58,2026-06-22 07:23:58,39,2026-06-23 12:00:00
710,dr-use1-eks,checkout,Warning,Evicted,Pod checkout-web-6e9e217-a5c79 evicted: node memory pressure,Pod,checkout-web-6e9e217-a5c79,controllermanager,2026-06-23 04:26:55,2026-06-23 05:39:55,30,2026-06-23 12:00:00
711,prod-usw2-eks,ledger,Warning,Evicted,Pod ledger-svc-2014124-29b88 evicted: node was low on resource ephemeral-storage,Pod,ledger-svc-2014124-29b88,controllermanager,2026-06-18 13:57:02,2026-06-18 15:53:02,32,2026-06-23 12:00:00
712,prod-usw2-eks,payments,Warning,Unhealthy,Liveness probe failed: HTTP 500 for payments-worker-1d1bf52-dff66,Pod,payments-worker-1d1bf52-dff66,controllermanager,2026-06-04 06:48:32,2026-06-04 08:17:32,20,2026-06-23 12:00:00
713,prod-use2-eks,kube-system,Warning,FreeDiskSpaceFailed,Failed to garbage collect on node ip-10-32-13-101,Pod,coredns-e513a45-fb7bf,kubelet,2026-06-20 14:56:07,2026-06-20 15:18:07,33,2026-06-23 12:00:00
714,prod-use2-eks,checkout,Warning,OOMKilling,Container cart-svc exceeded memory limit; OOMKilled,Pod,cart-svc-26a7d77-aafdc,controllermanager,2026-06-17 21:50:21,2026-06-17 23:23:21,19,2026-06-23 12:00:00
715,staging-use2-eks,identity,Warning,Unhealthy,Readiness probe errored: dial tcp i/o timeout for session-store-a097c68-649a1,Pod,session-store-a097c68-649a1,controllermanager,2026-06-12 22:48:10,2026-06-12 23:17:10,7,2026-06-23 12:00:00
716,prod-use2-eks,identity,Warning,Evicted,Pod session-store-4732511-0dba8 evicted: node memory pressure,Pod,session-store-4732511-0dba8,kubelet,2026-06-22 00:25:27,2026-06-22 01:41:27,11,2026-06-23 12:00:00
717,prod-usw2-eks,payments,Warning,OOMKilling,Container payments-api exceeded memory limit; OOMKilled,Pod,payments-api-b9a1287-dbbfe,default-scheduler,2026-06-09 09:05:30,2026-06-09 09:57:30,7,2026-06-23 12:00:00
718,prod-use2-eks,ledger,Warning,Unhealthy,Readiness probe failed: timeout for ledger-svc-f4a6d64-16dde,Pod,ledger-svc-f4a6d64-16dde,kubelet,2026-06-21 22:59:48,2026-06-21 23:34:48,18,2026-06-23 12:00:00
719,prod-usw2-eks,payments,Warning,Evicted,Pod payments-api-1e23165-1e35b evicted: node memory pressure,Pod,payments-api-1e23165-1e35b,kubelet,2026-06-14 10:37:36,2026-06-14 10:57:36,7,2026-06-23 12:00:00
720,prod-use2-eks,checkout,Warning,OOMKilling,Container cart-svc exceeded memory limit; OOMKilled,Pod,cart-svc-527eb80-045c0,default-scheduler,2026-06-23 00:37:18,2026-06-23 00:37:18,2,2026-06-23 12:00:00
721,prod-usw2-eks,ledger,Warning,Evicted,Pod ledger-svc-0744083-43011 evicted: node was low on resource ephemeral-storage,Pod,ledger-svc-0744083-43011,kubelet,2026-06-19 11:29:51,2026-06-19 11:33:51,39,2026-06-23 12:00:00
722,prod-usw2-eks,checkout,Warning,FreeDiskSpaceFailed,Failed to garbage collect on node ip-10-6-194-142,Pod,cart-svc-882ca58-64a75,controllermanager,2026-06-16 03:13:59,2026-06-16 03:58:59,22,2026-06-23 12:00:00
723,dr-use1-eks,notifications,Warning,Unhealthy,Liveness probe failed: HTTP 500 for notifications-b036879-82982,Pod,notifications-b036879-82982,default-scheduler,2026-06-23 10:59:50,2026-06-23 12:38:50,9,2026-06-23 12:00:00
724,prod-usw2-eks,payments,Warning,Evicted,Pod payments-api-423b015-b80bd evicted: node memory pressure,Pod,payments-api-423b015-b80bd,kubelet,2026-06-09 12:47:29,2026-06-09 13:13:29,18,2026-06-23 12:00:00
725,prod-use2-eks,platform,Normal,Throttling,CPU throttled for container config-svc,Pod,config-svc-027a395-39a4d,kubelet,2026-06-18 13:49:29,2026-06-18 15:33:29,1,2026-06-23 12:00:00
726,dr-use1-eks,orders,Warning,DNSConfigForming,Search line limits exceeded for orders-api-8330e48-f22f4,Pod,orders-api-8330e48-f22f4,controllermanager,2026-06-09 10:21:18,2026-06-09 11:17:18,9,2026-06-23 12:00:00
727,prod-use2-eks,checkout,Warning,Evicted,Pod cart-svc-51c2594-4d271 evicted: node memory pressure,Pod,cart-svc-51c2594-4d271,kubelet,2026-06-20 23:04:01,2026-06-20 23:14:01,38,2026-06-23 12:00:00
728,prod-use2-eks,kube-system,Warning,Evicted,Pod coredns-e513a45-fb7bf evicted: node was low on resource ephemeral-storage,Pod,coredns-e513a45-fb7bf,default-scheduler,2026-06-05 22:54:17,2026-06-05 22:54:17,9,2026-06-23 12:00:00
729,prod-usw2-eks,kube-system,Warning,NodeNotReady,Node ip-10-6-194-142 status is now: NodeNotReady,Pod,metrics-server-6162d13-d4a14,controllermanager,2026-06-14 16:22:59,2026-06-14 17:42:59,13,2026-06-23 12:00:00
730,prod-usw2-eks,search,Normal,Started,Started container recommendation,Pod,recommendation-87e3198-026ea,controllermanager,2026-06-05 01:27:49,2026-06-05 02:52:49,1,2026-06-23 12:00:00
731,dr-use1-eks,notifications,Warning,OOMKilling,Memory cgroup out of memory: Killed process in notifications-b036879-82982,Pod,notifications-b036879-82982,kubelet,2026-06-22 01:23:24,2026-06-22 02:09:24,32,2026-06-23 12:00:00
732,prod-usw2-eks,orders,Warning,BackOff,Back-off restarting failed container orders-api in pod orders-api-21c5d48-15186,Pod,orders-api-21c5d48-15186,default-scheduler,2026-06-15 07:42:08,2026-06-15 08:05:08,2,2026-06-23 12:00:00
733,prod-usw2-eks,search,Normal,Started,Started container indexer,Pod,indexer-6c1eb29-ca471,controllermanager,2026-05-30 08:04:21,2026-05-30 09:02:21,1,2026-06-23 12:00:00
734,prod-usw2-eks,notifications,Normal,Started,Started container notifications,Pod,notifications-abd2926-3451e,kubelet,2026-06-23 03:27:47,2026-06-23 04:27:47,1,2026-06-23 12:00:00
735,staging-use2-eks,checkout,Warning,NodeNotReady,Node ip-10-8-126-134 status is now: NodeNotReady,Pod,checkout-web-2b77739-52fdd,kubelet,2026-06-23 00:29:58,2026-06-23 00:45:58,15,2026-06-23 12:00:00
736,prod-use2-eks,checkout,Warning,Evicted,Pod cart-svc-26a7d77-aafdc evicted: node memory pressure,Pod,cart-svc-26a7d77-aafdc,controllermanager,2026-06-22 20:28:39,2026-06-22 21:11:39,20,2026-06-23 12:00:00
737,staging-use2-eks,search,Warning,Unhealthy,Readiness probe errored: dial tcp i/o timeout for search-api-1605640-8abaf,Pod,search-api-1605640-8abaf,controllermanager,2026-06-22 23:11:17,2026-06-23 01:07:17,30,2026-06-23 12:00:00
738,prod-usw2-eks,search,Warning,Evicted,Pod search-api-a47d446-4ffe2 evicted: node was low on resource ephemeral-storage,Pod,search-api-a47d446-4ffe2,controllermanager,2026-06-18 06:44:26,2026-06-18 08:15:26,27,2026-06-23 12:00:00
739,prod-usw2-eks,checkout,Normal,Scheduled,Successfully assigned checkout-web-c2b3638-fa6d0 to ip-10-22-107-136,Pod,checkout-web-c2b3638-fa6d0,kubelet,2026-06-07 15:53:22,2026-06-07 15:56:22,1,2026-06-23 12:00:00
740,prod-usw2-eks,checkout,Warning,FreeDiskSpaceFailed,Failed to garbage collect on node ip-10-6-194-142,Pod,cart-svc-ee38458-64d46,kubelet,2026-06-02 12:04:46,2026-06-02 13:10:46,11,2026-06-23 12:00:00
741,prod-usw2-eks,kube-system,Warning,Rebooted,Node ip-10-6-194-142 has been rebooted,Pod,metrics-server-6162d13-d4a14,controllermanager,2026-06-17 07:48:58,2026-06-17 09:10:58,16,2026-06-23 12:00:00
742,prod-usw2-eks,search,Warning,FreeDiskSpaceFailed,Failed to garbage collect on node ip-10-14-16-161,Pod,search-api-8352074-5b766,kubelet,2026-06-20 23:55:35,2026-06-21 00:21:35,9,2026-06-23 12:00:00
743,prod-use2-eks,search,Normal,Started,Started container recommendation,Pod,recommendation-e5d5555-c6e9b,controllermanager,2026-06-20 16:59:30,2026-06-20 18:05:30,1,2026-06-23 12:00:00
744,dr-use1-eks,checkout,Warning,Evicted,Pod checkout-web-6e9e217-a5c79 evicted: node memory pressure,Pod,checkout-web-6e9e217-a5c79,default-scheduler,2026-06-19 00:30:11,2026-06-19 02:11:11,24,2026-06-23 12:00:00
745,prod-use2-eks,checkout,Warning,OOMKilling,Container cart-svc exceeded memory limit; OOMKilled,Pod,cart-svc-26a7d77-aafdc,controllermanager,2026-06-14 15:24:19,2026-06-14 16:32:19,36,2026-06-23 12:00:00
746,prod-usw2-eks,payments,Warning,BackOff,Back-off restarting failed container payments-worker in pod payments-worker-bbc0947-0aa1a,Pod,payments-worker-bbc0947-0aa1a,kubelet,2026-06-20 12:41:53,2026-06-20 13:40:53,19,2026-06-23 12:00:00
747,prod-use2-eks,search,Normal,Started,Started container search-api,Pod,search-api-4350294-dbefb,kubelet,2026-06-01 21:21:59,2026-06-01 23:20:59,1,2026-06-23 12:00:00
748,prod-usw2-eks,orders,Warning,Unhealthy,Liveness probe failed: HTTP 500 for orders-api-cbca488-26609,Pod,orders-api-cbca488-26609,default-scheduler,2026-06-20 01:13:14,2026-06-20 02:36:14,28,2026-06-23 12:00:00
749,prod-usw2-eks,search,Normal,Pulled,Container image pulled for recommendation,Pod,recommendation-87e3198-026ea,controllermanager,2026-06-03 05:40:12,2026-06-03 06:49:12,1,2026-06-23 12:00:00
750,prod-use2-eks,payments,Warning,Evicted,Pod payments-api-58c5e74-26d34 evicted: node memory pressure,Pod,payments-api-58c5e74-26d34,default-scheduler,2026-06-23 01:29:38,2026-06-23 02:11:38,7,2026-06-23 12:00:00
751,prod-usw2-eks,checkout,Normal,Pulled,Container image pulled for checkout-web,Pod,checkout-web-ec64e26-f37ce,kubelet,2026-05-29 18:42:08,2026-05-29 19:32:08,1,2026-06-23 12:00:00
752,prod-use2-eks,platform,Warning,DNSConfigForming,Search line limits exceeded for image-resizer-7bb3c89-50e74,Pod,image-resizer-7bb3c89-50e74,controllermanager,2026-06-20 11:28:25,2026-06-20 12:22:25,12,2026-06-23 12:00:00
753,prod-use2-eks,orders,Warning,OOMKilling,Container orders-api exceeded memory limit; OOMKilled,Pod,orders-api-e9b4a39-c3784,kubelet,2026-06-11 10:44:53,2026-06-11 11:23:53,9,2026-06-23 12:00:00
754,dr-use1-eks,search,Warning,Evicted,Pod search-api-d416b43-7cb20 evicted: node was low on resource ephemeral-storage,Pod,search-api-d416b43-7cb20,controllermanager,2026-06-14 10:12:16,2026-06-14 10:53:16,18,2026-06-23 12:00:00
755,prod-usw2-eks,ledger,Warning,FreeDiskSpaceFailed,Failed to garbage collect on node ip-10-6-194-142,Pod,ledger-svc-842cd31-95bfa,kubelet,2026-06-22 16:45:30,2026-06-22 17:47:30,10,2026-06-23 12:00:00
756,prod-use2-eks,ledger,Warning,Unhealthy,Readiness probe failed: timeout for ledger-svc-204e643-7d23b,Pod,ledger-svc-204e643-7d23b,kubelet,2026-06-23 00:45:42,2026-06-23 02:34:42,39,2026-06-23 12:00:00
757,prod-use2-eks,platform,Warning,Unhealthy,Readiness probe errored: dial tcp i/o timeout for image-resizer-7bb3c89-50e74,Pod,image-resizer-7bb3c89-50e74,default-scheduler,2026-06-21 12:14:28,2026-06-21 12:46:28,25,2026-06-23 12:00:00
758,prod-usw2-eks,payments,Warning,Unhealthy,Liveness probe failed: HTTP 500 for payments-worker-bbc0947-0aa1a,Pod,payments-worker-bbc0947-0aa1a,controllermanager,2026-06-20 17:57:44,2026-06-20 19:49:44,36,2026-06-23 12:00:00
759,prod-usw2-eks,search,Warning,FreeDiskSpaceFailed,Failed to garbage collect on node ip-10-14-16-161,Pod,search-api-8352074-5b766,default-scheduler,2026-06-18 08:41:51,2026-06-18 10:00:51,29,2026-06-23 12:00:00
760,prod-usw2-eks,kube-system,Warning,Unhealthy,Readiness probe errored: dial tcp i/o timeout for coredns-37f1521-4cd3d,Pod,coredns-37f1521-4cd3d,default-scheduler,2026-06-17 08:26:01,2026-06-17 09:48:01,28,2026-06-23 12:00:00
761,prod-usw2-eks,payments,Normal,Pulled,Container image pulled for payments-worker,Pod,payments-worker-b4be648-d2dcb,controllermanager,2026-06-22 04:29:27,2026-06-22 05:26:27,1,2026-06-23 12:00:00
762,prod-usw2-eks,checkout,Warning,FreeDiskSpaceFailed,Failed to garbage collect on node ip-10-6-194-142,Pod,cart-svc-882ca58-64a75,kubelet,2026-06-12 21:26:19,2026-06-12 22:24:19,21,2026-06-23 12:00:00
763,prod-use2-eks,orders,Warning,OOMKilling,Container orders-api exceeded memory limit; OOMKilled,Pod,orders-api-bfb2f93-32ad3,kubelet,2026-06-11 06:58:21,2026-06-11 07:53:21,14,2026-06-23 12:00:00
764,prod-use2-eks,kube-system,Warning,Evicted,Pod coredns-e513a45-fb7bf evicted: node was low on resource ephemeral-storage,Pod,coredns-e513a45-fb7bf,kubelet,2026-06-22 03:38:14,2026-06-22 05:37:14,17,2026-06-23 12:00:00
765,prod-use2-eks,payments,Warning,Evicted,Pod payments-api-58c5e74-26d34 evicted: node memory pressure,Pod,payments-api-58c5e74-26d34,kubelet,2026-06-22 22:09:54,2026-06-22 23:10:54,19,2026-06-23 12:00:00
766,prod-use2-eks,checkout,Warning,Evicted,Pod cart-svc-26a7d77-aafdc evicted: node memory pressure,Pod,cart-svc-26a7d77-aafdc,default-scheduler,2026-06-16 06:33:21,2026-06-16 07:20:21,33,2026-06-23 12:00:00
767,prod-usw2-eks,inventory,Warning,BackOff,Back-off restarting failed container inventory-svc in pod inventory-svc-bf8f159-02345,Pod,inventory-svc-bf8f159-02345,kubelet,2026-06-23 03:00:54,2026-06-23 04:36:54,38,2026-06-23 12:00:00
768,staging-use2-eks,search,Normal,Scheduled,Successfully assigned search-api-8ca0b98-505ff to ip-10-20-108-255,Pod,search-api-8ca0b98-505ff,controllermanager,2026-06-22 22:32:00,2026-06-22 22:52:00,1,2026-06-23 12:00:00
769,prod-use2-eks,checkout,Warning,Evicted,Pod cart-svc-51c2594-4d271 evicted: node memory pressure,Pod,cart-svc-51c2594-4d271,kubelet,2026-06-21 00:48:27,2026-06-21 01:34:27,8,2026-06-23 12:00:00
770,prod-usw2-eks,orders,Normal,Scheduled,Successfully assigned orders-worker-0696c96-a62c8 to ip-10-12-35-23,Pod,orders-worker-0696c96-a62c8,kubelet,2026-06-23 10:25:26,2026-06-23 12:14:26,1,2026-06-23 12:00:00
771,prod-use2-eks,payments,Warning,Evicted,Pod payments-api-7fa4649-debd8 evicted: node memory pressure,Pod,payments-api-7fa4649-debd8,controllermanager,2026-06-22 22:35:46,2026-06-22 23:19:46,33,2026-06-23 12:00:00
772,prod-use2-eks,identity,Warning,Evicted,Pod session-store-1ac5266-1ca26 evicted: node memory pressure,Pod,session-store-1ac5266-1ca26,kubelet,2026-06-11 21:18:26,2026-06-11 22:01:26,20,2026-06-23 12:00:00
773,prod-usw2-eks,payments,Warning,OOMKilling,Container payments-api exceeded memory limit; OOMKilled,Pod,payments-api-1e23165-1e35b,controllermanager,2026-05-27 17:56:41,2026-05-27 19:45:41,35,2026-06-23 12:00:00
774,staging-use2-eks,payments,Normal,Pulled,Container image pulled for payments-api,Pod,payments-api-dde4d16-a3d09,controllermanager,2026-06-21 10:27:18,2026-06-21 10:54:18,1,2026-06-23 12:00:00
775,prod-usw2-eks,search,Warning,Evicted,Pod search-api-a47d446-4ffe2 evicted: node was low on resource ephemeral-storage,Pod,search-api-a47d446-4ffe2,kubelet,2026-06-20 04:13:22,2026-06-20 04:38:22,14,2026-06-23 12:00:00
776,prod-use2-eks,ledger,Warning,Unhealthy,Readiness probe failed: timeout for ledger-svc-f4a6d64-16dde,Pod,ledger-svc-f4a6d64-16dde,controllermanager,2026-06-22 07:39:52,2026-06-22 08:30:52,16,2026-06-23 12:00:00
777,prod-use2-eks,search,Normal,Scheduled,Successfully assigned indexer-b07f520-eaf04 to ip-10-17-79-110,Pod,indexer-b07f520-eaf04,default-scheduler,2026-06-11 03:34:51,2026-06-11 04:29:51,1,2026-06-23 12:00:00
778,prod-usw2-eks,identity,Warning,FreeDiskSpaceFailed,Failed to garbage collect on node ip-10-12-35-23,Pod,session-store-d825e25-14f9f,default-scheduler,2026-06-13 07:08:06,2026-06-13 08:58:06,39,2026-06-23 12:00:00
779,prod-usw2-eks,payments,Warning,BackOff,Back-off restarting failed container payments-worker in pod payments-worker-bbc0947-0aa1a,Pod,payments-worker-bbc0947-0aa1a,default-scheduler,2026-06-16 15:07:28,2026-06-16 15:12:28,3,2026-06-23 12:00:00
780,prod-use2-eks,checkout,Warning,Evicted,Pod cart-svc-527eb80-045c0 evicted: node memory pressure,Pod,cart-svc-527eb80-045c0,kubelet,2026-06-13 13:39:28,2026-06-13 14:10:28,18,2026-06-23 12:00:00
781,prod-use2-eks,payments,Warning,OOMKilling,Container payments-api exceeded memory limit; OOMKilled,Pod,payments-api-1ce3577-591ac,kubelet,2026-06-23 06:39:29,2026-06-23 08:12:29,38,2026-06-23 12:00:00
782,prod-usw2-eks,orders,Warning,OOMKilling,Memory cgroup out of memory: Killed process in orders-api-402bb51-ad48f,Pod,orders-api-402bb51-ad48f,kubelet,2026-06-22 12:05:02,2026-06-22 12:54:02,19,2026-06-23 12:00:00
783,prod-use2-eks,orders,Warning,Evicted,Pod orders-api-7f89525-97cdd evicted: node memory pressure,Pod,orders-api-7f89525-97cdd,default-scheduler,2026-06-10 14:34:05,2026-06-10 14:57:05,30,2026-06-23 12:00:00
784,dr-use1-eks,search,Warning,FreeDiskSpaceFailed,Failed to garbage collect on node ip-10-40-81-216,Pod,search-api-d416b43-7cb20,default-scheduler,2026-06-20 16:33:56,2026-06-20 18:19:56,32,2026-06-23 12:00:00
785,prod-use2-eks,search,Normal,Pulled,Container image pulled for recommendation,Pod,recommendation-e5d5555-c6e9b,controllermanager,2026-06-22 16:00:34,2026-06-22 16:55:34,1,2026-06-23 12:00:00
786,prod-usw2-eks,orders,Warning,Evicted,Pod orders-worker-8482791-f2d9f evicted: node was low on resource ephemeral-storage,Pod,orders-worker-8482791-f2d9f,controllermanager,2026-06-19 06:16:23,2026-06-19 07:19:23,35,2026-06-23 12:00:00
787,prod-use2-eks,notifications,Warning,Unhealthy,Readiness probe failed: timeout for notifications-1938743-28dca,Pod,notifications-1938743-28dca,kubelet,2026-06-12 01:54:54,2026-06-12 03:14:54,24,2026-06-23 12:00:00
788,prod-use2-eks,identity,Normal,Started,Started container auth-gateway,Pod,auth-gateway-bf1d422-2018d,controllermanager,2026-06-15 12:29:22,2026-06-15 13:33:22,1,2026-06-23 12:00:00
789,prod-usw2-eks,payments,Warning,OOMKilling,Container payments-api exceeded memory limit; OOMKilled,Pod,payments-api-423b015-b80bd,kubelet,2026-06-15 15:44:04,2026-06-15 15:54:04,37,2026-06-23 12:00:00
790,prod-use2-eks,identity,Warning,OOMKilling,Container session-store exceeded memory limit; OOMKilled,Pod,session-store-4732511-0dba8,controllermanager,2026-06-19 03:50:20,2026-06-19 05:36:20,37,2026-06-23 12:00:00
791,dr-use1-eks,search,Warning,NodeNotReady,Node ip-10-21-57-150 status is now: NodeNotReady,Pod,indexer-6af7422-f66fc,kubelet,2026-05-31 09:37:43,2026-05-31 09:38:43,37,2026-06-23 12:00:00
792,staging-use2-eks,checkout,Warning,NodeNotReady,Node ip-10-14-70-252 status is now: NodeNotReady,Pod,checkout-web-aca9086-f5fe6,controllermanager,2026-06-22 18:59:13,2026-06-22 20:28:13,9,2026-06-23 12:00:00
793,prod-usw2-eks,platform,Normal,Pulled,Container image pulled for image-resizer,Pod,image-resizer-9683178-b7560,default-scheduler,2026-06-21 22:36:51,2026-06-22 00:34:51,1,2026-06-23 12:00:00
794,prod-usw2-eks,payments,Warning,Evicted,Pod payments-api-423b015-b80bd evicted: node memory pressure,Pod,payments-api-423b015-b80bd,kubelet,2026-06-21 10:38:43,2026-06-21 11:24:43,31,2026-06-23 12:00:00
795,prod-usw2-eks,checkout,Warning,FreeDiskSpaceFailed,Failed to garbage collect on node ip-10-29-63-193,Pod,cart-svc-0a94879-c1bba,controllermanager,2026-06-03 01:53:35,2026-06-03 03:22:35,30,2026-06-23 12:00:00
796,prod-use2-eks,payments,Warning,Evicted,Pod payments-api-58c5e74-26d34 evicted: node memory pressure,Pod,payments-api-58c5e74-26d34,controllermanager,2026-06-22 19:04:52,2026-06-22 20:51:52,36,2026-06-23 12:00:00
797,prod-use2-eks,orders,Normal,Scheduled,Successfully assigned orders-worker-9681c18-374c7 to ip-10-6-44-216,Pod,orders-worker-9681c18-374c7,controllermanager,2026-06-05 13:20:45,2026-06-05 13:59:45,1,2026-06-23 12:00:00
798,prod-usw2-eks,checkout,Warning,FreeDiskSpaceFailed,Failed to garbage collect on node ip-10-29-63-193,Pod,cart-svc-0a94879-c1bba,default-scheduler,2026-06-11 19:51:36,2026-06-11 21:50:36,29,2026-06-23 12:00:00
799,prod-usw2-eks,orders,Warning,FreeDiskSpaceFailed,Failed to garbage collect on node ip-10-14-16-161,Pod,orders-worker-8482791-f2d9f,default-scheduler,2026-06-19 19:48:25,2026-06-19 20:38:25,17,2026-06-23 12:00:00
800,prod-use2-eks,platform,Normal,Scheduled,Successfully assigned config-svc-ddd1723-06ca5 to ip-10-24-49-183,Pod,config-svc-ddd1723-06ca5,controllermanager,2026-06-17 06:20:25,2026-06-17 07:54:25,1,2026-06-23 12:00:00
801,staging-use2-eks,platform,Warning,Evicted,Pod config-svc-929cd33-16be4 evicted: node was low on resource ephemeral-storage,Pod,config-svc-929cd33-16be4,default-scheduler,2026-06-17 09:49:32,2026-06-17 11:41:32,20,2026-06-23 12:00:00
802,prod-use2-eks,search,Normal,Scheduled,Successfully assigned indexer-4680271-0a829 to ip-10-17-79-110,Pod,indexer-4680271-0a829,kubelet,2026-06-08 05:31:41,2026-06-08 06:07:41,1,2026-06-23 12:00:00
803,prod-usw2-eks,identity,Warning,FreeDiskSpaceFailed,Failed to garbage collect on node ip-10-12-35-23,Pod,session-store-d825e25-14f9f,controllermanager,2026-06-10 23:22:52,2026-06-11 00:26:52,38,2026-06-23 12:00:00
804,prod-use2-eks,checkout,Warning,OOMKilling,Memory cgroup out of memory: Killed process in checkout-web-0101b48-2b2af,Pod,checkout-web-0101b48-2b2af,kubelet,2026-06-07 22:03:08,2026-06-07 22:24:08,18,2026-06-23 12:00:00
805,prod-use2-eks,orders,Warning,Evicted,Pod orders-api-e9b4a39-c3784 evicted: node memory pressure,Pod,orders-api-e9b4a39-c3784,controllermanager,2026-06-18 07:00:26,2026-06-18 07:21:26,27,2026-06-23 12:00:00
806,prod-usw2-eks,identity,Warning,FreeDiskSpaceFailed,Failed to garbage collect on node ip-10-12-35-23,Pod,session-store-d825e25-14f9f,controllermanager,2026-06-17 17:50:23,2026-06-17 18:57:23,15,2026-06-23 12:00:00
807,prod-usw2-eks,ledger,Warning,FreeDiskSpaceFailed,Failed to garbage collect on node ip-10-6-194-142,Pod,ledger-svc-842cd31-95bfa,default-scheduler,2026-06-15 04:59:51,2026-06-15 05:16:51,25,2026-06-23 12:00:00
808,staging-use2-eks,payments,Warning,FreeDiskSpaceFailed,Failed to garbage collect on node ip-10-20-108-255,Pod,payments-api-2729261-453da,kubelet,2026-06-03 16:28:42,2026-06-03 16:48:42,3,2026-06-23 12:00:00
809,prod-use2-eks,orders,Warning,Evicted,Pod orders-api-7f89525-97cdd evicted: node memory pressure,Pod,orders-api-7f89525-97cdd,kubelet,2026-06-10 18:08:51,2026-06-10 19:17:51,13,2026-06-23 12:00:00
810,prod-usw2-eks,search,Warning,Evicted,Pod search-api-8352074-5b766 evicted: node was low on resource ephemeral-storage,Pod,search-api-8352074-5b766,kubelet,2026-06-15 03:51:32,2026-06-15 04:04:32,2,2026-06-23 12:00:00
811,staging-use2-eks,identity,Warning,DNSConfigForming,Search line limits exceeded for session-store-a097c68-649a1,Pod,session-store-a097c68-649a1,default-scheduler,2026-06-17 06:18:06,2026-06-17 06:50:06,26,2026-06-23 12:00:00
812,prod-use2-eks,platform,Normal,Throttling,CPU throttled for container config-svc,Pod,config-svc-027a395-39a4d,default-scheduler,2026-06-20 12:01:00,2026-06-20 12:48:00,1,2026-06-23 12:00:00
813,prod-use2-eks,ledger,Normal,Throttling,CPU throttled for container ledger-svc,Pod,ledger-svc-204e643-7d23b,default-scheduler,2026-06-17 21:52:54,2026-06-17 22:05:54,1,2026-06-23 12:00:00
814,prod-use2-eks,notifications,Warning,Unhealthy,Readiness probe failed: timeout for notifications-1938743-28dca,Pod,notifications-1938743-28dca,default-scheduler,2026-06-10 08:37:51,2026-06-10 09:21:51,30,2026-06-23 12:00:00
815,dr-use1-eks,checkout,Warning,OOMKilling,Container checkout-web exceeded memory limit; OOMKilled,Pod,checkout-web-4263246-52f3a,controllermanager,2026-06-20 01:05:11,2026-06-20 02:57:11,29,2026-06-23 12:00:00
816,prod-usw2-eks,checkout,Warning,FreeDiskSpaceFailed,Failed to garbage collect on node ip-10-6-194-142,Pod,cart-svc-882ca58-64a75,controllermanager,2026-06-16 21:39:44,2026-06-16 22:09:44,6,2026-06-23 12:00:00
817,prod-usw2-eks,payments,Warning,Evicted,Pod payments-api-b9a1287-dbbfe evicted: node memory pressure,Pod,payments-api-b9a1287-dbbfe,kubelet,2026-06-21 04:18:48,2026-06-21 05:42:48,28,2026-06-23 12:00:00
818,staging-use2-eks,identity,Warning,DNSConfigForming,Search line limits exceeded for session-store-a097c68-649a1,Pod,session-store-a097c68-649a1,default-scheduler,2026-06-18 01:16:33,2026-06-18 02:41:33,35,2026-06-23 12:00:00
819,prod-usw2-eks,orders,Warning,Evicted,Pod orders-worker-b907131-2627d evicted: node was low on resource ephemeral-storage,Pod,orders-worker-b907131-2627d,kubelet,2026-06-19 11:30:48,2026-06-19 12:58:48,25,2026-06-23 12:00:00
820,prod-usw2-eks,checkout,Normal,Started,Started container checkout-web,Pod,checkout-web-f628153-c1833,kubelet,2026-06-10 23:52:15,2026-06-11 01:31:15,1,2026-06-23 12:00:00
821,prod-usw2-eks,kube-system,Warning,DNSConfigForming,Search line limits exceeded for coredns-37f1521-4cd3d,Pod,coredns-37f1521-4cd3d,controllermanager,2026-06-17 20:01:56,2026-06-17 20:40:56,28,2026-06-23 12:00:00
822,prod-usw2-eks,payments,Warning,OOMKilling,Container payments-api exceeded memory limit; OOMKilled,Pod,payments-api-423b015-b80bd,controllermanager,2026-06-12 12:09:43,2026-06-12 14:08:43,26,2026-06-23 12:00:00
823,prod-use2-eks,identity,Warning,Evicted,Pod session-store-4732511-0dba8 evicted: node memory pressure,Pod,session-store-4732511-0dba8,kubelet,2026-06-16 07:13:44,2026-06-16 08:15:44,24,2026-06-23 12:00:00
824,prod-usw2-eks,orders,Warning,BackOff,Back-off restarting failed container orders-api in pod orders-api-cbca488-26609,Pod,orders-api-cbca488-26609,controllermanager,2026-06-18 06:59:26,2026-06-18 08:46:26,37,2026-06-23 12:00:00
825,prod-use2-eks,payments,Warning,OOMKilling,Container payments-api exceeded memory limit; OOMKilled,Pod,payments-api-7fa4649-debd8,kubelet,2026-06-23 07:22:05,2026-06-23 08:45:05,1,2026-06-23 12:00:00
826,staging-use2-eks,checkout,Warning,Rebooted,Node ip-10-14-70-252 has been rebooted,Pod,checkout-web-aca9086-f5fe6,kubelet,2026-06-23 07:58:07,2026-06-23 09:24:07,39,2026-06-23 12:00:00
827,prod-usw2-eks,inventory,Warning,OOMKilling,Memory cgroup out of memory: Killed process in inventory-svc-bf8f159-02345,Pod,inventory-svc-bf8f159-02345,kubelet,2026-06-19 17:14:32,2026-06-19 17:38:32,9,2026-06-23 12:00:00
828,prod-usw2-eks,checkout,Warning,FreeDiskSpaceFailed,Failed to garbage collect on node ip-10-29-63-193,Pod,cart-svc-0a94879-c1bba,kubelet,2026-06-04 04:33:01,2026-06-04 06:12:01,9,2026-06-23 12:00:00
829,prod-use2-eks,kube-system,Warning,Unhealthy,Readiness probe errored: dial tcp i/o timeout for metrics-server-e2e6924-29c37,Pod,metrics-server-e2e6924-29c37,default-scheduler,2026-06-15 10:50:12,2026-06-15 12:23:12,18,2026-06-23 12:00:00
830,prod-use2-eks,checkout,Warning,OOMKilling,Memory cgroup out of memory: Killed process in checkout-web-c2eb578-2d181,Pod,checkout-web-c2eb578-2d181,default-scheduler,2026-06-19 00:06:12,2026-06-19 01:34:12,18,2026-06-23 12:00:00
831,prod-use2-eks,payments,Normal,Scheduled,Successfully assigned payments-worker-7a57672-86691 to ip-10-40-57-12,Pod,payments-worker-7a57672-86691,default-scheduler,2026-06-05 05:17:38,2026-06-05 06:09:38,1,2026-06-23 12:00:00
832,staging-use2-eks,inventory,Warning,OOMKilling,Container inventory-svc exceeded memory limit; OOMKilled,Pod,inventory-svc-1d6f570-1b50d,kubelet,2026-06-19 16:27:09,2026-06-19 17:33:09,23,2026-06-23 12:00:00
833,prod-use2-eks,search,Normal,Started,Started container indexer,Pod,indexer-b07f520-eaf04,kubelet,2026-05-28 10:39:47,2026-05-28 11:20:47,1,2026-06-23 12:00:00
834,prod-usw2-eks,search,Warning,Evicted,Pod search-api-8352074-5b766 evicted: node was low on resource ephemeral-storage,Pod,search-api-8352074-5b766,kubelet,2026-06-22 23:57:55,2026-06-23 00:03:55,1,2026-06-23 12:00:00
835,prod-use2-eks,platform,Normal,Throttling,CPU throttled for container config-svc,Pod,config-svc-027a395-39a4d,controllermanager,2026-06-23 03:36:29,2026-06-23 05:12:29,1,2026-06-23 12:00:00
836,prod-use2-eks,platform,Warning,Unhealthy,Readiness probe errored: dial tcp i/o timeout for image-resizer-7bb3c89-50e74,Pod,image-resizer-7bb3c89-50e74,kubelet,2026-06-22 08:46:05,2026-06-22 09:04:05,11,2026-06-23 12:00:00
837,prod-usw2-eks,orders,Warning,FreeDiskSpaceFailed,Failed to garbage collect on node ip-10-14-16-161,Pod,orders-worker-8482791-f2d9f,kubelet,2026-06-18 15:48:53,2026-06-18 16:50:53,23,2026-06-23 12:00:00
838,prod-use2-eks,payments,Warning,OOMKilling,Container payments-api exceeded memory limit; OOMKilled,Pod,payments-api-c9c2b74-00142,kubelet,2026-06-23 05:30:37,2026-06-23 06:35:37,16,2026-06-23 12:00:00
839,prod-usw2-eks,inventory,Warning,Unhealthy,Liveness probe failed: HTTP 500 for inventory-svc-bf8f159-02345,Pod,inventory-svc-bf8f159-02345,controllermanager,2026-06-21 22:19:55,2026-06-22 00:00:55,37,2026-06-23 12:00:00
840,prod-use2-eks,identity,Warning,Evicted,Pod session-store-4732511-0dba8 evicted: node memory pressure,Pod,session-store-4732511-0dba8,kubelet,2026-06-12 10:17:54,2026-06-12 10:28:54,20,2026-06-23 12:00:00
841,prod-usw2-eks,checkout,Normal,Scheduled,Successfully assigned checkout-web-ec64e26-f37ce to ip-10-22-107-136,Pod,checkout-web-ec64e26-f37ce,kubelet,2026-06-07 13:00:04,2026-06-07 14:25:04,1,2026-06-23 12:00:00
842,prod-use2-eks,notifications,Normal,Throttling,CPU throttled for container notifications,Pod,notifications-1938743-28dca,kubelet,2026-06-16 20:28:32,2026-06-16 22:28:32,1,2026-06-23 12:00:00
843,prod-usw2-eks,kube-system,Warning,Rebooted,Node ip-10-6-194-142 has been rebooted,Pod,metrics-server-6162d13-d4a14,default-scheduler,2026-06-18 12:46:02,2026-06-18 13:41:02,15,2026-06-23 12:00:00
844,prod-use2-eks,checkout,Warning,Evicted,Pod cart-svc-26a7d77-aafdc evicted: node memory pressure,Pod,cart-svc-26a7d77-aafdc,kubelet,2026-06-16 20:39:14,2026-06-16 21:35:14,29,2026-06-23 12:00:00
845,dr-use1-eks,notifications,Warning,BackOff,Back-off restarting failed container notifications in pod notifications-b036879-82982,Pod,notifications-b036879-82982,controllermanager,2026-06-22 06:44:04,2026-06-22 08:42:04,20,2026-06-23 12:00:00
846,prod-usw2-eks,orders,Warning,Evicted,Pod orders-worker-b907131-2627d evicted: node was low on resource ephemeral-storage,Pod,orders-worker-b907131-2627d,default-scheduler,2026-06-18 14:23:42,2026-06-18 15:17:42,25,2026-06-23 12:00:00
847,dr-use1-eks,orders,Normal,Started,Started container orders-worker,Pod,orders-worker-f884840-8265c,kubelet,2026-05-31 21:53:07,2026-05-31 23:35:07,1,2026-06-23 12:00:00
848,prod-usw2-eks,kube-system,Warning,Unhealthy,Readiness probe errored: dial tcp i/o timeout for coredns-37f1521-4cd3d,Pod,coredns-37f1521-4cd3d,default-scheduler,2026-06-20 22:41:27,2026-06-21 00:11:27,12,2026-06-23 12:00:00
849,prod-use2-eks,identity,Warning,OOMKilling,Container session-store exceeded memory limit; OOMKilled,Pod,session-store-1ac5266-1ca26,kubelet,2026-06-13 13:55:25,2026-06-13 15:48:25,7,2026-06-23 12:00:00
850,staging-use2-eks,platform,Warning,Evicted,Pod config-svc-929cd33-16be4 evicted: node was low on resource ephemeral-storage,Pod,config-svc-929cd33-16be4,kubelet,2026-06-18 03:39:04,2026-06-18 04:34:04,37,2026-06-23 12:00:00
851,prod-usw2-eks,checkout,Normal,Started,Started container checkout-web,Pod,checkout-web-ec64e26-f37ce,controllermanager,2026-06-09 16:30:27,2026-06-09 17:52:27,1,2026-06-23 12:00:00
852,prod-usw2-eks,orders,Warning,Evicted,Pod orders-worker-b907131-2627d evicted: node was low on resource ephemeral-storage,Pod,orders-worker-b907131-2627d,default-scheduler,2026-06-22 20:27:50,2026-06-22 20:51:50,29,2026-06-23 12:00:00
853,dr-use1-eks,search,Warning,NodeNotReady,Node ip-10-21-57-150 status is now: NodeNotReady,Pod,indexer-6af7422-f66fc,controllermanager,2026-06-19 01:25:48,2026-06-19 03:15:48,39,2026-06-23 12:00:00
854,prod-usw2-eks,orders,Warning,BackOff,Back-off restarting failed container orders-api in pod orders-api-21c5d48-15186,Pod,orders-api-21c5d48-15186,kubelet,2026-06-20 15:13:19,2026-06-20 16:09:19,8,2026-06-23 12:00:00
855,prod-use2-eks,checkout,Warning,Unhealthy,Liveness probe failed: HTTP 500 for checkout-web-c343d41-6a8d2,Pod,checkout-web-c343d41-6a8d2,default-scheduler,2026-06-16 02:41:17,2026-06-16 03:40:17,24,2026-06-23 12:00:00
856,prod-use2-eks,orders,Warning,Evicted,Pod orders-api-7f89525-97cdd evicted: node memory pressure,Pod,orders-api-7f89525-97cdd,controllermanager,2026-06-20 03:34:30,2026-06-20 03:45:30,6,2026-06-23 12:00:00
857,prod-usw2-eks,ledger,Warning,Evicted,Pod ledger-svc-842cd31-95bfa evicted: node was low on resource ephemeral-storage,Pod,ledger-svc-842cd31-95bfa,controllermanager,2026-06-23 08:30:01,2026-06-23 09:20:01,3,2026-06-23 12:00:00
858,prod-usw2-eks,kube-system,Warning,DNSConfigForming,Search line limits exceeded for coredns-4a8b365-1d9fc,Pod,coredns-4a8b365-1d9fc,kubelet,2026-06-20 21:15:30,2026-06-20 22:46:30,3,2026-06-23 12:00:00
859,prod-use2-eks,checkout,Warning,OOMKilling,Container cart-svc exceeded memory limit; OOMKilled,Pod,cart-svc-26a7d77-aafdc,default-scheduler,2026-06-16 19:36:19,2026-06-16 20:10:19,14,2026-06-23 12:00:00
860,prod-use2-eks,inventory,Normal,Scheduled,Successfully assigned inventory-svc-3e28589-98330 to ip-10-40-57-12,Pod,inventory-svc-3e28589-98330,controllermanager,2026-06-15 23:05:56,2026-06-16 00:48:56,1,2026-06-23 12:00:00
861,prod-usw2-eks,search,Warning,Evicted,Pod search-api-15a6d76-12766 evicted: node was low on resource ephemeral-storage,Pod,search-api-15a6d76-12766,controllermanager,2026-06-15 06:46:50,2026-06-15 08:23:50,11,2026-06-23 12:00:00
862,prod-usw2-eks,ledger,Warning,Evicted,Pod ledger-svc-0744083-43011 evicted: node was low on resource ephemeral-storage,Pod,ledger-svc-0744083-43011,controllermanager,2026-06-20 08:02:23,2026-06-20 08:21:23,30,2026-06-23 12:00:00
863,dr-use1-eks,search,Warning,Rebooted,Node ip-10-21-57-150 has been rebooted,Pod,indexer-6af7422-f66fc,kubelet,2026-06-07 15:35:14,2026-06-07 16:15:14,33,2026-06-23 12:00:00
864,prod-usw2-eks,identity,Normal,Scheduled,Successfully assigned auth-gateway-d4d3364-aac01 to ip-10-29-63-193,Pod,auth-gateway-d4d3364-aac01,controllermanager,2026-06-18 21:58:06,2026-06-18 23:53:06,1,2026-06-23 12:00:00
865,prod-usw2-eks,payments,Warning,Unhealthy,Liveness probe failed: HTTP 500 for payments-worker-bbc0947-0aa1a,Pod,payments-worker-bbc0947-0aa1a,kubelet,2026-06-05 18:29:03,2026-06-05 18:36:03,31,2026-06-23 12:00:00
866,prod-use2-eks,checkout,Warning,OOMKilling,Container cart-svc exceeded memory limit; OOMKilled,Pod,cart-svc-51c2594-4d271,kubelet,2026-06-18 10:22:52,2026-06-18 10:27:52,24,2026-06-23 12:00:00
867,prod-usw2-eks,inventory,Normal,Scheduled,Successfully assigned inventory-svc-0d33458-c137f to ip-10-15-83-236,Pod,inventory-svc-0d33458-c137f,controllermanager,2026-06-20 20:38:21,2026-06-20 21:32:21,1,2026-06-23 12:00:00
868,prod-use2-eks,identity,Warning,Evicted,Pod session-store-1ac5266-1ca26 evicted: node memory pressure,Pod,session-store-1ac5266-1ca26,controllermanager,2026-06-16 03:19:26,2026-06-16 04:19:26,28,2026-06-23 12:00:00
869,dr-use1-eks,orders,Warning,DNSConfigForming,Search line limits exceeded for orders-api-8330e48-f22f4,Pod,orders-api-8330e48-f22f4,controllermanager,2026-06-11 00:06:07,2026-06-11 00:58:07,24,2026-06-23 12:00:00
870,prod-use2-eks,search,Normal,Started,Started container search-api,Pod,search-api-4350294-dbefb,default-scheduler,2026-06-13 05:48:37,2026-06-13 07:11:37,1,2026-06-23 12:00:00
871,prod-use2-eks,ledger,Normal,Throttling,CPU throttled for container ledger-svc,Pod,ledger-svc-204e643-7d23b,controllermanager,2026-06-22 04:51:20,2026-06-22 05:18:20,1,2026-06-23 12:00:00
872,prod-usw2-eks,platform,Normal,Pulled,Container image pulled for image-resizer,Pod,image-resizer-9683178-b7560,default-scheduler,2026-06-18 02:25:57,2026-06-18 03:48:57,1,2026-06-23 12:00:00
873,prod-usw2-eks,kube-system,Warning,Rebooted,Node ip-10-6-194-142 has been rebooted,Pod,metrics-server-6162d13-d4a14,default-scheduler,2026-06-22 03:14:21,2026-06-22 05:14:21,34,2026-06-23 12:00:00
874,prod-use2-eks,orders,Warning,Evicted,Pod orders-api-bfb2f93-32ad3 evicted: node memory pressure,Pod,orders-api-bfb2f93-32ad3,controllermanager,2026-06-11 14:15:50,2026-06-11 14:40:50,27,2026-06-23 12:00:00
875,prod-usw2-eks,orders,Warning,FreeDiskSpaceFailed,Failed to garbage collect on node ip-10-14-16-161,Pod,orders-worker-b907131-2627d,kubelet,2026-06-20 11:36:30,2026-06-20 13:20:30,21,2026-06-23 12:00:00
876,prod-use2-eks,kube-system,Warning,Unhealthy,Readiness probe errored: dial tcp i/o timeout for metrics-server-e2e6924-29c37,Pod,metrics-server-e2e6924-29c37,default-scheduler,2026-06-19 12:06:53,2026-06-19 13:18:53,32,2026-06-23 12:00:00
877,prod-use2-eks,kube-system,Warning,FreeDiskSpaceFailed,Failed to garbage collect on node ip-10-32-13-101,Pod,coredns-e513a45-fb7bf,default-scheduler,2026-06-21 21:50:53,2026-06-21 23:31:53,27,2026-06-23 12:00:00
878,prod-use2-eks,payments,Warning,OOMKilling,Container payments-api exceeded memory limit; OOMKilled,Pod,payments-api-1ce3577-591ac,controllermanager,2026-06-23 04:42:54,2026-06-23 05:22:54,29,2026-06-23 12:00:00
879,prod-usw2-eks,search,Normal,Pulled,Container image pulled for indexer,Pod,indexer-6c1eb29-ca471,controllermanager,2026-06-15 14:28:10,2026-06-15 15:00:10,1,2026-06-23 12:00:00
880,prod-use2-eks,orders,Warning,OOMKilling,Container orders-api exceeded memory limit; OOMKilled,Pod,orders-api-7f89525-97cdd,kubelet,2026-06-16 02:50:49,2026-06-16 03:31:49,12,2026-06-23 12:00:00
881,prod-use2-eks,checkout,Warning,Evicted,Pod cart-svc-51c2594-4d271 evicted: node memory pressure,Pod,cart-svc-51c2594-4d271,controllermanager,2026-06-16 08:49:21,2026-06-16 09:36:21,38,2026-06-23 12:00:00
882,prod-use2-eks,checkout,Warning,Evicted,Pod cart-svc-26a7d77-aafdc evicted: node memory pressure,Pod,cart-svc-26a7d77-aafdc,default-scheduler,2026-06-19 13:02:47,2026-06-19 13:52:47,15,2026-06-23 12:00:00
883,prod-use2-eks,ledger,Warning,Unhealthy,Readiness probe failed: timeout for ledger-svc-f4a6d64-16dde,Pod,ledger-svc-f4a6d64-16dde,default-scheduler,2026-06-18 18:40:41,2026-06-18 19:07:41,28,2026-06-23 12:00:00
884,prod-usw2-eks,checkout,Normal,Pulled,Container image pulled for checkout-web,Pod,checkout-web-ec64e26-f37ce,kubelet,2026-05-25 21:17:30,2026-05-25 21:45:30,1,2026-06-23 12:00:00
885,prod-use2-eks,checkout,Warning,BackOff,Back-off restarting failed container checkout-web in pod checkout-web-0101b48-2b2af,Pod,checkout-web-0101b48-2b2af,kubelet,2026-06-13 12:24:53,2026-06-13 12:26:53,10,2026-06-23 12:00:00
886,prod-use2-eks,checkout,Warning,Evicted,Pod cart-svc-26a7d77-aafdc evicted: node memory pressure,Pod,cart-svc-26a7d77-aafdc,default-scheduler,2026-06-19 12:18:20,2026-06-19 14:12:20,10,2026-06-23 12:00:00
887,prod-use2-eks,checkout,Warning,OOMKilling,Container cart-svc exceeded memory limit; OOMKilled,Pod,cart-svc-26a7d77-aafdc,kubelet,2026-06-14 07:21:23,2026-06-14 07:32:23,24,2026-06-23 12:00:00
888,prod-usw2-eks,ledger,Warning,FreeDiskSpaceFailed,Failed to garbage collect on node ip-10-6-194-142,Pod,ledger-svc-842cd31-95bfa,controllermanager,2026-06-19 18:53:31,2026-06-19 19:26:31,9,2026-06-23 12:00:00
889,staging-use2-eks,identity,Normal,Pulled,Container image pulled for auth-gateway,Pod,auth-gateway-c975434-e6ef9,controllermanager,2026-06-13 19:20:49,2026-06-13 20:35:49,1,2026-06-23 12:00:00
890,prod-use2-eks,checkout,Warning,OOMKilling,Container cart-svc exceeded memory limit; OOMKilled,Pod,cart-svc-26a7d77-aafdc,controllermanager,2026-06-22 15:08:02,2026-06-22 17:07:02,30,2026-06-23 12:00:00
891,prod-usw2-eks,notifications,Normal,Pulled,Container image pulled for notifications,Pod,notifications-b2aff41-e1772,default-scheduler,2026-06-16 01:05:51,2026-06-16 02:03:51,1,2026-06-23 12:00:00
892,prod-use2-eks,payments,Warning,OOMKilling,Container payments-api exceeded memory limit; OOMKilled,Pod,payments-api-c9c2b74-00142,controllermanager,2026-06-23 10:47:08,2026-06-23 11:06:08,29,2026-06-23 12:00:00
893,prod-usw2-eks,payments,Warning,Evicted,Pod payments-api-423b015-b80bd evicted: node memory pressure,Pod,payments-api-423b015-b80bd,controllermanager,2026-06-22 23:25:12,2026-06-23 00:04:12,25,2026-06-23 12:00:00
894,prod-use2-eks,checkout,Warning,Evicted,Pod cart-svc-527eb80-045c0 evicted: node memory pressure,Pod,cart-svc-527eb80-045c0,controllermanager,2026-06-22 17:17:13,2026-06-22 18:29:13,1,2026-06-23 12:00:00
895,prod-use2-eks,checkout,Warning,Evicted,Pod cart-svc-51c2594-4d271 evicted: node memory pressure,Pod,cart-svc-51c2594-4d271,controllermanager,2026-06-18 01:09:35,2026-06-18 01:11:35,23,2026-06-23 12:00:00
896,prod-use2-eks,kube-system,Warning,Evicted,Pod coredns-47d4438-c55d7 evicted: node was low on resource ephemeral-storage,Pod,coredns-47d4438-c55d7,kubelet,2026-06-11 07:37:40,2026-06-11 08:50:40,28,2026-06-23 12:00:00
897,prod-use2-eks,checkout,Warning,OOMKilling,Memory cgroup out of memory: Killed process in checkout-web-c343d41-6a8d2,Pod,checkout-web-c343d41-6a8d2,kubelet,2026-06-08 09:35:27,2026-06-08 11:18:27,10,2026-06-23 12:00:00
898,prod-use2-eks,checkout,Warning,OOMKilling,Memory cgroup out of memory: Killed process in checkout-web-0101b48-2b2af,Pod,checkout-web-0101b48-2b2af,default-scheduler,2026-06-10 01:07:39,2026-06-10 01:38:39,11,2026-06-23 12:00:00
899,prod-use2-eks,platform,Warning,DNSConfigForming,Search line limits exceeded for image-resizer-9994630-7c707,Pod,image-resizer-9994630-7c707,controllermanager,2026-06-23 05:29:50,2026-06-23 05:50:50,39,2026-06-23 12:00:00
900,prod-use2-eks,payments,Warning,Evicted,Pod payments-api-7fa4649-debd8 evicted: node memory pressure,Pod,payments-api-7fa4649-debd8,controllermanager,2026-06-22 22:50:09,2026-06-23 00:17:09,13,2026-06-23 12:00:00
901,prod-usw2-eks,checkout,Warning,FreeDiskSpaceFailed,Failed to garbage collect on node ip-10-6-194-142,Pod,cart-svc-ee38458-64d46,default-scheduler,2026-06-20 15:15:37,2026-06-20 16:05:37,28,2026-06-23 12:00:00
902,prod-use2-eks,platform,Normal,Scheduled,Successfully assigned config-svc-ddd1723-06ca5 to ip-10-24-49-183,Pod,config-svc-ddd1723-06ca5,default-scheduler,2026-06-23 02:32:34,2026-06-23 03:48:34,1,2026-06-23 12:00:00
903,prod-usw2-eks,payments,Warning,OOMKilling,Container payments-api exceeded memory limit; OOMKilled,Pod,payments-api-1e23165-1e35b,controllermanager,2026-06-11 07:01:36,2026-06-11 07:51:36,25,2026-06-23 12:00:00
904,staging-use2-eks,identity,Normal,Started,Started container auth-gateway,Pod,auth-gateway-41b4f33-14ef9,controllermanager,2026-06-05 02:00:05,2026-06-05 03:35:05,1,2026-06-23 12:00:00
905,prod-usw2-eks,orders,Warning,FreeDiskSpaceFailed,Failed to garbage collect on node ip-10-14-16-161,Pod,orders-worker-8482791-f2d9f,kubelet,2026-06-23 03:46:37,2026-06-23 04:20:37,40,2026-06-23 12:00:00
906,prod-usw2-eks,search,Warning,FreeDiskSpaceFailed,Failed to garbage collect on node ip-10-14-16-161,Pod,search-api-a47d446-4ffe2,controllermanager,2026-06-22 06:49:45,2026-06-22 08:48:45,16,2026-06-23 12:00:00
907,prod-usw2-eks,checkout,Warning,FreeDiskSpaceFailed,Failed to garbage collect on node ip-10-6-194-142,Pod,cart-svc-882ca58-64a75,controllermanager,2026-06-02 10:58:26,2026-06-02 12:28:26,28,2026-06-23 12:00:00
908,staging-use2-eks,identity,Warning,Unhealthy,Readiness probe errored: dial tcp i/o timeout for session-store-a097c68-649a1,Pod,session-store-a097c68-649a1,default-scheduler,2026-06-08 23:59:31,2026-06-09 00:05:31,20,2026-06-23 12:00:00
909,dr-use1-eks,notifications,Warning,Unhealthy,Liveness probe failed: HTTP 500 for notifications-b036879-82982,Pod,notifications-b036879-82982,kubelet,2026-06-22 01:53:18,2026-06-22 03:02:18,16,2026-06-23 12:00:00
910,prod-use2-eks,payments,Warning,OOMKilling,Container payments-api exceeded memory limit; OOMKilled,Pod,payments-api-7fa4649-debd8,default-scheduler,2026-06-22 21:02:38,2026-06-22 22:02:38,13,2026-06-23 12:00:00
911,prod-use2-eks,orders,Warning,OOMKilling,Container orders-api exceeded memory limit; OOMKilled,Pod,orders-api-bfb2f93-32ad3,default-scheduler,2026-06-17 11:56:12,2026-06-17 12:59:12,14,2026-06-23 12:00:00
912,staging-use2-eks,inventory,Warning,OOMKilling,Container inventory-svc exceeded memory limit; OOMKilled,Pod,inventory-svc-1d6f570-1b50d,controllermanager,2026-06-19 23:20:57,2026-06-20 01:03:57,40,2026-06-23 12:00:00
913,staging-use2-eks,search,Normal,Started,Started container search-api,Pod,search-api-8ca0b98-505ff,kubelet,2026-06-23 06:59:36,2026-06-23 08:58:36,1,2026-06-23 12:00:00
914,prod-use2-eks,orders,Warning,Evicted,Pod orders-api-bfb2f93-32ad3 evicted: node memory pressure,Pod,orders-api-bfb2f93-32ad3,default-scheduler,2026-06-10 05:06:07,2026-06-10 05:29:07,33,2026-06-23 12:00:00
915,prod-usw2-eks,checkout,Normal,Scheduled,Successfully assigned checkout-web-2e5d994-d724e to ip-10-15-83-236,Pod,checkout-web-2e5d994-d724e,kubelet,2026-05-31 17:07:53,2026-05-31 17:53:53,1,2026-06-23 12:00:00
916,prod-use2-eks,orders,Warning,OOMKilling,Container orders-api exceeded memory limit; OOMKilled,Pod,orders-api-e9b4a39-c3784,controllermanager,2026-06-10 16:11:42,2026-06-10 17:48:42,26,2026-06-23 12:00:00
917,prod-usw2-eks,ledger,Warning,Evicted,Pod ledger-svc-842cd31-95bfa evicted: node was low on resource ephemeral-storage,Pod,ledger-svc-842cd31-95bfa,controllermanager,2026-06-17 09:51:12,2026-06-17 11:01:12,1,2026-06-23 12:00:00
918,prod-use2-eks,search,Normal,Pulled,Container image pulled for search-api,Pod,search-api-4350294-dbefb,kubelet,2026-05-25 20:45:40,2026-05-25 21:00:40,1,2026-06-23 12:00:00
919,dr-use1-eks,search,Warning,FreeDiskSpaceFailed,Failed to garbage collect on node ip-10-40-81-216,Pod,search-api-d416b43-7cb20,kubelet,2026-06-10 01:39:03,2026-06-10 02:02:03,3,2026-06-23 12:00:00
920,prod-usw2-eks,search,Warning,Evicted,Pod search-api-a47d446-4ffe2 evicted: node was low on resource ephemeral-storage,Pod,search-api-a47d446-4ffe2,kubelet,2026-06-22 08:57:36,2026-06-22 10:21:36,16,2026-06-23 12:00:00
921,prod-usw2-eks,orders,Warning,Unhealthy,Liveness probe failed: HTTP 500 for orders-api-402bb51-ad48f,Pod,orders-api-402bb51-ad48f,controllermanager,2026-06-17 05:49:40,2026-06-17 07:17:40,37,2026-06-23 12:00:00
922,prod-usw2-eks,search,Normal,Scheduled,Successfully assigned recommendation-87e3198-026ea to ip-10-15-83-236,Pod,recommendation-87e3198-026ea,controllermanager,2026-06-14 04:59:17,2026-06-14 06:13:17,1,2026-06-23 12:00:00
923,prod-usw2-eks,kube-system,Warning,NodeNotReady,Node ip-10-6-194-142 status is now: NodeNotReady,Pod,metrics-server-6162d13-d4a14,default-scheduler,2026-06-23 00:55:37,2026-06-23 02:42:37,25,2026-06-23 12:00:00
924,prod-use2-eks,checkout,Warning,OOMKilling,Container cart-svc exceeded memory limit; OOMKilled,Pod,cart-svc-51c2594-4d271,controllermanager,2026-06-22 19:51:39,2026-06-22 20:21:39,20,2026-06-23 12:00:00
925,prod-use2-eks,inventory,Normal,Started,Started container inventory-svc,Pod,inventory-svc-df6d343-0a45b,default-scheduler,2026-06-20 18:57:46,2026-06-20 19:11:46,1,2026-06-23 12:00:00
926,prod-use2-eks,orders,Warning,Evicted,Pod orders-api-e9b4a39-c3784 evicted: node memory pressure,Pod,orders-api-e9b4a39-c3784,default-scheduler,2026-06-11 09:23:07,2026-06-11 10:18:07,32,2026-06-23 12:00:00
927,prod-use2-eks,identity,Warning,Evicted,Pod session-store-1ac5266-1ca26 evicted: node memory pressure,Pod,session-store-1ac5266-1ca26,controllermanager,2026-06-23 03:24:02,2026-06-23 04:52:02,4,2026-06-23 12:00:00
928,prod-use2-eks,payments,Warning,OOMKilling,Container payments-api exceeded memory limit; OOMKilled,Pod,payments-api-58c5e74-26d34,kubelet,2026-06-22 23:12:33,2026-06-23 01:07:33,35,2026-06-23 12:00:00
929,prod-use2-eks,checkout,Warning,OOMKilling,Container cart-svc exceeded memory limit; OOMKilled,Pod,cart-svc-26a7d77-aafdc,controllermanager,2026-06-12 23:42:19,2026-06-13 01:15:19,16,2026-06-23 12:00:00
930,prod-use2-eks,payments,Warning,OOMKilling,Container payments-api exceeded memory limit; OOMKilled,Pod,payments-api-58c5e74-26d34,controllermanager,2026-06-22 18:16:29,2026-06-22 18:30:29,37,2026-06-23 12:00:00
931,prod-use2-eks,inventory,Normal,Scheduled,Successfully assigned inventory-svc-3e28589-98330 to ip-10-40-57-12,Pod,inventory-svc-3e28589-98330,controllermanager,2026-05-27 21:32:39,2026-05-27 22:59:39,1,2026-06-23 12:00:00
932,prod-use2-eks,kube-system,Warning,Evicted,Pod coredns-e513a45-fb7bf evicted: node was low on resource ephemeral-storage,Pod,coredns-e513a45-fb7bf,controllermanager,2026-06-08 11:00:52,2026-06-08 11:29:52,5,2026-06-23 12:00:00
933,prod-usw2-eks,platform,Normal,Pulled,Container image pulled for config-svc,Pod,config-svc-370d832-a686a,default-scheduler,2026-05-30 02:34:10,2026-05-30 03:23:10,1,2026-06-23 12:00:00
934,prod-use2-eks,identity,Warning,OOMKilling,Container session-store exceeded memory limit; OOMKilled,Pod,session-store-4732511-0dba8,kubelet,2026-06-21 17:48:32,2026-06-21 18:02:32,6,2026-06-23 12:00:00
935,prod-usw2-eks,orders,Warning,FreeDiskSpaceFailed,Failed to garbage collect on node ip-10-14-16-161,Pod,orders-worker-b907131-2627d,controllermanager,2026-06-21 20:39:03,2026-06-21 22:34:03,11,2026-06-23 12:00:00
936,prod-use2-eks,checkout,Warning,OOMKilling,Memory cgroup out of memory: Killed process in checkout-web-c2eb578-2d181,Pod,checkout-web-c2eb578-2d181,kubelet,2026-06-11 04:08:10,2026-06-11 05:43:10,2,2026-06-23 12:00:00
937,prod-usw2-eks,payments,Warning,Evicted,Pod payments-api-b9a1287-dbbfe evicted: node memory pressure,Pod,payments-api-b9a1287-dbbfe,default-scheduler,2026-06-10 04:19:09,2026-06-10 06:17:09,8,2026-06-23 12:00:00
938,staging-use2-eks,checkout,Warning,Rebooted,Node ip-10-8-126-134 has been rebooted,Pod,checkout-web-2b77739-52fdd,kubelet,2026-06-23 06:19:17,2026-06-23 06:41:17,39,2026-06-23 12:00:00
939,prod-use2-eks,platform,Warning,Unhealthy,Readiness probe errored: dial tcp i/o timeout for image-resizer-7bb3c89-50e74,Pod,image-resizer-7bb3c89-50e74,kubelet,2026-06-21 19:00:56,2026-06-21 19:55:56,17,2026-06-23 12:00:00
940,staging-use2-eks,search,Warning,Unhealthy,Readiness probe errored: dial tcp i/o timeout for search-api-1605640-8abaf,Pod,search-api-1605640-8abaf,controllermanager,2026-06-22 02:20:08,2026-06-22 03:33:08,3,2026-06-23 12:00:00
941,prod-usw2-eks,orders,Normal,Started,Started container orders-worker,Pod,orders-worker-0696c96-a62c8,default-scheduler,2026-06-22 08:19:03,2026-06-22 08:45:03,1,2026-06-23 12:00:00
942,prod-use2-eks,payments,Warning,Evicted,Pod payments-api-c9c2b74-00142 evicted: node memory pressure,Pod,payments-api-c9c2b74-00142,default-scheduler,2026-06-23 10:39:02,2026-06-23 12:20:02,1,2026-06-23 12:00:00
943,prod-usw2-eks,checkout,Normal,Started,Started container checkout-web,Pod,checkout-web-c2b3638-fa6d0,kubelet,2026-06-01 22:19:42,2026-06-01 22:26:42,1,2026-06-23 12:00:00
944,prod-use2-eks,payments,Warning,Evicted,Pod payments-api-c9c2b74-00142 evicted: node memory pressure,Pod,payments-api-c9c2b74-00142,kubelet,2026-06-22 19:14:48,2026-06-22 20:21:48,21,2026-06-23 12:00:00
945,prod-use2-eks,search,Normal,Scheduled,Successfully assigned recommendation-c460126-52814 to ip-10-37-142-3,Pod,recommendation-c460126-52814,default-scheduler,2026-06-09 22:22:44,2026-06-10 00:20:44,1,2026-06-23 12:00:00
946,prod-use2-eks,payments,Warning,OOMKilling,Container payments-api exceeded memory limit; OOMKilled,Pod,payments-api-7fa4649-debd8,default-scheduler,2026-06-23 06:36:08,2026-06-23 07:31:08,33,2026-06-23 12:00:00
947,prod-usw2-eks,orders,Warning,BackOff,Back-off restarting failed container orders-api in pod orders-api-402bb51-ad48f,Pod,orders-api-402bb51-ad48f,controllermanager,2026-06-21 01:12:10,2026-06-21 02:44:10,36,2026-06-23 12:00:00
948,prod-use2-eks,payments,Warning,Evicted,Pod payments-api-7fa4649-debd8 evicted: node memory pressure,Pod,payments-api-7fa4649-debd8,kubelet,2026-06-22 20:59:09,2026-06-22 21:42:09,19,2026-06-23 12:00:00
949,prod-use2-eks,checkout,Warning,Evicted,Pod cart-svc-527eb80-045c0 evicted: node memory pressure,Pod,cart-svc-527eb80-045c0,kubelet,2026-06-16 02:05:13,2026-06-16 03:08:13,1,2026-06-23 12:00:00
950,prod-usw2-eks,payments,Warning,BackOff,Back-off restarting failed container payments-worker in pod payments-worker-bbc0947-0aa1a,Pod,payments-worker-bbc0947-0aa1a,default-scheduler,2026-06-09 06:53:05,2026-06-09 07:24:05,39,2026-06-23 12:00:00
951,prod-use2-eks,identity,Warning,OOMKilling,Container session-store exceeded memory limit; OOMKilled,Pod,session-store-4732511-0dba8,controllermanager,2026-06-16 21:36:05,2026-06-16 22:46:05,8,2026-06-23 12:00:00
952,prod-use2-eks,identity,Warning,OOMKilling,Container session-store exceeded memory limit; OOMKilled,Pod,session-store-4732511-0dba8,kubelet,2026-06-13 19:28:36,2026-06-13 19:36:36,6,2026-06-23 12:00:00
953,prod-use2-eks,ledger,Warning,Unhealthy,Readiness probe failed: timeout for ledger-svc-204e643-7d23b,Pod,ledger-svc-204e643-7d23b,default-scheduler,2026-06-19 17:14:42,2026-06-19 18:22:42,13,2026-06-23 12:00:00
954,dr-use1-eks,search,Warning,NodeNotReady,Node ip-10-21-57-150 status is now: NodeNotReady,Pod,indexer-6af7422-f66fc,default-scheduler,2026-06-06 18:02:32,2026-06-06 18:07:32,12,2026-06-23 12:00:00
955,prod-use2-eks,orders,Warning,OOMKilling,Container orders-api exceeded memory limit; OOMKilled,Pod,orders-api-bfb2f93-32ad3,default-scheduler,2026-06-17 23:43:17,2026-06-18 01:25:17,18,2026-06-23 12:00:00
956,prod-use2-eks,orders,Normal,Pulled,Container image pulled for orders-worker,Pod,orders-worker-6ee3345-b0d20,default-scheduler,2026-05-25 23:17:49,2026-05-25 23:51:49,1,2026-06-23 12:00:00
957,dr-use1-eks,checkout,Warning,Evicted,Pod checkout-web-6e9e217-a5c79 evicted: node memory pressure,Pod,checkout-web-6e9e217-a5c79,controllermanager,2026-06-21 07:22:28,2026-06-21 08:13:28,33,2026-06-23 12:00:00
958,prod-usw2-eks,checkout,Warning,Evicted,Pod cart-svc-ee38458-64d46 evicted: node was low on resource ephemeral-storage,Pod,cart-svc-ee38458-64d46,kubelet,2026-06-04 07:07:48,2026-06-04 08:04:48,17,2026-06-23 12:00:00
959,prod-usw2-eks,search,Warning,Evicted,Pod search-api-a47d446-4ffe2 evicted: node was low on resource ephemeral-storage,Pod,search-api-a47d446-4ffe2,controllermanager,2026-06-15 21:18:19,2026-06-15 22:45:19,20,2026-06-23 12:00:00
960,prod-use2-eks,checkout,Warning,Unhealthy,Liveness probe failed: HTTP 500 for checkout-web-c343d41-6a8d2,Pod,checkout-web-c343d41-6a8d2,kubelet,2026-06-23 01:51:38,2026-06-23 03:04:38,34,2026-06-23 12:00:00
961,prod-use2-eks,identity,Normal,Scheduled,Successfully assigned auth-gateway-9bddb17-f3d59 to ip-10-40-57-12,Pod,auth-gateway-9bddb17-f3d59,default-scheduler,2026-06-23 09:41:30,2026-06-23 11:26:30,1,2026-06-23 12:00:00
962,prod-usw2-eks,ledger,Warning,FreeDiskSpaceFailed,Failed to garbage collect on node ip-10-14-16-161,Pod,ledger-svc-2014124-29b88,default-scheduler,2026-06-19 04:53:25,2026-06-19 05:49:25,26,2026-06-23 12:00:00
963,prod-use2-eks,orders,Warning,Evicted,Pod orders-api-bfb2f93-32ad3 evicted: node memory pressure,Pod,orders-api-bfb2f93-32ad3,default-scheduler,2026-06-08 18:14:16,2026-06-08 19:48:16,37,2026-06-23 12:00:00
964,prod-usw2-eks,orders,Normal,Scheduled,Successfully assigned orders-worker-0696c96-a62c8 to ip-10-12-35-23,Pod,orders-worker-0696c96-a62c8,kubelet,2026-06-20 22:05:53,2026-06-20 23:02:53,1,2026-06-23 12:00:00
965,prod-use2-eks,kube-system,Warning,Evicted,Pod coredns-47d4438-c55d7 evicted: node was low on resource ephemeral-storage,Pod,coredns-47d4438-c55d7,default-scheduler,2026-06-22 06:07:59,2026-06-22 07:44:59,31,2026-06-23 12:00:00
966,prod-use2-eks,identity,Warning,OOMKilling,Container session-store exceeded memory limit; OOMKilled,Pod,session-store-4732511-0dba8,kubelet,2026-06-18 10:16:18,2026-06-18 10:48:18,36,2026-06-23 12:00:00
967,prod-use2-eks,kube-system,Warning,Evicted,Pod coredns-e513a45-fb7bf evicted: node was low on resource ephemeral-storage,Pod,coredns-e513a45-fb7bf,kubelet,2026-06-10 18:57:10,2026-06-10 19:53:10,33,2026-06-23 12:00:00
968,prod-use2-eks,identity,Warning,Evicted,Pod session-store-4732511-0dba8 evicted: node memory pressure,Pod,session-store-4732511-0dba8,kubelet,2026-06-21 09:47:49,2026-06-21 11:06:49,10,2026-06-23 12:00:00
969,prod-usw2-eks,checkout,Warning,Evicted,Pod cart-svc-ee38458-64d46 evicted: node was low on resource ephemeral-storage,Pod,cart-svc-ee38458-64d46,controllermanager,2026-06-12 18:12:37,2026-06-12 19:23:37,34,2026-06-23 12:00:00
970,prod-use2-eks,notifications,Normal,Throttling,CPU throttled for container notifications,Pod,notifications-1938743-28dca,default-scheduler,2026-06-16 23:46:27,2026-06-17 00:08:27,1,2026-06-23 12:00:00
971,dr-use1-eks,checkout,Warning,OOMKilling,Container checkout-web exceeded memory limit; OOMKilled,Pod,checkout-web-4263246-52f3a,kubelet,2026-06-21 13:46:14,2026-06-21 15:06:14,13,2026-06-23 12:00:00
972,prod-usw2-eks,ledger,Warning,FreeDiskSpaceFailed,Failed to garbage collect on node ip-10-14-16-161,Pod,ledger-svc-2014124-29b88,kubelet,2026-06-22 13:41:00,2026-06-22 15:10:00,2,2026-06-23 12:00:00
973,prod-use2-eks,payments,Warning,OOMKilling,Container payments-api exceeded memory limit; OOMKilled,Pod,payments-api-c9c2b74-00142,controllermanager,2026-06-23 01:30:03,2026-06-23 02:24:03,26,2026-06-23 12:00:00
974,prod-usw2-eks,checkout,Normal,Started,Started container checkout-web,Pod,checkout-web-c2b3638-fa6d0,default-scheduler,2026-06-02 18:00:03,2026-06-02 18:36:03,1,2026-06-23 12:00:00
975,prod-use2-eks,ledger,Warning,Unhealthy,Readiness probe failed: timeout for ledger-svc-f4a6d64-16dde,Pod,ledger-svc-f4a6d64-16dde,controllermanager,2026-06-21 08:52:39,2026-06-21 10:03:39,16,2026-06-23 12:00:00
976,prod-usw2-eks,platform,Normal,Pulled,Container image pulled for image-resizer,Pod,image-resizer-6542c92-1100b,default-scheduler,2026-06-17 09:09:58,2026-06-17 09:25:58,1,2026-06-23 12:00:00
977,prod-usw2-eks,search,Warning,Evicted,Pod search-api-a47d446-4ffe2 evicted: node was low on resource ephemeral-storage,Pod,search-api-a47d446-4ffe2,default-scheduler,2026-06-18 14:01:23,2026-06-18 15:25:23,36,2026-06-23 12:00:00
978,prod-use2-eks,checkout,Warning,BackOff,Back-off restarting failed container checkout-web in pod checkout-web-c2eb578-2d181,Pod,checkout-web-c2eb578-2d181,kubelet,2026-06-10 15:58:47,2026-06-10 17:44:47,22,2026-06-23 12:00:00
979,prod-use2-eks,ledger,Normal,Scheduled,Successfully assigned ledger-svc-1232e29-49ea1 to ip-10-24-49-183,Pod,ledger-svc-1232e29-49ea1,controllermanager,2026-06-23 02:20:51,2026-06-23 02:40:51,1,2026-06-23 12:00:00
980,prod-use2-eks,identity,Normal,Pulled,Container image pulled for auth-gateway,Pod,auth-gateway-bf1d422-2018d,kubelet,2026-06-06 05:22:16,2026-06-06 05:56:16,1,2026-06-23 12:00:00
981,prod-use2-eks,identity,Warning,Evicted,Pod session-store-1ac5266-1ca26 evicted: node memory pressure,Pod,session-store-1ac5266-1ca26,kubelet,2026-06-18 19:36:54,2026-06-18 20:23:54,9,2026-06-23 12:00:00
982,prod-use2-eks,inventory,Normal,Pulled,Container image pulled for inventory-svc,Pod,inventory-svc-bfded25-1e6d2,default-scheduler,2026-06-19 23:12:43,2026-06-19 23:34:43,1,2026-06-23 12:00:00
983,prod-usw2-eks,payments,Warning,OOMKilling,Container payments-api exceeded memory limit; OOMKilled,Pod,payments-api-423b015-b80bd,controllermanager,2026-06-07 08:49:55,2026-06-07 09:42:55,34,2026-06-23 12:00:00
984,prod-use2-eks,inventory,Normal,Scheduled,Successfully assigned inventory-svc-df6d343-0a45b to ip-10-32-13-101,Pod,inventory-svc-df6d343-0a45b,kubelet,2026-06-04 10:23:40,2026-06-04 10:59:40,1,2026-06-23 12:00:00
985,prod-use2-eks,kube-system,Warning,FreeDiskSpaceFailed,Failed to garbage collect on node ip-10-6-44-216,Pod,coredns-47d4438-c55d7,controllermanager,2026-06-19 19:49:43,2026-06-19 21:45:43,8,2026-06-23 12:00:00
986,dr-use1-eks,checkout,Warning,Evicted,Pod checkout-web-6e9e217-a5c79 evicted: node memory pressure,Pod,checkout-web-6e9e217-a5c79,kubelet,2026-06-19 11:14:25,2026-06-19 11:24:25,19,2026-06-23 12:00:00
987,prod-usw2-eks,orders,Warning,FreeDiskSpaceFailed,Failed to garbage collect on node ip-10-14-16-161,Pod,orders-worker-b907131-2627d,default-scheduler,2026-06-19 02:38:28,2026-06-19 03:15:28,37,2026-06-23 12:00:00
988,prod-use2-eks,kube-system,Warning,FreeDiskSpaceFailed,Failed to garbage collect on node ip-10-6-44-216,Pod,coredns-47d4438-c55d7,kubelet,2026-06-16 22:35:33,2026-06-16 23:55:33,11,2026-06-23 12:00:00
989,prod-usw2-eks,ledger,Warning,FreeDiskSpaceFailed,Failed to garbage collect on node ip-10-6-194-142,Pod,ledger-svc-0744083-43011,default-scheduler,2026-06-16 10:52:33,2026-06-16 11:22:33,20,2026-06-23 12:00:00
990,dr-use1-eks,search,Warning,Rebooted,Node ip-10-21-57-150 has been rebooted,Pod,indexer-6af7422-f66fc,kubelet,2026-05-30 03:14:54,2026-05-30 03:29:54,40,2026-06-23 12:00:00
991,prod-usw2-eks,payments,Warning,Evicted,Pod payments-api-423b015-b80bd evicted: node memory pressure,Pod,payments-api-423b015-b80bd,kubelet,2026-06-16 19:56:29,2026-06-16 21:51:29,40,2026-06-23 12:00:00
992,prod-usw2-eks,payments,Warning,Evicted,Pod payments-api-1e23165-1e35b evicted: node memory pressure,Pod,payments-api-1e23165-1e35b,controllermanager,2026-06-01 08:34:53,2026-06-01 09:30:53,39,2026-06-23 12:00:00
993,prod-usw2-eks,orders,Warning,Unhealthy,Liveness probe failed: HTTP 500 for orders-api-cbca488-26609,Pod,orders-api-cbca488-26609,controllermanager,2026-06-16 04:13:27,2026-06-16 06:09:27,14,2026-06-23 12:00:00
994,prod-usw2-eks,orders,Warning,FreeDiskSpaceFailed,Failed to garbage collect on node ip-10-14-16-161,Pod,orders-worker-8482791-f2d9f,kubelet,2026-06-19 18:20:35,2026-06-19 19:06:35,37,2026-06-23 12:00:00
995,prod-use2-eks,payments,Warning,OOMKilling,Container payments-api exceeded memory limit; OOMKilled,Pod,payments-api-58c5e74-26d34,default-scheduler,2026-06-22 22:45:59,2026-06-22 23:32:59,8,2026-06-23 12:00:00
996,prod-usw2-eks,checkout,Warning,Evicted,Pod cart-svc-882ca58-64a75 evicted: node was low on resource ephemeral-storage,Pod,cart-svc-882ca58-64a75,default-scheduler,2026-06-18 20:07:08,2026-06-18 21:08:08,15,2026-06-23 12:00:00
997,prod-use2-eks,checkout,Warning,Unhealthy,Liveness probe failed: HTTP 500 for checkout-web-c343d41-6a8d2,Pod,checkout-web-c343d41-6a8d2,default-scheduler,2026-06-21 00:09:44,2026-06-21 01:08:44,4,2026-06-23 12:00:00
998,prod-usw2-eks,identity,Warning,Evicted,Pod session-store-28ebc77-cf7c8 evicted: node was low on resource ephemeral-storage,Pod,session-store-28ebc77-cf7c8,kubelet,2026-06-03 19:31:03,2026-06-03 19:34:03,13,2026-06-23 12:00:00
999,prod-use2-eks,orders,Warning,OOMKilling,Container orders-api exceeded memory limit; OOMKilled,Pod,orders-api-7f89525-97cdd,kubelet,2026-06-10 19:42:01,2026-06-10 21:17:01,20,2026-06-23 12:00:00
1000,prod-usw2-eks,checkout,Warning,FreeDiskSpaceFailed,Failed to garbage collect on node ip-10-6-194-142,Pod,cart-svc-ee38458-64d46,kubelet,2026-06-22 02:48:54,2026-06-22 04:23:54,20,2026-06-23 12:00:00
1001,staging-use2-eks,identity,Normal,Started,Started container auth-gateway,Pod,auth-gateway-41b4f33-14ef9,default-scheduler,2026-05-26 15:07:41,2026-05-26 16:27:41,1,2026-06-23 12:00:00
1002,prod-usw2-eks,payments,Warning,OOMKilling,Memory cgroup out of memory: Killed process in payments-worker-1d1bf52-dff66,Pod,payments-worker-1d1bf52-dff66,default-scheduler,2026-06-16 15:08:00,2026-06-16 15:22:00,38,2026-06-23 12:00:00
1003,prod-usw2-eks,payments,Warning,Evicted,Pod payments-api-1e23165-1e35b evicted: node memory pressure,Pod,payments-api-1e23165-1e35b,default-scheduler,2026-06-03 02:09:38,2026-06-03 03:26:38,29,2026-06-23 12:00:00
1004,staging-use2-eks,identity,Normal,Scheduled,Successfully assigned auth-gateway-c975434-e6ef9 to ip-10-14-70-252,Pod,auth-gateway-c975434-e6ef9,kubelet,2026-06-17 11:15:55,2026-06-17 12:21:55,1,2026-06-23 12:00:00
1005,prod-usw2-eks,search,Warning,Evicted,Pod search-api-a47d446-4ffe2 evicted: node was low on resource ephemeral-storage,Pod,search-api-a47d446-4ffe2,default-scheduler,2026-06-16 17:51:22,2026-06-16 18:00:22,1,2026-06-23 12:00:00
1006,prod-use2-eks,ledger,Normal,Throttling,CPU throttled for container ledger-svc,Pod,ledger-svc-f4a6d64-16dde,controllermanager,2026-06-17 10:47:54,2026-06-17 10:48:54,1,2026-06-23 12:00:00
1007,dr-use1-eks,inventory,Normal,Scheduled,Successfully assigned inventory-svc-4ccbe67-9cbde to ip-10-29-128-5,Pod,inventory-svc-4ccbe67-9cbde,kubelet,2026-06-03 01:15:47,2026-06-03 02:48:47,1,2026-06-23 12:00:00
1008,prod-use2-eks,orders,Warning,Evicted,Pod orders-api-7f89525-97cdd evicted: node memory pressure,Pod,orders-api-7f89525-97cdd,kubelet,2026-06-07 07:38:43,2026-06-07 08:01:43,17,2026-06-23 12:00:00
1009,prod-usw2-eks,orders,Warning,BackOff,Back-off restarting failed container orders-api in pod orders-api-21c5d48-15186,Pod,orders-api-21c5d48-15186,controllermanager,2026-06-19 10:20:31,2026-06-19 11:13:31,40,2026-06-23 12:00:00
1010,dr-use1-eks,checkout,Warning,OOMKilling,Container checkout-web exceeded memory limit; OOMKilled,Pod,checkout-web-4263246-52f3a,kubelet,2026-06-21 16:08:09,2026-06-21 16:15:09,8,2026-06-23 12:00:00
1011,dr-use1-eks,orders,Warning,Unhealthy,Readiness probe errored: dial tcp i/o timeout for orders-api-8330e48-f22f4,Pod,orders-api-8330e48-f22f4,controllermanager,2026-06-10 15:58:28,2026-06-10 16:35:28,40,2026-06-23 12:00:00
1012,prod-use2-eks,payments,Normal,Pulled,Container image pulled for payments-worker,Pod,payments-worker-7a57672-86691,default-scheduler,2026-06-12 01:18:12,2026-06-12 02:37:12,1,2026-06-23 12:00:00
1013,prod-usw2-eks,checkout,Warning,FreeDiskSpaceFailed,Failed to garbage collect on node ip-10-6-194-142,Pod,cart-svc-ee38458-64d46,kubelet,2026-06-12 03:24:39,2026-06-12 03:28:39,17,2026-06-23 12:00:00
1014,prod-usw2-eks,checkout,Warning,Evicted,Pod cart-svc-882ca58-64a75 evicted: node was low on resource ephemeral-storage,Pod,cart-svc-882ca58-64a75,default-scheduler,2026-06-07 02:33:47,2026-06-07 02:50:47,18,2026-06-23 12:00:00
1015,prod-use2-eks,payments,Warning,Evicted,Pod payments-api-c9c2b74-00142 evicted: node memory pressure,Pod,payments-api-c9c2b74-00142,kubelet,2026-06-22 16:47:11,2026-06-22 17:18:11,32,2026-06-23 12:00:00
1016,prod-usw2-eks,identity,Warning,FreeDiskSpaceFailed,Failed to garbage collect on node ip-10-12-35-23,Pod,session-store-d825e25-14f9f,controllermanager,2026-05-29 16:41:40,2026-05-29 17:28:40,23,2026-06-23 12:00:00
1017,prod-usw2-eks,search,Normal,Pulled,Container image pulled for recommendation,Pod,recommendation-1e52697-e4756,controllermanager,2026-06-15 16:42:16,2026-06-15 18:32:16,1,2026-06-23 12:00:00
1018,prod-usw2-eks,orders,Warning,OOMKilling,Memory cgroup out of memory: Killed process in orders-api-cbca488-26609,Pod,orders-api-cbca488-26609,kubelet,2026-06-20 08:49:30,2026-06-20 10:43:30,28,2026-06-23 12:00:00
1019,prod-usw2-eks,orders,Warning,Unhealthy,Liveness probe failed: HTTP 500 for orders-api-402bb51-ad48f,Pod,orders-api-402bb51-ad48f,kubelet,2026-06-21 08:03:43,2026-06-21 09:18:43,33,2026-06-23 12:00:00
1020,prod-use2-eks,platform,Warning,DNSConfigForming,Search line limits exceeded for image-resizer-9994630-7c707,Pod,image-resizer-9994630-7c707,default-scheduler,2026-06-21 18:19:35,2026-06-21 19:43:35,37,2026-06-23 12:00:00
1021,prod-usw2-eks,checkout,Warning,Evicted,Pod cart-svc-882ca58-64a75 evicted: node was low on resource ephemeral-storage,Pod,cart-svc-882ca58-64a75,kubelet,2026-06-09 11:52:59,2026-06-09 12:52:59,28,2026-06-23 12:00:00
1022,prod-usw2-eks,checkout,Normal,Scheduled,Successfully assigned checkout-web-2e5d994-d724e to ip-10-15-83-236,Pod,checkout-web-2e5d994-d724e,controllermanager,2026-05-25 17:03:36,2026-05-25 17:30:36,1,2026-06-23 12:00:00
1023,prod-usw2-eks,kube-system,Warning,Unhealthy,Readiness probe errored: dial tcp i/o timeout for coredns-4a8b365-1d9fc,Pod,coredns-4a8b365-1d9fc,kubelet,2026-06-19 01:18:24,2026-06-19 02:30:24,18,2026-06-23 12:00:00
1024,prod-use2-eks,checkout,Warning,OOMKilling,Memory cgroup out of memory: Killed process in checkout-web-c2eb578-2d181,Pod,checkout-web-c2eb578-2d181,controllermanager,2026-06-22 20:15:31,2026-06-22 20:18:31,28,2026-06-23 12:00:00
1025,prod-usw2-eks,orders,Warning,FreeDiskSpaceFailed,Failed to garbage collect on node ip-10-14-16-161,Pod,orders-worker-8482791-f2d9f,controllermanager,2026-06-22 02:39:56,2026-06-22 03:59:56,27,2026-06-23 12:00:00
1026,prod-usw2-eks,payments,Warning,Unhealthy,Liveness probe failed: HTTP 500 for payments-worker-1d1bf52-dff66,Pod,payments-worker-1d1bf52-dff66,default-scheduler,2026-05-28 20:01:57,2026-05-28 20:28:57,40,2026-06-23 12:00:00
1027,prod-usw2-eks,ledger,Warning,FreeDiskSpaceFailed,Failed to garbage collect on node ip-10-6-194-142,Pod,ledger-svc-842cd31-95bfa,kubelet,2026-06-22 16:52:08,2026-06-22 18:48:08,26,2026-06-23 12:00:00
1028,staging-use2-eks,platform,Warning,Evicted,Pod config-svc-929cd33-16be4 evicted: node was low on resource ephemeral-storage,Pod,config-svc-929cd33-16be4,kubelet,2026-06-20 12:22:31,2026-06-20 12:33:31,6,2026-06-23 12:00:00
1029,prod-use2-eks,identity,Warning,Evicted,Pod session-store-4732511-0dba8 evicted: node memory pressure,Pod,session-store-4732511-0dba8,default-scheduler,2026-06-10 20:13:22,2026-06-10 20:52:22,9,2026-06-23 12:00:00
1030,prod-use2-eks,platform,Warning,Unhealthy,Readiness probe errored: dial tcp i/o timeout for image-resizer-7bb3c89-50e74,Pod,image-resizer-7bb3c89-50e74,default-scheduler,2026-06-21 20:36:43,2026-06-21 21:20:43,9,2026-06-23 12:00:00
1031,prod-use2-eks,payments,Warning,Evicted,Pod payments-api-7fa4649-debd8 evicted: node memory pressure,Pod,payments-api-7fa4649-debd8,controllermanager,2026-06-23 11:34:17,2026-06-23 12:03:17,39,2026-06-23 12:00:00
1032,prod-use2-eks,kube-system,Warning,Evicted,Pod coredns-e513a45-fb7bf evicted: node was low on resource ephemeral-storage,Pod,coredns-e513a45-fb7bf,controllermanager,2026-06-11 08:34:48,2026-06-11 09:05:48,18,2026-06-23 12:00:00
1033,prod-usw2-eks,orders,Warning,Unhealthy,Liveness probe failed: HTTP 500 for orders-api-cbca488-26609,Pod,orders-api-cbca488-26609,kubelet,2026-06-22 23:53:50,2026-06-23 01:38:50,22,2026-06-23 12:00:00
1034,dr-use1-eks,search,Warning,Rebooted,Node ip-10-21-57-150 has been rebooted,Pod,indexer-6af7422-f66fc,default-scheduler,2026-06-21 10:10:28,2026-06-21 11:08:28,24,2026-06-23 12:00:00
1035,prod-usw2-eks,orders,Warning,OOMKilling,Memory cgroup out of memory: Killed process in orders-api-402bb51-ad48f,Pod,orders-api-402bb51-ad48f,controllermanager,2026-06-19 10:49:48,2026-06-19 12:46:48,23,2026-06-23 12:00:00
1036,prod-use2-eks,kube-system,Warning,Evicted,Pod coredns-47d4438-c55d7 evicted: node was low on resource ephemeral-storage,Pod,coredns-47d4438-c55d7,controllermanager,2026-06-08 07:43:39,2026-06-08 08:53:39,22,2026-06-23 12:00:00
1037,prod-usw2-eks,payments,Warning,Evicted,Pod payments-api-423b015-b80bd evicted: node memory pressure,Pod,payments-api-423b015-b80bd,kubelet,2026-06-17 22:14:27,2026-06-17 23:38:27,4,2026-06-23 12:00:00
1038,prod-use2-eks,platform,Warning,Unhealthy,Readiness probe failed: timeout for config-svc-027a395-39a4d,Pod,config-svc-027a395-39a4d,controllermanager,2026-06-22 13:40:38,2026-06-22 15:16:38,31,2026-06-23 12:00:00
1039,prod-use2-eks,checkout,Warning,Unhealthy,Liveness probe failed: HTTP 500 for checkout-web-c343d41-6a8d2,Pod,checkout-web-c343d41-6a8d2,default-scheduler,2026-06-05 19:15:50,2026-06-05 21:07:50,28,2026-06-23 12:00:00
1040,staging-use2-eks,notifications,Normal,Started,Started container notifications,Pod,notifications-26e9347-44fc8,default-scheduler,2026-06-05 10:08:02,2026-06-05 11:34:02,1,2026-06-23 12:00:00
1041,dr-use1-eks,checkout,Warning,OOMKilling,Container checkout-web exceeded memory limit; OOMKilled,Pod,checkout-web-6e9e217-a5c79,controllermanager,2026-06-19 03:48:34,2026-06-19 04:54:34,15,2026-06-23 12:00:00
1042,prod-use2-eks,payments,Normal,Pulled,Container image pulled for payments-worker,Pod,payments-worker-7a57672-86691,controllermanager,2026-05-24 12:39:48,2026-05-24 13:12:48,1,2026-06-23 12:00:00
1043,prod-use2-eks,kube-system,Warning,Evicted,Pod coredns-47d4438-c55d7 evicted: node was low on resource ephemeral-storage,Pod,coredns-47d4438-c55d7,kubelet,2026-06-22 10:14:34,2026-06-22 11:07:34,19,2026-06-23 12:00:00
1044,prod-use2-eks,platform,Normal,Throttling,CPU throttled for container config-svc,Pod,config-svc-027a395-39a4d,kubelet,2026-06-22 19:14:16,2026-06-22 21:01:16,1,2026-06-23 12:00:00
1045,prod-use2-eks,kube-system,Warning,Evicted,Pod coredns-47d4438-c55d7 evicted: node was low on resource ephemeral-storage,Pod,coredns-47d4438-c55d7,controllermanager,2026-06-18 03:24:30,2026-06-18 05:24:30,13,2026-06-23 12:00:00
1046,prod-usw2-eks,orders,Warning,OOMKilling,Memory cgroup out of memory: Killed process in orders-api-21c5d48-15186,Pod,orders-api-21c5d48-15186,kubelet,2026-06-20 18:55:41,2026-06-20 20:13:41,22,2026-06-23 12:00:00
1047,prod-use2-eks,orders,Warning,Evicted,Pod orders-api-e9b4a39-c3784 evicted: node memory pressure,Pod,orders-api-e9b4a39-c3784,controllermanager,2026-06-08 18:53:08,2026-06-08 19:14:08,28,2026-06-23 12:00:00
1048,prod-use2-eks,orders,Warning,Evicted,Pod orders-api-bfb2f93-32ad3 evicted: node memory pressure,Pod,orders-api-bfb2f93-32ad3,kubelet,2026-06-08 22:54:22,2026-06-08 23:20:22,26,2026-06-23 12:00:00
1049,prod-usw2-eks,payments,Normal,Scheduled,Successfully assigned payments-api-6c2b997-3e07d to ip-10-15-83-236,Pod,payments-api-6c2b997-3e07d,controllermanager,2026-05-29 10:03:19,2026-05-29 11:06:19,1,2026-06-23 12:00:00
1050,prod-use2-eks,checkout,Warning,Evicted,Pod cart-svc-26a7d77-aafdc evicted: node memory pressure,Pod,cart-svc-26a7d77-aafdc,controllermanager,2026-06-14 01:27:45,2026-06-14 02:15:45,12,2026-06-23 12:00:00
1051,prod-usw2-eks,search,Warning,Evicted,Pod search-api-a47d446-4ffe2 evicted: node was low on resource ephemeral-storage,Pod,search-api-a47d446-4ffe2,kubelet,2026-06-19 17:59:17,2026-06-19 18:35:17,33,2026-06-23 12:00:00
1052,dr-use1-eks,checkout,Normal,Started,Started container cart-svc,Pod,cart-svc-da3cf51-00806,kubelet,2026-05-26 11:29:19,2026-05-26 13:11:19,1,2026-06-23 12:00:00
1053,prod-usw2-eks,payments,Warning,OOMKilling,Container payments-api exceeded memory limit; OOMKilled,Pod,payments-api-1e23165-1e35b,controllermanager,2026-06-23 07:04:31,2026-06-23 08:46:31,13,2026-06-23 12:00:00
1054,prod-use2-eks,payments,Warning,Evicted,Pod payments-api-7fa4649-debd8 evicted: node memory pressure,Pod,payments-api-7fa4649-debd8,controllermanager,2026-06-22 18:29:36,2026-06-22 19:52:36,6,2026-06-23 12:00:00
1055,prod-usw2-eks,payments,Warning,Unhealthy,Liveness probe failed: HTTP 500 for payments-worker-1d1bf52-dff66,Pod,payments-worker-1d1bf52-dff66,kubelet,2026-06-18 09:38:05,2026-06-18 11:03:05,28,2026-06-23 12:00:00
1056,prod-use2-eks,payments,Warning,OOMKilling,Container payments-api exceeded memory limit; OOMKilled,Pod,payments-api-1ce3577-591ac,controllermanager,2026-06-22 13:25:56,2026-06-22 14:34:56,31,2026-06-23 12:00:00
1057,prod-use2-eks,search,Normal,Started,Started container search-api,Pod,search-api-1271443-2f040,kubelet,2026-06-20 18:07:24,2026-06-20 19:21:24,1,2026-06-23 12:00:00
1058,prod-usw2-eks,payments,Warning,OOMKilling,Memory cgroup out of memory: Killed process in payments-worker-1d1bf52-dff66,Pod,payments-worker-1d1bf52-dff66,default-scheduler,2026-06-16 07:55:56,2026-06-16 09:55:56,27,2026-06-23 12:00:00
1059,prod-usw2-eks,orders,Warning,OOMKilling,Memory cgroup out of memory: Killed process in orders-api-cbca488-26609,Pod,orders-api-cbca488-26609,default-scheduler,2026-06-16 12:08:54,2026-06-16 13:45:54,27,2026-06-23 12:00:00
1060,prod-usw2-eks,payments,Warning,Evicted,Pod payments-api-1e23165-1e35b evicted: node memory pressure,Pod,payments-api-1e23165-1e35b,default-scheduler,2026-06-06 04:20:21,2026-06-06 05:39:21,20,2026-06-23 12:00:00
1061,prod-use2-eks,checkout,Warning,Evicted,Pod cart-svc-51c2594-4d271 evicted: node memory pressure,Pod,cart-svc-51c2594-4d271,kubelet,2026-06-22 09:24:33,2026-06-22 10:42:33,33,2026-06-23 12:00:00
1062,staging-use2-eks,payments,Warning,FreeDiskSpaceFailed,Failed to garbage collect on node ip-10-20-108-255,Pod,payments-api-2729261-453da,kubelet,2026-06-03 16:24:10,2026-06-03 18:19:10,8,2026-06-23 12:00:00
1063,prod-use2-eks,kube-system,Warning,Unhealthy,Readiness probe errored: dial tcp i/o timeout for metrics-server-e2e6924-29c37,Pod,metrics-server-e2e6924-29c37,kubelet,2026-06-15 11:46:12,2026-06-15 12:16:12,24,2026-06-23 12:00:00
1064,prod-usw2-eks,identity,Warning,Evicted,Pod session-store-d825e25-14f9f evicted: node was low on resource ephemeral-storage,Pod,session-store-d825e25-14f9f,kubelet,2026-06-02 00:08:15,2026-06-02 01:31:15,16,2026-06-23 12:00:00
1065,prod-use2-eks,orders,Warning,OOMKilling,Container orders-api exceeded memory limit; OOMKilled,Pod,orders-api-7f89525-97cdd,default-scheduler,2026-06-12 18:06:31,2026-06-12 19:29:31,5,2026-06-23 12:00:00
1066,prod-use2-eks,kube-system,Warning,Evicted,Pod coredns-47d4438-c55d7 evicted: node was low on resource ephemeral-storage,Pod,coredns-47d4438-c55d7,default-scheduler,2026-06-13 16:51:05,2026-06-13 17:23:05,10,2026-06-23 12:00:00
1067,prod-use2-eks,identity,Warning,Evicted,Pod session-store-1ac5266-1ca26 evicted: node memory pressure,Pod,session-store-1ac5266-1ca26,default-scheduler,2026-06-08 13:16:46,2026-06-08 14:47:46,29,2026-06-23 12:00:00
1068,prod-usw2-eks,checkout,Normal,Scheduled,Successfully assigned checkout-web-2e5d994-d724e to ip-10-15-83-236,Pod,checkout-web-2e5d994-d724e,default-scheduler,2026-06-15 21:22:19,2026-06-15 22:01:19,1,2026-06-23 12:00:00
1069,prod-usw2-eks,orders,Warning,OOMKilling,Memory cgroup out of memory: Killed process in orders-api-21c5d48-15186,Pod,orders-api-21c5d48-15186,default-scheduler,2026-06-15 17:49:02,2026-06-15 19:00:02,27,2026-06-23 12:00:00
1070,prod-usw2-eks,kube-system,Warning,DNSConfigForming,Search line limits exceeded for coredns-37f1521-4cd3d,Pod,coredns-37f1521-4cd3d,controllermanager,2026-06-21 07:04:14,2026-06-21 08:56:14,30,2026-06-23 12:00:00
1071,prod-usw2-eks,search,Warning,FreeDiskSpaceFailed,Failed to garbage collect on node ip-10-6-194-142,Pod,search-api-15a6d76-12766,controllermanager,2026-06-15 05:49:16,2026-06-15 06:25:16,12,2026-06-23 12:00:00
1072,prod-usw2-eks,search,Normal,Pulled,Container image pulled for indexer,Pod,indexer-6c1eb29-ca471,kubelet,2026-06-18 06:02:17,2026-06-18 06:46:17,1,2026-06-23 12:00:00
1073,prod-use2-eks,payments,Normal,Scheduled,Successfully assigned payments-worker-7a57672-86691 to ip-10-40-57-12,Pod,payments-worker-7a57672-86691,default-scheduler,2026-05-31 08:48:02,2026-05-31 09:52:02,1,2026-06-23 12:00:00
1074,prod-usw2-eks,orders,Warning,OOMKilling,Memory cgroup out of memory: Killed process in orders-api-cbca488-26609,Pod,orders-api-cbca488-26609,default-scheduler,2026-06-21 08:50:25,2026-06-21 09:59:25,11,2026-06-23 12:00:00
1075,prod-use2-eks,checkout,Warning,OOMKilling,Container cart-svc exceeded memory limit; OOMKilled,Pod,cart-svc-51c2594-4d271,default-scheduler,2026-06-18 23:57:55,2026-06-19 01:43:55,38,2026-06-23 12:00:00
1076,dr-use1-eks,checkout,Warning,OOMKilling,Container checkout-web exceeded memory limit; OOMKilled,Pod,checkout-web-6e9e217-a5c79,controllermanager,2026-06-20 09:11:22,2026-06-20 10:25:22,22,2026-06-23 12:00:00
1077,prod-usw2-eks,search,Normal,Started,Started container recommendation,Pod,recommendation-1e52697-e4756,default-scheduler,2026-06-11 00:27:47,2026-06-11 02:14:47,1,2026-06-23 12:00:00
1078,prod-usw2-eks,checkout,Warning,FreeDiskSpaceFailed,Failed to garbage collect on node ip-10-29-63-193,Pod,cart-svc-0a94879-c1bba,default-scheduler,2026-06-23 11:08:19,2026-06-23 12:46:19,28,2026-06-23 12:00:00
1079,prod-use2-eks,checkout,Warning,Unhealthy,Liveness probe failed: HTTP 500 for checkout-web-c2eb578-2d181,Pod,checkout-web-c2eb578-2d181,kubelet,2026-05-30 06:37:06,2026-05-30 07:24:06,17,2026-06-23 12:00:00
1080,staging-use2-eks,payments,Normal,Scheduled,Successfully assigned payments-api-dde4d16-a3d09 to ip-10-14-70-252,Pod,payments-api-dde4d16-a3d09,controllermanager,2026-06-22 23:03:44,2026-06-23 00:10:44,1,2026-06-23 12:00:00
1081,prod-usw2-eks,search,Warning,FreeDiskSpaceFailed,Failed to garbage collect on node ip-10-14-16-161,Pod,search-api-8352074-5b766,kubelet,2026-06-16 03:11:57,2026-06-16 04:51:57,32,2026-06-23 12:00:00
1082,prod-usw2-eks,inventory,Normal,Pulled,Container image pulled for inventory-svc,Pod,inventory-svc-0d33458-c137f,controllermanager,2026-06-17 05:59:30,2026-06-17 07:26:30,1,2026-06-23 12:00:00
1083,prod-use2-eks,payments,Normal,Scheduled,Successfully assigned payments-worker-6e38c94-75bbf to ip-10-6-44-216,Pod,payments-worker-6e38c94-75bbf,default-scheduler,2026-06-20 07:10:08,2026-06-20 07:58:08,1,2026-06-23 12:00:00
1084,prod-use2-eks,payments,Warning,OOMKilling,Container payments-api exceeded memory limit; OOMKilled,Pod,payments-api-1ce3577-591ac,controllermanager,2026-06-22 21:44:52,2026-06-22 22:27:52,10,2026-06-23 12:00:00
1085,prod-usw2-eks,kube-system,Warning,Unhealthy,Readiness probe errored: dial tcp i/o timeout for coredns-37f1521-4cd3d,Pod,coredns-37f1521-4cd3d,kubelet,2026-06-22 21:34:31,2026-06-22 23:16:31,2,2026-06-23 12:00:00
1086,prod-usw2-eks,checkout,Warning,Evicted,Pod cart-svc-0a94879-c1bba evicted: node was low on resource ephemeral-storage,Pod,cart-svc-0a94879-c1bba,controllermanager,2026-06-11 03:15:46,2026-06-11 04:18:46,3,2026-06-23 12:00:00
1087,prod-usw2-eks,search,Normal,Pulled,Container image pulled for recommendation,Pod,recommendation-87e3198-026ea,kubelet,2026-05-25 18:52:58,2026-05-25 19:05:58,1,2026-06-23 12:00:00
1088,prod-use2-eks,checkout,Warning,Evicted,Pod cart-svc-527eb80-045c0 evicted: node memory pressure,Pod,cart-svc-527eb80-045c0,controllermanager,2026-06-12 14:42:19,2026-06-12 16:01:19,32,2026-06-23 12:00:00
1089,prod-usw2-eks,ledger,Warning,Evicted,Pod ledger-svc-2014124-29b88 evicted: node was low on resource ephemeral-storage,Pod,ledger-svc-2014124-29b88,default-scheduler,2026-06-18 05:17:03,2026-06-18 06:18:03,18,2026-06-23 12:00:00
1090,prod-use2-eks,search,Normal,Pulled,Container image pulled for search-api,Pod,search-api-eff0684-a368a,controllermanager,2026-06-03 20:37:25,2026-06-03 20:59:25,1,2026-06-23 12:00:00
1091,prod-usw2-eks,ledger,Warning,Evicted,Pod ledger-svc-0744083-43011 evicted: node was low on resource ephemeral-storage,Pod,ledger-svc-0744083-43011,default-scheduler,2026-06-22 09:02:08,2026-06-22 10:04:08,36,2026-06-23 12:00:00
1092,prod-usw2-eks,orders,Warning,FreeDiskSpaceFailed,Failed to garbage collect on node ip-10-14-16-161,Pod,orders-worker-b907131-2627d,controllermanager,2026-06-23 00:35:28,2026-06-23 00:41:28,23,2026-06-23 12:00:00
1093,dr-use1-eks,orders,Warning,DNSConfigForming,Search line limits exceeded for orders-api-8330e48-f22f4,Pod,orders-api-8330e48-f22f4,kubelet,2026-06-15 03:29:11,2026-06-15 04:13:11,33,2026-06-23 12:00:00
1094,prod-usw2-eks,orders,Warning,Evicted,Pod orders-worker-b907131-2627d evicted: node was low on resource ephemeral-storage,Pod,orders-worker-b907131-2627d,default-scheduler,2026-06-21 15:55:22,2026-06-21 17:21:22,24,2026-06-23 12:00:00
1095,staging-use2-eks,payments,Warning,FreeDiskSpaceFailed,Failed to garbage collect on node ip-10-20-108-255,Pod,payments-api-2729261-453da,default-scheduler,2026-06-08 23:04:51,2026-06-08 23:09:51,38,2026-06-23 12:00:00
1096,prod-usw2-eks,payments,Warning,OOMKilling,Container payments-api exceeded memory limit; OOMKilled,Pod,payments-api-423b015-b80bd,controllermanager,2026-06-07 00:20:07,2026-06-07 00:21:07,27,2026-06-23 12:00:00
1097,dr-use1-eks,orders,Warning,DNSConfigForming,Search line limits exceeded for orders-api-8330e48-f22f4,Pod,orders-api-8330e48-f22f4,kubelet,2026-06-11 12:37:09,2026-06-11 14:27:09,27,2026-06-23 12:00:00
1098,prod-use2-eks,checkout,Warning,OOMKilling,Container cart-svc exceeded memory limit; OOMKilled,Pod,cart-svc-527eb80-045c0,kubelet,2026-06-18 22:42:50,2026-06-18 23:05:50,27,2026-06-23 12:00:00
1099,dr-use1-eks,ledger,Normal,Pulled,Container image pulled for ledger-svc,Pod,ledger-svc-e00a046-6e2d6,controllermanager,2026-06-21 10:23:47,2026-06-21 10:42:47,1,2026-06-23 12:00:00
1100,prod-usw2-eks,checkout,Normal,Pulled,Container image pulled for checkout-web,Pod,checkout-web-c2b3638-fa6d0,kubelet,2026-05-26 12:30:38,2026-05-26 12:40:38,1,2026-06-23 12:00:00
1101,prod-usw2-eks,checkout,Warning,FreeDiskSpaceFailed,Failed to garbage collect on node ip-10-6-194-142,Pod,cart-svc-882ca58-64a75,controllermanager,2026-06-21 06:51:14,2026-06-21 08:45:14,29,2026-06-23 12:00:00
1102,staging-use2-eks,kube-system,Normal,Started,Started container coredns,Pod,coredns-b16ea15-07544,controllermanager,2026-06-19 19:41:45,2026-06-19 20:43:45,1,2026-06-23 12:00:00
1103,prod-usw2-eks,orders,Warning,FreeDiskSpaceFailed,Failed to garbage collect on node ip-10-14-16-161,Pod,orders-worker-8482791-f2d9f,controllermanager,2026-06-20 22:30:11,2026-06-20 23:47:11,33,2026-06-23 12:00:00
1104,prod-usw2-eks,kube-system,Warning,Unhealthy,Readiness probe errored: dial tcp i/o timeout for coredns-37f1521-4cd3d,Pod,coredns-37f1521-4cd3d,kubelet,2026-06-17 13:13:17,2026-06-17 13:20:17,28,2026-06-23 12:00:00
1105,prod-usw2-eks,identity,Normal,Started,Started container auth-gateway,Pod,auth-gateway-fb1c283-81cc8,controllermanager,2026-05-26 00:41:03,2026-05-26 01:07:03,1,2026-06-23 12:00:00
1106,dr-use1-eks,orders,Warning,Unhealthy,Readiness probe errored: dial tcp i/o timeout for orders-api-8330e48-f22f4,Pod,orders-api-8330e48-f22f4,controllermanager,2026-06-09 04:52:20,2026-06-09 06:25:20,23,2026-06-23 12:00:00
1107,prod-use2-eks,checkout,Warning,OOMKilling,Container cart-svc exceeded memory limit; OOMKilled,Pod,cart-svc-26a7d77-aafdc,kubelet,2026-06-15 01:34:47,2026-06-15 02:35:47,8,2026-06-23 12:00:00
1108,prod-usw2-eks,inventory,Normal,Started,Started container inventory-svc,Pod,inventory-svc-0d33458-c137f,kubelet,2026-06-17 08:33:03,2026-06-17 09:35:03,1,2026-06-23 12:00:00
1109,prod-use2-eks,identity,Normal,Started,Started container auth-gateway,Pod,auth-gateway-bf1d422-2018d,controllermanager,2026-05-27 05:08:35,2026-05-27 06:58:35,1,2026-06-23 12:00:00
1110,prod-usw2-eks,orders,Warning,Unhealthy,Liveness probe failed: HTTP 500 for orders-api-cbca488-26609,Pod,orders-api-cbca488-26609,default-scheduler,2026-06-20 07:01:59,2026-06-20 08:26:59,34,2026-06-23 12:00:00
1111,staging-use2-eks,identity,Normal,Pulled,Container image pulled for auth-gateway,Pod,auth-gateway-c975434-e6ef9,kubelet,2026-05-24 15:11:25,2026-05-24 15:33:25,1,2026-06-23 12:00:00
1112,prod-usw2-eks,payments,Normal,Scheduled,Successfully assigned payments-api-6c2b997-3e07d to ip-10-15-83-236,Pod,payments-api-6c2b997-3e07d,default-scheduler,2026-06-05 22:39:40,2026-06-05 23:05:40,1,2026-06-23 12:00:00
1113,prod-use2-eks,kube-system,Warning,FreeDiskSpaceFailed,Failed to garbage collect on node ip-10-32-13-101,Pod,coredns-e513a45-fb7bf,controllermanager,2026-06-13 12:34:34,2026-06-13 14:07:34,26,2026-06-23 12:00:00
1114,staging-use2-eks,search,Warning,DNSConfigForming,Search line limits exceeded for search-api-1605640-8abaf,Pod,search-api-1605640-8abaf,default-scheduler,2026-06-23 03:53:51,2026-06-23 05:45:51,1,2026-06-23 12:00:00
1115,prod-usw2-eks,search,Normal,Scheduled,Successfully assigned recommendation-1e52697-e4756 to ip-10-6-194-142,Pod,recommendation-1e52697-e4756,controllermanager,2026-05-31 00:18:12,2026-05-31 00:38:12,1,2026-06-23 12:00:00
1116,prod-use2-eks,payments,Warning,OOMKilling,Container payments-api exceeded memory limit; OOMKilled,Pod,payments-api-c9c2b74-00142,controllermanager,2026-06-23 05:52:43,2026-06-23 06:14:43,20,2026-06-23 12:00:00
1117,prod-use2-eks,platform,Warning,DNSConfigForming,Search line limits exceeded for image-resizer-9994630-7c707,Pod,image-resizer-9994630-7c707,kubelet,2026-06-20 18:03:02,2026-06-20 19:30:02,21,2026-06-23 12:00:00
1118,staging-use2-eks,inventory,Warning,Evicted,Pod inventory-svc-1d6f570-1b50d evicted: node memory pressure,Pod,inventory-svc-1d6f570-1b50d,kubelet,2026-06-21 23:00:50,2026-06-22 00:11:50,6,2026-06-23 12:00:00
1119,prod-usw2-eks,kube-system,Warning,NodeNotReady,Node ip-10-6-194-142 status is now: NodeNotReady,Pod,metrics-server-6162d13-d4a14,controllermanager,2026-06-14 03:56:02,2026-06-14 03:56:02,16,2026-06-23 12:00:00
1120,prod-usw2-eks,payments,Warning,Unhealthy,Liveness probe failed: HTTP 500 for payments-worker-1d1bf52-dff66,Pod,payments-worker-1d1bf52-dff66,default-scheduler,2026-06-15 18:36:45,2026-06-15 19:40:45,38,2026-06-23 12:00:00
1121,prod-usw2-eks,payments,Warning,OOMKilling,Container payments-api exceeded memory limit; OOMKilled,Pod,payments-api-423b015-b80bd,default-scheduler,2026-06-14 09:02:02,2026-06-14 09:27:02,36,2026-06-23 12:00:00
1122,dr-use1-eks,checkout,Warning,OOMKilling,Container checkout-web exceeded memory limit; OOMKilled,Pod,checkout-web-4263246-52f3a,controllermanager,2026-06-22 00:47:46,2026-06-22 02:46:46,7,2026-06-23 12:00:00
1123,prod-usw2-eks,kube-system,Warning,NodeNotReady,Node ip-10-6-194-142 status is now: NodeNotReady,Pod,metrics-server-6162d13-d4a14,kubelet,2026-06-18 10:55:58,2026-06-18 12:38:58,39,2026-06-23 12:00:00
1124,prod-usw2-eks,checkout,Warning,FreeDiskSpaceFailed,Failed to garbage collect on node ip-10-6-194-142,Pod,cart-svc-ee38458-64d46,kubelet,2026-06-10 06:35:10,2026-06-10 07:25:10,26,2026-06-23 12:00:00
1125,dr-use1-eks,checkout,Warning,Evicted,Pod checkout-web-6e9e217-a5c79 evicted: node memory pressure,Pod,checkout-web-6e9e217-a5c79,kubelet,2026-06-20 20:51:30,2026-06-20 22:14:30,33,2026-06-23 12:00:00
1126,prod-usw2-eks,payments,Warning,OOMKilling,Memory cgroup out of memory: Killed process in payments-worker-1d1bf52-dff66,Pod,payments-worker-1d1bf52-dff66,default-scheduler,2026-06-12 14:16:44,2026-06-12 14:17:44,18,2026-06-23 12:00:00
1127,prod-usw2-eks,ledger,Warning,FreeDiskSpaceFailed,Failed to garbage collect on node ip-10-14-16-161,Pod,ledger-svc-2014124-29b88,controllermanager,2026-06-20 03:49:40,2026-06-20 05:13:40,12,2026-06-23 12:00:00
1128,prod-use2-eks,payments,Warning,OOMKilling,Container payments-api exceeded memory limit; OOMKilled,Pod,payments-api-c9c2b74-00142,default-scheduler,2026-06-22 23:24:19,2026-06-23 00:45:19,14,2026-06-23 12:00:00
1129,prod-usw2-eks,checkout,Warning,Evicted,Pod cart-svc-0a94879-c1bba evicted: node was low on resource ephemeral-storage,Pod,cart-svc-0a94879-c1bba,controllermanager,2026-06-15 16:45:12,2026-06-15 17:17:12,10,2026-06-23 12:00:00
1130,prod-use2-eks,identity,Warning,Evicted,Pod session-store-4732511-0dba8 evicted: node memory pressure,Pod,session-store-4732511-0dba8,default-scheduler,2026-06-22 18:50:38,2026-06-22 19:47:38,22,2026-06-23 12:00:00
1131,prod-usw2-eks,search,Warning,FreeDiskSpaceFailed,Failed to garbage collect on node ip-10-6-194-142,Pod,search-api-15a6d76-12766,kubelet,2026-06-13 00:32:54,2026-06-13 01:19:54,16,2026-06-23 12:00:00
1132,prod-usw2-eks,orders,Warning,Unhealthy,Liveness probe failed: HTTP 500 for orders-api-cbca488-26609,Pod,orders-api-cbca488-26609,kubelet,2026-06-14 20:41:55,2026-06-14 22:10:55,5,2026-06-23 12:00:00
1133,prod-usw2-eks,payments,Warning,Evicted,Pod payments-api-b9a1287-dbbfe evicted: node memory pressure,Pod,payments-api-b9a1287-dbbfe,default-scheduler,2026-05-31 15:35:49,2026-05-31 17:16:49,40,2026-06-23 12:00:00
1134,prod-use2-eks,orders,Warning,Evicted,Pod orders-api-bfb2f93-32ad3 evicted: node memory pressure,Pod,orders-api-bfb2f93-32ad3,controllermanager,2026-06-09 06:43:17,2026-06-09 07:13:17,39,2026-06-23 12:00:00
1135,dr-use1-eks,search,Warning,NodeNotReady,Node ip-10-21-57-150 status is now: NodeNotReady,Pod,indexer-6af7422-f66fc,default-scheduler,2026-06-21 02:42:08,2026-06-21 02:57:08,5,2026-06-23 12:00:00
1136,prod-usw2-eks,orders,Warning,FreeDiskSpaceFailed,Failed to garbage collect on node ip-10-14-16-161,Pod,orders-worker-b907131-2627d,controllermanager,2026-06-20 11:50:01,2026-06-20 12:01:01,18,2026-06-23 12:00:00
1137,prod-usw2-eks,platform,Normal,Scheduled,Successfully assigned image-resizer-6542c92-1100b to ip-10-15-83-236,Pod,image-resizer-6542c92-1100b,default-scheduler,2026-06-05 17:54:39,2026-06-05 18:50:39,1,2026-06-23 12:00:00
1138,prod-use2-eks,kube-system,Warning,Evicted,Pod coredns-e513a45-fb7bf evicted: node was low on resource ephemeral-storage,Pod,coredns-e513a45-fb7bf,kubelet,2026-06-14 12:00:44,2026-06-14 13:30:44,11,2026-06-23 12:00:00
1139,prod-usw2-eks,kube-system,Warning,Rebooted,Node ip-10-6-194-142 has been rebooted,Pod,metrics-server-6162d13-d4a14,controllermanager,2026-06-15 01:38:46,2026-06-15 02:19:46,37,2026-06-23 12:00:00
1140,prod-usw2-eks,ledger,Warning,Evicted,Pod ledger-svc-0744083-43011 evicted: node was low on resource ephemeral-storage,Pod,ledger-svc-0744083-43011,controllermanager,2026-06-22 13:11:34,2026-06-22 13:50:34,9,2026-06-23 12:00:00
1141,prod-use2-eks,ledger,Normal,Throttling,CPU throttled for container ledger-svc,Pod,ledger-svc-204e643-7d23b,controllermanager,2026-06-18 03:37:20,2026-06-18 05:21:20,1,2026-06-23 12:00:00
1142,staging-use2-eks,platform,Warning,FreeDiskSpaceFailed,Failed to garbage collect on node ip-10-8-126-134,Pod,config-svc-929cd33-16be4,default-scheduler,2026-06-15 12:35:05,2026-06-15 12:44:05,27,2026-06-23 12:00:00
1143,prod-use2-eks,notifications,Normal,Throttling,CPU throttled for container notifications,Pod,notifications-1938743-28dca,default-scheduler,2026-06-08 19:43:21,2026-06-08 19:45:21,1,2026-06-23 12:00:00
1144,dr-use1-eks,checkout,Warning,OOMKilling,Container checkout-web exceeded memory limit; OOMKilled,Pod,checkout-web-4263246-52f3a,kubelet,2026-06-22 00:24:54,2026-06-22 01:53:54,38,2026-06-23 12:00:00
1145,prod-use2-eks,platform,Normal,Throttling,CPU throttled for container config-svc,Pod,config-svc-027a395-39a4d,controllermanager,2026-06-21 21:29:04,2026-06-21 21:53:04,1,2026-06-23 12:00:00
1146,prod-use2-eks,inventory,Normal,Started,Started container inventory-svc,Pod,inventory-svc-3e28589-98330,controllermanager,2026-06-14 09:48:55,2026-06-14 11:28:55,1,2026-06-23 12:00:00
1147,dr-use1-eks,checkout,Warning,OOMKilling,Container checkout-web exceeded memory limit; OOMKilled,Pod,checkout-web-4263246-52f3a,kubelet,2026-06-20 09:07:57,2026-06-20 10:21:57,1,2026-06-23 12:00:00
1148,prod-use2-eks,orders,Warning,OOMKilling,Container orders-api exceeded memory limit; OOMKilled,Pod,orders-api-7f89525-97cdd,default-scheduler,2026-06-17 08:34:17,2026-06-17 09:23:17,2,2026-06-23 12:00:00
1149,staging-use2-eks,search,Normal,Pulled,Container image pulled for search-api,Pod,search-api-8ca0b98-505ff,default-scheduler,2026-06-22 22:39:36,2026-06-22 22:43:36,1,2026-06-23 12:00:00
1150,prod-usw2-eks,orders,Warning,Unhealthy,Liveness probe failed: HTTP 500 for orders-api-402bb51-ad48f,Pod,orders-api-402bb51-ad48f,kubelet,2026-06-14 16:16:51,2026-06-14 16:16:51,29,2026-06-23 12:00:00
1151,prod-use2-eks,payments,Warning,OOMKilling,Container payments-api exceeded memory limit; OOMKilled,Pod,payments-api-c9c2b74-00142,controllermanager,2026-06-23 10:10:50,2026-06-23 12:10:50,14,2026-06-23 12:00:00
1152,dr-use1-eks,checkout,Warning,OOMKilling,Container checkout-web exceeded memory limit; OOMKilled,Pod,checkout-web-6e9e217-a5c79,controllermanager,2026-06-19 05:43:14,2026-06-19 06:37:14,37,2026-06-23 12:00:00
1153,prod-usw2-eks,orders,Normal,Pulled,Container image pulled for orders-worker,Pod,orders-worker-0696c96-a62c8,default-scheduler,2026-06-23 08:55:03,2026-06-23 09:15:03,1,2026-06-23 12:00:00
1154,prod-use2-eks,checkout,Warning,Evicted,Pod cart-svc-26a7d77-aafdc evicted: node memory pressure,Pod,cart-svc-26a7d77-aafdc,controllermanager,2026-06-14 22:31:57,2026-06-14 22:59:57,17,2026-06-23 12:00:00
1155,prod-usw2-eks,payments,Warning,Evicted,Pod payments-api-1e23165-1e35b evicted: node memory pressure,Pod,payments-api-1e23165-1e35b,default-scheduler,2026-06-07 21:21:32,2026-06-07 22:42:32,1,2026-06-23 12:00:00
1156,prod-usw2-eks,checkout,Normal,Started,Started container checkout-web,Pod,checkout-web-2e5d994-d724e,default-scheduler,2026-05-24 13:48:26,2026-05-24 15:12:26,1,2026-06-23 12:00:00
1157,prod-usw2-eks,orders,Warning,OOMKilling,Memory cgroup out of memory: Killed process in orders-api-402bb51-ad48f,Pod,orders-api-402bb51-ad48f,controllermanager,2026-06-22 00:25:57,2026-06-22 01:17:57,13,2026-06-23 12:00:00
1158,prod-use2-eks,payments,Warning,Evicted,Pod payments-api-1ce3577-591ac evicted: node memory pressure,Pod,payments-api-1ce3577-591ac,kubelet,2026-06-22 17:43:16,2026-06-22 18:59:16,29,2026-06-23 12:00:00
1159,prod-usw2-eks,payments,Warning,Evicted,Pod payments-api-b9a1287-dbbfe evicted: node memory pressure,Pod,payments-api-b9a1287-dbbfe,controllermanager,2026-06-16 02:43:33,2026-06-16 04:18:33,1,2026-06-23 12:00:00
1160,prod-use2-eks,ledger,Normal,Throttling,CPU throttled for container ledger-svc,Pod,ledger-svc-f4a6d64-16dde,controllermanager,2026-06-22 19:14:52,2026-06-22 20:22:52,1,2026-06-23 12:00:00
1161,dr-use1-eks,checkout,Warning,OOMKilling,Container checkout-web exceeded memory limit; OOMKilled,Pod,checkout-web-4263246-52f3a,default-scheduler,2026-06-22 01:49:48,2026-06-22 02:55:48,4,2026-06-23 12:00:00
1162,prod-usw2-eks,payments,Warning,Unhealthy,Liveness probe failed: HTTP 500 for payments-worker-1d1bf52-dff66,Pod,payments-worker-1d1bf52-dff66,default-scheduler,2026-05-31 16:28:19,2026-05-31 16:55:19,11,2026-06-23 12:00:00
1163,prod-use2-eks,identity,Warning,OOMKilling,Container session-store exceeded memory limit; OOMKilled,Pod,session-store-4732511-0dba8,kubelet,2026-06-14 17:49:30,2026-06-14 18:29:30,27,2026-06-23 12:00:00
1164,prod-usw2-eks,identity,Normal,Started,Started container auth-gateway,Pod,auth-gateway-fb1c283-81cc8,controllermanager,2026-06-20 08:06:07,2026-06-20 08:10:07,1,2026-06-23 12:00:00
1165,prod-usw2-eks,orders,Warning,Evicted,Pod orders-worker-8482791-f2d9f evicted: node was low on resource ephemeral-storage,Pod,orders-worker-8482791-f2d9f,default-scheduler,2026-06-19 08:28:44,2026-06-19 09:17:44,6,2026-06-23 12:00:00
1166,prod-use2-eks,search,Normal,Started,Started container recommendation,Pod,recommendation-c460126-52814,controllermanager,2026-06-17 02:58:20,2026-06-17 02:59:20,1,2026-06-23 12:00:00
1167,prod-use2-eks,orders,Warning,OOMKilling,Container orders-api exceeded memory limit; OOMKilled,Pod,orders-api-e9b4a39-c3784,default-scheduler,2026-06-22 22:15:29,2026-06-22 22:41:29,3,2026-06-23 12:00:00
1168,dr-use1-eks,checkout,Warning,Evicted,Pod checkout-web-6e9e217-a5c79 evicted: node memory pressure,Pod,checkout-web-6e9e217-a5c79,controllermanager,2026-06-19 17:49:45,2026-06-19 18:18:45,29,2026-06-23 12:00:00
1169,prod-usw2-eks,kube-system,Warning,DNSConfigForming,Search line limits exceeded for coredns-4a8b365-1d9fc,Pod,coredns-4a8b365-1d9fc,controllermanager,2026-06-18 20:05:35,2026-06-18 20:34:35,26,2026-06-23 12:00:00
1170,prod-usw2-eks,checkout,Warning,Evicted,Pod cart-svc-ee38458-64d46 evicted: node was low on resource ephemeral-storage,Pod,cart-svc-ee38458-64d46,kubelet,2026-06-13 06:31:41,2026-06-13 06:57:41,18,2026-06-23 12:00:00
1171,prod-usw2-eks,identity,Warning,FreeDiskSpaceFailed,Failed to garbage collect on node ip-10-14-16-161,Pod,session-store-28ebc77-cf7c8,default-scheduler,2026-06-22 01:43:10,2026-06-22 01:51:10,25,2026-06-23 12:00:00
1172,prod-use2-eks,checkout,Warning,BackOff,Back-off restarting failed container checkout-web in pod checkout-web-0101b48-2b2af,Pod,checkout-web-0101b48-2b2af,default-scheduler,2026-06-04 00:47:29,2026-06-04 01:24:29,1,2026-06-23 12:00:00
1173,prod-usw2-eks,notifications,Normal,Started,Started container notifications,Pod,notifications-b2aff41-e1772,controllermanager,2026-06-12 14:55:43,2026-06-12 16:36:43,1,2026-06-23 12:00:00
1174,prod-use2-eks,kube-system,Warning,Evicted,Pod coredns-e513a45-fb7bf evicted: node was low on resource ephemeral-storage,Pod,coredns-e513a45-fb7bf,controllermanager,2026-06-07 02:21:02,2026-06-07 02:26:02,38,2026-06-23 12:00:00
1175,prod-use2-eks,platform,Normal,Started,Started container config-svc,Pod,config-svc-ddd1723-06ca5,controllermanager,2026-06-19 02:23:00,2026-06-19 02:24:00,1,2026-06-23 12:00:00
1176,prod-use2-eks,checkout,Warning,Unhealthy,Liveness probe failed: HTTP 500 for checkout-web-c2eb578-2d181,Pod,checkout-web-c2eb578-2d181,kubelet,2026-06-13 04:51:22,2026-06-13 05:31:22,5,2026-06-23 12:00:00
1177,prod-usw2-eks,inventory,Warning,Unhealthy,Liveness probe failed: HTTP 500 for inventory-svc-bf8f159-02345,Pod,inventory-svc-bf8f159-02345,kubelet,2026-06-16 15:00:33,2026-06-16 16:33:33,38,2026-06-23 12:00:00
1178,prod-usw2-eks,kube-system,Warning,NodeNotReady,Node ip-10-6-194-142 status is now: NodeNotReady,Pod,metrics-server-6162d13-d4a14,controllermanager,2026-06-16 09:03:25,2026-06-16 10:00:25,35,2026-06-23 12:00:00
1179,prod-usw2-eks,orders,Warning,OOMKilling,Memory cgroup out of memory: Killed process in orders-api-cbca488-26609,Pod,orders-api-cbca488-26609,controllermanager,2026-06-22 03:26:05,2026-06-22 04:15:05,3,2026-06-23 12:00:00
1180,staging-use2-eks,checkout,Warning,Rebooted,Node ip-10-8-126-134 has been rebooted,Pod,checkout-web-2b77739-52fdd,kubelet,2026-06-23 09:45:41,2026-06-23 11:24:41,5,2026-06-23 12:00:00
1181,prod-use2-eks,platform,Warning,Unhealthy,Readiness probe errored: dial tcp i/o timeout for image-resizer-9994630-7c707,Pod,image-resizer-9994630-7c707,controllermanager,2026-06-22 06:41:51,2026-06-22 08:25:51,37,2026-06-23 12:00:00
1182,prod-usw2-eks,identity,Warning,Evicted,Pod session-store-28ebc77-cf7c8 evicted: node was low on resource ephemeral-storage,Pod,session-store-28ebc77-cf7c8,default-scheduler,2026-06-11 02:16:33,2026-06-11 03:41:33,19,2026-06-23 12:00:00
1183,prod-use2-eks,checkout,Warning,OOMKilling,Container cart-svc exceeded memory limit; OOMKilled,Pod,cart-svc-26a7d77-aafdc,kubelet,2026-06-18 07:06:38,2026-06-18 07:58:38,33,2026-06-23 12:00:00
1184,prod-usw2-eks,ledger,Warning,Evicted,Pod ledger-svc-0744083-43011 evicted: node was low on resource ephemeral-storage,Pod,ledger-svc-0744083-43011,controllermanager,2026-06-20 08:28:20,2026-06-20 08:29:20,29,2026-06-23 12:00:00
1185,prod-usw2-eks,kube-system,Warning,DNSConfigForming,Search line limits exceeded for coredns-37f1521-4cd3d,Pod,coredns-37f1521-4cd3d,kubelet,2026-06-18 13:44:24,2026-06-18 14:44:24,11,2026-06-23 12:00:00
1186,dr-use1-eks,checkout,Warning,Evicted,Pod checkout-web-6e9e217-a5c79 evicted: node memory pressure,Pod,checkout-web-6e9e217-a5c79,default-scheduler,2026-06-21 06:27:49,2026-06-21 06:42:49,36,2026-06-23 12:00:00
1187,staging-use2-eks,checkout,Warning,NodeNotReady,Node ip-10-14-70-252 status is now: NodeNotReady,Pod,checkout-web-aca9086-f5fe6,controllermanager,2026-06-22 16:05:47,2026-06-22 16:58:47,31,2026-06-23 12:00:00
1188,prod-usw2-eks,orders,Warning,OOMKilling,Memory cgroup out of memory: Killed process in orders-api-cbca488-26609,Pod,orders-api-cbca488-26609,default-scheduler,2026-06-18 00:46:47,2026-06-18 00:55:47,29,2026-06-23 12:00:00
1189,prod-usw2-eks,ledger,Warning,Evicted,Pod ledger-svc-0744083-43011 evicted: node was low on resource ephemeral-storage,Pod,ledger-svc-0744083-43011,kubelet,2026-06-21 11:11:25,2026-06-21 13:08:25,15,2026-06-23 12:00:00
1190,prod-usw2-eks,orders,Warning,OOMKilling,Memory cgroup out of memory: Killed process in orders-api-cbca488-26609,Pod,orders-api-cbca488-26609,kubelet,2026-06-21 16:39:51,2026-06-21 17:24:51,18,2026-06-23 12:00:00
1191,prod-usw2-eks,kube-system,Warning,NodeNotReady,Node ip-10-6-194-142 status is now: NodeNotReady,Pod,metrics-server-6162d13-d4a14,kubelet,2026-06-16 07:05:16,2026-06-16 07:58:16,1,2026-06-23 12:00:00
1192,prod-usw2-eks,orders,Warning,OOMKilling,Memory cgroup out of memory: Killed process in orders-api-cbca488-26609,Pod,orders-api-cbca488-26609,controllermanager,2026-06-19 04:08:38,2026-06-19 05:59:38,8,2026-06-23 12:00:00
1193,prod-use2-eks,ledger,Normal,Throttling,CPU throttled for container ledger-svc,Pod,ledger-svc-f4a6d64-16dde,kubelet,2026-06-21 06:30:39,2026-06-21 07:18:39,1,2026-06-23 12:00:00
1194,prod-usw2-eks,kube-system,Warning,DNSConfigForming,Search line limits exceeded for coredns-37f1521-4cd3d,Pod,coredns-37f1521-4cd3d,default-scheduler,2026-06-17 09:55:24,2026-06-17 11:08:24,26,2026-06-23 12:00:00
1195,prod-usw2-eks,orders,Warning,OOMKilling,Memory cgroup out of memory: Killed process in orders-api-21c5d48-15186,Pod,orders-api-21c5d48-15186,controllermanager,2026-06-20 17:17:21,2026-06-20 18:52:21,7,2026-06-23 12:00:00
1196,prod-use2-eks,checkout,Normal,Pulled,Container image pulled for checkout-web,Pod,checkout-web-47df111-4e24c,kubelet,2026-06-07 19:35:58,2026-06-07 20:20:58,1,2026-06-23 12:00:00
1197,prod-use2-eks,platform,Warning,DNSConfigForming,Search line limits exceeded for image-resizer-9994630-7c707,Pod,image-resizer-9994630-7c707,controllermanager,2026-06-22 09:12:50,2026-06-22 09:30:50,34,2026-06-23 12:00:00
1198,prod-use2-eks,platform,Warning,Unhealthy,Readiness probe failed: timeout for config-svc-027a395-39a4d,Pod,config-svc-027a395-39a4d,controllermanager,2026-06-21 17:47:05,2026-06-21 17:53:05,39,2026-06-23 12:00:00
1199,staging-use2-eks,checkout,Warning,Rebooted,Node ip-10-14-70-252 has been rebooted,Pod,checkout-web-aca9086-f5fe6,kubelet,2026-06-23 10:53:01,2026-06-23 11:33:01,7,2026-06-23 12:00:00
1200,prod-usw2-eks,orders,Warning,BackOff,Back-off restarting failed container orders-api in pod orders-api-21c5d48-15186,Pod,orders-api-21c5d48-15186,default-scheduler,2026-06-21 13:01:24,2026-06-21 13:10:24,35,2026-06-23 12:00:00
1201,prod-usw2-eks,payments,Normal,Pulled,Container image pulled for payments-worker,Pod,payments-worker-b4be648-d2dcb,default-scheduler,2026-06-16 14:54:46,2026-06-16 14:58:46,1,2026-06-23 12:00:00
1202,prod-use2-eks,payments,Warning,Evicted,Pod payments-api-7fa4649-debd8 evicted: node memory pressure,Pod,payments-api-7fa4649-debd8,kubelet,2026-06-23 05:50:30,2026-06-23 07:07:30,35,2026-06-23 12:00:00
1203,prod-usw2-eks,orders,Warning,Evicted,Pod orders-worker-b907131-2627d evicted: node was low on resource ephemeral-storage,Pod,orders-worker-b907131-2627d,kubelet,2026-06-23 10:55:23,2026-06-23 11:28:23,38,2026-06-23 12:00:00
1204,prod-usw2-eks,ledger,Warning,Evicted,Pod ledger-svc-2014124-29b88 evicted: node was low on resource ephemeral-storage,Pod,ledger-svc-2014124-29b88,default-scheduler,2026-06-16 10:25:54,2026-06-16 11:30:54,32,2026-06-23 12:00:00
1205,prod-use2-eks,payments,Warning,OOMKilling,Container payments-api exceeded memory limit; OOMKilled,Pod,payments-api-7fa4649-debd8,controllermanager,2026-06-23 10:03:54,2026-06-23 11:38:54,20,2026-06-23 12:00:00
1206,prod-usw2-eks,payments,Warning,OOMKilling,Container payments-api exceeded memory limit; OOMKilled,Pod,payments-api-1e23165-1e35b,controllermanager,2026-06-15 02:22:58,2026-06-15 03:35:58,14,2026-06-23 12:00:00
1207,prod-use2-eks,ledger,Normal,Throttling,CPU throttled for container ledger-svc,Pod,ledger-svc-f4a6d64-16dde,default-scheduler,2026-06-17 19:29:37,2026-06-17 20:26:37,1,2026-06-23 12:00:00
1208,prod-use2-eks,orders,Warning,Evicted,Pod orders-api-e9b4a39-c3784 evicted: node memory pressure,Pod,orders-api-e9b4a39-c3784,controllermanager,2026-06-21 04:34:28,2026-06-21 05:34:28,22,2026-06-23 12:00:00
1209,dr-use1-eks,checkout,Warning,OOMKilling,Container checkout-web exceeded memory limit; OOMKilled,Pod,checkout-web-6e9e217-a5c79,controllermanager,2026-06-20 11:25:00,2026-06-20 11:25:00,35,2026-06-23 12:00:00
1210,prod-use2-eks,checkout,Warning,OOMKilling,Container cart-svc exceeded memory limit; OOMKilled,Pod,cart-svc-26a7d77-aafdc,default-scheduler,2026-06-23 01:48:56,2026-06-23 01:59:56,10,2026-06-23 12:00:00
1211,prod-usw2-eks,notifications,Normal,Started,Started container notifications,Pod,notifications-abd2926-3451e,default-scheduler,2026-06-15 22:09:27,2026-06-15 23:47:27,1,2026-06-23 12:00:00
1212,dr-use1-eks,search,Warning,FreeDiskSpaceFailed,Failed to garbage collect on node ip-10-40-81-216,Pod,search-api-be84964-d972c,controllermanager,2026-06-12 13:40:26,2026-06-12 14:12:26,30,2026-06-23 12:00:00
1213,prod-usw2-eks,kube-system,Warning,Unhealthy,Readiness probe errored: dial tcp i/o timeout for coredns-4a8b365-1d9fc,Pod,coredns-4a8b365-1d9fc,controllermanager,2026-06-23 04:36:46,2026-06-23 05:36:46,14,2026-06-23 12:00:00
1214,prod-usw2-eks,ledger,Warning,FreeDiskSpaceFailed,Failed to garbage collect on node ip-10-14-16-161,Pod,ledger-svc-2014124-29b88,default-scheduler,2026-06-20 12:08:41,2026-06-20 13:19:41,18,2026-06-23 12:00:00
1215,prod-usw2-eks,kube-system,Warning,NodeNotReady,Node ip-10-6-194-142 status is now: NodeNotReady,Pod,metrics-server-6162d13-d4a14,controllermanager,2026-06-17 22:48:22,2026-06-18 00:39:22,7,2026-06-23 12:00:00
1216,prod-use2-eks,identity,Normal,Started,Started container auth-gateway,Pod,auth-gateway-9bddb17-f3d59,controllermanager,2026-05-29 03:36:44,2026-05-29 04:49:44,1,2026-06-23 12:00:00
1217,prod-use2-eks,orders,Warning,OOMKilling,Container orders-api exceeded memory limit; OOMKilled,Pod,orders-api-7f89525-97cdd,kubelet,2026-06-22 08:50:40,2026-06-22 09:55:40,15,2026-06-23 12:00:00
1218,prod-use2-eks,payments,Warning,Evicted,Pod payments-api-58c5e74-26d34 evicted: node memory pressure,Pod,payments-api-58c5e74-26d34,controllermanager,2026-06-22 15:51:42,2026-06-22 17:05:42,16,2026-06-23 12:00:00
1219,prod-usw2-eks,platform,Normal,Scheduled,Successfully assigned config-svc-d193d56-68bd9 to ip-10-22-107-136,Pod,config-svc-d193d56-68bd9,default-scheduler,2026-06-20 20:14:02,2026-06-20 20:49:02,1,2026-06-23 12:00:00
1220,prod-use2-eks,notifications,Warning,Unhealthy,Readiness probe failed: timeout for notifications-1938743-28dca,Pod,notifications-1938743-28dca,kubelet,2026-06-19 23:57:07,2026-06-20 00:37:07,40,2026-06-23 12:00:00
1221,prod-usw2-eks,orders,Warning,Evicted,Pod orders-worker-8482791-f2d9f evicted: node was low on resource ephemeral-storage,Pod,orders-worker-8482791-f2d9f,kubelet,2026-06-18 00:53:29,2026-06-18 02:46:29,1,2026-06-23 12:00:00
1222,prod-usw2-eks,payments,Warning,OOMKilling,Container payments-api exceeded memory limit; OOMKilled,Pod,payments-api-423b015-b80bd,controllermanager,2026-05-28 07:34:31,2026-05-28 07:53:31,11,2026-06-23 12:00:00
1223,prod-use2-eks,checkout,Warning,Evicted,Pod cart-svc-26a7d77-aafdc evicted: node memory pressure,Pod,cart-svc-26a7d77-aafdc,kubelet,2026-06-19 20:04:33,2026-06-19 20:43:33,40,2026-06-23 12:00:00
1224,prod-usw2-eks,search,Warning,FreeDiskSpaceFailed,Failed to garbage collect on node ip-10-6-194-142,Pod,search-api-15a6d76-12766,default-scheduler,2026-06-16 11:08:00,2026-06-16 12:54:00,7,2026-06-23 12:00:00
1225,prod-usw2-eks,search,Warning,FreeDiskSpaceFailed,Failed to garbage collect on node ip-10-6-194-142,Pod,search-api-15a6d76-12766,kubelet,2026-06-19 16:43:46,2026-06-19 17:01:46,6,2026-06-23 12:00:00
1226,staging-use2-eks,inventory,Warning,Evicted,Pod inventory-svc-1d6f570-1b50d evicted: node memory pressure,Pod,inventory-svc-1d6f570-1b50d,kubelet,2026-06-14 11:54:45,2026-06-14 13:42:45,27,2026-06-23 12:00:00
1227,dr-use1-eks,search,Warning,FreeDiskSpaceFailed,Failed to garbage collect on node ip-10-40-81-216,Pod,search-api-d416b43-7cb20,default-scheduler,2026-06-07 12:27:29,2026-06-07 13:23:29,14,2026-06-23 12:00:00
1228,prod-usw2-eks,ledger,Warning,Evicted,Pod ledger-svc-2014124-29b88 evicted: node was low on resource ephemeral-storage,Pod,ledger-svc-2014124-29b88,kubelet,2026-06-16 17:19:19,2026-06-16 19:07:19,37,2026-06-23 12:00:00
1229,prod-usw2-eks,orders,Warning,BackOff,Back-off restarting failed container orders-api in pod orders-api-cbca488-26609,Pod,orders-api-cbca488-26609,default-scheduler,2026-06-19 02:06:43,2026-06-19 03:05:43,19,2026-06-23 12:00:00
1230,prod-usw2-eks,checkout,Warning,Evicted,Pod cart-svc-0a94879-c1bba evicted: node was low on resource ephemeral-storage,Pod,cart-svc-0a94879-c1bba,default-scheduler,2026-06-09 13:31:28,2026-06-09 13:56:28,5,2026-06-23 12:00:00
1231,staging-use2-eks,platform,Warning,FreeDiskSpaceFailed,Failed to garbage collect on node ip-10-8-126-134,Pod,config-svc-929cd33-16be4,default-scheduler,2026-06-14 11:39:36,2026-06-14 11:59:36,7,2026-06-23 12:00:00
1232,dr-use1-eks,checkout,Warning,OOMKilling,Container checkout-web exceeded memory limit; OOMKilled,Pod,checkout-web-4263246-52f3a,kubelet,2026-06-21 00:59:12,2026-06-21 02:59:12,1,2026-06-23 12:00:00
1233,dr-use1-eks,search,Warning,Rebooted,Node ip-10-21-57-150 has been rebooted,Pod,indexer-6af7422-f66fc,controllermanager,2026-06-05 09:00:25,2026-06-05 10:45:25,4,2026-06-23 12:00:00
1234,staging-use2-eks,inventory,Warning,Evicted,Pod inventory-svc-1d6f570-1b50d evicted: node memory pressure,Pod,inventory-svc-1d6f570-1b50d,controllermanager,2026-06-16 14:50:16,2026-06-16 15:01:16,6,2026-06-23 12:00:00
1235,prod-use2-eks,notifications,Normal,Throttling,CPU throttled for container notifications,Pod,notifications-1938743-28dca,controllermanager,2026-06-20 05:16:25,2026-06-20 05:44:25,1,2026-06-23 12:00:00
1236,prod-usw2-eks,ledger,Warning,Evicted,Pod ledger-svc-842cd31-95bfa evicted: node was low on resource ephemeral-storage,Pod,ledger-svc-842cd31-95bfa,kubelet,2026-06-16 20:59:58,2026-06-16 22:30:58,7,2026-06-23 12:00:00
1237,prod-use2-eks,orders,Warning,Evicted,Pod orders-api-e9b4a39-c3784 evicted: node memory pressure,Pod,orders-api-e9b4a39-c3784,default-scheduler,2026-06-13 13:07:56,2026-06-13 13:29:56,25,2026-06-23 12:00:00
1238,dr-use1-eks,notifications,Warning,BackOff,Back-off restarting failed container notifications in pod notifications-b036879-82982,Pod,notifications-b036879-82982,default-scheduler,2026-06-22 14:58:42,2026-06-22 15:37:42,24,2026-06-23 12:00:00
1239,prod-usw2-eks,kube-system,Warning,Unhealthy,Readiness probe errored: dial tcp i/o timeout for coredns-37f1521-4cd3d,Pod,coredns-37f1521-4cd3d,default-scheduler,2026-06-20 11:10:20,2026-06-20 12:28:20,22,2026-06-23 12:00:00
1240,staging-use2-eks,platform,Warning,FreeDiskSpaceFailed,Failed to garbage collect on node ip-10-8-126-134,Pod,config-svc-929cd33-16be4,default-scheduler,2026-06-11 00:35:58,2026-06-11 00:44:58,37,2026-06-23 12:00:00
1241,prod-use2-eks,orders,Warning,OOMKilling,Container orders-api exceeded memory limit; OOMKilled,Pod,orders-api-e9b4a39-c3784,default-scheduler,2026-06-15 05:30:58,2026-06-15 05:40:58,34,2026-06-23 12:00:00
1242,prod-usw2-eks,platform,Normal,Pulled,Container image pulled for config-svc,Pod,config-svc-d193d56-68bd9,controllermanager,2026-06-15 22:10:08,2026-06-15 23:34:08,1,2026-06-23 12:00:00
1243,prod-use2-eks,checkout,Warning,OOMKilling,Memory cgroup out of memory: Killed process in checkout-web-c343d41-6a8d2,Pod,checkout-web-c343d41-6a8d2,default-scheduler,2026-06-20 20:15:32,2026-06-20 21:30:32,19,2026-06-23 12:00:00
1244,prod-use2-eks,identity,Normal,Pulled,Container image pulled for auth-gateway,Pod,auth-gateway-bf1d422-2018d,controllermanager,2026-06-01 08:31:46,2026-06-01 09:13:46,1,2026-06-23 12:00:00
1245,staging-use2-eks,checkout,Warning,NodeNotReady,Node ip-10-8-126-134 status is now: NodeNotReady,Pod,checkout-web-2b77739-52fdd,kubelet,2026-06-23 10:02:11,2026-06-23 11:57:11,25,2026-06-23 12:00:00
1246,prod-use2-eks,orders,Warning,OOMKilling,Container orders-api exceeded memory limit; OOMKilled,Pod,orders-api-e9b4a39-c3784,controllermanager,2026-06-13 14:54:19,2026-06-13 16:03:19,32,2026-06-23 12:00:00
1247,prod-usw2-eks,orders,Warning,Evicted,Pod orders-worker-8482791-f2d9f evicted: node was low on resource ephemeral-storage,Pod,orders-worker-8482791-f2d9f,kubelet,2026-06-22 14:15:37,2026-06-22 15:10:37,10,2026-06-23 12:00:00
1248,staging-use2-eks,payments,Normal,Scheduled,Successfully assigned payments-api-dde4d16-a3d09 to ip-10-14-70-252,Pod,payments-api-dde4d16-a3d09,default-scheduler,2026-06-21 07:03:31,2026-06-21 07:22:31,1,2026-06-23 12:00:00
1249,staging-use2-eks,search,Warning,Unhealthy,Readiness probe errored: dial tcp i/o timeout for search-api-1605640-8abaf,Pod,search-api-1605640-8abaf,kubelet,2026-06-22 09:28:33,2026-06-22 10:26:33,17,2026-06-23 12:00:00
1250,prod-use2-eks,orders,Warning,OOMKilling,Container orders-api exceeded memory limit; OOMKilled,Pod,orders-api-7f89525-97cdd,controllermanager,2026-06-18 04:50:38,2026-06-18 05:56:38,11,2026-06-23 12:00:00
1251,prod-use2-eks,search,Normal,Scheduled,Successfully assigned search-api-4350294-dbefb to ip-10-17-79-110,Pod,search-api-4350294-dbefb,kubelet,2026-06-13 08:04:50,2026-06-13 08:48:50,1,2026-06-23 12:00:00
1252,prod-usw2-eks,kube-system,Warning,Unhealthy,Readiness probe errored: dial tcp i/o timeout for coredns-37f1521-4cd3d,Pod,coredns-37f1521-4cd3d,default-scheduler,2026-06-22 11:06:32,2026-06-22 11:18:32,28,2026-06-23 12:00:00
1253,prod-use2-eks,platform,Warning,Unhealthy,Readiness probe errored: dial tcp i/o timeout for image-resizer-9994630-7c707,Pod,image-resizer-9994630-7c707,kubelet,2026-06-23 06:11:09,2026-06-23 07:14:09,13,2026-06-23 12:00:00
1254,prod-use2-eks,ledger,Normal,Throttling,CPU throttled for container ledger-svc,Pod,ledger-svc-204e643-7d23b,default-scheduler,2026-06-20 16:39:04,2026-06-20 17:24:04,1,2026-06-23 12:00:00
1255,staging-use2-eks,identity,Normal,Scheduled,Successfully assigned auth-gateway-c975434-e6ef9 to ip-10-14-70-252,Pod,auth-gateway-c975434-e6ef9,controllermanager,2026-05-29 14:54:26,2026-05-29 16:22:26,1,2026-06-23 12:00:00
1256,prod-usw2-eks,kube-system,Warning,Unhealthy,Readiness probe errored: dial tcp i/o timeout for coredns-37f1521-4cd3d,Pod,coredns-37f1521-4cd3d,controllermanager,2026-06-18 00:21:24,2026-06-18 01:46:24,12,2026-06-23 12:00:00
1257,prod-use2-eks,orders,Warning,Evicted,Pod orders-api-bfb2f93-32ad3 evicted: node memory pressure,Pod,orders-api-bfb2f93-32ad3,kubelet,2026-06-19 21:06:51,2026-06-19 22:11:51,12,2026-06-23 12:00:00
1258,prod-usw2-eks,ledger,Warning,FreeDiskSpaceFailed,Failed to garbage collect on node ip-10-6-194-142,Pod,ledger-svc-842cd31-95bfa,default-scheduler,2026-06-16 02:26:09,2026-06-16 03:36:09,29,2026-06-23 12:00:00
1259,staging-use2-eks,identity,Normal,Scheduled,Successfully assigned auth-gateway-41b4f33-14ef9 to ip-10-14-70-252,Pod,auth-gateway-41b4f33-14ef9,default-scheduler,2026-06-06 00:16:47,2026-06-06 00:37:47,1,2026-06-23 12:00:00
1260,prod-use2-eks,payments,Normal,Pulled,Container image pulled for payments-worker,Pod,payments-worker-6e38c94-75bbf,default-scheduler,2026-06-16 06:39:19,2026-06-16 08:13:19,1,2026-06-23 12:00:00
1261,prod-usw2-eks,platform,Normal,Scheduled,Successfully assigned image-resizer-9683178-b7560 to ip-10-6-194-142,Pod,image-resizer-9683178-b7560,controllermanager,2026-06-01 20:33:40,2026-06-01 20:41:40,1,2026-06-23 12:00:00
1262,prod-usw2-eks,inventory,Normal,Pulled,Container image pulled for inventory-svc,Pod,inventory-svc-4453f63-e15f3,kubelet,2026-06-03 11:55:11,2026-06-03 13:39:11,1,2026-06-23 12:00:00
1263,prod-usw2-eks,kube-system,Warning,NodeNotReady,Node ip-10-6-194-142 status is now: NodeNotReady,Pod,metrics-server-6162d13-d4a14,default-scheduler,2026-06-17 11:56:55,2026-06-17 12:28:55,11,2026-06-23 12:00:00
1264,staging-use2-eks,checkout,Warning,NodeNotReady,Node ip-10-14-70-252 status is now: NodeNotReady,Pod,checkout-web-aca9086-f5fe6,controllermanager,2026-06-23 07:25:55,2026-06-23 07:54:55,16,2026-06-23 12:00:00
1265,prod-use2-eks,platform,Warning,DNSConfigForming,Search line limits exceeded for image-resizer-7bb3c89-50e74,Pod,image-resizer-7bb3c89-50e74,default-scheduler,2026-06-20 04:45:54,2026-06-20 06:07:54,15,2026-06-23 12:00:00
1266,prod-use2-eks,checkout,Warning,OOMKilling,Container cart-svc exceeded memory limit; OOMKilled,Pod,cart-svc-26a7d77-aafdc,default-scheduler,2026-06-19 01:07:31,2026-06-19 01:26:31,38,2026-06-23 12:00:00
1267,prod-usw2-eks,identity,Warning,FreeDiskSpaceFailed,Failed to garbage collect on node ip-10-14-16-161,Pod,session-store-28ebc77-cf7c8,kubelet,2026-06-16 12:18:03,2026-06-16 12:46:03,2,2026-06-23 12:00:00
1268,prod-usw2-eks,orders,Warning,FreeDiskSpaceFailed,Failed to garbage collect on node ip-10-14-16-161,Pod,orders-worker-8482791-f2d9f,default-scheduler,2026-06-21 08:28:01,2026-06-21 09:39:01,7,2026-06-23 12:00:00
1269,prod-use2-eks,notifications,Warning,Unhealthy,Readiness probe failed: timeout for notifications-1938743-28dca,Pod,notifications-1938743-28dca,controllermanager,2026-06-14 08:29:39,2026-06-14 09:09:39,3,2026-06-23 12:00:00
1270,prod-use2-eks,kube-system,Warning,Evicted,Pod coredns-47d4438-c55d7 evicted: node was low on resource ephemeral-storage,Pod,coredns-47d4438-c55d7,controllermanager,2026-06-18 23:57:07,2026-06-19 01:02:07,18,2026-06-23 12:00:00
1271,prod-usw2-eks,checkout,Warning,Evicted,Pod cart-svc-0a94879-c1bba evicted: node was low on resource ephemeral-storage,Pod,cart-svc-0a94879-c1bba,default-scheduler,2026-06-08 05:22:28,2026-06-08 05:37:28,2,2026-06-23 12:00:00
1272,dr-use1-eks,search,Warning,Evicted,Pod search-api-d416b43-7cb20 evicted: node was low on resource ephemeral-storage,Pod,search-api-d416b43-7cb20,kubelet,2026-06-09 14:51:24,2026-06-09 14:58:24,11,2026-06-23 12:00:00
1273,prod-usw2-eks,orders,Warning,OOMKilling,Memory cgroup out of memory: Killed process in orders-api-21c5d48-15186,Pod,orders-api-21c5d48-15186,controllermanager,2026-06-16 22:55:20,2026-06-17 00:23:20,31,2026-06-23 12:00:00
1274,prod-use2-eks,identity,Normal,Started,Started container auth-gateway,Pod,auth-gateway-bf1d422-2018d,kubelet,2026-05-26 15:38:24,2026-05-26 16:40:24,1,2026-06-23 12:00:00
1275,staging-use2-eks,platform,Warning,Evicted,Pod config-svc-929cd33-16be4 evicted: node was low on resource ephemeral-storage,Pod,config-svc-929cd33-16be4,default-scheduler,2026-06-09 05:15:52,2026-06-09 06:05:52,17,2026-06-23 12:00:00
1276,dr-use1-eks,orders,Warning,DNSConfigForming,Search line limits exceeded for orders-api-8330e48-f22f4,Pod,orders-api-8330e48-f22f4,default-scheduler,2026-06-22 00:33:45,2026-06-22 01:15:45,34,2026-06-23 12:00:00
1277,prod-usw2-eks,orders,Warning,BackOff,Back-off restarting failed container orders-api in pod orders-api-402bb51-ad48f,Pod,orders-api-402bb51-ad48f,controllermanager,2026-06-18 16:52:39,2026-06-18 17:40:39,18,2026-06-23 12:00:00
1278,dr-use1-eks,checkout,Warning,OOMKilling,Container checkout-web exceeded memory limit; OOMKilled,Pod,checkout-web-6e9e217-a5c79,default-scheduler,2026-06-20 16:16:55,2026-06-20 17:04:55,15,2026-06-23 12:00:00
1279,staging-use2-eks,search,Warning,DNSConfigForming,Search line limits exceeded for search-api-1605640-8abaf,Pod,search-api-1605640-8abaf,default-scheduler,2026-06-23 05:57:36,2026-06-23 06:10:36,31,2026-06-23 12:00:00
1280,prod-usw2-eks,search,Warning,Evicted,Pod search-api-a47d446-4ffe2 evicted: node was low on resource ephemeral-storage,Pod,search-api-a47d446-4ffe2,default-scheduler,2026-06-18 11:25:30,2026-06-18 12:31:30,13,2026-06-23 12:00:00
1281,prod-usw2-eks,orders,Warning,Evicted,Pod orders-worker-b907131-2627d evicted: node was low on resource ephemeral-storage,Pod,orders-worker-b907131-2627d,controllermanager,2026-06-19 15:36:34,2026-06-19 17:02:34,9,2026-06-23 12:00:00
1282,prod-usw2-eks,checkout,Warning,FreeDiskSpaceFailed,Failed to garbage collect on node ip-10-6-194-142,Pod,cart-svc-ee38458-64d46,controllermanager,2026-05-31 15:38:49,2026-05-31 16:09:49,14,2026-06-23 12:00:00
1283,prod-use2-eks,identity,Warning,Evicted,Pod session-store-1ac5266-1ca26 evicted: node memory pressure,Pod,session-store-1ac5266-1ca26,controllermanager,2026-06-08 14:44:18,2026-06-08 16:23:18,26,2026-06-23 12:00:00
1284,prod-usw2-eks,orders,Warning,OOMKilling,Memory cgroup out of memory: Killed process in orders-api-21c5d48-15186,Pod,orders-api-21c5d48-15186,default-scheduler,2026-06-17 17:35:42,2026-06-17 18:46:42,28,2026-06-23 12:00:00
1285,prod-usw2-eks,search,Warning,Evicted,Pod search-api-a47d446-4ffe2 evicted: node was low on resource ephemeral-storage,Pod,search-api-a47d446-4ffe2,default-scheduler,2026-06-14 21:18:58,2026-06-14 21:43:58,7,2026-06-23 12:00:00
1286,prod-usw2-eks,orders,Warning,Evicted,Pod orders-worker-8482791-f2d9f evicted: node was low on resource ephemeral-storage,Pod,orders-worker-8482791-f2d9f,default-scheduler,2026-06-20 06:34:09,2026-06-20 08:20:09,10,2026-06-23 12:00:00
1287,prod-use2-eks,orders,Warning,OOMKilling,Container orders-api exceeded memory limit; OOMKilled,Pod,orders-api-bfb2f93-32ad3,default-scheduler,2026-06-12 07:10:17,2026-06-12 09:03:17,32,2026-06-23 12:00:00
1288,prod-usw2-eks,checkout,Normal,Started,Started container checkout-web,Pod,checkout-web-f628153-c1833,controllermanager,2026-05-31 09:37:37,2026-05-31 10:05:37,1,2026-06-23 12:00:00
1289,dr-use1-eks,checkout,Normal,Started,Started container cart-svc,Pod,cart-svc-da3cf51-00806,default-scheduler,2026-06-16 09:16:06,2026-06-16 09:46:06,1,2026-06-23 12:00:00
1290,prod-use2-eks,identity,Warning,Evicted,Pod session-store-4732511-0dba8 evicted: node memory pressure,Pod,session-store-4732511-0dba8,default-scheduler,2026-06-08 23:18:31,2026-06-08 23:42:31,35,2026-06-23 12:00:00
1291,staging-use2-eks,identity,Normal,Started,Started container auth-gateway,Pod,auth-gateway-c975434-e6ef9,kubelet,2026-06-18 14:24:40,2026-06-18 15:01:40,1,2026-06-23 12:00:00
1292,prod-use2-eks,payments,Warning,OOMKilling,Container payments-api exceeded memory limit; OOMKilled,Pod,payments-api-c9c2b74-00142,controllermanager,2026-06-22 13:21:22,2026-06-22 14:23:22,40,2026-06-23 12:00:00
1293,prod-use2-eks,platform,Warning,DNSConfigForming,Search line limits exceeded for image-resizer-9994630-7c707,Pod,image-resizer-9994630-7c707,controllermanager,2026-06-23 10:11:35,2026-06-23 11:13:35,18,2026-06-23 12:00:00
1294,staging-use2-eks,payments,Normal,Started,Started container payments-api,Pod,payments-api-dde4d16-a3d09,default-scheduler,2026-06-09 19:54:31,2026-06-09 19:58:31,1,2026-06-23 12:00:00
1295,prod-usw2-eks,inventory,Normal,Started,Started container inventory-svc,Pod,inventory-svc-0d33458-c137f,default-scheduler,2026-05-29 06:35:46,2026-05-29 07:33:46,1,2026-06-23 12:00:00
1296,prod-usw2-eks,search,Warning,FreeDiskSpaceFailed,Failed to garbage collect on node ip-10-14-16-161,Pod,search-api-a47d446-4ffe2,default-scheduler,2026-06-16 12:16:10,2026-06-16 13:29:10,25,2026-06-23 12:00:00
1297,prod-usw2-eks,payments,Warning,BackOff,Back-off restarting failed container payments-worker in pod payments-worker-bbc0947-0aa1a,Pod,payments-worker-bbc0947-0aa1a,kubelet,2026-06-13 07:50:38,2026-06-13 09:14:38,7,2026-06-23 12:00:00
1298,prod-usw2-eks,ledger,Warning,FreeDiskSpaceFailed,Failed to garbage collect on node ip-10-14-16-161,Pod,ledger-svc-2014124-29b88,kubelet,2026-06-15 02:13:18,2026-06-15 04:09:18,31,2026-06-23 12:00:00
1299,prod-usw2-eks,identity,Warning,Evicted,Pod session-store-d825e25-14f9f evicted: node was low on resource ephemeral-storage,Pod,session-store-d825e25-14f9f,controllermanager,2026-06-21 10:31:13,2026-06-21 10:33:13,34,2026-06-23 12:00:00
1300,prod-use2-eks,identity,Normal,Started,Started container auth-gateway,Pod,auth-gateway-7b28269-a7447,default-scheduler,2026-06-13 17:35:18,2026-06-13 18:29:18,1,2026-06-23 12:00:00
1301,prod-use2-eks,ledger,Warning,Unhealthy,Readiness probe failed: timeout for ledger-svc-f4a6d64-16dde,Pod,ledger-svc-f4a6d64-16dde,kubelet,2026-06-17 02:35:14,2026-06-17 04:29:14,11,2026-06-23 12:00:00
1302,prod-usw2-eks,checkout,Warning,FreeDiskSpaceFailed,Failed to garbage collect on node ip-10-29-63-193,Pod,cart-svc-0a94879-c1bba,controllermanager,2026-06-15 17:38:16,2026-06-15 19:10:16,5,2026-06-23 12:00:00
1303,dr-use1-eks,search,Warning,Evicted,Pod search-api-be84964-d972c evicted: node was low on resource ephemeral-storage,Pod,search-api-be84964-d972c,default-scheduler,2026-06-07 13:15:07,2026-06-07 13:38:07,33,2026-06-23 12:00:00
1304,prod-use2-eks,checkout,Warning,OOMKilling,Memory cgroup out of memory: Killed process in checkout-web-c343d41-6a8d2,Pod,checkout-web-c343d41-6a8d2,kubelet,2026-06-17 17:30:34,2026-06-17 18:03:34,8,2026-06-23 12:00:00
1305,prod-use2-eks,kube-system,Warning,FreeDiskSpaceFailed,Failed to garbage collect on node ip-10-6-44-216,Pod,coredns-47d4438-c55d7,default-scheduler,2026-06-23 10:33:48,2026-06-23 12:32:48,27,2026-06-23 12:00:00
1306,dr-use1-eks,checkout,Warning,OOMKilling,Container checkout-web exceeded memory limit; OOMKilled,Pod,checkout-web-6e9e217-a5c79,controllermanager,2026-06-20 09:18:14,2026-06-20 09:38:14,31,2026-06-23 12:00:00
1307,prod-use2-eks,orders,Warning,OOMKilling,Container orders-api exceeded memory limit; OOMKilled,Pod,orders-api-bfb2f93-32ad3,kubelet,2026-06-20 19:24:34,2026-06-20 19:45:34,38,2026-06-23 12:00:00
1308,prod-usw2-eks,kube-system,Warning,Rebooted,Node ip-10-6-194-142 has been rebooted,Pod,metrics-server-6162d13-d4a14,default-scheduler,2026-06-22 15:58:44,2026-06-22 17:11:44,11,2026-06-23 12:00:00
1309,prod-usw2-eks,search,Warning,Evicted,Pod search-api-15a6d76-12766 evicted: node was low on resource ephemeral-storage,Pod,search-api-15a6d76-12766,kubelet,2026-06-19 08:53:00,2026-06-19 10:14:00,26,2026-06-23 12:00:00
1310,prod-use2-eks,orders,Warning,Evicted,Pod orders-api-e9b4a39-c3784 evicted: node memory pressure,Pod,orders-api-e9b4a39-c3784,default-scheduler,2026-06-18 00:55:54,2026-06-18 02:47:54,36,2026-06-23 12:00:00
1311,prod-usw2-eks,orders,Warning,Evicted,Pod orders-worker-b907131-2627d evicted: node was low on resource ephemeral-storage,Pod,orders-worker-b907131-2627d,kubelet,2026-06-17 21:28:31,2026-06-17 22:26:31,18,2026-06-23 12:00:00
1312,prod-use2-eks,checkout,Warning,OOMKilling,Container cart-svc exceeded memory limit; OOMKilled,Pod,cart-svc-51c2594-4d271,controllermanager,2026-06-18 07:31:29,2026-06-18 08:22:29,24,2026-06-23 12:00:00
1313,prod-use2-eks,payments,Warning,Evicted,Pod payments-api-c9c2b74-00142 evicted: node memory pressure,Pod,payments-api-c9c2b74-00142,controllermanager,2026-06-23 07:35:20,2026-06-23 09:21:20,28,2026-06-23 12:00:00
1314,prod-usw2-eks,search,Warning,Evicted,Pod search-api-15a6d76-12766 evicted: node was low on resource ephemeral-storage,Pod,search-api-15a6d76-12766,kubelet,2026-06-15 11:33:32,2026-06-15 11:33:32,20,2026-06-23 12:00:00
1315,prod-usw2-eks,platform,Normal,Pulled,Container image pulled for config-svc,Pod,config-svc-d193d56-68bd9,default-scheduler,2026-05-25 14:04:14,2026-05-25 14:51:14,1,2026-06-23 12:00:00
1316,prod-use2-eks,checkout,Warning,BackOff,Back-off restarting failed container checkout-web in pod checkout-web-0101b48-2b2af,Pod,checkout-web-0101b48-2b2af,kubelet,2026-06-17 23:57:32,2026-06-18 01:30:32,8,2026-06-23 12:00:00
1317,dr-use1-eks,notifications,Warning,BackOff,Back-off restarting failed container notifications in pod notifications-b036879-82982,Pod,notifications-b036879-82982,default-scheduler,2026-06-22 11:27:38,2026-06-22 11:47:38,39,2026-06-23 12:00:00
1318,prod-usw2-eks,orders,Warning,Evicted,Pod orders-worker-8482791-f2d9f evicted: node was low on resource ephemeral-storage,Pod,orders-worker-8482791-f2d9f,controllermanager,2026-06-18 13:55:40,2026-06-18 15:19:40,36,2026-06-23 12:00:00
1319,prod-usw2-eks,kube-system,Warning,DNSConfigForming,Search line limits exceeded for coredns-37f1521-4cd3d,Pod,coredns-37f1521-4cd3d,controllermanager,2026-06-17 23:55:42,2026-06-18 00:29:42,14,2026-06-23 12:00:00
1320,prod-usw2-eks,inventory,Normal,Started,Started container inventory-svc,Pod,inventory-svc-0d33458-c137f,controllermanager,2026-06-09 23:32:36,2026-06-10 00:48:36,1,2026-06-23 12:00:00
1321,staging-use2-eks,payments,Warning,FreeDiskSpaceFailed,Failed to garbage collect on node ip-10-20-108-255,Pod,payments-api-2729261-453da,default-scheduler,2026-06-01 12:28:08,2026-06-01 13:56:08,39,2026-06-23 12:00:00
1322,prod-usw2-eks,payments,Normal,Pulled,Container image pulled for payments-api,Pod,payments-api-6c2b997-3e07d,default-scheduler,2026-06-13 13:28:44,2026-06-13 14:03:44,1,2026-06-23 12:00:00
1323,dr-use1-eks,checkout,Warning,Evicted,Pod checkout-web-6e9e217-a5c79 evicted: node memory pressure,Pod,checkout-web-6e9e217-a5c79,controllermanager,2026-06-21 00:19:42,2026-06-21 01:48:42,30,2026-06-23 12:00:00
1324,prod-usw2-eks,checkout,Warning,Evicted,Pod cart-svc-0a94879-c1bba evicted: node was low on resource ephemeral-storage,Pod,cart-svc-0a94879-c1bba,kubelet,2026-06-22 11:04:06,2026-06-22 13:00:06,31,2026-06-23 12:00:00
1325,prod-usw2-eks,search,Normal,Pulled,Container image pulled for recommendation,Pod,recommendation-87e3198-026ea,controllermanager,2026-05-30 03:00:36,2026-05-30 04:35:36,1,2026-06-23 12:00:00
1326,prod-use2-eks,kube-system,Warning,Evicted,Pod coredns-e513a45-fb7bf evicted: node was low on resource ephemeral-storage,Pod,coredns-e513a45-fb7bf,default-scheduler,2026-06-19 18:27:34,2026-06-19 18:42:34,32,2026-06-23 12:00:00
1327,prod-use2-eks,checkout,Warning,Evicted,Pod cart-svc-26a7d77-aafdc evicted: node memory pressure,Pod,cart-svc-26a7d77-aafdc,default-scheduler,2026-06-12 11:54:45,2026-06-12 12:31:45,7,2026-06-23 12:00:00
1328,prod-usw2-eks,ledger,Warning,Evicted,Pod ledger-svc-2014124-29b88 evicted: node was low on resource ephemeral-storage,Pod,ledger-svc-2014124-29b88,default-scheduler,2026-06-17 02:51:50,2026-06-17 03:39:50,11,2026-06-23 12:00:00
1329,prod-use2-eks,payments,Warning,OOMKilling,Container payments-api exceeded memory limit; OOMKilled,Pod,payments-api-7fa4649-debd8,kubelet,2026-06-22 18:32:02,2026-06-22 19:24:02,13,2026-06-23 12:00:00
1330,staging-use2-eks,platform,Warning,FreeDiskSpaceFailed,Failed to garbage collect on node ip-10-8-126-134,Pod,config-svc-929cd33-16be4,default-scheduler,2026-06-15 14:59:49,2026-06-15 16:38:49,10,2026-06-23 12:00:00
1331,prod-usw2-eks,payments,Warning,BackOff,Back-off restarting failed container payments-worker in pod payments-worker-bbc0947-0aa1a,Pod,payments-worker-bbc0947-0aa1a,controllermanager,2026-06-23 06:07:44,2026-06-23 07:37:44,29,2026-06-23 12:00:00
1332,prod-usw2-eks,orders,Warning,BackOff,Back-off restarting failed container orders-api in pod orders-api-cbca488-26609,Pod,orders-api-cbca488-26609,controllermanager,2026-06-18 08:05:20,2026-06-18 08:46:20,14,2026-06-23 12:00:00
1333,staging-use2-eks,payments,Normal,Pulled,Container image pulled for payments-api,Pod,payments-api-dde4d16-a3d09,controllermanager,2026-06-03 02:20:24,2026-06-03 03:18:24,1,2026-06-23 12:00:00
1334,prod-usw2-eks,platform,Normal,Started,Started container image-resizer,Pod,image-resizer-6542c92-1100b,controllermanager,2026-06-21 00:04:38,2026-06-21 00:41:38,1,2026-06-23 12:00:00
1335,prod-usw2-eks,search,Warning,Evicted,Pod search-api-15a6d76-12766 evicted: node was low on resource ephemeral-storage,Pod,search-api-15a6d76-12766,default-scheduler,2026-06-17 20:36:10,2026-06-17 21:26:10,27,2026-06-23 12:00:00
1336,staging-use2-eks,payments,Warning,Evicted,Pod payments-api-2729261-453da evicted: node was low on resource ephemeral-storage,Pod,payments-api-2729261-453da,kubelet,2026-06-19 17:30:58,2026-06-19 17:48:58,29,2026-06-23 12:00:00
1337,prod-use2-eks,platform,Warning,Unhealthy,Readiness probe errored: dial tcp i/o timeout for image-resizer-9994630-7c707,Pod,image-resizer-9994630-7c707,controllermanager,2026-06-23 07:54:16,2026-06-23 08:23:16,26,2026-06-23 12:00:00
1338,prod-use2-eks,platform,Normal,Throttling,CPU throttled for container config-svc,Pod,config-svc-027a395-39a4d,default-scheduler,2026-06-23 11:20:15,2026-06-23 13:13:15,1,2026-06-23 12:00:00
1339,prod-use2-eks,kube-system,Warning,FreeDiskSpaceFailed,Failed to garbage collect on node ip-10-6-44-216,Pod,coredns-47d4438-c55d7,default-scheduler,2026-06-06 04:39:50,2026-06-06 06:22:50,19,2026-06-23 12:00:00
1340,dr-use1-eks,search,Warning,NodeNotReady,Node ip-10-21-57-150 status is now: NodeNotReady,Pod,indexer-6af7422-f66fc,controllermanager,2026-06-23 00:02:47,2026-06-23 00:28:47,3,2026-06-23 12:00:00
1341,prod-use2-eks,payments,Warning,Evicted,Pod payments-api-c9c2b74-00142 evicted: node memory pressure,Pod,payments-api-c9c2b74-00142,default-scheduler,2026-06-23 04:25:39,2026-06-23 05:55:39,7,2026-06-23 12:00:00
1342,prod-use2-eks,kube-system,Warning,Evicted,Pod coredns-e513a45-fb7bf evicted: node was low on resource ephemeral-storage,Pod,coredns-e513a45-fb7bf,default-scheduler,2026-06-17 08:04:05,2026-06-17 10:00:05,12,2026-06-23 12:00:00
1343,prod-use2-eks,checkout,Warning,OOMKilling,Container cart-svc exceeded memory limit; OOMKilled,Pod,cart-svc-26a7d77-aafdc,kubelet,2026-06-20 05:01:44,2026-06-20 05:12:44,31,2026-06-23 12:00:00
1344,prod-use2-eks,checkout,Warning,Unhealthy,Liveness probe failed: HTTP 500 for checkout-web-0101b48-2b2af,Pod,checkout-web-0101b48-2b2af,default-scheduler,2026-05-31 11:34:41,2026-05-31 12:30:41,28,2026-06-23 12:00:00
1345,dr-use1-eks,notifications,Warning,OOMKilling,Memory cgroup out of memory: Killed process in notifications-b036879-82982,Pod,notifications-b036879-82982,default-scheduler,2026-06-22 04:28:43,2026-06-22 04:57:43,1,2026-06-23 12:00:00
1346,prod-use2-eks,checkout,Warning,OOMKilling,Memory cgroup out of memory: Killed process in checkout-web-c343d41-6a8d2,Pod,checkout-web-c343d41-6a8d2,controllermanager,2026-06-02 22:51:03,2026-06-03 00:41:03,8,2026-06-23 12:00:00
1347,prod-usw2-eks,search,Warning,FreeDiskSpaceFailed,Failed to garbage collect on node ip-10-14-16-161,Pod,search-api-8352074-5b766,controllermanager,2026-06-14 22:25:54,2026-06-14 22:46:54,15,2026-06-23 12:00:00
1348,prod-usw2-eks,orders,Warning,FreeDiskSpaceFailed,Failed to garbage collect on node ip-10-14-16-161,Pod,orders-worker-b907131-2627d,controllermanager,2026-06-22 23:35:47,2026-06-23 01:00:47,30,2026-06-23 12:00:00
1349,prod-usw2-eks,search,Warning,Evicted,Pod search-api-15a6d76-12766 evicted: node was low on resource ephemeral-storage,Pod,search-api-15a6d76-12766,kubelet,2026-06-15 03:19:00,2026-06-15 04:01:00,34,2026-06-23 12:00:00
1350,prod-use2-eks,checkout,Warning,BackOff,Back-off restarting failed container checkout-web in pod checkout-web-c343d41-6a8d2,Pod,checkout-web-c343d41-6a8d2,controllermanager,2026-06-04 13:55:16,2026-06-04 15:31:16,29,2026-06-23 12:00:00
1351,prod-usw2-eks,checkout,Warning,FreeDiskSpaceFailed,Failed to garbage collect on node ip-10-6-194-142,Pod,cart-svc-882ca58-64a75,default-scheduler,2026-06-07 08:27:20,2026-06-07 08:44:20,22,2026-06-23 12:00:00
1352,prod-use2-eks,platform,Warning,Unhealthy,Readiness probe failed: timeout for config-svc-027a395-39a4d,Pod,config-svc-027a395-39a4d,controllermanager,2026-06-17 09:37:24,2026-06-17 10:21:24,1,2026-06-23 12:00:00
1353,dr-use1-eks,notifications,Warning,OOMKilling,Memory cgroup out of memory: Killed process in notifications-b036879-82982,Pod,notifications-b036879-82982,controllermanager,2026-06-21 16:11:36,2026-06-21 16:58:36,11,2026-06-23 12:00:00
1354,prod-usw2-eks,payments,Warning,Evicted,Pod payments-api-423b015-b80bd evicted: node memory pressure,Pod,payments-api-423b015-b80bd,default-scheduler,2026-06-20 12:32:55,2026-06-20 12:43:55,18,2026-06-23 12:00:00
1355,prod-use2-eks,search,Normal,Pulled,Container image pulled for indexer,Pod,indexer-b07f520-eaf04,controllermanager,2026-06-21 08:26:17,2026-06-21 09:40:17,1,2026-06-23 12:00:00
1356,dr-use1-eks,checkout,Warning,Evicted,Pod checkout-web-4263246-52f3a evicted: node memory pressure,Pod,checkout-web-4263246-52f3a,controllermanager,2026-06-21 18:11:32,2026-06-21 19:01:32,21,2026-06-23 12:00:00
1357,staging-use2-eks,payments,Warning,FreeDiskSpaceFailed,Failed to garbage collect on node ip-10-20-108-255,Pod,payments-api-2729261-453da,kubelet,2026-06-04 18:54:21,2026-06-04 18:58:21,28,2026-06-23 12:00:00
1358,prod-use2-eks,search,Normal,Pulled,Container image pulled for indexer,Pod,indexer-4680271-0a829,kubelet,2026-06-13 11:10:07,2026-06-13 11:56:07,1,2026-06-23 12:00:00
1359,staging-use2-eks,identity,Warning,DNSConfigForming,Search line limits exceeded for session-store-a097c68-649a1,Pod,session-store-a097c68-649a1,kubelet,2026-06-17 18:08:15,2026-06-17 19:58:15,24,2026-06-23 12:00:00
1360,prod-usw2-eks,orders,Warning,Unhealthy,Liveness probe failed: HTTP 500 for orders-api-21c5d48-15186,Pod,orders-api-21c5d48-15186,kubelet,2026-06-16 14:25:22,2026-06-16 14:33:22,22,2026-06-23 12:00:00
1361,prod-use2-eks,checkout,Warning,OOMKilling,Memory cgroup out of memory: Killed process in checkout-web-c343d41-6a8d2,Pod,checkout-web-c343d41-6a8d2,default-scheduler,2026-06-18 16:33:45,2026-06-18 18:16:45,18,2026-06-23 12:00:00
1362,prod-usw2-eks,orders,Warning,Evicted,Pod orders-worker-8482791-f2d9f evicted: node was low on resource ephemeral-storage,Pod,orders-worker-8482791-f2d9f,default-scheduler,2026-06-21 12:32:57,2026-06-21 13:26:57,40,2026-06-23 12:00:00
1363,prod-use2-eks,identity,Warning,OOMKilling,Container session-store exceeded memory limit; OOMKilled,Pod,session-store-1ac5266-1ca26,kubelet,2026-06-22 13:24:31,2026-06-22 14:14:31,27,2026-06-23 12:00:00
1364,prod-use2-eks,kube-system,Warning,Unhealthy,Readiness probe errored: dial tcp i/o timeout for metrics-server-e2e6924-29c37,Pod,metrics-server-e2e6924-29c37,default-scheduler,2026-06-10 16:56:25,2026-06-10 17:27:25,28,2026-06-23 12:00:00
1365,prod-use2-eks,identity,Warning,OOMKilling,Container session-store exceeded memory limit; OOMKilled,Pod,session-store-4732511-0dba8,default-scheduler,2026-06-21 04:16:16,2026-06-21 04:21:16,17,2026-06-23 12:00:00
1366,prod-usw2-eks,orders,Warning,Evicted,Pod orders-worker-b907131-2627d evicted: node was low on resource ephemeral-storage,Pod,orders-worker-b907131-2627d,kubelet,2026-06-23 09:09:53,2026-06-23 09:43:53,1,2026-06-23 12:00:00
1367,prod-use2-eks,orders,Warning,OOMKilling,Container orders-api exceeded memory limit; OOMKilled,Pod,orders-api-e9b4a39-c3784,kubelet,2026-06-16 10:31:39,2026-06-16 11:49:39,29,2026-06-23 12:00:00
1368,prod-use2-eks,ledger,Warning,Unhealthy,Readiness probe failed: timeout for ledger-svc-f4a6d64-16dde,Pod,ledger-svc-f4a6d64-16dde,controllermanager,2026-06-22 00:15:22,2026-06-22 02:07:22,36,2026-06-23 12:00:00
1369,prod-use2-eks,ledger,Warning,Unhealthy,Readiness probe failed: timeout for ledger-svc-204e643-7d23b,Pod,ledger-svc-204e643-7d23b,controllermanager,2026-06-19 20:27:17,2026-06-19 21:52:17,20,2026-06-23 12:00:00
1370,staging-use2-eks,payments,Warning,Evicted,Pod payments-api-2729261-453da evicted: node was low on resource ephemeral-storage,Pod,payments-api-2729261-453da,controllermanager,2026-06-18 18:27:25,2026-06-18 18:41:25,26,2026-06-23 12:00:00
1371,dr-use1-eks,search,Warning,Evicted,Pod search-api-be84964-d972c evicted: node was low on resource ephemeral-storage,Pod,search-api-be84964-d972c,controllermanager,2026-05-28 16:34:51,2026-05-28 18:23:51,1,2026-06-23 12:00:00
1372,prod-usw2-eks,identity,Normal,Started,Started container auth-gateway,Pod,auth-gateway-d4d3364-aac01,controllermanager,2026-06-17 16:37:42,2026-06-17 18:28:42,1,2026-06-23 12:00:00
1373,staging-use2-eks,platform,Warning,Evicted,Pod config-svc-929cd33-16be4 evicted: node was low on resource ephemeral-storage,Pod,config-svc-929cd33-16be4,kubelet,2026-06-16 19:50:11,2026-06-16 20:14:11,18,2026-06-23 12:00:00
1374,prod-usw2-eks,platform,Normal,Scheduled,Successfully assigned image-resizer-9683178-b7560 to ip-10-6-194-142,Pod,image-resizer-9683178-b7560,kubelet,2026-06-03 16:44:22,2026-06-03 17:54:22,1,2026-06-23 12:00:00
1375,prod-use2-eks,identity,Warning,OOMKilling,Container session-store exceeded memory limit; OOMKilled,Pod,session-store-1ac5266-1ca26,default-scheduler,2026-06-13 11:30:23,2026-06-13 12:52:23,15,2026-06-23 12:00:00
1376,staging-use2-eks,checkout,Warning,Rebooted,Node ip-10-14-70-252 has been rebooted,Pod,checkout-web-aca9086-f5fe6,controllermanager,2026-06-23 07:54:27,2026-06-23 07:58:27,38,2026-06-23 12:00:00
1377,dr-use1-eks,checkout,Warning,OOMKilling,Container checkout-web exceeded memory limit; OOMKilled,Pod,checkout-web-4263246-52f3a,kubelet,2026-06-22 09:01:19,2026-06-22 09:53:19,5,2026-06-23 12:00:00
1378,prod-usw2-eks,search,Warning,FreeDiskSpaceFailed,Failed to garbage collect on node ip-10-14-16-161,Pod,search-api-8352074-5b766,controllermanager,2026-06-17 02:22:21,2026-06-17 02:31:21,9,2026-06-23 12:00:00
1379,dr-use1-eks,checkout,Normal,Pulled,Container image pulled for cart-svc,Pod,cart-svc-da3cf51-00806,default-scheduler,2026-06-20 16:07:00,2026-06-20 17:53:00,1,2026-06-23 12:00:00
1380,prod-use2-eks,ledger,Warning,Unhealthy,Readiness probe failed: timeout for ledger-svc-204e643-7d23b,Pod,ledger-svc-204e643-7d23b,controllermanager,2026-06-20 05:41:20,2026-06-20 07:08:20,10,2026-06-23 12:00:00
1381,prod-use2-eks,kube-system,Warning,Evicted,Pod coredns-e513a45-fb7bf evicted: node was low on resource ephemeral-storage,Pod,coredns-e513a45-fb7bf,kubelet,2026-06-12 11:00:13,2026-06-12 11:58:13,11,2026-06-23 12:00:00
1382,prod-use2-eks,ledger,Normal,Throttling,CPU throttled for container ledger-svc,Pod,ledger-svc-f4a6d64-16dde,controllermanager,2026-06-20 18:12:57,2026-06-20 19:44:57,1,2026-06-23 12:00:00
1383,prod-use2-eks,orders,Warning,OOMKilling,Container orders-api exceeded memory limit; OOMKilled,Pod,orders-api-e9b4a39-c3784,kubelet,2026-06-13 03:41:03,2026-06-13 03:41:03,38,2026-06-23 12:00:00
1384,prod-use2-eks,orders,Normal,Started,Started container orders-worker,Pod,orders-worker-9681c18-374c7,controllermanager,2026-06-18 19:16:07,2026-06-18 20:11:07,1,2026-06-23 12:00:00
1385,dr-use1-eks,platform,Normal,Started,Started container config-svc,Pod,config-svc-0f5b883-4b9e2,controllermanager,2026-06-04 02:50:42,2026-06-04 04:45:42,1,2026-06-23 12:00:00
1386,prod-usw2-eks,kube-system,Warning,Rebooted,Node ip-10-6-194-142 has been rebooted,Pod,metrics-server-6162d13-d4a14,controllermanager,2026-06-17 17:42:24,2026-06-17 19:02:24,32,2026-06-23 12:00:00
1387,prod-use2-eks,payments,Warning,Evicted,Pod payments-api-1ce3577-591ac evicted: node memory pressure,Pod,payments-api-1ce3577-591ac,default-scheduler,2026-06-23 11:30:17,2026-06-23 13:18:17,40,2026-06-23 12:00:00
1388,prod-use2-eks,checkout,Warning,Unhealthy,Liveness probe failed: HTTP 500 for checkout-web-c2eb578-2d181,Pod,checkout-web-c2eb578-2d181,default-scheduler,2026-06-13 00:24:34,2026-06-13 01:47:34,26,2026-06-23 12:00:00
1389,prod-use2-eks,checkout,Warning,Evicted,Pod cart-svc-527eb80-045c0 evicted: node memory pressure,Pod,cart-svc-527eb80-045c0,kubelet,2026-06-12 21:49:14,2026-06-12 23:41:14,25,2026-06-23 12:00:00
1390,dr-use1-eks,search,Warning,FreeDiskSpaceFailed,Failed to garbage collect on node ip-10-40-81-216,Pod,search-api-be84964-d972c,kubelet,2026-06-02 10:05:51,2026-06-02 11:53:51,9,2026-06-23 12:00:00
1391,prod-usw2-eks,orders,Warning,Evicted,Pod orders-worker-8482791-f2d9f evicted: node was low on resource ephemeral-storage,Pod,orders-worker-8482791-f2d9f,default-scheduler,2026-06-23 11:01:39,2026-06-23 11:50:39,36,2026-06-23 12:00:00
1392,dr-use1-eks,search,Warning,Evicted,Pod search-api-d416b43-7cb20 evicted: node was low on resource ephemeral-storage,Pod,search-api-d416b43-7cb20,controllermanager,2026-06-08 05:30:04,2026-06-08 07:20:04,14,2026-06-23 12:00:00
1393,staging-use2-eks,checkout,Warning,Rebooted,Node ip-10-14-70-252 has been rebooted,Pod,checkout-web-aca9086-f5fe6,controllermanager,2026-06-23 00:59:40,2026-06-23 01:49:40,21,2026-06-23 12:00:00
1394,prod-usw2-eks,kube-system,Warning,Unhealthy,Readiness probe errored: dial tcp i/o timeout for coredns-4a8b365-1d9fc,Pod,coredns-4a8b365-1d9fc,kubelet,2026-06-21 11:16:25,2026-06-21 12:29:25,33,2026-06-23 12:00:00
1395,dr-use1-eks,search,Warning,NodeNotReady,Node ip-10-21-57-150 status is now: NodeNotReady,Pod,indexer-6af7422-f66fc,default-scheduler,2026-06-10 19:28:48,2026-06-10 20:49:48,24,2026-06-23 12:00:00
1396,prod-use2-eks,ledger,Warning,Unhealthy,Readiness probe failed: timeout for ledger-svc-f4a6d64-16dde,Pod,ledger-svc-f4a6d64-16dde,controllermanager,2026-06-21 08:33:39,2026-06-21 09:40:39,31,2026-06-23 12:00:00
1397,prod-usw2-eks,search,Normal,Started,Started container search-api,Pod,search-api-db28570-d359e,kubelet,2026-06-13 21:01:08,2026-06-13 21:02:08,1,2026-06-23 12:00:00
1398,prod-usw2-eks,payments,Warning,Evicted,Pod payments-api-1e23165-1e35b evicted: node memory pressure,Pod,payments-api-1e23165-1e35b,kubelet,2026-06-06 19:43:58,2026-06-06 20:30:58,13,2026-06-23 12:00:00
1399,prod-usw2-eks,search,Warning,FreeDiskSpaceFailed,Failed to garbage collect on node ip-10-14-16-161,Pod,search-api-a47d446-4ffe2,default-scheduler,2026-06-21 09:54:25,2026-06-21 11:22:25,30,2026-06-23 12:00:00
1400,prod-use2-eks,checkout,Warning,OOMKilling,Memory cgroup out of memory: Killed process in checkout-web-c2eb578-2d181,Pod,checkout-web-c2eb578-2d181,kubelet,2026-06-12 06:18:59,2026-06-12 07:18:59,6,2026-06-23 12:00:00
1401,dr-use1-eks,inventory,Normal,Pulled,Container image pulled for inventory-svc,Pod,inventory-svc-4ccbe67-9cbde,kubelet,2026-05-28 04:23:29,2026-05-28 05:41:29,1,2026-06-23 12:00:00
1402,prod-usw2-eks,ledger,Warning,FreeDiskSpaceFailed,Failed to garbage collect on node ip-10-6-194-142,Pod,ledger-svc-0744083-43011,controllermanager,2026-06-23 04:50:11,2026-06-23 06:35:11,31,2026-06-23 12:00:00
1403,dr-use1-eks,checkout,Warning,OOMKilling,Container checkout-web exceeded memory limit; OOMKilled,Pod,checkout-web-6e9e217-a5c79,controllermanager,2026-06-19 06:05:30,2026-06-19 06:07:30,9,2026-06-23 12:00:00
1404,prod-usw2-eks,orders,Warning,OOMKilling,Memory cgroup out of memory: Killed process in orders-api-402bb51-ad48f,Pod,orders-api-402bb51-ad48f,default-scheduler,2026-06-15 00:54:47,2026-06-15 01:10:47,2,2026-06-23 12:00:00
1405,prod-use2-eks,kube-system,Warning,Unhealthy,Readiness probe errored: dial tcp i/o timeout for metrics-server-e2e6924-29c37,Pod,metrics-server-e2e6924-29c37,controllermanager,2026-06-07 04:49:25,2026-06-07 06:26:25,25,2026-06-23 12:00:00
1406,prod-use2-eks,ledger,Normal,Throttling,CPU throttled for container ledger-svc,Pod,ledger-svc-f4a6d64-16dde,default-scheduler,2026-06-18 08:55:46,2026-06-18 10:20:46,1,2026-06-23 12:00:00
1407,prod-use2-eks,orders,Normal,Started,Started container orders-worker,Pod,orders-worker-06e2683-7270e,kubelet,2026-06-01 22:56:58,2026-06-02 00:15:58,1,2026-06-23 12:00:00
1408,prod-usw2-eks,kube-system,Warning,Unhealthy,Readiness probe errored: dial tcp i/o timeout for coredns-4a8b365-1d9fc,Pod,coredns-4a8b365-1d9fc,controllermanager,2026-06-18 04:59:14,2026-06-18 06:28:14,16,2026-06-23 12:00:00
1409,prod-usw2-eks,identity,Warning,FreeDiskSpaceFailed,Failed to garbage collect on node ip-10-14-16-161,Pod,session-store-28ebc77-cf7c8,default-scheduler,2026-06-19 04:32:27,2026-06-19 06:21:27,28,2026-06-23 12:00:00
1410,prod-use2-eks,payments,Warning,Evicted,Pod payments-api-7fa4649-debd8 evicted: node memory pressure,Pod,payments-api-7fa4649-debd8,controllermanager,2026-06-22 21:42:39,2026-06-22 22:14:39,32,2026-06-23 12:00:00
1411,prod-usw2-eks,checkout,Warning,Evicted,Pod cart-svc-882ca58-64a75 evicted: node was low on resource ephemeral-storage,Pod,cart-svc-882ca58-64a75,kubelet,2026-06-17 18:53:40,2026-06-17 20:17:40,7,2026-06-23 12:00:00
1412,prod-use2-eks,platform,Warning,Unhealthy,Readiness probe errored: dial tcp i/o timeout for image-resizer-7bb3c89-50e74,Pod,image-resizer-7bb3c89-50e74,default-scheduler,2026-06-21 22:41:01,2026-06-21 23:12:01,33,2026-06-23 12:00:00
1413,staging-use2-eks,platform,Warning,Evicted,Pod config-svc-929cd33-16be4 evicted: node was low on resource ephemeral-storage,Pod,config-svc-929cd33-16be4,controllermanager,2026-06-14 14:04:27,2026-06-14 15:13:27,6,2026-06-23 12:00:00
1414,prod-usw2-eks,ledger,Warning,FreeDiskSpaceFailed,Failed to garbage collect on node ip-10-6-194-142,Pod,ledger-svc-0744083-43011,controllermanager,2026-06-21 15:51:04,2026-06-21 16:19:04,23,2026-06-23 12:00:00
1415,dr-use1-eks,checkout,Warning,Evicted,Pod checkout-web-6e9e217-a5c79 evicted: node memory pressure,Pod,checkout-web-6e9e217-a5c79,kubelet,2026-06-19 03:50:27,2026-06-19 05:05:27,21,2026-06-23 12:00:00
1416,prod-usw2-eks,checkout,Normal,Scheduled,Successfully assigned checkout-web-f628153-c1833 to ip-10-22-107-136,Pod,checkout-web-f628153-c1833,kubelet,2026-05-28 12:25:52,2026-05-28 13:11:52,1,2026-06-23 12:00:00
1417,prod-usw2-eks,orders,Warning,OOMKilling,Memory cgroup out of memory: Killed process in orders-api-402bb51-ad48f,Pod,orders-api-402bb51-ad48f,default-scheduler,2026-06-18 10:43:30,2026-06-18 11:41:30,12,2026-06-23 12:00:00
1418,prod-usw2-eks,orders,Warning,Unhealthy,Liveness probe failed: HTTP 500 for orders-api-21c5d48-15186,Pod,orders-api-21c5d48-15186,kubelet,2026-06-17 09:59:52,2026-06-17 11:23:52,11,2026-06-23 12:00:00
1419,prod-usw2-eks,orders,Warning,FreeDiskSpaceFailed,Failed to garbage collect on node ip-10-14-16-161,Pod,orders-worker-8482791-f2d9f,default-scheduler,2026-06-18 15:23:44,2026-06-18 16:30:44,7,2026-06-23 12:00:00
1420,prod-use2-eks,payments,Normal,Scheduled,Successfully assigned payments-worker-7a57672-86691 to ip-10-40-57-12,Pod,payments-worker-7a57672-86691,kubelet,2026-06-14 19:54:08,2026-06-14 21:01:08,1,2026-06-23 12:00:00
1421,staging-use2-eks,checkout,Warning,Rebooted,Node ip-10-14-70-252 has been rebooted,Pod,checkout-web-aca9086-f5fe6,default-scheduler,2026-06-23 05:46:27,2026-06-23 06:55:27,35,2026-06-23 12:00:00
1422,staging-use2-eks,payments,Warning,FreeDiskSpaceFailed,Failed to garbage collect on node ip-10-20-108-255,Pod,payments-api-2729261-453da,controllermanager,2026-06-03 01:05:14,2026-06-03 02:46:14,2,2026-06-23 12:00:00
1423,prod-usw2-eks,orders,Warning,OOMKilling,Memory cgroup out of memory: Killed process in orders-api-cbca488-26609,Pod,orders-api-cbca488-26609,controllermanager,2026-06-22 13:57:25,2026-06-22 14:28:25,38,2026-06-23 12:00:00
1424,prod-usw2-eks,identity,Normal,Started,Started container auth-gateway,Pod,auth-gateway-7d2aa28-56f78,default-scheduler,2026-06-02 19:58:22,2026-06-02 20:05:22,1,2026-06-23 12:00:00
1425,prod-usw2-eks,search,Warning,Evicted,Pod search-api-8352074-5b766 evicted: node was low on resource ephemeral-storage,Pod,search-api-8352074-5b766,controllermanager,2026-06-20 00:10:49,2026-06-20 00:53:49,12,2026-06-23 12:00:00
1426,prod-usw2-eks,checkout,Warning,Evicted,Pod cart-svc-882ca58-64a75 evicted: node was low on resource ephemeral-storage,Pod,cart-svc-882ca58-64a75,default-scheduler,2026-06-03 23:47:39,2026-06-04 00:39:39,21,2026-06-23 12:00:00
1427,prod-usw2-eks,payments,Warning,Unhealthy,Liveness probe failed: HTTP 500 for payments-worker-1d1bf52-dff66,Pod,payments-worker-1d1bf52-dff66,controllermanager,2026-06-14 18:35:41,2026-06-14 19:12:41,31,2026-06-23 12:00:00
1428,prod-usw2-eks,payments,Warning,Unhealthy,Liveness probe failed: HTTP 500 for payments-worker-bbc0947-0aa1a,Pod,payments-worker-bbc0947-0aa1a,controllermanager,2026-06-09 05:26:32,2026-06-09 07:03:32,5,2026-06-23 12:00:00
1429,staging-use2-eks,inventory,Warning,Evicted,Pod inventory-svc-1d6f570-1b50d evicted: node memory pressure,Pod,inventory-svc-1d6f570-1b50d,controllermanager,2026-06-15 23:39:43,2026-06-16 01:36:43,27,2026-06-23 12:00:00
1430,prod-use2-eks,checkout,Warning,Unhealthy,Liveness probe failed: HTTP 500 for checkout-web-0101b48-2b2af,Pod,checkout-web-0101b48-2b2af,controllermanager,2026-06-07 01:34:06,2026-06-07 02:15:06,19,2026-06-23 12:00:00
1431,prod-usw2-eks,search,Warning,Evicted,Pod search-api-15a6d76-12766 evicted: node was low on resource ephemeral-storage,Pod,search-api-15a6d76-12766,kubelet,2026-06-20 05:55:59,2026-06-20 07:26:59,5,2026-06-23 12:00:00
1432,prod-usw2-eks,kube-system,Warning,DNSConfigForming,Search line limits exceeded for coredns-37f1521-4cd3d,Pod,coredns-37f1521-4cd3d,controllermanager,2026-06-18 02:54:05,2026-06-18 03:00:05,22,2026-06-23 12:00:00
1433,prod-use2-eks,notifications,Normal,Throttling,CPU throttled for container notifications,Pod,notifications-1938743-28dca,default-scheduler,2026-06-05 22:15:35,2026-06-05 23:28:35,1,2026-06-23 12:00:00
1434,prod-usw2-eks,payments,Warning,OOMKilling,Container payments-api exceeded memory limit; OOMKilled,Pod,payments-api-b9a1287-dbbfe,default-scheduler,2026-06-10 04:05:22,2026-06-10 05:58:22,38,2026-06-23 12:00:00
1435,prod-use2-eks,platform,Warning,DNSConfigForming,Search line limits exceeded for image-resizer-7bb3c89-50e74,Pod,image-resizer-7bb3c89-50e74,kubelet,2026-06-22 09:18:02,2026-06-22 10:48:02,37,2026-06-23 12:00:00
1436,prod-usw2-eks,checkout,Warning,Evicted,Pod cart-svc-ee38458-64d46 evicted: node was low on resource ephemeral-storage,Pod,cart-svc-ee38458-64d46,kubelet,2026-06-19 03:21:57,2026-06-19 03:26:57,9,2026-06-23 12:00:00
1437,prod-usw2-eks,checkout,Warning,Evicted,Pod cart-svc-882ca58-64a75 evicted: node was low on resource ephemeral-storage,Pod,cart-svc-882ca58-64a75,kubelet,2026-06-01 01:50:12,2026-06-01 03:25:12,2,2026-06-23 12:00:00
1438,prod-usw2-eks,identity,Normal,Pulled,Container image pulled for auth-gateway,Pod,auth-gateway-7d2aa28-56f78,controllermanager,2026-06-13 12:49:10,2026-06-13 12:56:10,1,2026-06-23 12:00:00
1439,prod-use2-eks,search,Normal,Scheduled,Successfully assigned recommendation-c460126-52814 to ip-10-37-142-3,Pod,recommendation-c460126-52814,default-scheduler,2026-06-03 03:42:15,2026-06-03 04:57:15,1,2026-06-23 12:00:00
1440,prod-use2-eks,checkout,Warning,OOMKilling,Container cart-svc exceeded memory limit; OOMKilled,Pod,cart-svc-26a7d77-aafdc,default-scheduler,2026-06-18 16:54:20,2026-06-18 17:06:20,26,2026-06-23 12:00:00
1441,staging-use2-eks,inventory,Warning,OOMKilling,Container inventory-svc exceeded memory limit; OOMKilled,Pod,inventory-svc-1d6f570-1b50d,kubelet,2026-06-20 06:44:25,2026-06-20 08:15:25,1,2026-06-23 12:00:00
1442,dr-use1-eks,checkout,Warning,Evicted,Pod checkout-web-4263246-52f3a evicted: node memory pressure,Pod,checkout-web-4263246-52f3a,kubelet,2026-06-21 01:04:16,2026-06-21 01:38:16,31,2026-06-23 12:00:00
1443,prod-use2-eks,search,Normal,Pulled,Container image pulled for search-api,Pod,search-api-eff0684-a368a,controllermanager,2026-06-19 05:37:18,2026-06-19 06:14:18,1,2026-06-23 12:00:00
1444,prod-usw2-eks,kube-system,Warning,DNSConfigForming,Search line limits exceeded for coredns-4a8b365-1d9fc,Pod,coredns-4a8b365-1d9fc,controllermanager,2026-06-19 18:01:15,2026-06-19 18:39:15,9,2026-06-23 12:00:00
1445,prod-use2-eks,checkout,Warning,OOMKilling,Container cart-svc exceeded memory limit; OOMKilled,Pod,cart-svc-26a7d77-aafdc,kubelet,2026-06-22 22:43:45,2026-06-22 23:41:45,23,2026-06-23 12:00:00
1446,prod-usw2-eks,orders,Warning,Evicted,Pod orders-worker-b907131-2627d evicted: node was low on resource ephemeral-storage,Pod,orders-worker-b907131-2627d,kubelet,2026-06-21 23:08:42,2026-06-22 00:31:42,5,2026-06-23 12:00:00
1447,dr-use1-eks,ledger,Normal,Pulled,Container image pulled for ledger-svc,Pod,ledger-svc-e00a046-6e2d6,kubelet,2026-05-30 16:05:01,2026-05-30 16:46:01,1,2026-06-23 12:00:00
1448,prod-usw2-eks,payments,Warning,OOMKilling,Memory cgroup out of memory: Killed process in payments-worker-bbc0947-0aa1a,Pod,payments-worker-bbc0947-0aa1a,controllermanager,2026-06-07 03:57:44,2026-06-07 04:58:44,29,2026-06-23 12:00:00
1449,prod-use2-eks,checkout,Warning,Evicted,Pod cart-svc-51c2594-4d271 evicted: node memory pressure,Pod,cart-svc-51c2594-4d271,default-scheduler,2026-06-22 10:23:04,2026-06-22 12:05:04,9,2026-06-23 12:00:00
1450,prod-use2-eks,kube-system,Warning,FreeDiskSpaceFailed,Failed to garbage collect on node ip-10-6-44-216,Pod,coredns-47d4438-c55d7,controllermanager,2026-06-11 02:33:58,2026-06-11 02:41:58,14,2026-06-23 12:00:00
1451,prod-usw2-eks,search,Normal,Started,Started container recommendation,Pod,recommendation-1e52697-e4756,controllermanager,2026-06-11 05:00:29,2026-06-11 05:11:29,1,2026-06-23 12:00:00
1452,prod-usw2-eks,orders,Warning,FreeDiskSpaceFailed,Failed to garbage collect on node ip-10-14-16-161,Pod,orders-worker-8482791-f2d9f,controllermanager,2026-06-17 23:22:56,2026-06-17 23:25:56,12,2026-06-23 12:00:00
1453,prod-usw2-eks,payments,Warning,OOMKilling,Container payments-api exceeded memory limit; OOMKilled,Pod,payments-api-423b015-b80bd,controllermanager,2026-06-21 21:26:54,2026-06-21 21:30:54,37,2026-06-23 12:00:00
1454,prod-use2-eks,ledger,Normal,Throttling,CPU throttled for container ledger-svc,Pod,ledger-svc-204e643-7d23b,controllermanager,2026-06-19 11:50:09,2026-06-19 12:42:09,1,2026-06-23 12:00:00
1455,prod-usw2-eks,orders,Warning,Unhealthy,Liveness probe failed: HTTP 500 for orders-api-402bb51-ad48f,Pod,orders-api-402bb51-ad48f,controllermanager,2026-06-16 19:23:23,2026-06-16 19:34:23,10,2026-06-23 12:00:00
1456,prod-usw2-eks,kube-system,Warning,NodeNotReady,Node ip-10-6-194-142 status is now: NodeNotReady,Pod,metrics-server-6162d13-d4a14,default-scheduler,2026-06-16 18:48:04,2026-06-16 19:37:04,15,2026-06-23 12:00:00
1457,prod-usw2-eks,checkout,Warning,Evicted,Pod cart-svc-0a94879-c1bba evicted: node was low on resource ephemeral-storage,Pod,cart-svc-0a94879-c1bba,kubelet,2026-06-18 12:14:18,2026-06-18 12:33:18,4,2026-06-23 12:00:00
1458,prod-use2-eks,inventory,Normal,Pulled,Container image pulled for inventory-svc,Pod,inventory-svc-bfded25-1e6d2,controllermanager,2026-06-21 09:46:09,2026-06-21 10:33:09,1,2026-06-23 12:00:00
1459,dr-use1-eks,orders,Warning,DNSConfigForming,Search line limits exceeded for orders-api-8330e48-f22f4,Pod,orders-api-8330e48-f22f4,controllermanager,2026-06-11 17:47:09,2026-06-11 19:21:09,29,2026-06-23 12:00:00
1460,prod-usw2-eks,orders,Warning,BackOff,Back-off restarting failed container orders-api in pod orders-api-402bb51-ad48f,Pod,orders-api-402bb51-ad48f,default-scheduler,2026-06-17 05:49:21,2026-06-17 07:00:21,1,2026-06-23 12:00:00
1461,prod-usw2-eks,kube-system,Warning,Unhealthy,Readiness probe errored: dial tcp i/o timeout for coredns-37f1521-4cd3d,Pod,coredns-37f1521-4cd3d,controllermanager,2026-06-21 07:06:53,2026-06-21 08:34:53,12,2026-06-23 12:00:00
1462,prod-usw2-eks,inventory,Normal,Pulled,Container image pulled for inventory-svc,Pod,inventory-svc-4453f63-e15f3,default-scheduler,2026-06-18 13:15:58,2026-06-18 13:49:58,1,2026-06-23 12:00:00
1463,prod-usw2-eks,payments,Warning,OOMKilling,Container payments-api exceeded memory limit; OOMKilled,Pod,payments-api-423b015-b80bd,kubelet,2026-06-01 12:03:36,2026-06-01 12:36:36,25,2026-06-23 12:00:00
1464,prod-usw2-eks,checkout,Warning,Evicted,Pod cart-svc-ee38458-64d46 evicted: node was low on resource ephemeral-storage,Pod,cart-svc-ee38458-64d46,kubelet,2026-06-15 14:36:37,2026-06-15 16:14:37,16,2026-06-23 12:00:00
1465,prod-use2-eks,checkout,Warning,OOMKilling,Memory cgroup out of memory: Killed process in checkout-web-c343d41-6a8d2,Pod,checkout-web-c343d41-6a8d2,default-scheduler,2026-06-07 06:21:04,2026-06-07 06:49:04,20,2026-06-23 12:00:00
1466,prod-usw2-eks,kube-system,Warning,NodeNotReady,Node ip-10-6-194-142 status is now: NodeNotReady,Pod,metrics-server-6162d13-d4a14,controllermanager,2026-06-19 13:21:43,2026-06-19 14:38:43,5,2026-06-23 12:00:00
1467,prod-usw2-eks,payments,Warning,Evicted,Pod payments-api-b9a1287-dbbfe evicted: node memory pressure,Pod,payments-api-b9a1287-dbbfe,kubelet,2026-06-02 10:14:04,2026-06-02 11:37:04,2,2026-06-23 12:00:00
1468,prod-usw2-eks,payments,Warning,OOMKilling,Container payments-api exceeded memory limit; OOMKilled,Pod,payments-api-1e23165-1e35b,kubelet,2026-06-15 17:09:34,2026-06-15 17:54:34,8,2026-06-23 12:00:00
1469,prod-usw2-eks,payments,Warning,Evicted,Pod payments-api-1e23165-1e35b evicted: node memory pressure,Pod,payments-api-1e23165-1e35b,default-scheduler,2026-05-29 01:59:56,2026-05-29 03:50:56,33,2026-06-23 12:00:00
1470,dr-use1-eks,checkout,Warning,OOMKilling,Container checkout-web exceeded memory limit; OOMKilled,Pod,checkout-web-4263246-52f3a,kubelet,2026-06-22 20:20:33,2026-06-22 20:31:33,33,2026-06-23 12:00:00
1471,prod-usw2-eks,checkout,Warning,FreeDiskSpaceFailed,Failed to garbage collect on node ip-10-29-63-193,Pod,cart-svc-0a94879-c1bba,controllermanager,2026-06-18 02:36:13,2026-06-18 04:09:13,13,2026-06-23 12:00:00
1472,prod-usw2-eks,checkout,Warning,Evicted,Pod cart-svc-ee38458-64d46 evicted: node was low on resource ephemeral-storage,Pod,cart-svc-ee38458-64d46,kubelet,2026-06-14 10:00:37,2026-06-14 11:01:37,24,2026-06-23 12:00:00
1473,dr-use1-eks,orders,Warning,Unhealthy,Readiness probe errored: dial tcp i/o timeout for orders-api-8330e48-f22f4,Pod,orders-api-8330e48-f22f4,default-scheduler,2026-06-19 09:47:22,2026-06-19 11:01:22,39,2026-06-23 12:00:00
1474,prod-usw2-eks,payments,Warning,Evicted,Pod payments-api-b9a1287-dbbfe evicted: node memory pressure,Pod,payments-api-b9a1287-dbbfe,default-scheduler,2026-06-08 23:24:11,2026-06-09 00:10:11,4,2026-06-23 12:00:00
1475,prod-usw2-eks,inventory,Normal,Started,Started container inventory-svc,Pod,inventory-svc-0d33458-c137f,kubelet,2026-06-15 23:48:41,2026-06-16 00:48:41,1,2026-06-23 12:00:00
1476,prod-use2-eks,search,Normal,Started,Started container indexer,Pod,indexer-4680271-0a829,controllermanager,2026-06-11 03:13:37,2026-06-11 04:02:37,1,2026-06-23 12:00:00
1477,prod-usw2-eks,search,Warning,Evicted,Pod search-api-a47d446-4ffe2 evicted: node was low on resource ephemeral-storage,Pod,search-api-a47d446-4ffe2,kubelet,2026-06-16 01:59:29,2026-06-16 03:44:29,36,2026-06-23 12:00:00
1478,prod-use2-eks,payments,Warning,OOMKilling,Container payments-api exceeded memory limit; OOMKilled,Pod,payments-api-58c5e74-26d34,kubelet,2026-06-23 03:30:59,2026-06-23 03:57:59,37,2026-06-23 12:00:00
1479,staging-use2-eks,checkout,Warning,NodeNotReady,Node ip-10-14-70-252 status is now: NodeNotReady,Pod,checkout-web-aca9086-f5fe6,default-scheduler,2026-06-22 18:59:53,2026-06-22 20:04:53,9,2026-06-23 12:00:00
1480,prod-usw2-eks,orders,Warning,OOMKilling,Memory cgroup out of memory: Killed process in orders-api-21c5d48-15186,Pod,orders-api-21c5d48-15186,kubelet,2026-06-18 04:01:38,2026-06-18 04:32:38,11,2026-06-23 12:00:00
1481,prod-usw2-eks,identity,Warning,FreeDiskSpaceFailed,Failed to garbage collect on node ip-10-12-35-23,Pod,session-store-d825e25-14f9f,default-scheduler,2026-05-29 21:48:39,2026-05-29 21:58:39,32,2026-06-23 12:00:00
1482,prod-usw2-eks,kube-system,Warning,Unhealthy,Readiness probe errored: dial tcp i/o timeout for coredns-37f1521-4cd3d,Pod,coredns-37f1521-4cd3d,controllermanager,2026-06-20 10:03:39,2026-06-20 11:23:39,12,2026-06-23 12:00:00
1483,prod-use2-eks,orders,Warning,Evicted,Pod orders-api-bfb2f93-32ad3 evicted: node memory pressure,Pod,orders-api-bfb2f93-32ad3,default-scheduler,2026-06-20 01:19:21,2026-06-20 02:14:21,6,2026-06-23 12:00:00
1484,dr-use1-eks,search,Warning,FreeDiskSpaceFailed,Failed to garbage collect on node ip-10-40-81-216,Pod,search-api-d416b43-7cb20,kubelet,2026-06-06 05:16:02,2026-06-06 05:35:02,39,2026-06-23 12:00:00
1485,prod-use2-eks,kube-system,Warning,FreeDiskSpaceFailed,Failed to garbage collect on node ip-10-32-13-101,Pod,coredns-e513a45-fb7bf,default-scheduler,2026-06-21 08:34:57,2026-06-21 09:45:57,35,2026-06-23 12:00:00
1486,prod-use2-eks,payments,Warning,Evicted,Pod payments-api-c9c2b74-00142 evicted: node memory pressure,Pod,payments-api-c9c2b74-00142,kubelet,2026-06-22 16:05:50,2026-06-22 17:15:50,10,2026-06-23 12:00:00
1487,prod-usw2-eks,ledger,Warning,Evicted,Pod ledger-svc-0744083-43011 evicted: node was low on resource ephemeral-storage,Pod,ledger-svc-0744083-43011,kubelet,2026-06-20 03:15:34,2026-06-20 04:00:34,15,2026-06-23 12:00:00
1488,prod-usw2-eks,identity,Warning,FreeDiskSpaceFailed,Failed to garbage collect on node ip-10-12-35-23,Pod,session-store-d825e25-14f9f,kubelet,2026-06-10 22:03:46,2026-06-10 22:50:46,32,2026-06-23 12:00:00
1489,prod-use2-eks,checkout,Warning,Evicted,Pod cart-svc-26a7d77-aafdc evicted: node memory pressure,Pod,cart-svc-26a7d77-aafdc,controllermanager,2026-06-21 07:49:27,2026-06-21 08:41:27,39,2026-06-23 12:00:00
1490,dr-use1-eks,checkout,Warning,OOMKilling,Container checkout-web exceeded memory limit; OOMKilled,Pod,checkout-web-4263246-52f3a,controllermanager,2026-06-20 12:24:06,2026-06-20 13:27:06,20,2026-06-23 12:00:00
1491,prod-use2-eks,notifications,Normal,Throttling,CPU throttled for container notifications,Pod,notifications-1938743-28dca,default-scheduler,2026-06-08 07:45:34,2026-06-08 09:12:34,1,2026-06-23 12:00:00
1492,prod-usw2-eks,identity,Warning,Evicted,Pod session-store-d825e25-14f9f evicted: node was low on resource ephemeral-storage,Pod,session-store-d825e25-14f9f,kubelet,2026-05-30 15:01:49,2026-05-30 16:11:49,1,2026-06-23 12:00:00
1493,prod-usw2-eks,kube-system,Warning,Unhealthy,Readiness probe errored: dial tcp i/o timeout for coredns-4a8b365-1d9fc,Pod,coredns-4a8b365-1d9fc,controllermanager,2026-06-20 10:03:58,2026-06-20 11:04:58,4,2026-06-23 12:00:00
1494,prod-usw2-eks,platform,Normal,Pulled,Container image pulled for config-svc,Pod,config-svc-370d832-a686a,default-scheduler,2026-06-18 01:33:13,2026-06-18 03:09:13,1,2026-06-23 12:00:00
1495,prod-usw2-eks,ledger,Warning,FreeDiskSpaceFailed,Failed to garbage collect on node ip-10-6-194-142,Pod,ledger-svc-842cd31-95bfa,default-scheduler,2026-06-19 13:46:24,2026-06-19 14:53:24,1,2026-06-23 12:00:00
1496,prod-use2-eks,payments,Warning,Evicted,Pod payments-api-58c5e74-26d34 evicted: node memory pressure,Pod,payments-api-58c5e74-26d34,default-scheduler,2026-06-22 23:18:16,2026-06-22 23:50:16,32,2026-06-23 12:00:00
1497,prod-use2-eks,orders,Warning,OOMKilling,Container orders-api exceeded memory limit; OOMKilled,Pod,orders-api-7f89525-97cdd,default-scheduler,2026-06-14 03:08:37,2026-06-14 03:56:37,36,2026-06-23 12:00:00
1498,prod-usw2-eks,payments,Warning,Evicted,Pod payments-api-1e23165-1e35b evicted: node memory pressure,Pod,payments-api-1e23165-1e35b,kubelet,2026-06-07 00:45:26,2026-06-07 02:44:26,22,2026-06-23 12:00:00
1499,prod-use2-eks,ledger,Normal,Throttling,CPU throttled for container ledger-svc,Pod,ledger-svc-f4a6d64-16dde,controllermanager,2026-06-19 19:42:07,2026-06-19 20:55:07,1,2026-06-23 12:00:00
1500,prod-use2-eks,checkout,Warning,OOMKilling,Container cart-svc exceeded memory limit; OOMKilled,Pod,cart-svc-527eb80-045c0,kubelet,2026-06-22 23:28:34,2026-06-22 23:47:34,37,2026-06-23 12:00:00
1501,dr-use1-eks,search,Warning,FreeDiskSpaceFailed,Failed to garbage collect on node ip-10-40-81-216,Pod,search-api-be84964-d972c,controllermanager,2026-06-21 09:57:21,2026-06-21 10:11:21,11,2026-06-23 12:00:00
1502,prod-use2-eks,orders,Warning,Evicted,Pod orders-api-bfb2f93-32ad3 evicted: node memory pressure,Pod,orders-api-bfb2f93-32ad3,default-scheduler,2026-06-06 13:56:22,2026-06-06 14:33:22,14,2026-06-23 12:00:00
1503,dr-use1-eks,search,Warning,Rebooted,Node ip-10-21-57-150 has been rebooted,Pod,indexer-6af7422-f66fc,kubelet,2026-06-03 14:50:45,2026-06-03 15:31:45,21,2026-06-23 12:00:00
1504,prod-use2-eks,identity,Warning,Evicted,Pod session-store-1ac5266-1ca26 evicted: node memory pressure,Pod,session-store-1ac5266-1ca26,default-scheduler,2026-06-08 11:15:58,2026-06-08 12:15:58,1,2026-06-23 12:00:00
1505,prod-usw2-eks,payments,Warning,BackOff,Back-off restarting failed container payments-worker in pod payments-worker-1d1bf52-dff66,Pod,payments-worker-1d1bf52-dff66,default-scheduler,2026-06-13 17:02:48,2026-06-13 17:22:48,37,2026-06-23 12:00:00
1506,prod-use2-eks,ledger,Normal,Throttling,CPU throttled for container ledger-svc,Pod,ledger-svc-f4a6d64-16dde,default-scheduler,2026-06-23 03:59:42,2026-06-23 04:56:42,1,2026-06-23 12:00:00
1507,prod-usw2-eks,payments,Normal,Pulled,Container image pulled for payments-api,Pod,payments-api-6c2b997-3e07d,controllermanager,2026-05-27 23:52:18,2026-05-28 01:28:18,1,2026-06-23 12:00:00
1508,prod-use2-eks,platform,Warning,Unhealthy,Readiness probe failed: timeout for config-svc-027a395-39a4d,Pod,config-svc-027a395-39a4d,default-scheduler,2026-06-21 00:36:30,2026-06-21 02:12:30,6,2026-06-23 12:00:00
1509,prod-usw2-eks,platform,Normal,Scheduled,Successfully assigned image-resizer-6542c92-1100b to ip-10-15-83-236,Pod,image-resizer-6542c92-1100b,default-scheduler,2026-06-05 03:59:03,2026-06-05 04:25:03,1,2026-06-23 12:00:00
1510,prod-usw2-eks,checkout,Warning,FreeDiskSpaceFailed,Failed to garbage collect on node ip-10-6-194-142,Pod,cart-svc-882ca58-64a75,controllermanager,2026-06-12 13:43:26,2026-06-12 15:18:26,20,2026-06-23 12:00:00
1511,prod-usw2-eks,ledger,Warning,FreeDiskSpaceFailed,Failed to garbage collect on node ip-10-6-194-142,Pod,ledger-svc-842cd31-95bfa,default-scheduler,2026-06-22 16:02:07,2026-06-22 16:16:07,24,2026-06-23 12:00:00
1512,staging-use2-eks,identity,Warning,DNSConfigForming,Search line limits exceeded for session-store-a097c68-649a1,Pod,session-store-a097c68-649a1,controllermanager,2026-06-22 17:33:58,2026-06-22 18:49:58,17,2026-06-23 12:00:00
1513,prod-use2-eks,orders,Warning,Evicted,Pod orders-api-bfb2f93-32ad3 evicted: node memory pressure,Pod,orders-api-bfb2f93-32ad3,default-scheduler,2026-06-10 16:31:01,2026-06-10 16:54:01,37,2026-06-23 12:00:00
1514,prod-use2-eks,checkout,Warning,Evicted,Pod cart-svc-26a7d77-aafdc evicted: node memory pressure,Pod,cart-svc-26a7d77-aafdc,kubelet,2026-06-17 17:31:52,2026-06-17 18:27:52,18,2026-06-23 12:00:00
1515,prod-use2-eks,orders,Warning,OOMKilling,Container orders-api exceeded memory limit; OOMKilled,Pod,orders-api-7f89525-97cdd,controllermanager,2026-06-10 08:01:36,2026-06-10 08:59:36,18,2026-06-23 12:00:00
1516,prod-usw2-eks,payments,Warning,OOMKilling,Container payments-api exceeded memory limit; OOMKilled,Pod,payments-api-1e23165-1e35b,kubelet,2026-06-17 17:17:19,2026-06-17 19:15:19,40,2026-06-23 12:00:00
1517,prod-usw2-eks,search,Warning,FreeDiskSpaceFailed,Failed to garbage collect on node ip-10-14-16-161,Pod,search-api-8352074-5b766,controllermanager,2026-06-16 03:41:41,2026-06-16 05:32:41,32,2026-06-23 12:00:00
1518,staging-use2-eks,platform,Warning,Evicted,Pod config-svc-929cd33-16be4 evicted: node was low on resource ephemeral-storage,Pod,config-svc-929cd33-16be4,controllermanager,2026-06-10 15:37:04,2026-06-10 15:42:04,12,2026-06-23 12:00:00
1519,prod-use2-eks,payments,Warning,OOMKilling,Container payments-api exceeded memory limit; OOMKilled,Pod,payments-api-c9c2b74-00142,default-scheduler,2026-06-22 19:16:47,2026-06-22 19:52:47,1,2026-06-23 12:00:00
1520,prod-use2-eks,identity,Normal,Pulled,Container image pulled for auth-gateway,Pod,auth-gateway-7b28269-a7447,default-scheduler,2026-05-31 09:40:57,2026-05-31 10:50:57,1,2026-06-23 12:00:00
1521,prod-use2-eks,payments,Normal,Pulled,Container image pulled for payments-worker,Pod,payments-worker-7a57672-86691,kubelet,2026-06-15 09:08:13,2026-06-15 10:21:13,1,2026-06-23 12:00:00
1522,prod-use2-eks,ledger,Warning,Unhealthy,Readiness probe failed: timeout for ledger-svc-f4a6d64-16dde,Pod,ledger-svc-f4a6d64-16dde,controllermanager,2026-06-18 19:34:57,2026-06-18 21:08:57,9,2026-06-23 12:00:00
1523,prod-use2-eks,orders,Warning,OOMKilling,Container orders-api exceeded memory limit; OOMKilled,Pod,orders-api-e9b4a39-c3784,kubelet,2026-06-09 18:17:17,2026-06-09 20:17:17,15,2026-06-23 12:00:00
1524,prod-use2-eks,payments,Warning,Evicted,Pod payments-api-7fa4649-debd8 evicted: node memory pressure,Pod,payments-api-7fa4649-debd8,default-scheduler,2026-06-22 19:35:24,2026-06-22 21:27:24,13,2026-06-23 12:00:00
1525,dr-use1-eks,orders,Warning,DNSConfigForming,Search line limits exceeded for orders-api-8330e48-f22f4,Pod,orders-api-8330e48-f22f4,default-scheduler,2026-06-16 17:46:46,2026-06-16 19:45:46,31,2026-06-23 12:00:00
1526,prod-usw2-eks,search,Warning,Evicted,Pod search-api-15a6d76-12766 evicted: node was low on resource ephemeral-storage,Pod,search-api-15a6d76-12766,controllermanager,2026-06-18 18:34:34,2026-06-18 18:57:34,11,2026-06-23 12:00:00
1527,prod-use2-eks,identity,Warning,Evicted,Pod session-store-1ac5266-1ca26 evicted: node memory pressure,Pod,session-store-1ac5266-1ca26,default-scheduler,2026-06-22 05:30:56,2026-06-22 06:41:56,34,2026-06-23 12:00:00
1528,prod-usw2-eks,checkout,Warning,FreeDiskSpaceFailed,Failed to garbage collect on node ip-10-6-194-142,Pod,cart-svc-ee38458-64d46,controllermanager,2026-06-15 01:44:10,2026-06-15 03:34:10,33,2026-06-23 12:00:00
1529,staging-use2-eks,search,Warning,DNSConfigForming,Search line limits exceeded for search-api-1605640-8abaf,Pod,search-api-1605640-8abaf,default-scheduler,2026-06-23 11:21:35,2026-06-23 11:52:35,30,2026-06-23 12:00:00
1530,dr-use1-eks,checkout,Warning,Evicted,Pod checkout-web-6e9e217-a5c79 evicted: node memory pressure,Pod,checkout-web-6e9e217-a5c79,controllermanager,2026-06-20 17:52:55,2026-06-20 19:36:55,38,2026-06-23 12:00:00
1531,prod-use2-eks,notifications,Normal,Throttling,CPU throttled for container notifications,Pod,notifications-1938743-28dca,default-scheduler,2026-06-20 01:08:56,2026-06-20 01:11:56,1,2026-06-23 12:00:00
1532,prod-usw2-eks,checkout,Warning,FreeDiskSpaceFailed,Failed to garbage collect on node ip-10-29-63-193,Pod,cart-svc-0a94879-c1bba,default-scheduler,2026-06-12 02:18:12,2026-06-12 02:19:12,21,2026-06-23 12:00:00
1533,prod-usw2-eks,kube-system,Warning,NodeNotReady,Node ip-10-6-194-142 status is now: NodeNotReady,Pod,metrics-server-6162d13-d4a14,default-scheduler,2026-06-20 12:45:10,2026-06-20 13:31:10,19,2026-06-23 12:00:00
1534,prod-usw2-eks,payments,Warning,Unhealthy,Liveness probe failed: HTTP 500 for payments-worker-bbc0947-0aa1a,Pod,payments-worker-bbc0947-0aa1a,kubelet,2026-06-01 02:28:06,2026-06-01 04:28:06,26,2026-06-23 12:00:00
1535,dr-use1-eks,notifications,Warning,Unhealthy,Liveness probe failed: HTTP 500 for notifications-b036879-82982,Pod,notifications-b036879-82982,controllermanager,2026-06-23 11:32:24,2026-06-23 11:42:24,2,2026-06-23 12:00:00
1536,prod-usw2-eks,orders,Warning,Unhealthy,Liveness probe failed: HTTP 500 for orders-api-cbca488-26609,Pod,orders-api-cbca488-26609,controllermanager,2026-06-16 10:11:39,2026-06-16 10:29:39,12,2026-06-23 12:00:00
1537,prod-use2-eks,checkout,Warning,OOMKilling,Memory cgroup out of memory: Killed process in checkout-web-0101b48-2b2af,Pod,checkout-web-0101b48-2b2af,default-scheduler,2026-06-11 17:24:14,2026-06-11 18:13:14,23,2026-06-23 12:00:00
1538,prod-use2-eks,platform,Warning,DNSConfigForming,Search line limits exceeded for image-resizer-7bb3c89-50e74,Pod,image-resizer-7bb3c89-50e74,default-scheduler,2026-06-22 08:36:51,2026-06-22 09:39:51,23,2026-06-23 12:00:00
1539,prod-usw2-eks,orders,Warning,OOMKilling,Memory cgroup out of memory: Killed process in orders-api-402bb51-ad48f,Pod,orders-api-402bb51-ad48f,controllermanager,2026-06-17 05:40:14,2026-06-17 07:27:14,38,2026-06-23 12:00:00
1540,prod-usw2-eks,kube-system,Warning,DNSConfigForming,Search line limits exceeded for coredns-4a8b365-1d9fc,Pod,coredns-4a8b365-1d9fc,controllermanager,2026-06-18 01:36:06,2026-06-18 01:47:06,21,2026-06-23 12:00:00
1541,prod-usw2-eks,search,Warning,FreeDiskSpaceFailed,Failed to garbage collect on node ip-10-6-194-142,Pod,search-api-15a6d76-12766,controllermanager,2026-06-19 21:02:45,2026-06-19 22:06:45,33,2026-06-23 12:00:00
1542,prod-usw2-eks,identity,Normal,Pulled,Container image pulled for auth-gateway,Pod,auth-gateway-fb1c283-81cc8,kubelet,2026-06-14 20:31:29,2026-06-14 21:59:29,1,2026-06-23 12:00:00
1543,prod-use2-eks,payments,Warning,Evicted,Pod payments-api-58c5e74-26d34 evicted: node memory pressure,Pod,payments-api-58c5e74-26d34,default-scheduler,2026-06-22 16:07:05,2026-06-22 17:26:05,26,2026-06-23 12:00:00
1544,prod-use2-eks,checkout,Warning,OOMKilling,Memory cgroup out of memory: Killed process in checkout-web-0101b48-2b2af,Pod,checkout-web-0101b48-2b2af,default-scheduler,2026-06-11 20:11:58,2026-06-11 20:15:58,40,2026-06-23 12:00:00
1545,prod-usw2-eks,kube-system,Warning,Unhealthy,Readiness probe errored: dial tcp i/o timeout for coredns-37f1521-4cd3d,Pod,coredns-37f1521-4cd3d,kubelet,2026-06-19 06:25:03,2026-06-19 07:17:03,13,2026-06-23 12:00:00
1546,prod-usw2-eks,payments,Warning,BackOff,Back-off restarting failed container payments-worker in pod payments-worker-bbc0947-0aa1a,Pod,payments-worker-bbc0947-0aa1a,controllermanager,2026-05-30 03:08:40,2026-05-30 03:21:40,9,2026-06-23 12:00:00
1547,prod-usw2-eks,search,Warning,Evicted,Pod search-api-15a6d76-12766 evicted: node was low on resource ephemeral-storage,Pod,search-api-15a6d76-12766,kubelet,2026-06-18 13:56:54,2026-06-18 14:57:54,2,2026-06-23 12:00:00
1548,prod-usw2-eks,orders,Warning,FreeDiskSpaceFailed,Failed to garbage collect on node ip-10-14-16-161,Pod,orders-worker-8482791-f2d9f,controllermanager,2026-06-18 20:47:59,2026-06-18 22:25:59,37,2026-06-23 12:00:00
1549,prod-use2-eks,notifications,Normal,Started,Started container notifications,Pod,notifications-c882a21-88bb7,default-scheduler,2026-06-13 23:13:33,2026-06-13 23:23:33,1,2026-06-23 12:00:00
1550,prod-use2-eks,identity,Normal,Pulled,Container image pulled for auth-gateway,Pod,auth-gateway-bf1d422-2018d,default-scheduler,2026-05-31 17:45:37,2026-05-31 19:13:37,1,2026-06-23 12:00:00
1551,prod-use2-eks,payments,Normal,Started,Started container payments-worker,Pod,payments-worker-7a57672-86691,kubelet,2026-06-04 15:49:29,2026-06-04 15:53:29,1,2026-06-23 12:00:00
1552,prod-use2-eks,ledger,Warning,Unhealthy,Readiness probe failed: timeout for ledger-svc-204e643-7d23b,Pod,ledger-svc-204e643-7d23b,controllermanager,2026-06-23 08:28:45,2026-06-23 10:26:45,28,2026-06-23 12:00:00
1553,prod-usw2-eks,orders,Warning,BackOff,Back-off restarting failed container orders-api in pod orders-api-cbca488-26609,Pod,orders-api-cbca488-26609,default-scheduler,2026-06-16 03:02:36,2026-06-16 03:45:36,26,2026-06-23 12:00:00
1554,prod-use2-eks,payments,Warning,Evicted,Pod payments-api-1ce3577-591ac evicted: node memory pressure,Pod,payments-api-1ce3577-591ac,default-scheduler,2026-06-22 23:00:56,2026-06-23 00:12:56,24,2026-06-23 12:00:00
1555,staging-use2-eks,notifications,Normal,Scheduled,Successfully assigned notifications-26e9347-44fc8 to ip-10-20-108-255,Pod,notifications-26e9347-44fc8,default-scheduler,2026-06-15 13:12:34,2026-06-15 13:49:34,1,2026-06-23 12:00:00
1556,prod-use2-eks,payments,Warning,Evicted,Pod payments-api-58c5e74-26d34 evicted: node memory pressure,Pod,payments-api-58c5e74-26d34,default-scheduler,2026-06-23 10:36:06,2026-06-23 12:31:06,29,2026-06-23 12:00:00
1557,prod-use2-eks,kube-system,Warning,Evicted,Pod coredns-e513a45-fb7bf evicted: node was low on resource ephemeral-storage,Pod,coredns-e513a45-fb7bf,default-scheduler,2026-06-10 13:49:42,2026-06-10 15:17:42,12,2026-06-23 12:00:00
1558,prod-usw2-eks,kube-system,Warning,Unhealthy,Readiness probe errored: dial tcp i/o timeout for coredns-37f1521-4cd3d,Pod,coredns-37f1521-4cd3d,default-scheduler,2026-06-17 03:56:12,2026-06-17 05:39:12,35,2026-06-23 12:00:00
1559,prod-usw2-eks,orders,Warning,BackOff,Back-off restarting failed container orders-api in pod orders-api-21c5d48-15186,Pod,orders-api-21c5d48-15186,controllermanager,2026-06-16 05:45:20,2026-06-16 06:22:20,32,2026-06-23 12:00:00
1560,staging-use2-eks,inventory,Warning,Evicted,Pod inventory-svc-1d6f570-1b50d evicted: node memory pressure,Pod,inventory-svc-1d6f570-1b50d,controllermanager,2026-06-19 22:48:30,2026-06-19 22:50:30,3,2026-06-23 12:00:00
1561,dr-use1-eks,checkout,Warning,OOMKilling,Container checkout-web exceeded memory limit; OOMKilled,Pod,checkout-web-4263246-52f3a,kubelet,2026-06-18 12:31:49,2026-06-18 13:18:49,19,2026-06-23 12:00:00
1562,prod-usw2-eks,orders,Warning,FreeDiskSpaceFailed,Failed to garbage collect on node ip-10-14-16-161,Pod,orders-worker-b907131-2627d,default-scheduler,2026-06-20 23:45:45,2026-06-21 00:33:45,8,2026-06-23 12:00:00
1563,prod-usw2-eks,notifications,Normal,Scheduled,Successfully assigned notifications-abd2926-3451e to ip-10-12-35-23,Pod,notifications-abd2926-3451e,controllermanager,2026-06-06 08:14:52,2026-06-06 09:59:52,1,2026-06-23 12:00:00
1564,prod-use2-eks,platform,Warning,DNSConfigForming,Search line limits exceeded for image-resizer-9994630-7c707,Pod,image-resizer-9994630-7c707,kubelet,2026-06-22 05:12:08,2026-06-22 05:41:08,28,2026-06-23 12:00:00
1565,prod-use2-eks,payments,Warning,Evicted,Pod payments-api-c9c2b74-00142 evicted: node memory pressure,Pod,payments-api-c9c2b74-00142,kubelet,2026-06-22 22:09:59,2026-06-22 22:14:59,23,2026-06-23 12:00:00
1566,staging-use2-eks,checkout,Warning,Rebooted,Node ip-10-8-126-134 has been rebooted,Pod,checkout-web-2b77739-52fdd,kubelet,2026-06-22 21:39:53,2026-06-22 23:01:53,20,2026-06-23 12:00:00
1567,prod-use2-eks,identity,Warning,OOMKilling,Container session-store exceeded memory limit; OOMKilled,Pod,session-store-4732511-0dba8,default-scheduler,2026-06-17 19:58:32,2026-06-17 21:49:32,2,2026-06-23 12:00:00
1568,prod-usw2-eks,inventory,Warning,Unhealthy,Liveness probe failed: HTTP 500 for inventory-svc-bf8f159-02345,Pod,inventory-svc-bf8f159-02345,default-scheduler,2026-05-29 04:53:07,2026-05-29 06:10:07,25,2026-06-23 12:00:00
1569,prod-usw2-eks,inventory,Warning,BackOff,Back-off restarting failed container inventory-svc in pod inventory-svc-bf8f159-02345,Pod,inventory-svc-bf8f159-02345,controllermanager,2026-06-05 22:49:35,2026-06-06 00:18:35,23,2026-06-23 12:00:00
1570,prod-usw2-eks,checkout,Warning,Evicted,Pod cart-svc-882ca58-64a75 evicted: node was low on resource ephemeral-storage,Pod,cart-svc-882ca58-64a75,controllermanager,2026-06-21 16:05:44,2026-06-21 16:55:44,15,2026-06-23 12:00:00
1571,prod-use2-eks,inventory,Normal,Pulled,Container image pulled for inventory-svc,Pod,inventory-svc-df6d343-0a45b,kubelet,2026-06-02 06:52:28,2026-06-02 08:43:28,1,2026-06-23 12:00:00
1572,prod-use2-eks,kube-system,Warning,FreeDiskSpaceFailed,Failed to garbage collect on node ip-10-6-44-216,Pod,coredns-47d4438-c55d7,default-scheduler,2026-06-19 07:32:03,2026-06-19 07:36:03,7,2026-06-23 12:00:00
1573,prod-use2-eks,checkout,Warning,OOMKilling,Container cart-svc exceeded memory limit; OOMKilled,Pod,cart-svc-527eb80-045c0,controllermanager,2026-06-16 07:51:26,2026-06-16 09:16:26,19,2026-06-23 12:00:00
1574,prod-use2-eks,checkout,Warning,Evicted,Pod cart-svc-527eb80-045c0 evicted: node memory pressure,Pod,cart-svc-527eb80-045c0,controllermanager,2026-06-16 21:35:27,2026-06-16 22:52:27,16,2026-06-23 12:00:00
1575,prod-use2-eks,payments,Normal,Started,Started container payments-worker,Pod,payments-worker-6e38c94-75bbf,default-scheduler,2026-05-25 13:06:13,2026-05-25 13:33:13,1,2026-06-23 12:00:00
1576,dr-use1-eks,checkout,Warning,OOMKilling,Container checkout-web exceeded memory limit; OOMKilled,Pod,checkout-web-6e9e217-a5c79,controllermanager,2026-06-19 19:43:23,2026-06-19 21:25:23,36,2026-06-23 12:00:00
1577,prod-usw2-eks,orders,Warning,Unhealthy,Liveness probe failed: HTTP 500 for orders-api-402bb51-ad48f,Pod,orders-api-402bb51-ad48f,kubelet,2026-06-15 19:42:05,2026-06-15 20:20:05,21,2026-06-23 12:00:00
1578,prod-usw2-eks,search,Normal,Pulled,Container image pulled for indexer,Pod,indexer-b957537-8aa20,default-scheduler,2026-05-27 18:49:56,2026-05-27 18:55:56,1,2026-06-23 12:00:00
1579,prod-usw2-eks,orders,Warning,FreeDiskSpaceFailed,Failed to garbage collect on node ip-10-14-16-161,Pod,orders-worker-b907131-2627d,kubelet,2026-06-18 18:50:39,2026-06-18 20:05:39,32,2026-06-23 12:00:00
1580,prod-use2-eks,identity,Warning,Evicted,Pod session-store-1ac5266-1ca26 evicted: node memory pressure,Pod,session-store-1ac5266-1ca26,controllermanager,2026-06-23 00:56:59,2026-06-23 01:09:59,35,2026-06-23 12:00:00
1581,prod-use2-eks,payments,Warning,OOMKilling,Container payments-api exceeded memory limit; OOMKilled,Pod,payments-api-1ce3577-591ac,default-scheduler,2026-06-23 08:29:15,2026-06-23 09:17:15,35,2026-06-23 12:00:00
1582,prod-usw2-eks,ledger,Warning,Evicted,Pod ledger-svc-842cd31-95bfa evicted: node was low on resource ephemeral-storage,Pod,ledger-svc-842cd31-95bfa,kubelet,2026-06-19 15:07:47,2026-06-19 15:19:47,24,2026-06-23 12:00:00
1583,prod-use2-eks,search,Normal,Pulled,Container image pulled for recommendation,Pod,recommendation-e5d5555-c6e9b,default-scheduler,2026-06-21 07:47:08,2026-06-21 08:06:08,1,2026-06-23 12:00:00
1584,prod-use2-eks,checkout,Normal,Scheduled,Successfully assigned checkout-web-47df111-4e24c to ip-10-40-57-12,Pod,checkout-web-47df111-4e24c,default-scheduler,2026-06-02 21:41:24,2026-06-02 22:09:24,1,2026-06-23 12:00:00
1585,prod-use2-eks,identity,Warning,Evicted,Pod session-store-4732511-0dba8 evicted: node memory pressure,Pod,session-store-4732511-0dba8,default-scheduler,2026-06-14 10:33:07,2026-06-14 11:23:07,33,2026-06-23 12:00:00
1586,staging-use2-eks,payments,Warning,Evicted,Pod payments-api-2729261-453da evicted: node was low on resource ephemeral-storage,Pod,payments-api-2729261-453da,default-scheduler,2026-06-18 04:49:44,2026-06-18 06:47:44,38,2026-06-23 12:00:00
1587,prod-usw2-eks,kube-system,Warning,DNSConfigForming,Search line limits exceeded for coredns-37f1521-4cd3d,Pod,coredns-37f1521-4cd3d,kubelet,2026-06-20 04:07:35,2026-06-20 05:18:35,24,2026-06-23 12:00:00
1588,prod-usw2-eks,search,Normal,Started,Started container indexer,Pod,indexer-6c1eb29-ca471,default-scheduler,2026-06-08 16:02:25,2026-06-08 16:17:25,1,2026-06-23 12:00:00
1589,prod-use2-eks,checkout,Warning,OOMKilling,Container cart-svc exceeded memory limit; OOMKilled,Pod,cart-svc-527eb80-045c0,default-scheduler,2026-06-13 11:04:29,2026-06-13 11:16:29,22,2026-06-23 12:00:00
1590,prod-use2-eks,payments,Warning,Evicted,Pod payments-api-1ce3577-591ac evicted: node memory pressure,Pod,payments-api-1ce3577-591ac,default-scheduler,2026-06-22 15:32:30,2026-06-22 17:18:30,6,2026-06-23 12:00:00
1591,prod-use2-eks,ledger,Normal,Throttling,CPU throttled for container ledger-svc,Pod,ledger-svc-204e643-7d23b,default-scheduler,2026-06-17 11:26:18,2026-06-17 12:08:18,1,2026-06-23 12:00:00
1592,prod-use2-eks,checkout,Warning,Evicted,Pod cart-svc-51c2594-4d271 evicted: node memory pressure,Pod,cart-svc-51c2594-4d271,kubelet,2026-06-20 22:05:40,2026-06-20 23:00:40,24,2026-06-23 12:00:00
1593,dr-use1-eks,platform,Normal,Pulled,Container image pulled for config-svc,Pod,config-svc-0f5b883-4b9e2,controllermanager,2026-06-13 23:10:29,2026-06-14 00:44:29,1,2026-06-23 12:00:00
1594,prod-usw2-eks,search,Warning,FreeDiskSpaceFailed,Failed to garbage collect on node ip-10-14-16-161,Pod,search-api-a47d446-4ffe2,controllermanager,2026-06-20 14:58:53,2026-06-20 15:45:53,19,2026-06-23 12:00:00
1595,prod-usw2-eks,notifications,Normal,Started,Started container notifications,Pod,notifications-b2aff41-e1772,kubelet,2026-06-18 16:16:52,2026-06-18 18:02:52,1,2026-06-23 12:00:00
1596,prod-usw2-eks,platform,Normal,Pulled,Container image pulled for config-svc,Pod,config-svc-d193d56-68bd9,default-scheduler,2026-06-10 05:32:51,2026-06-10 06:48:51,1,2026-06-23 12:00:00
1597,staging-use2-eks,checkout,Warning,Rebooted,Node ip-10-8-126-134 has been rebooted,Pod,checkout-web-2b77739-52fdd,kubelet,2026-06-22 17:20:03,2026-06-22 19:03:03,39,2026-06-23 12:00:00
1598,prod-use2-eks,checkout,Warning,Evicted,Pod cart-svc-26a7d77-aafdc evicted: node memory pressure,Pod,cart-svc-26a7d77-aafdc,default-scheduler,2026-06-15 04:36:53,2026-06-15 06:10:53,26,2026-06-23 12:00:00
1599,dr-use1-eks,inventory,Normal,Scheduled,Successfully assigned inventory-svc-4ccbe67-9cbde to ip-10-29-128-5,Pod,inventory-svc-4ccbe67-9cbde,controllermanager,2026-06-18 00:03:41,2026-06-18 00:56:41,1,2026-06-23 12:00:00
1600,staging-use2-eks,identity,Warning,DNSConfigForming,Search line limits exceeded for session-store-a097c68-649a1,Pod,session-store-a097c68-649a1,default-scheduler,2026-06-09 23:22:34,2026-06-10 00:17:34,8,2026-06-23 12:00:00
